Workbook

Sheet Turns
A1: Request | B1: Turn | C1: Sequence | D1: Tokens | E1: EUR / execution | F1: USD / execution | G1: Projected EUR | H1: Projected USD | I1: Content | J1: Model · effort | K1: Status | L1: Context total tokens | M1: Span ID
C2: Run total | E2: =IF(COUNT('Turns'!E16,'Turns'!E31,'Turns'!E44,'Turns'!E59)=4,SUM('Turns'!E16,'Turns'!E31,'Turns'!E44,'Turns'!E59),"Unknown") -> 0.00029355164 | F2: =IF(COUNT('Turns'!F16,'Turns'!F31,'Turns'!F44,'Turns'!F59)=4,SUM('Turns'!F16,'Turns'!F31,'Turns'!F44,'Turns'!F59),"Unknown") -> 0.00033368 | G2: =IF(ISNUMBER(E2),ROUND(E2*'Reference data'!$B$2,0),"Unknown") -> 29 | H2: =IF(ISNUMBER(F2),ROUND(F2*'Reference data'!$B$2,0),"Unknown") -> 33
B3: 1 | C3: Turn 1 | E3: =IF(COUNT('Turns'!E16,'Turns'!E31)=2,SUM('Turns'!E16,'Turns'!E31),"Unknown") -> 0.00014579051 | F3: =IF(COUNT('Turns'!F16,'Turns'!F31)=2,SUM('Turns'!F16,'Turns'!F31),"Unknown") -> 0.00016572 | G3: =IF(ISNUMBER(E3),ROUND(E3*'Reference data'!$B$2,0),"Unknown") -> 15 | H3: =IF(ISNUMBER(F3),ROUND(F3*'Reference data'!$B$2,0),"Unknown") -> 17
A4: R1 | B4: 1 | C4: LLM request | D4: 162 | J4: scripted-chat | M4: 01a1143f-6444-7680-bc85-0a90355e7da8
A5: R1 | B5: 1 | C5: Input at standard rate | D5: 162 | E5: =IF(AND(ISNUMBER(F5),ISNUMBER('Reference data'!$B$3)),F5*'Reference data'!$B$3,"Unknown") -> 2.8503576e-05 | F5: =IF(D5=0,0,IF(ISNUMBER('Reference data'!B22),D5*'Reference data'!B22/1000000,"Unknown")) -> 3.24e-05 | G5: =IF(ISNUMBER(E5),ROUND(E5*'Reference data'!$B$2,0),"Unknown") -> 3 | H5: =IF(ISNUMBER(F5),ROUND(F5*'Reference data'!$B$2,0),"Unknown") -> 3
A6: R1 | B6: 1 | C6: Tool definitions | D6: 79
A7: R1 | B7: 1 | C7: System prompt | D7: 53 | I7: Call echo_tool with the user's text, then answer concisely using the returned echo. The tool repeats input; it provides no independent factual evidence.
A8: R1 | B8: 1 | C8: User prompt | D8: 30 | I8: Echo this text: ReAct
A9: R1 | B9: 1 | C9: Cache write | D9: 162
A10: R1 | B10: 1 | C10: Context · added / total | D10: 162 | L10: 162
A11: R1 | B11: 1 | C11: LLM response | D11: 54
A12: R1 | B12: 1 | C12: Output | D12: 54 | E12: =IF(AND(ISNUMBER(F12),ISNUMBER('Reference data'!$B$3)),F12*'Reference data'!$B$3,"Unknown") -> 5.7007152e-05 | F12: =IF(D12=0,0,IF(ISNUMBER('Reference data'!E22),D12*'Reference data'!E22/1000000,"Unknown")) -> 6.48e-05 | G12: =IF(ISNUMBER(E12),ROUND(E12*'Reference data'!$B$2,0),"Unknown") -> 6 | H12: =IF(ISNUMBER(F12),ROUND(F12*'Reference data'!$B$2,0),"Unknown") -> 6
A13: R1 | B13: 1 | C13: Output content | I13: {"name": "echo_tool", "args": {"text": "ReAct"}, "id": "reference-1", "type": "tool_call"}
A14: R1 | B14: 1 | C14: Cache write | D14: 54
A15: R1 | B15: 1 | C15: Context · added / total | D15: 54 | L15: 216
A16: R1 | B16: 1 | C16: Call total | E16: =IF(COUNT('Turns'!E5,'Turns'!E12)=2,SUM('Turns'!E5,'Turns'!E12),"Unknown") -> 8.5510728e-05 | F16: =IF(COUNT('Turns'!F5,'Turns'!F12)=2,SUM('Turns'!F5,'Turns'!F12),"Unknown") -> 9.72e-05 | G16: =IF(ISNUMBER(E16),ROUND(E16*'Reference data'!$B$2,0),"Unknown") -> 9 | H16: =IF(ISNUMBER(F16),ROUND(F16*'Reference data'!$B$2,0),"Unknown") -> 10 | K16: ok
B17: 1 | C17: Tool · echo_tool | K17: ok | M17: 01a1143f-64c5-7f82-947a-0ca5a458daaa
B18: 1 | C18: Arguments | I18: {'text': 'ReAct'}
B19: 1 | C19: Result | I19: Your input was: ReAct
A20: R2 | B20: 1 | C20: LLM request | D20: 249 | J20: scripted-chat | M20: 01a1143f-64c7-7432-b7e2-cd7cb402eabb
A21: R2 | B21: 1 | C21: Conversation history · cache read | D21: 216 | E21: =IF(AND(ISNUMBER(F21),ISNUMBER('Reference data'!$B$3)),F21*'Reference data'!$B$3,"Unknown") -> 3.8004768e-06 | F21: =IF(D21=0,0,IF(ISNUMBER('Reference data'!C22),D21*'Reference data'!C22/1000000,"Unknown")) -> 4.32e-06 | G21: =IF(ISNUMBER(E21),ROUND(E21*'Reference data'!$B$2,0),"Unknown") -> 0 | H21: =IF(ISNUMBER(F21),ROUND(F21*'Reference data'!$B$2,0),"Unknown") -> 0
A22: R2 | B22: 1 | C22: Input at standard rate | D22: 33 | E22: =IF(AND(ISNUMBER(F22),ISNUMBER('Reference data'!$B$3)),F22*'Reference data'!$B$3,"Unknown") -> 5.806284e-06 | F22: =IF(D22=0,0,IF(ISNUMBER('Reference data'!B22),D22*'Reference data'!B22/1000000,"Unknown")) -> 6.6e-06 | G22: =IF(ISNUMBER(E22),ROUND(E22*'Reference data'!$B$2,0),"Unknown") -> 1 | H22: =IF(ISNUMBER(F22),ROUND(F22*'Reference data'!$B$2,0),"Unknown") -> 1
A23: R2 | B23: 1 | C23: Tool result | D23: 33 | I23: Your input was: ReAct
A24: R2 | B24: 1 | C24: Cache write | D24: 33
A25: R2 | B25: 1 | C25: Context · added / total | D25: 33 | L25: 249
A26: R2 | B26: 1 | C26: LLM response | D26: 48
A27: R2 | B27: 1 | C27: Output | D27: 48 | E27: =IF(AND(ISNUMBER(F27),ISNUMBER('Reference data'!$B$3)),F27*'Reference data'!$B$3,"Unknown") -> 5.0673024e-05 | F27: =IF(D27=0,0,IF(ISNUMBER('Reference data'!E22),D27*'Reference data'!E22/1000000,"Unknown")) -> 5.76e-05 | G27: =IF(ISNUMBER(E27),ROUND(E27*'Reference data'!$B$2,0),"Unknown") -> 5 | H27: =IF(ISNUMBER(F27),ROUND(F27*'Reference data'!$B$2,0),"Unknown") -> 6
A28: R2 | B28: 1 | C28: Output content | I28: The tool returned "Your input was: ReAct". This shows the model requesting a tool and then reading its result.
A29: R2 | B29: 1 | C29: Cache write | D29: 48
A30: R2 | B30: 1 | C30: Context · added / total | D30: 48 | L30: 297
A31: R2 | B31: 1 | C31: Call total | E31: =IF(COUNT('Turns'!E21,'Turns'!E22,'Turns'!E27)=3,SUM('Turns'!E21,'Turns'!E22,'Turns'!E27),"Unknown") -> 6.0279785e-05 | F31: =IF(COUNT('Turns'!F21,'Turns'!F22,'Turns'!F27)=3,SUM('Turns'!F21,'Turns'!F22,'Turns'!F27),"Unknown") -> 6.852e-05 | G31: =IF(ISNUMBER(E31),ROUND(E31*'Reference data'!$B$2,0),"Unknown") -> 6 | H31: =IF(ISNUMBER(F31),ROUND(F31*'Reference data'!$B$2,0),"Unknown") -> 7 | K31: ok
B32: 2 | C32: Turn 2 | E32: =IF(COUNT('Turns'!E44,'Turns'!E59)=2,SUM('Turns'!E44,'Turns'!E59),"Unknown") -> 0.00014776113 | F32: =IF(COUNT('Turns'!F44,'Turns'!F59)=2,SUM('Turns'!F44,'Turns'!F59),"Unknown") -> 0.00016796 | G32: =IF(ISNUMBER(E32),ROUND(E32*'Reference data'!$B$2,0),"Unknown") -> 15 | H32: =IF(ISNUMBER(F32),ROUND(F32*'Reference data'!$B$2,0),"Unknown") -> 17
A33: R3 | B33: 2 | C33: LLM request | D33: 327 | J33: scripted-chat | M33: 01a1143f-64da-79b2-bb70-8cfdd71325cd
A34: R3 | B34: 2 | C34: Conversation history · cache read | D34: 297 | E34: =IF(AND(ISNUMBER(F34),ISNUMBER('Reference data'!$B$3)),F34*'Reference data'!$B$3,"Unknown") -> 5.2256556e-06 | F34: =IF(D34=0,0,IF(ISNUMBER('Reference data'!C22),D34*'Reference data'!C22/1000000,"Unknown")) -> 5.94e-06 | G34: =IF(ISNUMBER(E34),ROUND(E34*'Reference data'!$B$2,0),"Unknown") -> 1 | H34: =IF(ISNUMBER(F34),ROUND(F34*'Reference data'!$B$2,0),"Unknown") -> 1
A35: R3 | B35: 2 | C35: Input at standard rate | D35: 30 | E35: =IF(AND(ISNUMBER(F35),ISNUMBER('Reference data'!$B$3)),F35*'Reference data'!$B$3,"Unknown") -> 5.27844e-06 | F35: =IF(D35=0,0,IF(ISNUMBER('Reference data'!B22),D35*'Reference data'!B22/1000000,"Unknown")) -> 6e-06 | G35: =IF(ISNUMBER(E35),ROUND(E35*'Reference data'!$B$2,0),"Unknown") -> 1 | H35: =IF(ISNUMBER(F35),ROUND(F35*'Reference data'!$B$2,0),"Unknown") -> 1
A36: R3 | B36: 2 | C36: User prompt | D36: 30 | I36: Echo this text: Tool observations
A37: R3 | B37: 2 | C37: Cache write | D37: 30
A38: R3 | B38: 2 | C38: Context · added / total | D38: 30 | L38: 327
A39: R3 | B39: 2 | C39: LLM response | D39: 64
A40: R3 | B40: 2 | C40: Output | D40: 64 | E40: =IF(AND(ISNUMBER(F40),ISNUMBER('Reference data'!$B$3)),F40*'Reference data'!$B$3,"Unknown") -> 6.7564032e-05 | F40: =IF(D40=0,0,IF(ISNUMBER('Reference data'!E22),D40*'Reference data'!E22/1000000,"Unknown")) -> 7.68e-05 | G40: =IF(ISNUMBER(E40),ROUND(E40*'Reference data'!$B$2,0),"Unknown") -> 7 | H40: =IF(ISNUMBER(F40),ROUND(F40*'Reference data'!$B$2,0),"Unknown") -> 8
...

Sheet Execution tree
A1: Operation | B1: Depth | C1: Type | D1: Model · effort | E1: Status | F1: Input context tokens | G1: Description | H1: Span ID | I1: Parent ID | J1: Input at standard rate tokens | K1: Input at standard rate EUR | L1: Input at standard rate USD | M1: Cache read tokens | N1: Cache read EUR | O1: Cache read USD | P1: Cache write tokens | Q1: Cache write EUR | R1: Cache write USD | S1: Output (non-reasoning) tokens | T1: Output (non-reasoning) EUR | U1: Output (non-reasoning) USD | V1: Reasoning tokens | W1: Reasoning EUR | X1: Reasoning USD | Y1: Total EUR | Z1: Total USD | AA1: Projected EUR | AB1: Projected USD | AC1: Request | AD1: Elapsed ms | AE1: Accounting
A2: reference_chat_agent | B2: 0 | C2: workflow | E2: ok | G2: Execute the reference_chat_agent workflow operation and pass its result to the next graph step. | H2: 01a1143f-6441-7a22-a31c-1a1915e9a0ff | J2: =IF(COUNT('Turns'!D5,'Turns'!D22)=2,SUM('Turns'!D5,'Turns'!D22),"Unknown") -> 195 | K2: =IF(COUNT('Turns'!E5,'Turns'!E22)=2,SUM('Turns'!E5,'Turns'!E22),"Unknown") -> 3.430986e-05 | L2: =IF(COUNT('Turns'!F5,'Turns'!F22)=2,SUM('Turns'!F5,'Turns'!F22),"Unknown") -> 3.9e-05 | M2: =IF(COUNT('Turns'!D21)=1,SUM('Turns'!D21),"Unknown") -> 216 | N2: =IF(COUNT('Turns'!E21)=1,SUM('Turns'!E21),"Unknown") -> 3.8004768e-06 | O2: =IF(COUNT('Turns'!F21)=1,SUM('Turns'!F21),"Unknown") -> 4.32e-06 | P2: 0 | Q2: 0 | R2: 0 | S2: =IF(COUNT('Turns'!D12,'Turns'!D27)=2,SUM('Turns'!D12,'Turns'!D27),"Unknown") -> 102 | T2: =IF(COUNT('Turns'!E12,'Turns'!E27)=2,SUM('Turns'!E12,'Turns'!E27),"Unknown") -> 0.00010768018 | U2: =IF(COUNT('Turns'!F12,'Turns'!F27)=2,SUM('Turns'!F12,'Turns'!F27),"Unknown") -> 0.0001224 | V2: 0 | W2: 0 | X2: 0 | Y2: =IF(COUNT('Turns'!E16,'Turns'!E31)=2,SUM('Turns'!E16,'Turns'!E31),"Unknown") -> 0.00014579051 | Z2: =IF(COUNT('Turns'!F16,'Turns'!F31)=2,SUM('Turns'!F16,'Turns'!F31),"Unknown") -> 0.00016572 | AA2: =IF(ISNUMBER(Y2),ROUND(Y2*'Reference data'!$B$2,0),"Unknown") -> 15 | AB2: =IF(ISNUMBER(Z2),ROUND(Z2*'Reference data'!$B$2,0),"Unknown") -> 17 | AD2: 136.06 | AE2: Subtree total
A3: model | B3: 1 | C3: workflow | E3: ok | G3: Prepare the current conversation, run model middleware, and invoke the chat model. | H3: 01a1143f-6443-7f50-b6a4-980bd9cd6c47 | I3: 01a1143f-6441-7a22-a31c-1a1915e9a0ff | J3: =IF(COUNT('Turns'!D5)=1,SUM('Turns'!D5),"Unknown") -> 162 | K3: =IF(COUNT('Turns'!E5)=1,SUM('Turns'!E5),"Unknown") -> 2.8503576e-05 | L3: =IF(COUNT('Turns'!F5)=1,SUM('Turns'!F5),"Unknown") -> 3.24e-05 | M3: 0 | N3: 0 | O3: 0 | P3: 0 | Q3: 0 | R3: 0 | S3: =IF(COUNT('Turns'!D12)=1,SUM('Turns'!D12),"Unknown") -> 54 | T3: =IF(COUNT('Turns'!E12)=1,SUM('Turns'!E12),"Unknown") -> 5.7007152e-05 | U3: =IF(COUNT('Turns'!F12)=1,SUM('Turns'!F12),"Unknown") -> 6.48e-05 | V3: 0 | W3: 0 | X3: 0 | Y3: =IF(COUNT('Turns'!E16)=1,SUM('Turns'!E16),"Unknown") -> 8.5510728e-05 | Z3: =IF(COUNT('Turns'!F16)=1,SUM('Turns'!F16),"Unknown") -> 9.72e-05 | AA3: =IF(ISNUMBER(Y3),ROUND(Y3*'Reference data'!$B$2,0),"Unknown") -> 9 | AB3: =IF(ISNUMBER(Z3),ROUND(Z3*'Reference data'!$B$2,0),"Unknown") -> 10 | AD3: 128.865 | AE3: Subtree total
A4: SimulatedModel | B4: 2 | C4: model | D4: scripted-chat | E4: ok | F4: 162 | G4: Watch an agent echo your input through a tool. | H4: 01a1143f-6444-7680-bc85-0a90355e7da8 | I4: 01a1143f-6443-7f50-b6a4-980bd9cd6c47 | J4: =IF(COUNT('Turns'!D5)=1,SUM('Turns'!D5),"Unknown") -> 162 | K4: =IF(COUNT('Turns'!E5)=1,SUM('Turns'!E5),"Unknown") -> 2.8503576e-05 | L4: =IF(COUNT('Turns'!F5)=1,SUM('Turns'!F5),"Unknown") -> 3.24e-05 | M4: 0 | N4: 0 | O4: 0 | P4: 0 | Q4: 0 | R4: 0 | S4: =IF(COUNT('Turns'!D12)=1,SUM('Turns'!D12),"Unknown") -> 54 | T4: =IF(COUNT('Turns'!E12)=1,SUM('Turns'!E12),"Unknown") -> 5.7007152e-05 | U4: =IF(COUNT('Turns'!F12)=1,SUM('Turns'!F12),"Unknown") -> 6.48e-05 | V4: 0 | W4: 0 | X4: 0 | Y4: =IF(COUNT('Turns'!E16)=1,SUM('Turns'!E16),"Unknown") -> 8.5510728e-05 | Z4: =IF(COUNT('Turns'!F16)=1,SUM('Turns'!F16),"Unknown") -> 9.72e-05 | AA4: =IF(ISNUMBER(Y4),ROUND(Y4*'Reference data'!$B$2,0),"Unknown") -> 9 | AB4: =IF(ISNUMBER(Z4),ROUND(Z4*'Reference data'!$B$2,0),"Unknown") -> 10 | AC4: R1 | AD4: 127.304 | AE4: Own call
A5: tools | B5: 1 | C5: workflow | E5: ok | G5: Execute tool calls requested by the preceding model response and return their observations. | H5: 01a1143f-64c5-7f82-947a-0c90945e3935 | I5: 01a1143f-6441-7a22-a31c-1a1915e9a0ff | AD5: 1.396 | AE5: No model charge
A6: echo_tool | B6: 2 | C6: tool | E6: ok | G6: Return the provided text prefixed with "Your input was: ". | H6: 01a1143f-64c5-7f82-947a-0ca5a458daaa | I6: 01a1143f-64c5-7f82-947a-0c90945e3935 | AD6: 0.434 | AE6: No model charge
A7: model | B7: 1 | C7: workflow | E7: ok | G7: Prepare the current conversation, run model middleware, and invoke the chat model. | H7: 01a1143f-64c7-7432-b7e2-cd69558c2618 | I7: 01a1143f-6441-7a22-a31c-1a1915e9a0ff | J7: =IF(COUNT('Turns'!D22)=1,SUM('Turns'!D22),"Unknown") -> 33 | K7: =IF(COUNT('Turns'!E22)=1,SUM('Turns'!E22),"Unknown") -> 5.806284e-06 | L7: =IF(COUNT('Turns'!F22)=1,SUM('Turns'!F22),"Unknown") -> 6.6e-06 | M7: =IF(COUNT('Turns'!D21)=1,SUM('Turns'!D21),"Unknown") -> 216 | N7: =IF(COUNT('Turns'!E21)=1,SUM('Turns'!E21),"Unknown") -> 3.8004768e-06 | O7: =IF(COUNT('Turns'!F21)=1,SUM('Turns'!F21),"Unknown") -> 4.32e-06 | P7: 0 | Q7: 0 | R7: 0 | S7: =IF(COUNT('Turns'!D27)=1,SUM('Turns'!D27),"Unknown") -> 48 | T7: =IF(COUNT('Turns'!E27)=1,SUM('Turns'!E27),"Unknown") -> 5.0673024e-05 | U7: =IF(COUNT('Turns'!F27)=1,SUM('Turns'!F27),"Unknown") -> 5.76e-05 | V7: 0 | W7: 0 | X7: 0 | Y7: =IF(COUNT('Turns'!E31)=1,SUM('Turns'!E31),"Unknown") -> 6.0279785e-05 | Z7: =IF(COUNT('Turns'!F31)=1,SUM('Turns'!F31),"Unknown") -> 6.852e-05 | AA7: =IF(ISNUMBER(Y7),ROUND(Y7*'Reference data'!$B$2,0),"Unknown") -> 6 | AB7: =IF(ISNUMBER(Z7),ROUND(Z7*'Reference data'!$B$2,0),"Unknown") -> 7 | AD7: 2.809 | AE7: Subtree total
A8: SimulatedModel | B8: 2 | C8: model | D8: scripted-chat | E8: ok | F8: 249 | G8: Watch an agent echo your input through a tool. | H8: 01a1143f-64c7-7432-b7e2-cd7cb402eabb | I8: 01a1143f-64c7-7432-b7e2-cd69558c2618 | J8: =IF(COUNT('Turns'!D22)=1,SUM('Turns'!D22),"Unknown") -> 33 | K8: =IF(COUNT('Turns'!E22)=1,SUM('Turns'!E22),"Unknown") -> 5.806284e-06 | L8: =IF(COUNT('Turns'!F22)=1,SUM('Turns'!F22),"Unknown") -> 6.6e-06 | M8: =IF(COUNT('Turns'!D21)=1,SUM('Turns'!D21),"Unknown") -> 216 | N8: =IF(COUNT('Turns'!E21)=1,SUM('Turns'!E21),"Unknown") -> 3.8004768e-06 | O8: =IF(COUNT('Turns'!F21)=1,SUM('Turns'!F21),"Unknown") -> 4.32e-06 | P8: 0 | Q8: 0 | R8: 0 | S8: =IF(COUNT('Turns'!D27)=1,SUM('Turns'!D27),"Unknown") -> 48 | T8: =IF(COUNT('Turns'!E27)=1,SUM('Turns'!E27),"Unknown") -> 5.0673024e-05 | U8: =IF(COUNT('Turns'!F27)=1,SUM('Turns'!F27),"Unknown") -> 5.76e-05 | V8: 0 | W8: 0 | X8: 0 | Y8: =IF(COUNT('Turns'!E31)=1,SUM('Turns'!E31),"Unknown") -> 6.0279785e-05 | Z8: =IF(COUNT('Turns'!F31)=1,SUM('Turns'!F31),"Unknown") -> 6.852e-05 | AA8: =IF(ISNUMBER(Y8),ROUND(Y8*'Reference data'!$B$2,0),"Unknown") -> 6 | AB8: =IF(ISNUMBER(Z8),ROUND(Z8*'Reference data'!$B$2,0),"Unknown") -> 7 | AC8: R2 | AD8: 1.317 | AE8: Own call
A9: reference_chat_agent | B9: 0 | C9: workflow | E9: ok | G9: Execute the reference_chat_agent workflow operation and pass its result to the next graph step. | H9: 01a1143f-64d9-71c0-9d6a-90e1dab89467 | J9: =IF(COUNT('Turns'!D35,'Turns'!D50)=2,SUM('Turns'!D35,'Turns'!D50),"Unknown") -> 63 | K9: =IF(COUNT('Turns'!E35,'Turns'!E50)=2,SUM('Turns'!E35,'Turns'!E50),"Unknown") -> 1.1084724e-05 | L9: =IF(COUNT('Turns'!F35,'Turns'!F50)=2,SUM('Turns'!F35,'Turns'!F50),"Unknown") -> 1.26e-05 | M9: =IF(COUNT('Turns'!D34,'Turns'!D49)=2,SUM('Turns'!D34,'Turns'!D49),"Unknown") -> 688 | N9: =IF(COUNT('Turns'!E34,'Turns'!E49)=2,SUM('Turns'!E34,'Turns'!E49),"Unknown") -> 1.2105222e-05 | O9: =IF(COUNT('Turns'!F34,'Turns'!F49)=2,SUM('Turns'!F34,'Turns'!F49),"Unknown") -> 1.376e-05 | P9: 0 | Q9: 0 | R9: 0 | S9: =IF(COUNT('Turns'!D40,'Turns'!D55)=2,SUM('Turns'!D40,'Turns'!D55),"Unknown") -> 118 | T9: =IF(COUNT('Turns'!E40,'Turns'!E55)=2,SUM('Turns'!E40,'Turns'!E55),"Unknown") -> 0.00012457118 | U9: =IF(COUNT('Turns'!F40,'Turns'!F55)=2,SUM('Turns'!F40,'Turns'!F55),"Unknown") -> 0.0001416 | V9: 0 | W9: 0 | X9: 0 | Y9: =IF(COUNT('Turns'!E44,'Turns'!E59)=2,SUM('Turns'!E44,'Turns'!E59),"Unknown") -> 0.00014776113 | Z9: =IF(COUNT('Turns'!F44,'Turns'!F59)=2,SUM('Turns'!F44,'Turns'!F59),"Unknown") -> 0.00016796 | AA9: =IF(ISNUMBER(Y9),ROUND(Y9*'Reference data'!$B$2,0),"Unknown") -> 15 | AB9: =IF(ISNUMBER(Z9),ROUND(Z9*'Reference data'!$B$2,0),"Unknown") -> 17 | AD9: 8.732 | AE9: Subtree total
A10: model | B10: 1 | C10: workflow | E10: ok | G10: Prepare the current conversation, run model middleware, and invoke the chat model. | H10: 01a1143f-64da-79b2-bb70-8ce531e628e5 | I10: 01a1143f-64d9-71c0-9d6a-90e1dab89467 | J10: =IF(COUNT('Turns'!D35)=1,SUM('Turns'!D35),"Unknown") -> 30 | K10: =IF(COUNT('Turns'!E35)=1,SUM('Turns'!E35),"Unknown") -> 5.27844e-06 | L10: =IF(COUNT('Turns'!F35)=1,SUM('Turns'!F35),"Unknown") -> 6e-06 | M10: =IF(COUNT('Turns'!D34)=1,SUM('Turns'!D34),"Unknown") -> 297 | N10: =IF(COUNT('Turns'!E34)=1,SUM('Turns'!E34),"Unknown") -> 5.2256556e-06 | O10: =IF(COUNT('Turns'!F34)=1,SUM('Turns'!F34),"Unknown") -> 5.94e-06 | P10: 0 | Q10: 0 | R10: 0 | S10: =IF(COUNT('Turns'!D40)=1,SUM('Turns'!D40),"Unknown") -> 64 | T10: =IF(COUNT('Turns'!E40)=1,SUM('Turns'!E40),"Unknown") -> 6.7564032e-05 | U10: =IF(COUNT('Turns'!F40)=1,SUM('Turns'!F40),"Unknown") -> 7.68e-05 | V10: 0 | W10: 0 | X10: 0 | Y10: =IF(COUNT('Turns'!E44)=1,SUM('Turns'!E44),"Unknown") -> 7.8068128e-05 | Z10: =IF(COUNT('Turns'!F44)=1,SUM('Turns'!F44),"Unknown") -> 8.874e-05 | AA10: =IF(ISNUMBER(Y10),ROUND(Y10*'Reference data'!$B$2,0),"Unknown") -> 8 | AB10: =IF(ISNUMBER(Z10),ROUND(Z10*'Reference data'!$B$2,0),"Unknown") -> 9 | AD10: 2.803 | AE10: Subtree total
A11: SimulatedModel | B11: 2 | C11: model | D11: scripted-chat | E11: ok | F11: 327 | G11: Watch an agent echo your input through a tool. | H11: 01a1143f-64da-79b2-bb70-8cfdd71325cd | I11: 01a1143f-64da-79b2-bb70-8ce531e628e5 | J11: =IF(COUNT('Turns'!D35)=1,SUM('Turns'!D35),"Unknown") -> 30 | K11: =IF(COUNT('Turns'!E35)=1,SUM('Turns'!E35),"Unknown") -> 5.27844e-06 | L11: =IF(COUNT('Turns'!F35)=1,SUM('Turns'!F35),"Unknown") -> 6e-06 | M11: =IF(COUNT('Turns'!D34)=1,SUM('Turns'!D34),"Unknown") -> 297 | N11: =IF(COUNT('Turns'!E34)=1,SUM('Turns'!E34),"Unknown") -> 5.2256556e-06 | O11: =IF(COUNT('Turns'!F34)=1,SUM('Turns'!F34),"Unknown") -> 5.94e-06 | P11: 0 | Q11: 0 | R11: 0 | S11: =IF(COUNT('Turns'!D40)=1,SUM('Turns'!D40),"Unknown") -> 64 | T11: =IF(COUNT('Turns'!E40)=1,SUM('Turns'!E40),"Unknown") -> 6.7564032e-05 | U11: =IF(COUNT('Turns'!F40)=1,SUM('Turns'!F40),"Unknown") -> 7.68e-05 | V11: 0 | W11: 0 | X11: 0 | Y11: =IF(COUNT('Turns'!E44)=1,SUM('Turns'!E44),"Unknown") -> 7.8068128e-05 | Z11: =IF(COUNT('Turns'!F44)=1,SUM('Turns'!F44),"Unknown") -> 8.874e-05 | AA11: =IF(ISNUMBER(Y11),ROUND(Y11*'Reference data'!$B$2,0),"Unknown") -> 8 | AB11: =IF(ISNUMBER(Z11),ROUND(Z11*'Reference data'!$B$2,0),"Unknown") -> 9 | AC11: R3 | AD11: 1.916 | AE11: Own call
A12: tools | B12: 1 | C12: workflow | E12: ok | G12: Execute tool calls requested by the preceding model response and return their observations. | H12: 01a1143f-64dd-7ff3-8cc9-d0daa1018b93 | I12: 01a1143f-64d9-71c0-9d6a-90e1dab89467 | AD12: 1.366 | AE12: No model charge
A13: echo_tool | B13: 2 | C13: tool | E13: ok | G13: Return the provided text prefixed with "Your input was: ". | H13: 01a1143f-64de-70a2-beb0-52f17b493c75 | I13: 01a1143f-64dd-7ff3-8cc9-d0daa1018b93 | AD13: 0.419 | AE13: No model charge
A14: model | B14: 1 | C14: workflow | E14: ok | G14: Prepare the current conversation, run model middleware, and invoke the chat model. | H14: 01a1143f-64df-7832-b9ec-d82145a6dff0 | I14: 01a1143f-64d9-71c0-9d6a-90e1dab89467 | J14: =IF(COUNT('Turns'!D50)=1,SUM('Turns'!D50),"Unknown") -> 33 | K14: =IF(COUNT('Turns'!E50)=1,SUM('Turns'!E50),"Unknown") -> 5.806284e-06 | L14: =IF(COUNT('Turns'!F50)=1,SUM('Turns'!F50),"Unknown") -> 6.6e-06 | M14: =IF(COUNT('Turns'!D49)=1,SUM('Turns'!D49),"Unknown") -> 391 | N14: =IF(COUNT('Turns'!E49)=1,SUM('Turns'!E49),"Unknown") -> 6.8795668e-06 | O14: =IF(COUNT('Turns'!F49)=1,SUM('Turns'!F49),"Unknown") -> 7.82e-06 | P14: 0 | Q14: 0 | R14: 0 | S14: =IF(COUNT('Turns'!D55)=1,SUM('Turns'!D55),"Unknown") -> 54 | T14: =IF(COUNT('Turns'!E55)=1,SUM('Turns'!E55),"Unknown") -> 5.7007152e-05 | U14: =IF(COUNT('Turns'!F55)=1,SUM('Turns'!F55),"Unknown") -> 6.48e-05 | V14: 0 | W14: 0 | X14: 0 | Y14: =IF(COUNT('Turns'!E59)=1,SUM('Turns'!E59),"Unknown") -> 6.9693003e-05 | Z14: =IF(COUNT('Turns'!F59)=1,SUM('Turns'!F59),"Unknown") -> 7.922e-05 | AA14: =IF(ISNUMBER(Y14),ROUND(Y14*'Reference data'!$B$2,0),"Unknown") -> 7 | AB14: =IF(ISNUMBER(Z14),ROUND(Z14*'Reference data'!$B$2,0),"Unknown") -> 8 | AD14: 2.023 | AE14: Subtree total
A15: SimulatedModel | B15: 2 | C15: model | D15: scripted-chat | E15: ok | F15: 424 | G15: Watch an agent echo your input through a tool. | H15: 01a1143f-64e0-74e3-a5b3-78238b132705 | I15: 01a1143f-64df-7832-b9ec-d82145a6dff0 | J15: =IF(COUNT('Turns'!D50)=1,SUM('Turns'!D50),"Unknown") -> 33 | K15: =IF(COUNT('Turns'!E50)=1,SUM('Turns'!E50),"Unknown") -> 5.806284e-06 | L15: =IF(COUNT('Turns'!F50)=1,SUM('Turns'!F50),"Unknown") -> 6.6e-06 | M15: =IF(COUNT('Turns'!D49)=1,SUM('Turns'!D49),"Unknown") -> 391 | N15: =IF(COUNT('Turns'!E49)=1,SUM('Turns'!E49),"Unknown") -> 6.8795668e-06 | O15: =IF(COUNT('Turns'!F49)=1,SUM('Turns'!F49),"Unknown") -> 7.82e-06 | P15: 0 | Q15: 0 | R15: 0 | S15: =IF(COUNT('Turns'!D55)=1,SUM('Turns'!D55),"Unknown") -> 54 | T15: =IF(COUNT('Turns'!E55)=1,SUM('Turns'!E55),"Unknown") -> 5.7007152e-05 | U15: =IF(COUNT('Turns'!F55)=1,SUM('Turns'!F55),"Unknown") -> 6.48e-05 | V15: 0 | W15: 0 | X15: 0 | Y15: =IF(COUNT('Turns'!E59)=1,SUM('Turns'!E59),"Unknown") -> 6.9693003e-05 | Z15: =IF(COUNT('Turns'!F59)=1,SUM('Turns'!F59),"Unknown") -> 7.922e-05 | AA15: =IF(ISNUMBER(Y15),ROUND(Y15*'Reference data'!$B$2,0),"Unknown") -> 7 | AB15: =IF(ISNUMBER(Z15),ROUND(Z15*'Reference data'!$B$2,0),"Unknown") -> 8 | AC15: R4 | AD15: 1.265 | AE15: Own call

Sheet Reference data
A1: Parameter | B1: Value | C1: Unit
A2: Number of executions | B2: 100000 | C2: executions
A3: USD → EUR | B3: 0.87974 | C3: EUR per USD
A4: Cache duration | B4: 5m
A5: Run ID | B5: 01a1143f-6441-7a22-a31c-1a1915e9a0ff
A6: Recording | B6: Offline simulation
A7: FX reference date | B7: 2026-09-24
A8: FX fetched at | B8: 2026-09-24T22:21:31.719587Z | C8: UTC
A9: FX source | B9: https://api.frankfurter.dev/v2/rate/usd/eur?providers=ecb
A10: Rounding | B10: Only projected costs: ROUND(cost × executions, 0)
A11: Tree totals | B11: Parent rows include descendants; do not sum all tree rows.
A12: Cache writes | B12: Simulated context movement is not a provider-billed write.
A13: Pricing scope | B13: Published online token rates verified 2026-10-05. Copilot uses GitHub rates, including saved long-context tiers, before plan allowances; these are usage estimates, not subscription invoices. Cache writes with unspecified lifetime use the 5-minute rate unless an explicit cache_write rate is configured. Direct OpenAI and Anthropic entries use standard rates; no batch, regional, tool, negotiated, or unrecorded context-tier adjustments are applied. Model availability and context capacity require separate verification.
A15: Model | B15: Input USD / 1M tokens | C15: Cache read USD / 1M tokens | D15: Cache write USD / 1M tokens | E15: Output USD / 1M tokens | F15: Reasoning USD / 1M tokens | G15: Verified date | H15: Source | I15: Notes
A16: openai:gpt-5.5 | B16: 5 | C16: 0.5 | D16: Unknown | E16: 30 | F16: 30 | G16: 2026-10-05 | H16: https://developers.openai.com/api/docs/models/gpt-5.5.md | I16: Cache write assumes 5m when unspecified
A17: openai:gpt-5.6-luna | B17: 0.2 | C17: 0.02 | D17: 0.25 | E17: 1.2 | F17: 1.2 | G17: 2026-10-05 | H17: https://developers.openai.com/api/docs/models/gpt-5.6-luna.md | I17: Cache write assumes 5m when unspecified
A18: openai:gpt-5.6-sol | B18: 4 | C18: 0.4 | D18: 5 | E18: 20 | F18: 20 | G18: 2026-10-05 | H18: https://developers.openai.com/api/docs/models/gpt-5.6-sol.md | I18: Cache write assumes 5m when unspecified
A19: anthropic:claude-sonnet-5 | B19: 2 | C19: 0.2 | D19: 2.5 | E19: 10 | F19: 10 | G19: 2026-10-05 | H19: https://platform.claude.com/docs/en/about-claude/pricing | I19: Cache write assumes 5m when unspecified
A20: anthropic:claude-opus-4-8 | B20: 5 | C20: 0.5 | D20: 6.25 | E20: 25 | F20: 25 | G20: 2026-10-05 | H20: https://platform.claude.com/docs/en/about-claude/pricing | I20: Cache write assumes 5m when unspecified
A21: anthropic:claude-fable-5-1 | B21: 10 | C21: 0.25 | D21: 12.5 | E21: 50 | F21: 50 | G21: 2026-10-05 | H21: https://platform.claude.com/docs/en/about-claude/pricing | I21: Cache write assumes 5m when unspecified
A22: demo:scripted-chat | B22: 0.2 | C22: 0.02 | D22: 0.25 | E22: 1.2 | F22: 1.2 | G22: 2026-10-05 | H22: Illustrative demo rates based on openai:gpt-5.6-luna; no provider billing | I22: Cache write assumes 5m when unspecified
A23: anthropic:claude-haiku-4-5 | B23: 1 | C23: 0.1 | D23: 1.25 | E23: 5 | F23: 5 | G23: 2026-10-05 | H23: https://platform.claude.com/docs/en/about-claude/pricing | I23: Cache write assumes 5m when unspecified
A24: anthropic:claude-haiku-4-5-20251001 | B24: 1 | C24: 0.1 | D24: 1.25 | E24: 5 | F24: 5 | G24: 2026-10-05 | H24: https://platform.claude.com/docs/en/about-claude/pricing | I24: Cache write assumes 5m when unspecified
A25: anthropic:claude-opus-5-5 | B25: 4 | C25: 0.2 | D25: 5 | E25: 20 | F25: 20 | G25: 2026-10-05 | H25: https://platform.claude.com/docs/en/about-claude/pricing | I25: Cache write assumes 5m when unspecified
A26: anthropic:claude-sonnet-4-6 | B26: 3 | C26: 0.3 | D26: 3.75 | E26: 15 | F26: 15 | G26: 2026-10-05 | H26: https://platform.claude.com/docs/en/about-claude/pricing | I26: Cache write assumes 5m when unspecified
A27: anthropic:claude-sonnet-5-5 | B27: 2 | C27: 0.2 | D27: 2.5 | E27: 10 | F27: 10 | G27: 2026-10-05 | H27: https://platform.claude.com/docs/en/about-claude/pricing | I27: Cache write assumes 5m when unspecified
A28: copilot:claude-haiku-4.5 | B28: 1 | C28: 0.1 | D28: 1.25 | E28: 5 | F28: 5 | G28: 2026-10-05 | H28: https://docs.github.com/en/copilot/reference/copilot-billing/models-and-pricing | I28: Cache write assumes 5m when unspecified
... A31: copilot:claude-sonnet-5.5 | B31: 2 | C31: 0.2 | D31: 2.5 | E31: 10 | F31: 10 | G31: 2026-10-05 | H31: https://docs.github.com/en/copilot/reference/copilot-billing/models-and-pricing | I31: Cache write assumes 5m when unspecified
A32: copilot:gemini-3.8-flash | B32: 0.75 | C32: 0.075 | D32: Unknown | E32: 3.75 | F32: 3.75 | G32: 2026-10-05 | H32: https://docs.github.com/en/copilot/reference/copilot-billing/models-and-pricing | I32: Cache write assumes 5m when unspecified
A33: copilot:gpt-5.3-codex | B33: 1.75 | C33: 0.175 | D33: Unknown | E33: 14 | F33: 14 | G33: 2026-10-05 | H33: https://docs.github.com/en/copilot/reference/copilot-billing/models-and-pricing | I33: Cache write assumes 5m when unspecified
A34: copilot:gpt-5.4 | B34: 2.5 | C34: 0.25 | D34: Unknown | E34: 15 | F34: 15 | G34: 2026-10-05 | H34: https://docs.github.com/en/copilot/reference/copilot-billing/models-and-pricing | I34: Cache write assumes 5m when unspecified
A35: copilot:gpt-6-astra | B35: 10 | C35: 1 | D35: 12.5 | E35: 50 | F35: 50 | G35: 2026-10-05 | H35: https://docs.github.com/en/copilot/reference/copilot-billing/models-and-pricing | I35: Cache write assumes 5m when unspecified
A36: copilot:gpt-6-luna | B36: 0.1 | C36: 0.01 | D36: 0.125 | E36: 0.5 | F36: 0.5 | G36: 2026-10-05 | H36: https://docs.github.com/en/copilot/reference/copilot-billing/models-and-pricing | I36: Cache write assumes 5m when unspecified
A37: copilot:gpt-6-sol | B37: 2 | C37: 0.2 | D37: 2.5 | E37: 10 | F37: 10 | G37: 2026-10-05 | H37: https://docs.github.com/en/copilot/reference/copilot-billing/models-and-pricing | I37: Cache write assumes 5m when unspecified
A38: copilot:gpt-6.1-sol | B38: 2 | C38: 0.1 | D38: 2.5 | E38: 10 | F38: 10 | G38: 2026-10-05 | H38: https://docs.github.com/en/copilot/reference/copilot-billing/models-and-pricing | I38: Cache write assumes 5m when unspecified
A39: openai:gpt-6-astra | B39: 10 | C39: 1 | D39: 12.5 | E39: 50 | F39: 50 | G39: 2026-10-05 | H39: https://developers.openai.com/api/docs/models/gpt-6-astra.md | I39: Cache write assumes 5m when unspecified
A40: openai:gpt-6-luna | B40: 0.1 | C40: 0.01 | D40: 0.125 | E40: 0.5 | F40: 0.5 | G40: 2026-10-05 | H40: https://developers.openai.com/api/docs/models/gpt-6-luna.md | I40: Cache write assumes 5m when unspecified
A41: openai:gpt-6-sol | B41: 2 | C41: 0.2 | D41: 2.5 | E41: 10 | F41: 10 | G41: 2026-10-05 | H41: https://developers.openai.com/api/docs/models/gpt-6-sol.md | I41: Cache write assumes 5m when unspecified
A42: openai:gpt-6.1-sol | B42: 2 | C42: 0.1 | D42: 2.5 | E42: 10 | F42: 10 | G42: 2026-10-05 | H42: https://developers.openai.com/api/docs/models/gpt-6.1-sol.md | I42: Cache write assumes 5m when unspecified
A43: copilot:gpt-5.4 [long context] | B43: 5 | C43: 0.5 | D43: Unknown | E43: 22.5 | F43: 22.5 | G43: 2026-10-05 | H43: https://docs.github.com/en/copilot/reference/copilot-billing/models-and-pricing | I43: Above 272,000 input tokens
...
