Workbook

Sheet Turns
A1: Request | B1: Turn | C1: Sequence | D1: Tokens | E1: EUR / execution | F1: USD / execution | G1: Projected EUR | H1: Projected USD | I1: Content | J1: Model · effort | K1: Status | L1: Context total tokens | M1: Span ID
C2: Run total | E2: =IF(COUNT('Turns'!E16,'Turns'!E31,'Turns'!E44,'Turns'!E59,'Turns'!E74,'Turns'!E86,'Turns'!E101,'Turns'!E116,'Turns'!E128,'Turns'!E143,'Turns'!E158,'Turns'!E169,'Turns'!E184,'Turns'!E199,'Turns'!E212,'Turns'!E227,'Turns'!E242,'Turns'!E257,'Turns'!E269,'Turns'!E281,'Turns'!E296,'Turns'!E311,'Turns'!E326,'Turns'!E337,'Turns'!E352,'Turns'!E367,'Turns'!E382,'Turns'!E394,'Turns'!E409,'Turns'!E424,'Turns'!E439,'Turns'!E453,'Turns'!E468,'Turns'!E480,'Turns'!E495,'Turns'!E507,'Turns'!E522,'Turns'!E537,'Turns'!E552,'Turns'!E563,'Turns'!E578,'Turns'!E593,'Turns'!E608,'Turns'!E620,'Turns'!E635,'Turns'!E650,'Turns'!E664,'Turns'!E676)=48,SUM('Turns'!E16,'Turns'!E31,'Turns'!E44,'Turns'!E59,'Turns'!E74,'Turns'!E86,'Turns'!E101,'Turns'!E116,'Turns'!E128,'Turns'!E143,'Turns'!E158,'Turns'!E169,'Turns'!E184,'Turns'!E199,'Turns'!E212,'Turns'!E227,'Turns'!E242,'Turns'!E257,'Turns'!E269,'Turns'!E281,'Turns'!E296,'Turns'!E311,'Turns'!E326,'Turns'!E337,'Turns'!E352,'Turns'!E367,'Turns'!E382,'Turns'!E394,'Turns'!E409,'Turns'!E424,'Turns'!E439,'Turns'!E453,'Turns'!E468,'Turns'!E480,'Turns'!E495,'Turns'!E507,'Turns'!E522,'Turns'!E537,'Turns'!E552,'Turns'!E563,'Turns'!E578,'Turns'!E593,'Turns'!E608,'Turns'!E620,'Turns'!E635,'Turns'!E650,'Turns'!E664,'Turns'!E676),"Unknown") -> 0.043677332 | F2: =IF(COUNT('Turns'!F16,'Turns'!F31,'Turns'!F44,'Turns'!F59,'Turns'!F74,'Turns'!F86,'Turns'!F101,'Turns'!F116,'Turns'!F128,'Turns'!F143,'Turns'!F158,'Turns'!F169,'Turns'!F184,'Turns'!F199,'Turns'!F212,'Turns'!F227,'Turns'!F242,'Turns'!F257,'Turns'!F269,'Turns'!F281,'Turns'!F296,'Turns'!F311,'Turns'!F326,'Turns'!F337,'Turns'!F352,'Turns'!F367,'Turns'!F382,'Turns'!F394,'Turns'!F409,'Turns'!F424,'Turns'!F439,'Turns'!F453,'Turns'!F468,'Turns'!F480,'Turns'!F495,'Turns'!F507,'Turns'!F522,'Turns'!F537,'Turns'!F552,'Turns'!F563,'Turns'!F578,'Turns'!F593,'Turns'!F608,'Turns'!F620,'Turns'!F635,'Turns'!F650,'Turns'!F664,'Turns'!F676)=48,SUM('Turns'!F16,'Turns'!F31,'Turns'!F44,'Turns'!F59,'Turns'!F74,'Turns'!F86,'Turns'!F101,'Turns'!F116,'Turns'!F128,'Turns'!F143,'Turns'!F158,'Turns'!F169,'Turns'!F184,'Turns'!F199,'Turns'!F212,'Turns'!F227,'Turns'!F242,'Turns'!F257,'Turns'!F269,'Turns'!F281,'Turns'!F296,'Turns'!F311,'Turns'!F326,'Turns'!F337,'Turns'!F352,'Turns'!F367,'Turns'!F382,'Turns'!F394,'Turns'!F409,'Turns'!F424,'Turns'!F439,'Turns'!F453,'Turns'!F468,'Turns'!F480,'Turns'!F495,'Turns'!F507,'Turns'!F522,'Turns'!F537,'Turns'!F552,'Turns'!F563,'Turns'!F578,'Turns'!F593,'Turns'!F608,'Turns'!F620,'Turns'!F635,'Turns'!F650,'Turns'!F664,'Turns'!F676),"Unknown") -> 0.049648 | G2: =IF(ISNUMBER(E2),ROUND(E2*'Reference data'!$B$2,0),"Unknown") -> 4368 | H2: =IF(ISNUMBER(F2),ROUND(F2*'Reference data'!$B$2,0),"Unknown") -> 4965
B3: 1 | C3: Turn 1 | E3: =IF(COUNT('Turns'!E16,'Turns'!E31,'Turns'!E44,'Turns'!E59,'Turns'!E74,'Turns'!E86,'Turns'!E101,'Turns'!E116,'Turns'!E128,'Turns'!E143,'Turns'!E158,'Turns'!E169,'Turns'!E184,'Turns'!E199,'Turns'!E212,'Turns'!E227,'Turns'!E242,'Turns'!E257,'Turns'!E269,'Turns'!E281,'Turns'!E296,'Turns'!E311,'Turns'!E326,'Turns'!E337,'Turns'!E352,'Turns'!E367,'Turns'!E382,'Turns'!E394,'Turns'!E409,'Turns'!E424,'Turns'!E439)=31,SUM('Turns'!E16,'Turns'!E31,'Turns'!E44,'Turns'!E59,'Turns'!E74,'Turns'!E86,'Turns'!E101,'Turns'!E116,'Turns'!E128,'Turns'!E143,'Turns'!E158,'Turns'!E169,'Turns'!E184,'Turns'!E199,'Turns'!E212,'Turns'!E227,'Turns'!E242,'Turns'!E257,'Turns'!E269,'Turns'!E281,'Turns'!E296,'Turns'!E311,'Turns'!E326,'Turns'!E337,'Turns'!E352,'Turns'!E367,'Turns'!E382,'Turns'!E394,'Turns'!E409,'Turns'!E424,'Turns'!E439),"Unknown") -> 0.028328508 | F3: =IF(COUNT('Turns'!F16,'Turns'!F31,'Turns'!F44,'Turns'!F59,'Turns'!F74,'Turns'!F86,'Turns'!F101,'Turns'!F116,'Turns'!F128,'Turns'!F143,'Turns'!F158,'Turns'!F169,'Turns'!F184,'Turns'!F199,'Turns'!F212,'Turns'!F227,'Turns'!F242,'Turns'!F257,'Turns'!F269,'Turns'!F281,'Turns'!F296,'Turns'!F311,'Turns'!F326,'Turns'!F337,'Turns'!F352,'Turns'!F367,'Turns'!F382,'Turns'!F394,'Turns'!F409,'Turns'!F424,'Turns'!F439)=31,SUM('Turns'!F16,'Turns'!F31,'Turns'!F44,'Turns'!F59,'Turns'!F74,'Turns'!F86,'Turns'!F101,'Turns'!F116,'Turns'!F128,'Turns'!F143,'Turns'!F158,'Turns'!F169,'Turns'!F184,'Turns'!F199,'Turns'!F212,'Turns'!F227,'Turns'!F242,'Turns'!F257,'Turns'!F269,'Turns'!F281,'Turns'!F296,'Turns'!F311,'Turns'!F326,'Turns'!F337,'Turns'!F352,'Turns'!F367,'Turns'!F382,'Turns'!F394,'Turns'!F409,'Turns'!F424,'Turns'!F439),"Unknown") -> 0.032201 | G3: =IF(ISNUMBER(E3),ROUND(E3*'Reference data'!$B$2,0),"Unknown") -> 2833 | H3: =IF(ISNUMBER(F3),ROUND(F3*'Reference data'!$B$2,0),"Unknown") -> 3220
A4: R1 | B4: 1 | C4: LLM request | D4: 3426 | J4: scripted-chat | M4: 01a11680-ba2a-7ed1-921e-253b3a50ca31
A5: R1 | B5: 1 | C5: Input at standard rate | D5: 3426 | E5: =IF(AND(ISNUMBER(F5),ISNUMBER('Reference data'!$B$3)),F5*'Reference data'!$B$3,"Unknown") -> 0.00060279785 | F5: =IF(D5=0,0,IF(ISNUMBER('Reference data'!B22),D5*'Reference data'!B22/1000000,"Unknown")) -> 0.0006852 | G5: =IF(ISNUMBER(E5),ROUND(E5*'Reference data'!$B$2,0),"Unknown") -> 60 | H5: =IF(ISNUMBER(F5),ROUND(F5*'Reference data'!$B$2,0),"Unknown") -> 69
A6: R1 | B6: 1 | C6: Tool definitions | D6: 848
A7: R1 | B7: 1 | C7: System prompt | D7: 1387 | I7: You are the planner. You own only /plan.md; never implement or repair code or tests. The only implementation paths are /slug.py and /test_slug.py; the public function is slugify imported from slug. The workflow automatically executes /test_slug.py after each worker invocation and supplies test_execution evidence before review. On the initial planning invocation, read an existing plan if present, then create or extend an ordered plan of concrete implementation steps with stable task IDs, acceptance criteria, and pending status. Review and closeout are part of EVERY implementation step, never separate plan tasks. NEVER assign source review, cross-file review, approval, verification-only work, or closeout to the worker. The independent reviewer node already handles those checks for each implementation step. For the initial slug request, plan two implementation steps: implement the function, then write its tests. For a follow-up request, add only the concrete requested code/test changes. Preserve earlier evidence. Assign exactly ONE pending task to the worker, then stop. On an approved-step invocation, update ONLY the named approved task to complete using the supplied reviewer evidence, reread /plan.md, then assign the next pending task or finish. Do not mark a task complete on worker claims, your own inspection, or a summary. Only the workflow-supplied approval authorizes that update. Never repair a rejected task yourself. Your final response must be a JSON object with action (work or finish), task_id (the next task ID, or empty when finishing), files (an array of writable paths for this task chosen from /slug.py and /test_slug.py, empty when finishing), and message (a self-contained assignment including acceptance criteria, or final report). No Markdown fences. A work response must name exactly one task. Include the observed test count, exit status and independent review outcome in the plan and final report; never substitute written tests for execution evidence. Sample practices: # Coding practices for a small Python change This guidance is part of the context-budget sample. It is deliberately self-contained: no external skill, service, repository-specific command, or server is required. Apply it to the local exercise described in the plan. The plan is the durable coordination record; conversation text is transient. ## Establish the task Read the current plan before choosing work. Identify the requested behavior, the intended user, inputs and outputs, file ownership, and acceptance criteria. Separate requirements from implementation guesses. If a task cannot be completed because information is missing, record the exact gap in the plan rather than silently inventing a contract. Prefer a small explicit contract over speculative flexibility. Make names describe responsibilities and avoid adding an abstraction that has only one use. If prior tasks changed the plan, use its latest on-disk version, not an older summary of it. ## Design before editing For each task, describe the observable before and after behavior. List one or two representative examples and the most important edge cases. Decide where input validation belongs and what should happen for invalid values. Choose deterministic behavior that can be checked without external services. Keep the public function small and place supporting logic near it. Avoid hidden state and avoid catching errors so broadly that a failed edit looks successful. Do not make a safety claim that the code cannot enforce. ## Implement in small verified steps Read the existing file before editing it. Change only the files named by the plan. Preserve content outside the task. When creating code, include a plain-language file header stating purpose, responsibilities, assumptions, AI assistance, and copyright. Explain non-obvious control flow and why a particular branch exists. Comments should clarify intent, not repeat syntax. After each tool result, check whether the operation succeeded before recording progress. If an edit fails or replaces the wrong string, stop and repair that step. Never record a task as complete simply because a tool was called. ## Tests and evidence Write tests for external behavior, important boundaries, and regressions the task is meant to prevent. Do not write a test that only copies the implementation's branching. A test should distinguish a plausible bug from correct behavior. Keep test data readable. After each worker handoff the workflow runs /test_slug.py with standard-library unittest. Use the supplied test_execution receipt, including failures, when reporting verification; never substitute a code review for execution evidence. A reviewer may inspect coverage and syntax, but a review report is not a passing test result. ## Plan maintenance The planner marks a task complete only after the independent reviewer approves that task's current files. An existing artifact alone is not approval. The worker reports concrete tool outcomes but does not edit the plan. The planner uses a narrow replacement that preserves other tasks, with concise evidence such as the created file, test name, or reviewer finding. Read the plan again after every status edit, even if the edit succeeded, so the next decision uses the current document. Keep a pending, complete, or blocked status for every task. Record uncertainty under the relevant task instead of hiding it in a final answer. If the reviewer requests changes, the same task stays incomplete. The worker repairs it and the reviewer checks the new version before the planner records completion. ## Handoff and review The planner supplies a self-contained task assignment: the plan path, code paths, intended behavior, and acceptance criteria. The workflow forwards that assignment to the reviewer after the worker returns. The reviewer starts with an isolated context and has no access to this conversation. Ask for source-backed findings with severity and uncertainty. The workflow delivers the independent verdict. A rejection returns the same task to the worker. Approval lets the planner record completion and reread the plan before assigning another task. Report only what the visible evidence supports. ## Context limits Large instructions, file reads, tool schemas, and tool results consume context. Use compaction to preserve durable decisions and current task state when earlier conversation is summarized. The on-disk plan remains authoritative; after compaction, reread it before the next task. Do not infer that a summary retains every line of a file. When a read is truncated, request the missing section. Keep final messages concise enough to show the task status, verification level, and next action without duplicating the entire plan. Role ownership survives compaction: only the worker edits source/tests, only the reviewer issues approval, and only the planner updates plan status. The current workflow assignment and verdict override incomplete history summaries. Authoritative current workflow operation; do ONLY this operation, even if a history summary suggests later work: {"operation": "plan", "instruction": "Prepare pending steps for the latest user request; assign one. Do not record completion."}
A8: R1 | B8: 1 | C8: User prompt | D8: 50 | I8: {"operation": "plan", "instruction": "Prepare pending steps for the latest user request; assign one. Do not record completion."}
A9: R1 | B9: 1 | C9: Cache write | D9: 3426
A10: R1 | B10: 1 | C10: Context · added / total | D10: 3426 | L10: 3426
A11: R1 | B11: 1 | C11: LLM response | D11: 773
A12: R1 | B12: 1 | C12: Output | D12: 773 | E12: =IF(AND(ISNUMBER(F12),ISNUMBER('Reference data'!$B$3)),F12*'Reference data'!$B$3,"Unknown") -> 0.00081604682 | F12: =IF(D12=0,0,IF(ISNUMBER('Reference data'!E22),D12*'Reference data'!E22/1000000,"Unknown")) -> 0.0009276 | G12: =IF(ISNUMBER(E12),ROUND(E12*'Reference data'!$B$2,0),"Unknown") -> 82 | H12: =IF(ISNUMBER(F12),ROUND(F12*'Reference data'!$B$2,0),"Unknown") -> 93
A13: R1 | B13: 1 | C13: Output content | I13: {"name": "write_file", "args": {"file_path": "/plan.md", "content": "# Slug utility delivery plan\n\nGoal: provide one deterministic Python function named slugify in /slug.py. It turns a title into a lowercase ASCII slug suitable for a local document name. The sample must demonstrate file-backed coordination and independent review, not a production packaging workflow. /test_slug.py contains focused unittest coverage. Each step follows worker implementation, independent approval, then planner completion before the next step starts.\n\nWorking agreement: every task has a stable ID. An edit changes only the named task status and evidence. Pending means no artifact is claimed. Complete means the current version was independently approved and the planner recorded that approval. Blocked means a concrete missing input or failed operation. A reviewer report is evidence of inspection, not evidence that tests executed. The reviewer has read-only access and a separate context; its assignment must include all paths and intended behavior. The planner retains ownership of the plan. The worker reports implementation evidence but does not edit the plan.\n\nDesign contract: accept a string title. Normalize accented Latin letters to their ASCII base where Unicode decomposition provides one. Convert to lowercase. Treat runs of punctuation and whitespace as a single hyphen. Strip leading and trailing hyphens. Empty or separator-only text returns an empty string. A non-string input raises TypeError with a clear message. Do not use network calls, environment configuration, or generated identifiers. Preserve deterministic output for the same input.\n\nImplementation notes: prefer unicodedata.normalize over a third-party transliteration package. Encode decomposed text as ASCII while dropping characters that have no ASCII form. Explain that limitation in a docstring because some scripts become empty. Use a regular expression for separator runs and make its pattern explicit. Keep the public function side-effect free. Avoid broad exception handlers and hidden fallback behavior. Include a purpose header, AI attribution, and the project copyright in each Python file.\n\nVerification agreement: tests use only Python's standard library unittest. They should verify a normal title, repeated whitespace and punctuation, accented Latin input, leading and trailing separators, empty input, and invalid type. Tests are source artifacts until a command actually executes them; the workflow runs /test_slug.py after each worker handoff and supplies its execution receipt to the reviewer. The final report must distinguish written tests from passing tests. Review findings should name a triggering example and the affected task.\n\nTask T1 \u2014 implement the public function. Status: pending. Acceptance: /slug.py exposes slugify; ordinary words become lowercase with one hyphen; accents with Latin decompositions lose marks; punctuation runs do not create repeated hyphens; non-string values fail visibly. Read the plan after recording completion.\n\nTask T2 \u2014 create focused tests. Status: pending. Acceptance: /test_slug.py imports slugify and uses unittest with examples for normal titles, spacing, punctuation, accents, empty input, and invalid input. The tests should distinguish a plausible broken implementation from the expected contract. Read the plan after recording completion.\n\nRisk notes: file reads may be paginated, so inspect the rest if a native read is truncated. A successful write does not prove behavior; it only proves content was saved. A summary may omit exact plan lines, so the current file controls status after compaction. If a tool reports an error, keep the task pending or blocked and explain why. Avoid broadening the task to packaging, CLI behavior, or external deployment. The intended learning is the relationship among plan state, conversation state, reviewer isolation, and context limits.\n"}, "id": "write_file-1", "type": "tool_call"}
A14: R1 | B14: 1 | C14: Cache write | D14: 773
A15: R1 | B15: 1 | C15: Context · added / total | D15: 773 | L15: 4199
A16: R1 | B16: 1 | C16: Call total | E16: =IF(COUNT('Turns'!E5,'Turns'!E12)=2,SUM('Turns'!E5,'Turns'!E12),"Unknown") -> 0.0014188447 | F16: =IF(COUNT('Turns'!F5,'Turns'!F12)=2,SUM('Turns'!F5,'Turns'!F12),"Unknown") -> 0.0016128 | G16: =IF(ISNUMBER(E16),ROUND(E16*'Reference data'!$B$2,0),"Unknown") -> 142 | H16: =IF(ISNUMBER(F16),ROUND(F16*'Reference data'!$B$2,0),"Unknown") -> 161 | K16: ok
B17: 1 | C17: Tool · write_file | K17: ok | M17: 01a11680-baca-7f12-92a5-0ac9dce287bb
B18: 1 | C18: Arguments | I18: {'file_path': '/plan.md', 'content': "# Slug utility delivery plan\n\nGoal: provide one deterministic Python function named slugify in /slug.py. It turns a title into a lowercase ASCII slug suitable for a local document name. The sample must demonstrate file-backed coordination and independent review, not a production packaging workflow. /test_slug.py contains focused unittest coverage. Each step follows worker implementation, independent approval, then planner completion before the next step starts.\n\nWorking agreement: every task has a stable ID. An edit changes only the named task status and evidence. Pending means no artifact is claimed. Complete means the current version was independently approved and the planner recorded that approval. Blocked means a concrete missing input or failed operation. A reviewer report is evidence of inspection, not evidence that tests executed. The reviewer has read-only access and a separate context; its assignment must include all paths and intended behavior. The planner retains ownership of the plan. The worker reports implementation evidence but does not edit the plan.\n\nDesign contract: accept a string title. Normalize accented Latin letters to their ASCII base where Unicode decomposition provides one. Convert to lowercase. Treat runs of punctuation and whitespace as a single hyphen. Strip leading and trailing hyphens. Empty or separator-only text returns an empty string. A non-string input raises TypeError with a clear message. Do not use network calls, environment configuration, or generated identifiers. Preserve deterministic output for the same input.\n\nImplementation notes: prefer unicodedata.normalize over a third-party transliteration package. Encode decomposed text as ASCII while dropping characters that have no ASCII form. Explain that limitation in a docstring because some scripts become empty. Use a regular expression for separator runs and make its pattern explicit. Keep the public function side-effect free. Avoid broad exception handlers and hidden fallback behavior. Include a purpose header, AI attribution, and the project copyright in each Python file.\n\nVerification agreement: tests use only Python's standard library unittest. They should verify a normal title, repeated whitespace and punctuation, accented Latin input, leading and trailing separators, empty input, and invalid type. Tests are source artifacts until a command actually executes them; the workflow runs /test_slug.py after each worker handoff and supplies its execution receipt to the reviewer. The final report must distinguish written tests from passing tests. Review findings should name a triggering example and the affected task.\n\nTask T1 — implement the public function. Status: pending. Acceptance: /slug.py exposes slugify; ordinary words become lowercase with one hyphen; accents with Latin decompositions lose marks; punctuation runs do not create repeated hyphens; non-string values fail visibly. Read the plan after recording completion.\n\nTask T2 — create focused tests. Status: pending. Acceptance: /test_slug.py imports slugify and uses unittest with examples for normal titles, spacing, punctuation, accents, empty input, and invalid input. The tests should distinguish a plausible broken implementation from the expected contract. Read the plan after recording completion.\n\nRisk notes: file reads may be paginated, so inspect the rest if a native read is truncated. A successful write does not prove behavior; it only proves content was saved. A summary may omit exact plan lines, so the current file controls status after compaction. If a tool reports an error, keep the task pending or blocked and explain why. Avoid broadening the task to packaging, CLI behavior, or external deployment. The intended learning is the relationship among plan state, conversation state, reviewer isolation, and context limits.\n"}
B19: 1 | C19: Result | I19: Updated file /plan.md
A20: R2 | B20: 1 | C20: LLM request | D20: 4232 | J20: scripted-chat | M20: 01a11680-bace-7ff1-8eda-cf49e5e80a45
A21: R2 | B21: 1 | C21: Conversation history · cache read | D21: 0 | E21: =IF(AND(ISNUMBER(F21),ISNUMBER('Reference data'!$B$3)),F21*'Reference data'!$B$3,"Unknown") -> 0 | F21: =IF(D21=0,0,IF(ISNUMBER('Reference data'!C22),D21*'Reference data'!C22/1000000,"Unknown")) -> 0 | G21: =IF(ISNUMBER(E21),ROUND(E21*'Reference data'!$B$2,0),"Unknown") -> 0 | H21: =IF(ISNUMBER(F21),ROUND(F21*'Reference data'!$B$2,0),"Unknown") -> 0
A22: R2 | B22: 1 | C22: Input at standard rate | D22: 4232 | E22: =IF(AND(ISNUMBER(F22),ISNUMBER('Reference data'!$B$3)),F22*'Reference data'!$B$3,"Unknown") -> 0.00074461194 | F22: =IF(D22=0,0,IF(ISNUMBER('Reference data'!B22),D22*'Reference data'!B22/1000000,"Unknown")) -> 0.0008464 | G22: =IF(ISNUMBER(E22),ROUND(E22*'Reference data'!$B$2,0),"Unknown") -> 74 | H22: =IF(ISNUMBER(F22),ROUND(F22*'Reference data'!$B$2,0),"Unknown") -> 85
A23: R2 | B23: 1 | C23: Tool result | D23: 33 | I23: Updated file /plan.md
A24: R2 | B24: 1 | C24: Cache write | D24: 4232
A25: R2 | B25: 1 | C25: Context · added / total | D25: 4232 | L25: 4232
A26: R2 | B26: 1 | C26: LLM response | D26: 73
A27: R2 | B27: 1 | C27: Output | D27: 73 | E27: =IF(AND(ISNUMBER(F27),ISNUMBER('Reference data'!$B$3)),F27*'Reference data'!$B$3,"Unknown") -> 7.7065224e-05 | F27: =IF(D27=0,0,IF(ISNUMBER('Reference data'!E22),D27*'Reference data'!E22/1000000,"Unknown")) -> 8.76e-05 | G27: =IF(ISNUMBER(E27),ROUND(E27*'Reference data'!$B$2,0),"Unknown") -> 8 | H27: =IF(ISNUMBER(F27),ROUND(F27*'Reference data'!$B$2,0),"Unknown") -> 9
A28: R2 | B28: 1 | C28: Output content | I28: {"action": "work", "task_id": "T1", "files": ["/slug.py"], "message": "Implement T1 only: write /slug.py according to /plan.md. Tests belong to the next step."}
A29: R2 | B29: 1 | C29: Cache write | D29: 73
A30: R2 | B30: 1 | C30: Context · added / total | D30: 73 | L30: 4305
A31: R2 | B31: 1 | C31: Call total | E31: =IF(COUNT('Turns'!E21,'Turns'!E22,'Turns'!E27)=3,SUM('Turns'!E21,'Turns'!E22,'Turns'!E27),"Unknown") -> 0.00082167716 | F31: =IF(COUNT('Turns'!F21,'Turns'!F22,'Turns'!F27)=3,SUM('Turns'!F21,'Turns'!F22,'Turns'!F27),"Unknown") -> 0.000934 | G31: =IF(ISNUMBER(E31),ROUND(E31*'Reference data'!$B$2,0),"Unknown") -> 82 | H31: =IF(ISNUMBER(F31),ROUND(F31*'Reference data'!$B$2,0),"Unknown") -> 93 | K31: ok
A32: R3 | B32: 1 | C32: LLM request | D32: 4285 | J32: scripted-chat | M32: 01a11680-bad9-7c43-bbf3-55eafafd586b
A33: R3 | B33: 1 | C33: Input at standard rate | D33: 4285 | E33: =IF(AND(ISNUMBER(F33),ISNUMBER('Reference data'!$B$3)),F33*'Reference data'!$B$3,"Unknown") -> 0.00075393718 | F33: =IF(D33=0,0,IF(ISNUMBER('Reference data'!B22),D33*'Reference data'!B22/1000000,"Unknown")) -> 0.000857 | G33: =IF(ISNUMBER(E33),ROUND(E33*'Reference data'!$B$2,0),"Unknown") -> 75 | H33: =IF(ISNUMBER(F33),ROUND(F33*'Reference data'!$B$2,0),"Unknown") -> 86
A34: R3 | B34: 1 | C34: Tool definitions | D34: 848
A35: R3 | B35: 1 | C35: System prompt | D35: 1273 | I35: You are the worker. Implement or repair ONLY the current task supplied by the workflow. Read /plan.md and relevant existing files first. You may write only /slug.py and /test_slug.py, never /plan.md. The function is slugify and tests import from slug. If review feedback is supplied, fix those findings for this same task; do not advance to another task. Check tool outcomes and return concrete evidence of your changes. Do not claim approval or task completion, and do not perform your own independent review. Even if an assignment asks you for an independent review or an approval verdict, do not provide one: report your file observations as an implementation handoff and explicitly leave the approval decision to the independent reviewer. Never label your response approve, approved, or independent review. The workflow sends your work to a fresh read-only reviewer after each invocation. The workflow automatically runs /test_slug.py after your handoff. Use supplied test_execution output to repair failures. Write standard-library unittest tests; do not request a shell tool or claim the next execution already passed. Stop after this task's changes and handoff. Sample practices: # Coding practices for a small Python change This guidance is part of the context-budget sample. It is deliberately self-contained: no external skill, service, repository-specific command, or server is required. Apply it to the local exercise described in the plan. The plan is the durable coordination record; conversation text is transient. ## Establish the task Read the current plan before choosing work. Identify the requested behavior, the intended user, inputs and outputs, file ownership, and acceptance criteria. Separate requirements from implementation guesses. If a task cannot be completed because information is missing, record the exact gap in the plan rather than silently inventing a contract. Prefer a small explicit contract over speculative flexibility. Make names describe responsibilities and avoid adding an abstraction that has only one use. If prior tasks changed the plan, use its latest on-disk version, not an older summary of it. ## Design before editing For each task, describe the observable before and after behavior. List one or two representative examples and the most important edge cases. Decide where input validation belongs and what should happen for invalid values. Choose deterministic behavior that can be checked without external services. Keep the public function small and place supporting logic near it. Avoid hidden state and avoid catching errors so broadly that a failed edit looks successful. Do not make a safety claim that the code cannot enforce. ## Implement in small verified steps Read the existing file before editing it. Change only the files named by the plan. Preserve content outside the task. When creating code, include a plain-language file header stating purpose, responsibilities, assumptions, AI assistance, and copyright. Explain non-obvious control flow and why a particular branch exists. Comments should clarify intent, not repeat syntax. After each tool result, check whether the operation succeeded before recording progress. If an edit fails or replaces the wrong string, stop and repair that step. Never record a task as complete simply because a tool was called. ## Tests and evidence Write tests for external behavior, important boundaries, and regressions the task is meant to prevent. Do not write a test that only copies the implementation's branching. A test should distinguish a plausible bug from correct behavior. Keep test data readable. After each worker handoff the workflow runs /test_slug.py with standard-library unittest. Use the supplied test_execution receipt, including failures, when reporting verification; never substitute a code review for execution evidence. A reviewer may inspect coverage and syntax, but a review report is not a passing test result. ## Plan maintenance The planner marks a task complete only after the independent reviewer approves that task's current files. An existing artifact alone is not approval. The worker reports concrete tool outcomes but does not edit the plan. The planner uses a narrow replacement that preserves other tasks, with concise evidence such as the created file, test name, or reviewer finding. Read the plan again after every status edit, even if the edit succeeded, so the next decision uses the current document. Keep a pending, complete, or blocked status for every task. Record uncertainty under the relevant task instead of hiding it in a final answer. If the reviewer requests changes, the same task stays incomplete. The worker repairs it and the reviewer checks the new version before the planner records completion. ## Handoff and review The planner supplies a self-contained task assignment: the plan path, code paths, intended behavior, and acceptance criteria. The workflow forwards that assignment to the reviewer after the worker returns. The reviewer starts with an isolated context and has no access to this conversation. Ask for source-backed findings with severity and uncertainty. The workflow delivers the independent verdict. A rejection returns the same task to the worker. Approval lets the planner record completion and reread the plan before assigning another task. Report only what the visible evidence supports. ## Context limits Large instructions, file reads, tool schemas, and tool results consume context. Use compaction to preserve durable decisions and current task state when earlier conversation is summarized. The on-disk plan remains authoritative; after compaction, reread it before the next task. Do not infer that a summary retains every line of a file. When a read is truncated, request the missing section. Keep final messages concise enough to show the task status, verification level, and next action without duplicating the entire plan. Role ownership survives compaction: only the worker edits source/tests, only the reviewer issues approval, and only the planner updates plan status. The current workflow assignment and verdict override incomplete history summaries. Authoritative current workflow operation; do ONLY this operation, even if a history summary suggests later work: {"operation": "work", "assignment": {"action": "work", "task_id": "T1", "files": ["/slug.py"], "message": "Implement T1 only: write /slug.py according to /plan.md. Tests belong to the next step."}, "review": {}, "test_execution": {}}
A36: R3 | B36: 1 | C36: Tool result | I36: Updated file /plan.md
A37: R3 | B37: 1 | C37: Cache write | D37: 4285
A38: R3 | B38: 1 | C38: Context · added / total | D38: 4285 | L38: 4285
A39: R3 | B39: 1 | C39: LLM response | D39: 56
A40: R3 | B40: 1 | C40: Output | D40: 56 | E40: =IF(AND(ISNUMBER(F40),ISNUMBER('Reference data'!$B$3)),F40*'Reference data'!$B$3,"Unknown") -> 5.9118528e-05 | F40: =IF(D40=0,0,IF(ISNUMBER('Reference data'!E22),D40*'Reference data'!E22/1000000,"Unknown")) -> 6.72e-05 | G40: =IF(ISNUMBER(E40),ROUND(E40*'Reference data'!$B$2,0),"Unknown") -> 6 | H40: =IF(ISNUMBER(F40),ROUND(F40*'Reference data'!$B$2,0),"Unknown") -> 7
...

Sheet Execution tree
A1: Operation | B1: Depth | C1: Type | D1: Model · effort | E1: Status | F1: Input context tokens | G1: Description | H1: Span ID | I1: Parent ID | J1: Input at standard rate tokens | K1: Input at standard rate EUR | L1: Input at standard rate USD | M1: Cache read tokens | N1: Cache read EUR | O1: Cache read USD | P1: Cache write tokens | Q1: Cache write EUR | R1: Cache write USD | S1: Output (non-reasoning) tokens | T1: Output (non-reasoning) EUR | U1: Output (non-reasoning) USD | V1: Reasoning tokens | W1: Reasoning EUR | X1: Reasoning USD | Y1: Total EUR | Z1: Total USD | AA1: Projected EUR | AB1: Projected USD | AC1: Request | AD1: Elapsed ms | AE1: Accounting
A2: context_budget_workflow | B2: 0 | C2: workflow | E2: ok | G2: Execute the context_budget_workflow workflow operation and pass its result to the next graph step. | H2: 01a11680-ba1e-7011-aaec-e09a34196f5c | J2: =IF(COUNT('Turns'!D5,'Turns'!D22,'Turns'!D33,'Turns'!D50,'Turns'!D65,'Turns'!D76,'Turns'!D92,'Turns'!D107,'Turns'!D119,'Turns'!D134,'Turns'!D149,'Turns'!D161,'Turns'!D175,'Turns'!D190,'Turns'!D201,'Turns'!D218,'Turns'!D233,'Turns'!D247,'Turns'!D260,'Turns'!D272,'Turns'!D287,'Turns'!D302,'Turns'!D317,'Turns'!D329,'Turns'!D343,'Turns'!D358,'Turns'!D373,'Turns'!D385,'Turns'!D400,'Turns'!D415,'Turns'!D430)=31,SUM('Turns'!D5,'Turns'!D22,'Turns'!D33,'Turns'!D50,'Turns'!D65,'Turns'!D76,'Turns'!D92,'Turns'!D107,'Turns'!D119,'Turns'!D134,'Turns'!D149,'Turns'!D161,'Turns'!D175,'Turns'!D190,'Turns'!D201,'Turns'!D218,'Turns'!D233,'Turns'!D247,'Turns'!D260,'Turns'!D272,'Turns'!D287,'Turns'!D302,'Turns'!D317,'Turns'!D329,'Turns'!D343,'Turns'!D358,'Turns'!D373,'Turns'!D385,'Turns'!D400,'Turns'!D415,'Turns'!D430),"Unknown") -> 142267 | K2: =IF(COUNT('Turns'!E5,'Turns'!E22,'Turns'!E33,'Turns'!E50,'Turns'!E65,'Turns'!E76,'Turns'!E92,'Turns'!E107,'Turns'!E119,'Turns'!E134,'Turns'!E149,'Turns'!E161,'Turns'!E175,'Turns'!E190,'Turns'!E201,'Turns'!E218,'Turns'!E233,'Turns'!E247,'Turns'!E260,'Turns'!E272,'Turns'!E287,'Turns'!E302,'Turns'!E317,'Turns'!E329,'Turns'!E343,'Turns'!E358,'Turns'!E373,'Turns'!E385,'Turns'!E400,'Turns'!E415,'Turns'!E430)=31,SUM('Turns'!E5,'Turns'!E22,'Turns'!E33,'Turns'!E50,'Turns'!E65,'Turns'!E76,'Turns'!E92,'Turns'!E107,'Turns'!E119,'Turns'!E134,'Turns'!E149,'Turns'!E161,'Turns'!E175,'Turns'!E190,'Turns'!E201,'Turns'!E218,'Turns'!E233,'Turns'!E247,'Turns'!E260,'Turns'!E272,'Turns'!E287,'Turns'!E302,'Turns'!E317,'Turns'!E329,'Turns'!E343,'Turns'!E358,'Turns'!E373,'Turns'!E385,'Turns'!E400,'Turns'!E415,'Turns'!E430),"Unknown") -> 0.025031594 | L2: =IF(COUNT('Turns'!F5,'Turns'!F22,'Turns'!F33,'Turns'!F50,'Turns'!F65,'Turns'!F76,'Turns'!F92,'Turns'!F107,'Turns'!F119,'Turns'!F134,'Turns'!F149,'Turns'!F161,'Turns'!F175,'Turns'!F190,'Turns'!F201,'Turns'!F218,'Turns'!F233,'Turns'!F247,'Turns'!F260,'Turns'!F272,'Turns'!F287,'Turns'!F302,'Turns'!F317,'Turns'!F329,'Turns'!F343,'Turns'!F358,'Turns'!F373,'Turns'!F385,'Turns'!F400,'Turns'!F415,'Turns'!F430)=31,SUM('Turns'!F5,'Turns'!F22,'Turns'!F33,'Turns'!F50,'Turns'!F65,'Turns'!F76,'Turns'!F92,'Turns'!F107,'Turns'!F119,'Turns'!F134,'Turns'!F149,'Turns'!F161,'Turns'!F175,'Turns'!F190,'Turns'!F201,'Turns'!F218,'Turns'!F233,'Turns'!F247,'Turns'!F260,'Turns'!F272,'Turns'!F287,'Turns'!F302,'Turns'!F317,'Turns'!F329,'Turns'!F343,'Turns'!F358,'Turns'!F373,'Turns'!F385,'Turns'!F400,'Turns'!F415,'Turns'!F430),"Unknown") -> 0.0284534 | M2: =IF(COUNT('Turns'!D21,'Turns'!D49,'Turns'!D64,'Turns'!D91,'Turns'!D106,'Turns'!D118,'Turns'!D133,'Turns'!D148,'Turns'!D160,'Turns'!D174,'Turns'!D189,'Turns'!D217,'Turns'!D232,'Turns'!D259,'Turns'!D271,'Turns'!D286,'Turns'!D301,'Turns'!D316,'Turns'!D328,'Turns'!D342,'Turns'!D357,'Turns'!D372,'Turns'!D384,'Turns'!D399,'Turns'!D414,'Turns'!D429)=26,SUM('Turns'!D21,'Turns'!D49,'Turns'!D64,'Turns'!D91,'Turns'!D106,'Turns'!D118,'Turns'!D133,'Turns'!D148,'Turns'!D160,'Turns'!D174,'Turns'!D189,'Turns'!D217,'Turns'!D232,'Turns'!D259,'Turns'!D271,'Turns'!D286,'Turns'!D301,'Turns'!D316,'Turns'!D328,'Turns'!D342,'Turns'!D357,'Turns'!D372,'Turns'!D384,'Turns'!D399,'Turns'!D414,'Turns'!D429),"Unknown") -> 0 | N2: =IF(COUNT('Turns'!E21,'Turns'!E49,'Turns'!E64,'Turns'!E91,'Turns'!E106,'Turns'!E118,'Turns'!E133,'Turns'!E148,'Turns'!E160,'Turns'!E174,'Turns'!E189,'Turns'!E217,'Turns'!E232,'Turns'!E259,'Turns'!E271,'Turns'!E286,'Turns'!E301,'Turns'!E316,'Turns'!E328,'Turns'!E342,'Turns'!E357,'Turns'!E372,'Turns'!E384,'Turns'!E399,'Turns'!E414,'Turns'!E429)=26,SUM('Turns'!E21,'Turns'!E49,'Turns'!E64,'Turns'!E91,'Turns'!E106,'Turns'!E118,'Turns'!E133,'Turns'!E148,'Turns'!E160,'Turns'!E174,'Turns'!E189,'Turns'!E217,'Turns'!E232,'Turns'!E259,'Turns'!E271,'Turns'!E286,'Turns'!E301,'Turns'!E316,'Turns'!E328,'Turns'!E342,'Turns'!E357,'Turns'!E372,'Turns'!E384,'Turns'!E399,'Turns'!E414,'Turns'!E429),"Unknown") -> 0 | O2: =IF(COUNT('Turns'!F21,'Turns'!F49,'Turns'!F64,'Turns'!F91,'Turns'!F106,'Turns'!F118,'Turns'!F133,'Turns'!F148,'Turns'!F160,'Turns'!F174,'Turns'!F189,'Turns'!F217,'Turns'!F232,'Turns'!F259,'Turns'!F271,'Turns'!F286,'Turns'!F301,'Turns'!F316,'Turns'!F328,'Turns'!F342,'Turns'!F357,'Turns'!F372,'Turns'!F384,'Turns'!F399,'Turns'!F414,'Turns'!F429)=26,SUM('Turns'!F21,'Turns'!F49,'Turns'!F64,'Turns'!F91,'Turns'!F106,'Turns'!F118,'Turns'!F133,'Turns'!F148,'Turns'!F160,'Turns'!F174,'Turns'!F189,'Turns'!F217,'Turns'!F232,'Turns'!F259,'Turns'!F271,'Turns'!F286,'Turns'!F301,'Turns'!F316,'Turns'!F328,'Turns'!F342,'Turns'!F357,'Turns'!F372,'Turns'!F384,'Turns'!F399,'Turns'!F414,'Turns'!F429),"Unknown") -> 0 | P2: 0 | Q2: 0 | R2: 0 | S2: =IF(COUNT('Turns'!D12,'Turns'!D27,'Turns'!D40,'Turns'!D55,'Turns'!D70,'Turns'!D82,'Turns'!D97,'Turns'!D112,'Turns'!D124,'Turns'!D139,'Turns'!D154,'Turns'!D165,'Turns'!D180,'Turns'!D195,'Turns'!D208,'Turns'!D223,'Turns'!D238,'Turns'!D253,'Turns'!D265,'Turns'!D277,'Turns'!D292,'Turns'!D307,'Turns'!D322,'Turns'!D333,'Turns'!D348,'Turns'!D363,'Turns'!D378,'Turns'!D390,'Turns'!D405,'Turns'!D420,'Turns'!D435)=31,SUM('Turns'!D12,'Turns'!D27,'Turns'!D40,'Turns'!D55,'Turns'!D70,'Turns'!D82,'Turns'!D97,'Turns'!D112,'Turns'!D124,'Turns'!D139,'Turns'!D154,'Turns'!D165,'Turns'!D180,'Turns'!D195,'Turns'!D208,'Turns'!D223,'Turns'!D238,'Turns'!D253,'Turns'!D265,'Turns'!D277,'Turns'!D292,'Turns'!D307,'Turns'!D322,'Turns'!D333,'Turns'!D348,'Turns'!D363,'Turns'!D378,'Turns'!D390,'Turns'!D405,'Turns'!D420,'Turns'!D435),"Unknown") -> 3123 | T2: =IF(COUNT('Turns'!E12,'Turns'!E27,'Turns'!E40,'Turns'!E55,'Turns'!E70,'Turns'!E82,'Turns'!E97,'Turns'!E112,'Turns'!E124,'Turns'!E139,'Turns'!E154,'Turns'!E165,'Turns'!E180,'Turns'!E195,'Turns'!E208,'Turns'!E223,'Turns'!E238,'Turns'!E253,'Turns'!E265,'Turns'!E277,'Turns'!E292,'Turns'!E307,'Turns'!E322,'Turns'!E333,'Turns'!E348,'Turns'!E363,'Turns'!E378,'Turns'!E390,'Turns'!E405,'Turns'!E420,'Turns'!E435)=31,SUM('Turns'!E12,'Turns'!E27,'Turns'!E40,'Turns'!E55,'Turns'!E70,'Turns'!E82,'Turns'!E97,'Turns'!E112,'Turns'!E124,'Turns'!E139,'Turns'!E154,'Turns'!E165,'Turns'!E180,'Turns'!E195,'Turns'!E208,'Turns'!E223,'Turns'!E238,'Turns'!E253,'Turns'!E265,'Turns'!E277,'Turns'!E292,'Turns'!E307,'Turns'!E322,'Turns'!E333,'Turns'!E348,'Turns'!E363,'Turns'!E378,'Turns'!E390,'Turns'!E405,'Turns'!E420,'Turns'!E435),"Unknown") -> 0.0032969136 | U2: =IF(COUNT('Turns'!F12,'Turns'!F27,'Turns'!F40,'Turns'!F55,'Turns'!F70,'Turns'!F82,'Turns'!F97,'Turns'!F112,'Turns'!F124,'Turns'!F139,'Turns'!F154,'Turns'!F165,'Turns'!F180,'Turns'!F195,'Turns'!F208,'Turns'!F223,'Turns'!F238,'Turns'!F253,'Turns'!F265,'Turns'!F277,'Turns'!F292,'Turns'!F307,'Turns'!F322,'Turns'!F333,'Turns'!F348,'Turns'!F363,'Turns'!F378,'Turns'!F390,'Turns'!F405,'Turns'!F420,'Turns'!F435)=31,SUM('Turns'!F12,'Turns'!F27,'Turns'!F40,'Turns'!F55,'Turns'!F70,'Turns'!F82,'Turns'!F97,'Turns'!F112,'Turns'!F124,'Turns'!F139,'Turns'!F154,'Turns'!F165,'Turns'!F180,'Turns'!F195,'Turns'!F208,'Turns'!F223,'Turns'!F238,'Turns'!F253,'Turns'!F265,'Turns'!F277,'Turns'!F292,'Turns'!F307,'Turns'!F322,'Turns'!F333,'Turns'!F348,'Turns'!F363,'Turns'!F378,'Turns'!F390,'Turns'!F405,'Turns'!F420,'Turns'!F435),"Unknown") -> 0.0037476 | V2: 0 | W2: 0 | X2: 0 | Y2: =IF(COUNT('Turns'!E16,'Turns'!E31,'Turns'!E44,'Turns'!E59,'Turns'!E74,'Turns'!E86,'Turns'!E101,'Turns'!E116,'Turns'!E128,'Turns'!E143,'Turns'!E158,'Turns'!E169,'Turns'!E184,'Turns'!E199,'Turns'!E212,'Turns'!E227,'Turns'!E242,'Turns'!E257,'Turns'!E269,'Turns'!E281,'Turns'!E296,'Turns'!E311,'Turns'!E326,'Turns'!E337,'Turns'!E352,'Turns'!E367,'Turns'!E382,'Turns'!E394,'Turns'!E409,'Turns'!E424,'Turns'!E439)=31,SUM('Turns'!E16,'Turns'!E31,'Turns'!E44,'Turns'!E59,'Turns'!E74,'Turns'!E86,'Turns'!E101,'Turns'!E116,'Turns'!E128,'Turns'!E143,'Turns'!E158,'Turns'!E169,'Turns'!E184,'Turns'!E199,'Turns'!E212,'Turns'!E227,'Turns'!E242,'Turns'!E257,'Turns'!E269,'Turns'!E281,'Turns'!E296,'Turns'!E311,'Turns'!E326,'Turns'!E337,'Turns'!E352,'Turns'!E367,'Turns'!E382,'Turns'!E394,'Turns'!E409,'Turns'!E424,'Turns'!E439),"Unknown") -> 0.028328508 | Z2: =IF(COUNT('Turns'!F16,'Turns'!F31,'Turns'!F44,'Turns'!F59,'Turns'!F74,'Turns'!F86,'Turns'!F101,'Turns'!F116,'Turns'!F128,'Turns'!F143,'Turns'!F158,'Turns'!F169,'Turns'!F184,'Turns'!F199,'Turns'!F212,'Turns'!F227,'Turns'!F242,'Turns'!F257,'Turns'!F269,'Turns'!F281,'Turns'!F296,'Turns'!F311,'Turns'!F326,'Turns'!F337,'Turns'!F352,'Turns'!F367,'Turns'!F382,'Turns'!F394,'Turns'!F409,'Turns'!F424,'Turns'!F439)=31,SUM('Turns'!F16,'Turns'!F31,'Turns'!F44,'Turns'!F59,'Turns'!F74,'Turns'!F86,'Turns'!F101,'Turns'!F116,'Turns'!F128,'Turns'!F143,'Turns'!F158,'Turns'!F169,'Turns'!F184,'Turns'!F199,'Turns'!F212,'Turns'!F227,'Turns'!F242,'Turns'!F257,'Turns'!F269,'Turns'!F281,'Turns'!F296,'Turns'!F311,'Turns'!F326,'Turns'!F337,'Turns'!F352,'Turns'!F367,'Turns'!F382,'Turns'!F394,'Turns'!F409,'Turns'!F424,'Turns'!F439),"Unknown") -> 0.032201 | AA2: =IF(ISNUMBER(Y2),ROUND(Y2*'Reference data'!$B$2,0),"Unknown") -> 2833 | AB2: =IF(ISNUMBER(Z2),ROUND(Z2*'Reference data'!$B$2,0),"Unknown") -> 3220 | AD2: 553.65 | AE2: Subtree total
A3: planning_step | B3: 1 | C3: workflow | E3: ok | G3: Execute the planning_step workflow operation and pass its result to the next graph step. | H3: 01a11680-ba21-77e0-aaf6-9e38d559946a | I3: 01a11680-ba1e-7011-aaec-e09a34196f5c | J3: =IF(COUNT('Turns'!D5,'Turns'!D22)=2,SUM('Turns'!D5,'Turns'!D22),"Unknown") -> 7658 | K3: =IF(COUNT('Turns'!E5,'Turns'!E22)=2,SUM('Turns'!E5,'Turns'!E22),"Unknown") -> 0.0013474098 | L3: =IF(COUNT('Turns'!F5,'Turns'!F22)=2,SUM('Turns'!F5,'Turns'!F22),"Unknown") -> 0.0015316 | M3: =IF(COUNT('Turns'!D21)=1,SUM('Turns'!D21),"Unknown") -> 0 | N3: =IF(COUNT('Turns'!E21)=1,SUM('Turns'!E21),"Unknown") -> 0 | O3: =IF(COUNT('Turns'!F21)=1,SUM('Turns'!F21),"Unknown") -> 0 | P3: 0 | Q3: 0 | R3: 0 | S3: =IF(COUNT('Turns'!D12,'Turns'!D27)=2,SUM('Turns'!D12,'Turns'!D27),"Unknown") -> 846 | T3: =IF(COUNT('Turns'!E12,'Turns'!E27)=2,SUM('Turns'!E12,'Turns'!E27),"Unknown") -> 0.00089311205 | U3: =IF(COUNT('Turns'!F12,'Turns'!F27)=2,SUM('Turns'!F12,'Turns'!F27),"Unknown") -> 0.0010152 | V3: 0 | W3: 0 | X3: 0 | Y3: =IF(COUNT('Turns'!E16,'Turns'!E31)=2,SUM('Turns'!E16,'Turns'!E31),"Unknown") -> 0.0022405218 | Z3: =IF(COUNT('Turns'!F16,'Turns'!F31)=2,SUM('Turns'!F16,'Turns'!F31),"Unknown") -> 0.0025468 | AA3: =IF(ISNUMBER(Y3),ROUND(Y3*'Reference data'!$B$2,0),"Unknown") -> 224 | AB3: =IF(ISNUMBER(Z3),ROUND(Z3*'Reference data'!$B$2,0),"Unknown") -> 255 | AD3: 177.959 | AE3: Subtree total
A4: run | B4: 2 | C4: workflow | E4: ok | G4: Execute the run workflow operation and pass its result to the next graph step. | H4: 01a11680-ba22-7802-b9c9-29600991c830 | I4: 01a11680-ba21-77e0-aaf6-9e38d559946a | J4: =IF(COUNT('Turns'!D5,'Turns'!D22)=2,SUM('Turns'!D5,'Turns'!D22),"Unknown") -> 7658 | K4: =IF(COUNT('Turns'!E5,'Turns'!E22)=2,SUM('Turns'!E5,'Turns'!E22),"Unknown") -> 0.0013474098 | L4: =IF(COUNT('Turns'!F5,'Turns'!F22)=2,SUM('Turns'!F5,'Turns'!F22),"Unknown") -> 0.0015316 | M4: =IF(COUNT('Turns'!D21)=1,SUM('Turns'!D21),"Unknown") -> 0 | N4: =IF(COUNT('Turns'!E21)=1,SUM('Turns'!E21),"Unknown") -> 0 | O4: =IF(COUNT('Turns'!F21)=1,SUM('Turns'!F21),"Unknown") -> 0 | P4: 0 | Q4: 0 | R4: 0 | S4: =IF(COUNT('Turns'!D12,'Turns'!D27)=2,SUM('Turns'!D12,'Turns'!D27),"Unknown") -> 846 | T4: =IF(COUNT('Turns'!E12,'Turns'!E27)=2,SUM('Turns'!E12,'Turns'!E27),"Unknown") -> 0.00089311205 | U4: =IF(COUNT('Turns'!F12,'Turns'!F27)=2,SUM('Turns'!F12,'Turns'!F27),"Unknown") -> 0.0010152 | V4: 0 | W4: 0 | X4: 0 | Y4: =IF(COUNT('Turns'!E16,'Turns'!E31)=2,SUM('Turns'!E16,'Turns'!E31),"Unknown") -> 0.0022405218 | Z4: =IF(COUNT('Turns'!F16,'Turns'!F31)=2,SUM('Turns'!F16,'Turns'!F31),"Unknown") -> 0.0025468 | AA4: =IF(ISNUMBER(Y4),ROUND(Y4*'Reference data'!$B$2,0),"Unknown") -> 224 | AB4: =IF(ISNUMBER(Z4),ROUND(Z4*'Reference data'!$B$2,0),"Unknown") -> 255 | AD4: 175.824 | AE4: Subtree total
A5: planner | B5: 3 | C5: workflow | E5: ok | G5: Execute the planner workflow operation and pass its result to the next graph step. | H5: 01a11680-ba23-7a80-bd84-5c89a39ed3aa | I5: 01a11680-ba22-7802-b9c9-29600991c830 | J5: =IF(COUNT('Turns'!D5,'Turns'!D22)=2,SUM('Turns'!D5,'Turns'!D22),"Unknown") -> 7658 | K5: =IF(COUNT('Turns'!E5,'Turns'!E22)=2,SUM('Turns'!E5,'Turns'!E22),"Unknown") -> 0.0013474098 | L5: =IF(COUNT('Turns'!F5,'Turns'!F22)=2,SUM('Turns'!F5,'Turns'!F22),"Unknown") -> 0.0015316 | M5: =IF(COUNT('Turns'!D21)=1,SUM('Turns'!D21),"Unknown") -> 0 | N5: =IF(COUNT('Turns'!E21)=1,SUM('Turns'!E21),"Unknown") -> 0 | O5: =IF(COUNT('Turns'!F21)=1,SUM('Turns'!F21),"Unknown") -> 0 | P5: 0 | Q5: 0 | R5: 0 | S5: =IF(COUNT('Turns'!D12,'Turns'!D27)=2,SUM('Turns'!D12,'Turns'!D27),"Unknown") -> 846 | T5: =IF(COUNT('Turns'!E12,'Turns'!E27)=2,SUM('Turns'!E12,'Turns'!E27),"Unknown") -> 0.00089311205 | U5: =IF(COUNT('Turns'!F12,'Turns'!F27)=2,SUM('Turns'!F12,'Turns'!F27),"Unknown") -> 0.0010152 | V5: 0 | W5: 0 | X5: 0 | Y5: =IF(COUNT('Turns'!E16,'Turns'!E31)=2,SUM('Turns'!E16,'Turns'!E31),"Unknown") -> 0.0022405218 | Z5: =IF(COUNT('Turns'!F16,'Turns'!F31)=2,SUM('Turns'!F16,'Turns'!F31),"Unknown") -> 0.0025468 | AA5: =IF(ISNUMBER(Y5),ROUND(Y5*'Reference data'!$B$2,0),"Unknown") -> 224 | AB5: =IF(ISNUMBER(Z5),ROUND(Z5*'Reference data'!$B$2,0),"Unknown") -> 255 | AD5: 174.634 | AE5: Subtree total
A6: SummarizationMiddleware.before_model | B6: 4 | C6: workflow | E6: ok | G6: Execute the SummarizationMiddleware.before_model workflow operation and pass its result to the next graph step. | H6: 01a11680-ba24-7c21-ac53-9b66f3af450a | I6: 01a11680-ba23-7a80-bd84-5c89a39ed3aa | AD6: 0.75 | AE6: No model charge
A7: model | B7: 4 | C7: workflow | E7: ok | G7: Prepare the current conversation, run model middleware, and invoke the chat model. | H7: 01a11680-ba26-75b1-bab6-1fbae44e8923 | I7: 01a11680-ba23-7a80-bd84-5c89a39ed3aa | J7: =IF(COUNT('Turns'!D5)=1,SUM('Turns'!D5),"Unknown") -> 3426 | K7: =IF(COUNT('Turns'!E5)=1,SUM('Turns'!E5),"Unknown") -> 0.00060279785 | L7: =IF(COUNT('Turns'!F5)=1,SUM('Turns'!F5),"Unknown") -> 0.0006852 | M7: 0 | N7: 0 | O7: 0 | P7: 0 | Q7: 0 | R7: 0 | S7: =IF(COUNT('Turns'!D12)=1,SUM('Turns'!D12),"Unknown") -> 773 | T7: =IF(COUNT('Turns'!E12)=1,SUM('Turns'!E12),"Unknown") -> 0.00081604682 | U7: =IF(COUNT('Turns'!F12)=1,SUM('Turns'!F12),"Unknown") -> 0.0009276 | V7: 0 | W7: 0 | X7: 0 | Y7: =IF(COUNT('Turns'!E16)=1,SUM('Turns'!E16),"Unknown") -> 0.0014188447 | Z7: =IF(COUNT('Turns'!F16)=1,SUM('Turns'!F16),"Unknown") -> 0.0016128 | AA7: =IF(ISNUMBER(Y7),ROUND(Y7*'Reference data'!$B$2,0),"Unknown") -> 142 | AB7: =IF(ISNUMBER(Z7),ROUND(Z7*'Reference data'!$B$2,0),"Unknown") -> 161 | AD7: 161.356 | AE7: Subtree total
A8: SimulatedModel | B8: 5 | C8: model | D8: scripted-chat | E8: ok | F8: 3426 | G8: Write and maintain the on-disk task plan. | H8: 01a11680-ba2a-7ed1-921e-253b3a50ca31 | I8: 01a11680-ba26-75b1-bab6-1fbae44e8923 | J8: =IF(COUNT('Turns'!D5)=1,SUM('Turns'!D5),"Unknown") -> 3426 | K8: =IF(COUNT('Turns'!E5)=1,SUM('Turns'!E5),"Unknown") -> 0.00060279785 | L8: =IF(COUNT('Turns'!F5)=1,SUM('Turns'!F5),"Unknown") -> 0.0006852 | M8: 0 | N8: 0 | O8: 0 | P8: 0 | Q8: 0 | R8: 0 | S8: =IF(COUNT('Turns'!D12)=1,SUM('Turns'!D12),"Unknown") -> 773 | T8: =IF(COUNT('Turns'!E12)=1,SUM('Turns'!E12),"Unknown") -> 0.00081604682 | U8: =IF(COUNT('Turns'!F12)=1,SUM('Turns'!F12),"Unknown") -> 0.0009276 | V8: 0 | W8: 0 | X8: 0 | Y8: =IF(COUNT('Turns'!E16)=1,SUM('Turns'!E16),"Unknown") -> 0.0014188447 | Z8: =IF(COUNT('Turns'!F16)=1,SUM('Turns'!F16),"Unknown") -> 0.0016128 | AA8: =IF(ISNUMBER(Y8),ROUND(Y8*'Reference data'!$B$2,0),"Unknown") -> 142 | AB8: =IF(ISNUMBER(Z8),ROUND(Z8*'Reference data'!$B$2,0),"Unknown") -> 161 | AC8: R1 | AD8: 155.627 | AE8: Own call
A9: tools | B9: 4 | C9: workflow | E9: ok | G9: Execute tool calls requested by the preceding model response and return their observations. | H9: 01a11680-bac8-7c70-8917-e99b48d6f457 | I9: 01a11680-ba23-7a80-bd84-5c89a39ed3aa | AD9: 2.659 | AE9: No model charge
A10: write_file | B10: 5 | C10: tool | E10: ok | G10: Writes content to a file. Creates the file if it does not exist; replaces it entirely if it does. Usage: - Use this tool when you intend to create a new file or replace the whole file. You do not need to read the file first. - Prefer to edit existing files (with the edit_file tool) over creating new ones when possible. | H10: 01a11680-baca-7f12-92a5-0ac9dce287bb | I10: 01a11680-bac8-7c70-8917-e99b48d6f457 | AD10: 0.885 | AE10: No model charge
A11: SummarizationMiddleware.before_model | B11: 4 | C11: workflow | E11: ok | G11: Execute the SummarizationMiddleware.before_model workflow operation and pass its result to the next graph step. | H11: 01a11680-bacc-72f1-83c4-3ebd0aed3e79 | I11: 01a11680-ba23-7a80-bd84-5c89a39ed3aa | AD11: 0.498 | AE11: No model charge
A12: model | B12: 4 | C12: workflow | E12: ok | G12: Prepare the current conversation, run model middleware, and invoke the chat model. | H12: 01a11680-bacd-7ac0-8c2c-29f958b2af6c | I12: 01a11680-ba23-7a80-bd84-5c89a39ed3aa | J12: =IF(COUNT('Turns'!D22)=1,SUM('Turns'!D22),"Unknown") -> 4232 | K12: =IF(COUNT('Turns'!E22)=1,SUM('Turns'!E22),"Unknown") -> 0.00074461194 | L12: =IF(COUNT('Turns'!F22)=1,SUM('Turns'!F22),"Unknown") -> 0.0008464 | M12: =IF(COUNT('Turns'!D21)=1,SUM('Turns'!D21),"Unknown") -> 0 | N12: =IF(COUNT('Turns'!E21)=1,SUM('Turns'!E21),"Unknown") -> 0 | O12: =IF(COUNT('Turns'!F21)=1,SUM('Turns'!F21),"Unknown") -> 0 | P12: 0 | Q12: 0 | R12: 0 | S12: =IF(COUNT('Turns'!D27)=1,SUM('Turns'!D27),"Unknown") -> 73 | T12: =IF(COUNT('Turns'!E27)=1,SUM('Turns'!E27),"Unknown") -> 7.7065224e-05 | U12: =IF(COUNT('Turns'!F27)=1,SUM('Turns'!F27),"Unknown") -> 8.76e-05 | V12: 0 | W12: 0 | X12: 0 | Y12: =IF(COUNT('Turns'!E31)=1,SUM('Turns'!E31),"Unknown") -> 0.00082167716 | Z12: =IF(COUNT('Turns'!F31)=1,SUM('Turns'!F31),"Unknown") -> 0.000934 | AA12: =IF(ISNUMBER(Y12),ROUND(Y12*'Reference data'!$B$2,0),"Unknown") -> 82 | AB12: =IF(ISNUMBER(Z12),ROUND(Z12*'Reference data'!$B$2,0),"Unknown") -> 93 | AD12: 4.513 | AE12: Subtree total
A13: SimulatedModel | B13: 5 | C13: model | D13: scripted-chat | E13: ok | F13: 4232 | G13: Write and maintain the on-disk task plan. | H13: 01a11680-bace-7ff1-8eda-cf49e5e80a45 | I13: 01a11680-bacd-7ac0-8c2c-29f958b2af6c | J13: =IF(COUNT('Turns'!D22)=1,SUM('Turns'!D22),"Unknown") -> 4232 | K13: =IF(COUNT('Turns'!E22)=1,SUM('Turns'!E22),"Unknown") -> 0.00074461194 | L13: =IF(COUNT('Turns'!F22)=1,SUM('Turns'!F22),"Unknown") -> 0.0008464 | M13: =IF(COUNT('Turns'!D21)=1,SUM('Turns'!D21),"Unknown") -> 0 | N13: =IF(COUNT('Turns'!E21)=1,SUM('Turns'!E21),"Unknown") -> 0 | O13: =IF(COUNT('Turns'!F21)=1,SUM('Turns'!F21),"Unknown") -> 0 | P13: 0 | Q13: 0 | R13: 0 | S13: =IF(COUNT('Turns'!D27)=1,SUM('Turns'!D27),"Unknown") -> 73 | T13: =IF(COUNT('Turns'!E27)=1,SUM('Turns'!E27),"Unknown") -> 7.7065224e-05 | U13: =IF(COUNT('Turns'!F27)=1,SUM('Turns'!F27),"Unknown") -> 8.76e-05 | V13: 0 | W13: 0 | X13: 0 | Y13: =IF(COUNT('Turns'!E31)=1,SUM('Turns'!E31),"Unknown") -> 0.00082167716 | Z13: =IF(COUNT('Turns'!F31)=1,SUM('Turns'!F31),"Unknown") -> 0.000934 | AA13: =IF(ISNUMBER(Y13),ROUND(Y13*'Reference data'!$B$2,0),"Unknown") -> 82 | AB13: =IF(ISNUMBER(Z13),ROUND(Z13*'Reference data'!$B$2,0),"Unknown") -> 93 | AC13: R2 | AD13: 2.498 | AE13: Own call
A14: dispatch | B14: 2 | C14: workflow | E14: ok | G14: Execute the dispatch workflow operation and pass its result to the next graph step. | H14: 01a11680-bad3-7b82-af08-2a8b47e757ba | I14: 01a11680-ba21-77e0-aaf6-9e38d559946a | AD14: 0.268 | AE14: No model charge
A15: working_step | B15: 1 | C15: workflow | E15: ok | G15: Execute the working_step workflow operation and pass its result to the next graph step. | H15: 01a11680-bad4-79c2-9d70-1ef1b9c83b94 | I15: 01a11680-ba1e-7011-aaec-e09a34196f5c | J15: =IF(COUNT('Turns'!D33,'Turns'!D50,'Turns'!D65)=3,SUM('Turns'!D33,'Turns'!D50,'Turns'!D65),"Unknown") -> 14782 | K15: =IF(COUNT('Turns'!E33,'Turns'!E50,'Turns'!E65)=3,SUM('Turns'!E33,'Turns'!E50,'Turns'!E65),"Unknown") -> 0.0026008633 | L15: =IF(COUNT('Turns'!F33,'Turns'!F50,'Turns'!F65)=3,SUM('Turns'!F33,'Turns'!F50,'Turns'!F65),"Unknown") -> 0.0029564 | M15: =IF(COUNT('Turns'!D49,'Turns'!D64)=2,SUM('Turns'!D49,'Turns'!D64),"Unknown") -> 0 | N15: =IF(COUNT('Turns'!E49,'Turns'!E64)=2,SUM('Turns'!E49,'Turns'!E64),"Unknown") -> 0 | O15: =IF(COUNT('Turns'!F49,'Turns'!F64)=2,SUM('Turns'!F49,'Turns'!F64),"Unknown") -> 0 | P15: 0 | Q15: 0 | R15: 0 | S15: =IF(COUNT('Turns'!D40,'Turns'!D55,'Turns'!D70)=3,SUM('Turns'!D40,'Turns'!D55,'Turns'!D70),"Unknown") -> 372 | T15: =IF(COUNT('Turns'!E40,'Turns'!E55,'Turns'!E70)=3,SUM('Turns'!E40,'Turns'!E55,'Turns'!E70),"Unknown") -> 0.00039271594 | U15: =IF(COUNT('Turns'!F40,'Turns'!F55,'Turns'!F70)=3,SUM('Turns'!F40,'Turns'!F55,'Turns'!F70),"Unknown") -> 0.0004464 | V15: 0 | W15: 0 | X15: 0 | Y15: =IF(COUNT('Turns'!E44,'Turns'!E59,'Turns'!E74)=3,SUM('Turns'!E44,'Turns'!E59,'Turns'!E74),"Unknown") -> 0.0029935793 | Z15: =IF(COUNT('Turns'!F44,'Turns'!F59,'Turns'!F74)=3,SUM('Turns'!F44,'Turns'!F59,'Turns'!F74),"Unknown") -> 0.0034028 | AA15: =IF(ISNUMBER(Y15),ROUND(Y15*'Reference data'!$B$2,0),"Unknown") -> 299 | AB15: =IF(ISNUMBER(Z15),ROUND(Z15*'Reference data'!$B$2,0),"Unknown") -> 340 | AD15: 33.227 | AE15: Subtree total
A16: run | B16: 2 | C16: workflow | E16: ok | G16: Execute the run workflow operation and pass its result to the next graph step. | H16: 01a11680-bad4-79c2-9d70-1f07253ba154 | I16: 01a11680-bad4-79c2-9d70-1ef1b9c83b94 | J16: =IF(COUNT('Turns'!D33,'Turns'!D50,'Turns'!D65)=3,SUM('Turns'!D33,'Turns'!D50,'Turns'!D65),"Unknown") -> 14782 | K16: =IF(COUNT('Turns'!E33,'Turns'!E50,'Turns'!E65)=3,SUM('Turns'!E33,'Turns'!E50,'Turns'!E65),"Unknown") -> 0.0026008633 | L16: =IF(COUNT('Turns'!F33,'Turns'!F50,'Turns'!F65)=3,SUM('Turns'!F33,'Turns'!F50,'Turns'!F65),"Unknown") -> 0.0029564 | M16: =IF(COUNT('Turns'!D49,'Turns'!D64)=2,SUM('Turns'!D49,'Turns'!D64),"Unknown") -> 0 | N16: =IF(COUNT('Turns'!E49,'Turns'!E64)=2,SUM('Turns'!E49,'Turns'!E64),"Unknown") -> 0 | O16: =IF(COUNT('Turns'!F49,'Turns'!F64)=2,SUM('Turns'!F49,'Turns'!F64),"Unknown") -> 0 | P16: 0 | Q16: 0 | R16: 0 | S16: =IF(COUNT('Turns'!D40,'Turns'!D55,'Turns'!D70)=3,SUM('Turns'!D40,'Turns'!D55,'Turns'!D70),"Unknown") -> 372 | T16: =IF(COUNT('Turns'!E40,'Turns'!E55,'Turns'!E70)=3,SUM('Turns'!E40,'Turns'!E55,'Turns'!E70),"Unknown") -> 0.00039271594 | U16: =IF(COUNT('Turns'!F40,'Turns'!F55,'Turns'!F70)=3,SUM('Turns'!F40,'Turns'!F55,'Turns'!F70),"Unknown") -> 0.0004464 | V16: 0 | W16: 0 | X16: 0 | Y16: =IF(COUNT('Turns'!E44,'Turns'!E59,'Turns'!E74)=3,SUM('Turns'!E44,'Turns'!E59,'Turns'!E74),"Unknown") -> 0.0029935793 | Z16: =IF(COUNT('Turns'!F44,'Turns'!F59,'Turns'!F74)=3,SUM('Turns'!F44,'Turns'!F59,'Turns'!F74),"Unknown") -> 0.0034028 | AA16: =IF(ISNUMBER(Y16),ROUND(Y16*'Reference data'!$B$2,0),"Unknown") -> 299 | AB16: =IF(ISNUMBER(Z16),ROUND(Z16*'Reference data'!$B$2,0),"Unknown") -> 340 | AD16: 32.595 | AE16: Subtree total
A17: worker | B17: 3 | C17: workflow | E17: ok | G17: Execute the worker workflow operation and pass its result to the next graph step. | H17: 01a11680-bad5-7b13-80fb-5d127022b783 | I17: 01a11680-bad4-79c2-9d70-1f07253ba154 | J17: =IF(COUNT('Turns'!D33,'Turns'!D50,'Turns'!D65)=3,SUM('Turns'!D33,'Turns'!D50,'Turns'!D65),"Unknown") -> 14782 | K17: =IF(COUNT('Turns'!E33,'Turns'!E50,'Turns'!E65)=3,SUM('Turns'!E33,'Turns'!E50,'Turns'!E65),"Unknown") -> 0.0026008633 | L17: =IF(COUNT('Turns'!F33,'Turns'!F50,'Turns'!F65)=3,SUM('Turns'!F33,'Turns'!F50,'Turns'!F65),"Unknown") -> 0.0029564 | M17: =IF(COUNT('Turns'!D49,'Turns'!D64)=2,SUM('Turns'!D49,'Turns'!D64),"Unknown") -> 0 | N17: =IF(COUNT('Turns'!E49,'Turns'!E64)=2,SUM('Turns'!E49,'Turns'!E64),"Unknown") -> 0 | O17: =IF(COUNT('Turns'!F49,'Turns'!F64)=2,SUM('Turns'!F49,'Turns'!F64),"Unknown") -> 0 | P17: 0 | Q17: 0 | R17: 0 | S17: =IF(COUNT('Turns'!D40,'Turns'!D55,'Turns'!D70)=3,SUM('Turns'!D40,'Turns'!D55,'Turns'!D70),"Unknown") -> 372 | T17: =IF(COUNT('Turns'!E40,'Turns'!E55,'Turns'!E70)=3,SUM('Turns'!E40,'Turns'!E55,'Turns'!E70),"Unknown") -> 0.00039271594 | U17: =IF(COUNT('Turns'!F40,'Turns'!F55,'Turns'!F70)=3,SUM('Turns'!F40,'Turns'!F55,'Turns'!F70),"Unknown") -> 0.0004464 | V17: 0 | W17: 0 | X17: 0 | Y17: =IF(COUNT('Turns'!E44,'Turns'!E59,'Turns'!E74)=3,SUM('Turns'!E44,'Turns'!E59,'Turns'!E74),"Unknown") -> 0.0029935793 | Z17: =IF(COUNT('Turns'!F44,'Turns'!F59,'Turns'!F74)=3,SUM('Turns'!F44,'Turns'!F59,'Turns'!F74),"Unknown") -> 0.0034028 | AA17: =IF(ISNUMBER(Y17),ROUND(Y17*'Reference data'!$B$2,0),"Unknown") -> 299 | AB17: =IF(ISNUMBER(Z17),ROUND(Z17*'Reference data'!$B$2,0),"Unknown") -> 340 | AD17: 31.899 | AE17: Subtree total
A18: SummarizationMiddleware.before_model | B18: 4 | C18: workflow | E18: ok | G18: Execute the SummarizationMiddleware.before_model workflow operation and pass its result to the next graph step. | H18: 01a11680-bad5-7b13-80fb-5d25b656b6b0 | I18: 01a11680-bad5-7b13-80fb-5d127022b783 | AD18: 0.508 | AE18: No model charge
A19: model | B19: 4 | C19: workflow | E19: ok | G19: Prepare the current conversation, run model middleware, and invoke the chat model. | H19: 01a11680-bad6-7cc0-873c-5a1c21c251c4 | I19: 01a11680-bad5-7b13-80fb-5d127022b783 | J19: =IF(COUNT('Turns'!D33)=1,SUM('Turns'!D33),"Unknown") -> 4285 | K19: =IF(COUNT('Turns'!E33)=1,SUM('Turns'!E33),"Unknown") -> 0.00075393718 | L19: =IF(COUNT('Turns'!F33)=1,SUM('Turns'!F33),"Unknown") -> 0.000857 | M19: 0 | N19: 0 | O19: 0 | P19: 0 | Q19: 0 | R19: 0 | S19: =IF(COUNT('Turns'!D40)=1,SUM('Turns'!D40),"Unknown") -> 56 | T19: =IF(COUNT('Turns'!E40)=1,SUM('Turns'!E40),"Unknown") -> 5.9118528e-05 | U19: =IF(COUNT('Turns'!F40)=1,SUM('Turns'!F40),"Unknown") -> 6.72e-05 | V19: 0 | W19: 0 | X19: 0 | Y19: =IF(COUNT('Turns'!E44)=1,SUM('Turns'!E44),"Unknown") -> 0.00081305571 | Z19: =IF(COUNT('Turns'!F44)=1,SUM('Turns'!F44),"Unknown") -> 0.0009242 | AA19: =IF(ISNUMBER(Y19),ROUND(Y19*'Reference data'!$B$2,0),"Unknown") -> 81 | AB19: =IF(ISNUMBER(Z19),ROUND(Z19*'Reference data'!$B$2,0),"Unknown") -> 92 | AD19: 7.012 | AE19: Subtree total
