Workbook

Sheet QA
A1: Criterion | B1: Score / 100 | C1: Reason
A2: Status | B2: completed | C2: codex:gpt-6-sol
A3: Overall | B3: 75.1 | C3: Rubric coverage: 100%; available weights renormalized
A4: Judge overhead | B4: 13.47s | C4: 0.035052 USD estimated
A5: Summary | C5: The execution answered both questions clearly but only partially met the stated goal because it did not demonstrate how a specific tool observation supports a next action or final answer.
A6: Goal Achievement | B6: 65 | C6: The first CodexChatModel response (01a111d2-309c-7bc0-aaf3-f0a734a28bec) clearly explains the workflow steps, and the second (01a111d2-6342-7351-99ec-1f3a828fd569) explains how observations inform an answer or next action. The stated goal also requires an example of using a tool observation; naming file contents and test results does not show a specific observation leading to a decision.
A7: Answer Quality | B7: 72 | C7: Both answers are clear, relevant, and appropriately concise. The observation answer is accurate but lacks a concrete evidence-to-action example. No tool was used, so the record does not support a claim that an actual observation was evaluated. The event record is not truncated.
A8: Speed | B8: 80 | C8: The recorded 17,884 ms covers two model calls and appears reasonable for two short chat answers. It includes workflow overhead; without an SLA or comparison baseline, a stronger speed judgment is not supported.
A9: Cost | B9: 82 | C9: The estimated cost is $0.0034632 for two model calls, with no missing usage or unpriced calls. That is modest for the useful answers, though the missing concrete example reduces value. This is an estimate, not a subscription charge.

Sheet Turns
A1: Request | B1: Turn | C1: Sequence | D1: Tokens | E1: EUR / execution | F1: USD / execution | G1: Projected EUR | H1: Projected USD | I1: Content | J1: Model · effort | K1: Status | L1: Context total tokens | M1: Span ID
C2: Run total | E2: =IF(COUNT('Turns'!E16,'Turns'!E29)=2,SUM('Turns'!E16,'Turns'!E29),"Unknown") -> 0.0030467156 | F2: =IF(COUNT('Turns'!F16,'Turns'!F29)=2,SUM('Turns'!F16,'Turns'!F29),"Unknown") -> 0.0034632 | G2: =IF(ISNUMBER(E2),ROUND(E2*'Reference data'!$B$2,0),"Unknown") -> 305 | H2: =IF(ISNUMBER(F2),ROUND(F2*'Reference data'!$B$2,0),"Unknown") -> 346
B3: 1 | C3: Turn 1 | E3: =IF(COUNT('Turns'!E16)=1,SUM('Turns'!E16),"Unknown") -> 0.001536202 | F3: =IF(COUNT('Turns'!F16)=1,SUM('Turns'!F16),"Unknown") -> 0.0017462 | G3: =IF(ISNUMBER(E3),ROUND(E3*'Reference data'!$B$2,0),"Unknown") -> 154 | H3: =IF(ISNUMBER(F3),ROUND(F3*'Reference data'!$B$2,0),"Unknown") -> 175
A4: R1 | B4: 1 | C4: LLM request | D4: 16752 | J4: gpt-6-luna | M4: 01a111d2-309c-7bc0-aaf3-f0a734a28bec
A5: R1 | B5: 1 | C5: Input at standard rate | D5: 16752 | E5: =IF(AND(ISNUMBER(F5),ISNUMBER('Reference data'!$B$3)),F5*'Reference data'!$B$3,"Unknown") -> 0.0014737404 | F5: =IF(D5=0,0,IF(ISNUMBER('Reference data'!B40),D5*'Reference data'!B40/1000000,"Unknown")) -> 0.0016752 | G5: =IF(ISNUMBER(E5),ROUND(E5*'Reference data'!$B$2,0),"Unknown") -> 147 | H5: =IF(ISNUMBER(F5),ROUND(F5*'Reference data'!$B$2,0),"Unknown") -> 168
A6: R1 | B6: 1 | C6: Tool definitions
A7: R1 | B7: 1 | C7: System prompt | I7: Answer the user's chat question directly and concisely. Do not use tools for this simple chat exercise.
A8: R1 | B8: 1 | C8: User prompt | I8: Explain the main steps in an agent workflow.
A9: R1 | B9: 1 | C9: Cache write
A10: R1 | B10: 1 | C10: Context · added / total
A11: R1 | B11: 1 | C11: LLM response | D11: 142
A12: R1 | B12: 1 | C12: Output | D12: 142 | E12: =IF(AND(ISNUMBER(F12),ISNUMBER('Reference data'!$B$3)),F12*'Reference data'!$B$3,"Unknown") -> 6.246154e-05 | F12: =IF(D12=0,0,IF(ISNUMBER('Reference data'!E40),D12*'Reference data'!E40/1000000,"Unknown")) -> 7.1e-05 | G12: =IF(ISNUMBER(E12),ROUND(E12*'Reference data'!$B$2,0),"Unknown") -> 6 | H12: =IF(ISNUMBER(F12),ROUND(F12*'Reference data'!$B$2,0),"Unknown") -> 7
A13: R1 | B13: 1 | C13: Output content | I13: An agent workflow typically follows these steps: 1. **Understand the task** and identify the goal, constraints, and expected result. 2. **Gather context** by inspecting relevant files, data, or instructions. 3. **Plan the work**, breaking it into manageable steps and deciding whether tools or collaborators are needed. 4. **Take action** by making changes, answering questions, or using tools as appropriate. 5. **Verify the result** against the requirements, using tests or checks when relevant. 6. **Report back** with a concise summary of what was done and any limitations.
A14: R1 | B14: 1 | C14: Cache write
A15: R1 | B15: 1 | C15: Context · added / total
A16: R1 | B16: 1 | C16: Call total | E16: =IF(COUNT('Turns'!E5,'Turns'!E12)=2,SUM('Turns'!E5,'Turns'!E12),"Unknown") -> 0.001536202 | F16: =IF(COUNT('Turns'!F5,'Turns'!F12)=2,SUM('Turns'!F5,'Turns'!F12),"Unknown") -> 0.0017462 | G16: =IF(ISNUMBER(E16),ROUND(E16*'Reference data'!$B$2,0),"Unknown") -> 154 | H16: =IF(ISNUMBER(F16),ROUND(F16*'Reference data'!$B$2,0),"Unknown") -> 175 | K16: ok
B17: 2 | C17: Turn 2 | E17: =IF(COUNT('Turns'!E29)=1,SUM('Turns'!E29),"Unknown") -> 0.0015105136 | F17: =IF(COUNT('Turns'!F29)=1,SUM('Turns'!F29),"Unknown") -> 0.001717 | G17: =IF(ISNUMBER(E17),ROUND(E17*'Reference data'!$B$2,0),"Unknown") -> 151 | H17: =IF(ISNUMBER(F17),ROUND(F17*'Reference data'!$B$2,0),"Unknown") -> 172
A18: R2 | B18: 2 | C18: LLM request | D18: 16905 | J18: gpt-6-luna | M18: 01a111d2-6342-7351-99ec-1f3a828fd569
A19: R2 | B19: 2 | C19: Conversation history · cache read | D19: 0 | E19: =IF(AND(ISNUMBER(F19),ISNUMBER('Reference data'!$B$3)),F19*'Reference data'!$B$3,"Unknown") -> 0 | F19: =IF(D19=0,0,IF(ISNUMBER('Reference data'!C40),D19*'Reference data'!C40/1000000,"Unknown")) -> 0 | G19: =IF(ISNUMBER(E19),ROUND(E19*'Reference data'!$B$2,0),"Unknown") -> 0 | H19: =IF(ISNUMBER(F19),ROUND(F19*'Reference data'!$B$2,0),"Unknown") -> 0
A20: R2 | B20: 2 | C20: Input at standard rate | D20: 16905 | E20: =IF(AND(ISNUMBER(F20),ISNUMBER('Reference data'!$B$3)),F20*'Reference data'!$B$3,"Unknown") -> 0.0014872005 | F20: =IF(D20=0,0,IF(ISNUMBER('Reference data'!B40),D20*'Reference data'!B40/1000000,"Unknown")) -> 0.0016905 | G20: =IF(ISNUMBER(E20),ROUND(E20*'Reference data'!$B$2,0),"Unknown") -> 149 | H20: =IF(ISNUMBER(F20),ROUND(F20*'Reference data'!$B$2,0),"Unknown") -> 169
A21: R2 | B21: 2 | C21: User prompt | I21: How does a tool observation help the agent answer?
A22: R2 | B22: 2 | C22: Cache write
A23: R2 | B23: 2 | C23: Context · added / total
A24: R2 | B24: 2 | C24: LLM response | D24: 53
A25: R2 | B25: 2 | C25: Output | D25: 53 | E25: =IF(AND(ISNUMBER(F25),ISNUMBER('Reference data'!$B$3)),F25*'Reference data'!$B$3,"Unknown") -> 2.331311e-05 | F25: =IF(D25=0,0,IF(ISNUMBER('Reference data'!E40),D25*'Reference data'!E40/1000000,"Unknown")) -> 2.65e-05 | G25: =IF(ISNUMBER(E25),ROUND(E25*'Reference data'!$B$2,0),"Unknown") -> 2 | H25: =IF(ISNUMBER(F25),ROUND(F25*'Reference data'!$B$2,0),"Unknown") -> 3
A26: R2 | B26: 2 | C26: Output content | I26: A tool observation gives the agent new information—such as file contents or test results—so it can ground its answer in evidence, check assumptions, and decide what to do next.
A27: R2 | B27: 2 | C27: Cache write
A28: R2 | B28: 2 | C28: Context · added / total
A29: R2 | B29: 2 | C29: Call total | E29: =IF(COUNT('Turns'!E19,'Turns'!E20,'Turns'!E25)=3,SUM('Turns'!E19,'Turns'!E20,'Turns'!E25),"Unknown") -> 0.0015105136 | F29: =IF(COUNT('Turns'!F19,'Turns'!F20,'Turns'!F25)=3,SUM('Turns'!F19,'Turns'!F20,'Turns'!F25),"Unknown") -> 0.001717 | G29: =IF(ISNUMBER(E29),ROUND(E29*'Reference data'!$B$2,0),"Unknown") -> 151 | H29: =IF(ISNUMBER(F29),ROUND(F29*'Reference data'!$B$2,0),"Unknown") -> 172 | K29: ok

Sheet Execution tree
A1: Operation | B1: Depth | C1: Type | D1: Model · effort | E1: Status | F1: Input context tokens | G1: Description | H1: Span ID | I1: Parent ID | J1: Input at standard rate tokens | K1: Input at standard rate EUR | L1: Input at standard rate USD | M1: Cache read tokens | N1: Cache read EUR | O1: Cache read USD | P1: Cache write tokens | Q1: Cache write EUR | R1: Cache write USD | S1: Output (non-reasoning) tokens | T1: Output (non-reasoning) EUR | U1: Output (non-reasoning) USD | V1: Reasoning tokens | W1: Reasoning EUR | X1: Reasoning USD | Y1: Total EUR | Z1: Total USD | AA1: Projected EUR | AB1: Projected USD | AC1: Request | AD1: Elapsed ms | AE1: Accounting
A2: chat_agent | B2: 0 | C2: workflow | E2: ok | G2: Coordinate a direct chat response: prepare messages and invoke the model. | H2: 01a111d2-3092-7143-bc76-e25a40051556 | J2: =IF(COUNT('Turns'!D5)=1,SUM('Turns'!D5),"Unknown") -> 16752 | K2: =IF(COUNT('Turns'!E5)=1,SUM('Turns'!E5),"Unknown") -> 0.0014737404 | L2: =IF(COUNT('Turns'!F5)=1,SUM('Turns'!F5),"Unknown") -> 0.0016752 | M2: 0 | N2: 0 | O2: 0 | P2: 0 | Q2: 0 | R2: 0 | S2: =IF(COUNT('Turns'!D12)=1,SUM('Turns'!D12),"Unknown") -> 142 | T2: =IF(COUNT('Turns'!E12)=1,SUM('Turns'!E12),"Unknown") -> 6.246154e-05 | U2: =IF(COUNT('Turns'!F12)=1,SUM('Turns'!F12),"Unknown") -> 7.1e-05 | V2: 0 | W2: 0 | X2: 0 | Y2: =IF(COUNT('Turns'!E16)=1,SUM('Turns'!E16),"Unknown") -> 0.001536202 | Z2: =IF(COUNT('Turns'!F16)=1,SUM('Turns'!F16),"Unknown") -> 0.0017462 | AA2: =IF(ISNUMBER(Y2),ROUND(Y2*'Reference data'!$B$2,0),"Unknown") -> 154 | AB2: =IF(ISNUMBER(Z2),ROUND(Z2*'Reference data'!$B$2,0),"Unknown") -> 175 | AD2: 12944.852 | AE2: Subtree total
A3: PatchToolCallsMiddleware.before_agent | B3: 1 | C3: workflow | E3: ok | G3: Check message history and repair missing tool responses before the agent starts. | H3: 01a111d2-3095-7c23-a055-b3c987d2ee8f | I3: 01a111d2-3092-7143-bc76-e25a40051556 | AD3: 0.466 | AE3: No model charge
A4: model | B4: 1 | C4: workflow | E4: ok | G4: Prepare the current conversation, run model middleware, and invoke the chat model. | H4: 01a111d2-3097-70a1-b4ac-80479f2dcb83 | I4: 01a111d2-3092-7143-bc76-e25a40051556 | J4: =IF(COUNT('Turns'!D5)=1,SUM('Turns'!D5),"Unknown") -> 16752 | K4: =IF(COUNT('Turns'!E5)=1,SUM('Turns'!E5),"Unknown") -> 0.0014737404 | L4: =IF(COUNT('Turns'!F5)=1,SUM('Turns'!F5),"Unknown") -> 0.0016752 | M4: 0 | N4: 0 | O4: 0 | P4: 0 | Q4: 0 | R4: 0 | S4: =IF(COUNT('Turns'!D12)=1,SUM('Turns'!D12),"Unknown") -> 142 | T4: =IF(COUNT('Turns'!E12)=1,SUM('Turns'!E12),"Unknown") -> 6.246154e-05 | U4: =IF(COUNT('Turns'!F12)=1,SUM('Turns'!F12),"Unknown") -> 7.1e-05 | V4: 0 | W4: 0 | X4: 0 | Y4: =IF(COUNT('Turns'!E16)=1,SUM('Turns'!E16),"Unknown") -> 0.001536202 | Z4: =IF(COUNT('Turns'!F16)=1,SUM('Turns'!F16),"Unknown") -> 0.0017462 | AA4: =IF(ISNUMBER(Y4),ROUND(Y4*'Reference data'!$B$2,0),"Unknown") -> 154 | AB4: =IF(ISNUMBER(Z4),ROUND(Z4*'Reference data'!$B$2,0),"Unknown") -> 175 | AD4: 12940.641 | AE4: Subtree total
A5: CodexChatModel | B5: 2 | C5: model | D5: gpt-6-luna | E5: ok | F5: 16752 | G5: A direct conversation with a Deep Agent. | H5: 01a111d2-309c-7bc0-aaf3-f0a734a28bec | I5: 01a111d2-3097-70a1-b4ac-80479f2dcb83 | J5: =IF(COUNT('Turns'!D5)=1,SUM('Turns'!D5),"Unknown") -> 16752 | K5: =IF(COUNT('Turns'!E5)=1,SUM('Turns'!E5),"Unknown") -> 0.0014737404 | L5: =IF(COUNT('Turns'!F5)=1,SUM('Turns'!F5),"Unknown") -> 0.0016752 | M5: 0 | N5: 0 | O5: 0 | P5: 0 | Q5: 0 | R5: 0 | S5: =IF(COUNT('Turns'!D12)=1,SUM('Turns'!D12),"Unknown") -> 142 | T5: =IF(COUNT('Turns'!E12)=1,SUM('Turns'!E12),"Unknown") -> 6.246154e-05 | U5: =IF(COUNT('Turns'!F12)=1,SUM('Turns'!F12),"Unknown") -> 7.1e-05 | V5: 0 | W5: 0 | X5: 0 | Y5: =IF(COUNT('Turns'!E16)=1,SUM('Turns'!E16),"Unknown") -> 0.001536202 | Z5: =IF(COUNT('Turns'!F16)=1,SUM('Turns'!F16),"Unknown") -> 0.0017462 | AA5: =IF(ISNUMBER(Y5),ROUND(Y5*'Reference data'!$B$2,0),"Unknown") -> 154 | AB5: =IF(ISNUMBER(Z5),ROUND(Z5*'Reference data'!$B$2,0),"Unknown") -> 175 | AC5: R1 | AD5: 12933.585 | AE5: Own call
A6: chat_agent | B6: 0 | C6: workflow | E6: ok | G6: Coordinate a direct chat response: prepare messages and invoke the model. | H6: 01a111d2-633c-7272-a8d1-d8e9b41ed4cf | J6: =IF(COUNT('Turns'!D20)=1,SUM('Turns'!D20),"Unknown") -> 16905 | K6: =IF(COUNT('Turns'!E20)=1,SUM('Turns'!E20),"Unknown") -> 0.0014872005 | L6: =IF(COUNT('Turns'!F20)=1,SUM('Turns'!F20),"Unknown") -> 0.0016905 | M6: =IF(COUNT('Turns'!D19)=1,SUM('Turns'!D19),"Unknown") -> 0 | N6: =IF(COUNT('Turns'!E19)=1,SUM('Turns'!E19),"Unknown") -> 0 | O6: =IF(COUNT('Turns'!F19)=1,SUM('Turns'!F19),"Unknown") -> 0 | P6: 0 | Q6: 0 | R6: 0 | S6: =IF(COUNT('Turns'!D25)=1,SUM('Turns'!D25),"Unknown") -> 53 | T6: =IF(COUNT('Turns'!E25)=1,SUM('Turns'!E25),"Unknown") -> 2.331311e-05 | U6: =IF(COUNT('Turns'!F25)=1,SUM('Turns'!F25),"Unknown") -> 2.65e-05 | V6: 0 | W6: 0 | X6: 0 | Y6: =IF(COUNT('Turns'!E29)=1,SUM('Turns'!E29),"Unknown") -> 0.0015105136 | Z6: =IF(COUNT('Turns'!F29)=1,SUM('Turns'!F29),"Unknown") -> 0.001717 | AA6: =IF(ISNUMBER(Y6),ROUND(Y6*'Reference data'!$B$2,0),"Unknown") -> 151 | AB6: =IF(ISNUMBER(Z6),ROUND(Z6*'Reference data'!$B$2,0),"Unknown") -> 172 | AD6: 4915.206 | AE6: Subtree total
A7: PatchToolCallsMiddleware.before_agent | B7: 1 | C7: workflow | E7: ok | G7: Check message history and repair missing tool responses before the agent starts. | H7: 01a111d2-633e-7ad3-a616-1bd2e2d64124 | I7: 01a111d2-633c-7272-a8d1-d8e9b41ed4cf | AD7: 0.426 | AE7: No model charge
A8: model | B8: 1 | C8: workflow | E8: ok | G8: Prepare the current conversation, run model middleware, and invoke the chat model. | H8: 01a111d2-633f-7ab0-a0fa-5605af284d17 | I8: 01a111d2-633c-7272-a8d1-d8e9b41ed4cf | J8: =IF(COUNT('Turns'!D20)=1,SUM('Turns'!D20),"Unknown") -> 16905 | K8: =IF(COUNT('Turns'!E20)=1,SUM('Turns'!E20),"Unknown") -> 0.0014872005 | L8: =IF(COUNT('Turns'!F20)=1,SUM('Turns'!F20),"Unknown") -> 0.0016905 | M8: =IF(COUNT('Turns'!D19)=1,SUM('Turns'!D19),"Unknown") -> 0 | N8: =IF(COUNT('Turns'!E19)=1,SUM('Turns'!E19),"Unknown") -> 0 | O8: =IF(COUNT('Turns'!F19)=1,SUM('Turns'!F19),"Unknown") -> 0 | P8: 0 | Q8: 0 | R8: 0 | S8: =IF(COUNT('Turns'!D25)=1,SUM('Turns'!D25),"Unknown") -> 53 | T8: =IF(COUNT('Turns'!E25)=1,SUM('Turns'!E25),"Unknown") -> 2.331311e-05 | U8: =IF(COUNT('Turns'!F25)=1,SUM('Turns'!F25),"Unknown") -> 2.65e-05 | V8: 0 | W8: 0 | X8: 0 | Y8: =IF(COUNT('Turns'!E29)=1,SUM('Turns'!E29),"Unknown") -> 0.0015105136 | Z8: =IF(COUNT('Turns'!F29)=1,SUM('Turns'!F29),"Unknown") -> 0.001717 | AA8: =IF(ISNUMBER(Y8),ROUND(Y8*'Reference data'!$B$2,0),"Unknown") -> 151 | AB8: =IF(ISNUMBER(Z8),ROUND(Z8*'Reference data'!$B$2,0),"Unknown") -> 172 | AD8: 4911.752 | AE8: Subtree total
A9: CodexChatModel | B9: 2 | C9: model | D9: gpt-6-luna | E9: ok | F9: 16905 | G9: A direct conversation with a Deep Agent. | H9: 01a111d2-6342-7351-99ec-1f3a828fd569 | I9: 01a111d2-633f-7ab0-a0fa-5605af284d17 | J9: =IF(COUNT('Turns'!D20)=1,SUM('Turns'!D20),"Unknown") -> 16905 | K9: =IF(COUNT('Turns'!E20)=1,SUM('Turns'!E20),"Unknown") -> 0.0014872005 | L9: =IF(COUNT('Turns'!F20)=1,SUM('Turns'!F20),"Unknown") -> 0.0016905 | M9: =IF(COUNT('Turns'!D19)=1,SUM('Turns'!D19),"Unknown") -> 0 | N9: =IF(COUNT('Turns'!E19)=1,SUM('Turns'!E19),"Unknown") -> 0 | O9: =IF(COUNT('Turns'!F19)=1,SUM('Turns'!F19),"Unknown") -> 0 | P9: 0 | Q9: 0 | R9: 0 | S9: =IF(COUNT('Turns'!D25)=1,SUM('Turns'!D25),"Unknown") -> 53 | T9: =IF(COUNT('Turns'!E25)=1,SUM('Turns'!E25),"Unknown") -> 2.331311e-05 | U9: =IF(COUNT('Turns'!F25)=1,SUM('Turns'!F25),"Unknown") -> 2.65e-05 | V9: 0 | W9: 0 | X9: 0 | Y9: =IF(COUNT('Turns'!E29)=1,SUM('Turns'!E29),"Unknown") -> 0.0015105136 | Z9: =IF(COUNT('Turns'!F29)=1,SUM('Turns'!F29),"Unknown") -> 0.001717 | AA9: =IF(ISNUMBER(Y9),ROUND(Y9*'Reference data'!$B$2,0),"Unknown") -> 151 | AB9: =IF(ISNUMBER(Z9),ROUND(Z9*'Reference data'!$B$2,0),"Unknown") -> 172 | AC9: R2 | AD9: 4907.097 | AE9: Own call

Sheet Reference data
A1: Parameter | B1: Value | C1: Unit
A2: Number of executions | B2: 100000 | C2: executions
A3: USD → EUR | B3: 0.87974 | C3: EUR per USD
A4: Cache duration | B4: 5m
A5: Run ID | B5: 01a111d2-3092-7143-bc76-e25a40051556
A6: Recording | B6: Provider trace
A7: FX reference date | B7: 2026-09-24
A8: FX fetched at | B8: 2026-09-24T22:21:31.719587Z | C8: UTC
A9: FX source | B9: https://api.frankfurter.dev/v2/rate/usd/eur?providers=ecb
A10: Rounding | B10: Only projected costs: ROUND(cost × executions, 0)
A11: Tree totals | B11: Parent rows include descendants; do not sum all tree rows.
A12: Cache writes | B12: Simulated context movement is not a provider-billed write.
A13: Pricing scope | B13: Published online token rates verified 2026-10-05. Copilot uses GitHub rates, including saved long-context tiers, before plan allowances; these are usage estimates, not subscription invoices. Cache writes with unspecified lifetime use the 5-minute rate unless an explicit cache_write rate is configured. Direct OpenAI and Anthropic entries use standard rates; no batch, regional, tool, negotiated, or unrecorded context-tier adjustments are applied. Model availability and context capacity require separate verification.
A15: Model | B15: Input USD / 1M tokens | C15: Cache read USD / 1M tokens | D15: Cache write USD / 1M tokens | E15: Output USD / 1M tokens | F15: Reasoning USD / 1M tokens | G15: Verified date | H15: Source | I15: Notes
A16: openai:gpt-5.5 | B16: 5 | C16: 0.5 | D16: Unknown | E16: 30 | F16: 30 | G16: 2026-10-05 | H16: https://developers.openai.com/api/docs/models/gpt-5.5.md | I16: Cache write assumes 5m when unspecified
A17: openai:gpt-5.6-luna | B17: 0.2 | C17: 0.02 | D17: 0.25 | E17: 1.2 | F17: 1.2 | G17: 2026-10-05 | H17: https://developers.openai.com/api/docs/models/gpt-5.6-luna.md | I17: Cache write assumes 5m when unspecified
A18: openai:gpt-5.6-sol | B18: 4 | C18: 0.4 | D18: 5 | E18: 20 | F18: 20 | G18: 2026-10-05 | H18: https://developers.openai.com/api/docs/models/gpt-5.6-sol.md | I18: Cache write assumes 5m when unspecified
A19: anthropic:claude-sonnet-5 | B19: 2 | C19: 0.2 | D19: 2.5 | E19: 10 | F19: 10 | G19: 2026-10-05 | H19: https://platform.claude.com/docs/en/about-claude/pricing | I19: Cache write assumes 5m when unspecified
A20: anthropic:claude-opus-4-8 | B20: 5 | C20: 0.5 | D20: 6.25 | E20: 25 | F20: 25 | G20: 2026-10-05 | H20: https://platform.claude.com/docs/en/about-claude/pricing | I20: Cache write assumes 5m when unspecified
A21: anthropic:claude-fable-5-1 | B21: 10 | C21: 0.25 | D21: 12.5 | E21: 50 | F21: 50 | G21: 2026-10-05 | H21: https://platform.claude.com/docs/en/about-claude/pricing | I21: Cache write assumes 5m when unspecified
A22: demo:scripted-chat | B22: 0.2 | C22: 0.02 | D22: 0.25 | E22: 1.2 | F22: 1.2 | G22: 2026-10-05 | H22: Illustrative demo rates based on openai:gpt-5.6-luna; no provider billing | I22: Cache write assumes 5m when unspecified
A23: anthropic:claude-haiku-4-5 | B23: 1 | C23: 0.1 | D23: 1.25 | E23: 5 | F23: 5 | G23: 2026-10-05 | H23: https://platform.claude.com/docs/en/about-claude/pricing | I23: Cache write assumes 5m when unspecified
A24: anthropic:claude-haiku-4-5-20251001 | B24: 1 | C24: 0.1 | D24: 1.25 | E24: 5 | F24: 5 | G24: 2026-10-05 | H24: https://platform.claude.com/docs/en/about-claude/pricing | I24: Cache write assumes 5m when unspecified
A25: anthropic:claude-opus-5-5 | B25: 4 | C25: 0.2 | D25: 5 | E25: 20 | F25: 20 | G25: 2026-10-05 | H25: https://platform.claude.com/docs/en/about-claude/pricing | I25: Cache write assumes 5m when unspecified
A26: anthropic:claude-sonnet-4-6 | B26: 3 | C26: 0.3 | D26: 3.75 | E26: 15 | F26: 15 | G26: 2026-10-05 | H26: https://platform.claude.com/docs/en/about-claude/pricing | I26: Cache write assumes 5m when unspecified
A27: anthropic:claude-sonnet-5-5 | B27: 2 | C27: 0.2 | D27: 2.5 | E27: 10 | F27: 10 | G27: 2026-10-05 | H27: https://platform.claude.com/docs/en/about-claude/pricing | I27: Cache write assumes 5m when unspecified
A28: copilot:claude-haiku-4.5 | B28: 1 | C28: 0.1 | D28: 1.25 | E28: 5 | F28: 5 | G28: 2026-10-05 | H28: https://docs.github.com/en/copilot/reference/copilot-billing/models-and-pricing | I28: Cache write assumes 5m when unspecified
... A31: copilot:claude-sonnet-5.5 | B31: 2 | C31: 0.2 | D31: 2.5 | E31: 10 | F31: 10 | G31: 2026-10-05 | H31: https://docs.github.com/en/copilot/reference/copilot-billing/models-and-pricing | I31: Cache write assumes 5m when unspecified
A32: copilot:gemini-3.8-flash | B32: 0.75 | C32: 0.075 | D32: Unknown | E32: 3.75 | F32: 3.75 | G32: 2026-10-05 | H32: https://docs.github.com/en/copilot/reference/copilot-billing/models-and-pricing | I32: Cache write assumes 5m when unspecified
A33: copilot:gpt-5.3-codex | B33: 1.75 | C33: 0.175 | D33: Unknown | E33: 14 | F33: 14 | G33: 2026-10-05 | H33: https://docs.github.com/en/copilot/reference/copilot-billing/models-and-pricing | I33: Cache write assumes 5m when unspecified
A34: copilot:gpt-5.4 | B34: 2.5 | C34: 0.25 | D34: Unknown | E34: 15 | F34: 15 | G34: 2026-10-05 | H34: https://docs.github.com/en/copilot/reference/copilot-billing/models-and-pricing | I34: Cache write assumes 5m when unspecified
A35: copilot:gpt-6-astra | B35: 10 | C35: 1 | D35: 12.5 | E35: 50 | F35: 50 | G35: 2026-10-05 | H35: https://docs.github.com/en/copilot/reference/copilot-billing/models-and-pricing | I35: Cache write assumes 5m when unspecified
A36: copilot:gpt-6-luna | B36: 0.1 | C36: 0.01 | D36: 0.125 | E36: 0.5 | F36: 0.5 | G36: 2026-10-05 | H36: https://docs.github.com/en/copilot/reference/copilot-billing/models-and-pricing | I36: Cache write assumes 5m when unspecified
A37: copilot:gpt-6-sol | B37: 2 | C37: 0.2 | D37: 2.5 | E37: 10 | F37: 10 | G37: 2026-10-05 | H37: https://docs.github.com/en/copilot/reference/copilot-billing/models-and-pricing | I37: Cache write assumes 5m when unspecified
A38: copilot:gpt-6.1-sol | B38: 2 | C38: 0.1 | D38: 2.5 | E38: 10 | F38: 10 | G38: 2026-10-05 | H38: https://docs.github.com/en/copilot/reference/copilot-billing/models-and-pricing | I38: Cache write assumes 5m when unspecified
A39: openai:gpt-6-astra | B39: 10 | C39: 1 | D39: 12.5 | E39: 50 | F39: 50 | G39: 2026-10-05 | H39: https://developers.openai.com/api/docs/models/gpt-6-astra.md | I39: Cache write assumes 5m when unspecified
A40: openai:gpt-6-luna | B40: 0.1 | C40: 0.01 | D40: 0.125 | E40: 0.5 | F40: 0.5 | G40: 2026-10-05 | H40: https://developers.openai.com/api/docs/models/gpt-6-luna.md | I40: Cache write assumes 5m when unspecified
A41: openai:gpt-6-sol | B41: 2 | C41: 0.2 | D41: 2.5 | E41: 10 | F41: 10 | G41: 2026-10-05 | H41: https://developers.openai.com/api/docs/models/gpt-6-sol.md | I41: Cache write assumes 5m when unspecified
A42: openai:gpt-6.1-sol | B42: 2 | C42: 0.1 | D42: 2.5 | E42: 10 | F42: 10 | G42: 2026-10-05 | H42: https://developers.openai.com/api/docs/models/gpt-6.1-sol.md | I42: Cache write assumes 5m when unspecified
A43: copilot:gpt-5.4 [long context] | B43: 5 | C43: 0.5 | D43: Unknown | E43: 22.5 | F43: 22.5 | G43: 2026-10-05 | H43: https://docs.github.com/en/copilot/reference/copilot-billing/models-and-pricing | I43: Above 272,000 input tokens
...
