Workbook

Sheet Turns
A1: Request | B1: Turn | C1: Sequence | D1: Tokens | E1: EUR / execution | F1: USD / execution | G1: Projected EUR | H1: Projected USD | I1: Content | J1: Model · effort | K1: Status | L1: Context total tokens | M1: Span ID
C2: Run total | E2: =IF(COUNT('Turns'!E16,'Turns'!E31,'Turns'!E46,'Turns'!E58,'Turns'!E71,'Turns'!E86,'Turns'!E101,'Turns'!E113,'Turns'!E126,'Turns'!E142,'Turns'!E157,'Turns'!E169)=12,SUM('Turns'!E16,'Turns'!E31,'Turns'!E46,'Turns'!E58,'Turns'!E71,'Turns'!E86,'Turns'!E101,'Turns'!E113,'Turns'!E126,'Turns'!E142,'Turns'!E157,'Turns'!E169),"Unknown") -> 0.0012698167 | F2: =IF(COUNT('Turns'!F16,'Turns'!F31,'Turns'!F46,'Turns'!F58,'Turns'!F71,'Turns'!F86,'Turns'!F101,'Turns'!F113,'Turns'!F126,'Turns'!F142,'Turns'!F157,'Turns'!F169)=12,SUM('Turns'!F16,'Turns'!F31,'Turns'!F46,'Turns'!F58,'Turns'!F71,'Turns'!F86,'Turns'!F101,'Turns'!F113,'Turns'!F126,'Turns'!F142,'Turns'!F157,'Turns'!F169),"Unknown") -> 0.0014434 | G2: =IF(ISNUMBER(E2),ROUND(E2*'Reference data'!$B$2,0),"Unknown") -> 127 | H2: =IF(ISNUMBER(F2),ROUND(F2*'Reference data'!$B$2,0),"Unknown") -> 144
B3: 1 | C3: Turn 1 | E3: =IF(COUNT('Turns'!E16,'Turns'!E31,'Turns'!E46,'Turns'!E58)=4,SUM('Turns'!E16,'Turns'!E31,'Turns'!E46,'Turns'!E58),"Unknown") -> 0.00034204291 | F3: =IF(COUNT('Turns'!F16,'Turns'!F31,'Turns'!F46,'Turns'!F58)=4,SUM('Turns'!F16,'Turns'!F31,'Turns'!F46,'Turns'!F58),"Unknown") -> 0.0003888 | G3: =IF(ISNUMBER(E3),ROUND(E3*'Reference data'!$B$2,0),"Unknown") -> 34 | H3: =IF(ISNUMBER(F3),ROUND(F3*'Reference data'!$B$2,0),"Unknown") -> 39
A4: R1 | B4: 1 | C4: LLM request | D4: 262 | J4: gpt-5.6-luna | M4: 01a0d584-431e-7ec2-a707-25d39b0d3bb6
A5: R1 | B5: 1 | C5: Input at standard rate | D5: 262 | E5: =IF(AND(ISNUMBER(F5),ISNUMBER('Reference data'!$B$3)),F5*'Reference data'!$B$3,"Unknown") -> 4.6098376e-05 | F5: =IF(D5=0,0,IF(ISNUMBER('Reference data'!B17),D5*'Reference data'!B17/1000000,"Unknown")) -> 5.24e-05 | G5: =IF(ISNUMBER(E5),ROUND(E5*'Reference data'!$B$2,0),"Unknown") -> 5 | H5: =IF(ISNUMBER(F5),ROUND(F5*'Reference data'!$B$2,0),"Unknown") -> 5
A6: R1 | B6: 1 | C6: Tool definitions
A7: R1 | B7: 1 | C7: System prompt | I7: You are a dispatcher for movies, sports, and history. For each question, select the most relevant expert from the task tool descriptions and delegate a self-contained question to exactly that expert. Include relevant context from earlier turns when needed. Use the expert's answer to respond; do not answer domain questions yourself. For ambiguous questions ask the user which domain they mean. For requests outside these domains explain the supported subjects without delegating. Never choose an expert merely to force a match.
A8: R1 | B8: 1 | C8: User prompt | I8: Who directed Spirited Away?
A9: R1 | B9: 1 | C9: Cache write
A10: R1 | B10: 1 | C10: Context · added / total
A11: R1 | B11: 1 | C11: LLM response | D11: 56
A12: R1 | B12: 1 | C12: Output | D12: 56 | E12: =IF(AND(ISNUMBER(F12),ISNUMBER('Reference data'!$B$3)),F12*'Reference data'!$B$3,"Unknown") -> 5.9118528e-05 | F12: =IF(D12=0,0,IF(ISNUMBER('Reference data'!E17),D12*'Reference data'!E17/1000000,"Unknown")) -> 6.72e-05 | G12: =IF(ISNUMBER(E12),ROUND(E12*'Reference data'!$B$2,0),"Unknown") -> 6 | H12: =IF(ISNUMBER(F12),ROUND(F12*'Reference data'!$B$2,0),"Unknown") -> 7
A13: R1 | B13: 1 | C13: Output content | I13: [{"type": "function_call", "name": "task", "arguments": "{\"description\":\"Answer the movie question: Who directed the film Spirited Away? Provide the director's name and, if useful, a brief identifying detail. Be accurate and concise.\",\"subagent_type\":\"movie_expert\"}", "call_id": "call_vwmI5a38fUZInRHJUPZSkwga", "id": "fc_0ca30177df7fe36f006ab5a2e2f28087d2b80b1536d128db5c", "index": 0}] {"name": "task", "args": {"description": "Answer the movie question: Who directed the film Spirited Away? Provide the director's name and, if useful, a brief identifying detail. Be accurate and concise.", "subagent_type": "movie_expert"}, "id": "call_vwmI5a38fUZInRHJUPZSkwga", "type": "tool_call"}
A14: R1 | B14: 1 | C14: Cache write
A15: R1 | B15: 1 | C15: Context · added / total
A16: R1 | B16: 1 | C16: Call total | E16: =IF(COUNT('Turns'!E5,'Turns'!E12)=2,SUM('Turns'!E5,'Turns'!E12),"Unknown") -> 0.0001052169 | F16: =IF(COUNT('Turns'!F5,'Turns'!F12)=2,SUM('Turns'!F5,'Turns'!F12),"Unknown") -> 0.0001196 | G16: =IF(ISNUMBER(E16),ROUND(E16*'Reference data'!$B$2,0),"Unknown") -> 11 | H16: =IF(ISNUMBER(F16),ROUND(F16*'Reference data'!$B$2,0),"Unknown") -> 12 | K16: ok
B17: 1 | C17: Tool · task | K17: ok | M17: 01a0d584-48a6-7703-97a7-b1ecc8438e8d
B18: 1 | C18: Arguments | I18: {'description': "Answer the movie question: Who directed the film Spirited Away? Provide the director's name and, if useful, a brief identifying detail. Be accurate and concise.", 'subagent_type': 'movie_expert'}
B19: 1 | C19: Result | I19: Command(update={'messages': [ToolMessage(content='*Spirited Away* was directed by **Hayao Miyazaki**, the acclaimed Studio Ghibli filmmaker. Source: https://www.ghibli.jp/works/', tool_call_id='call_vwmI5a38fUZInRHJUPZSkwga')]})
A20: R2 | B20: 1 | C20: LLM request | D20: 193 | J20: gpt-5.6-luna | M20: 01a0d584-48a9-76d2-b472-9ff9ea6c4ec1
A21: R2 | B21: 1 | C21: Input at standard rate | D21: 193 | E21: =IF(AND(ISNUMBER(F21),ISNUMBER('Reference data'!$B$3)),F21*'Reference data'!$B$3,"Unknown") -> 3.3957964e-05 | F21: =IF(D21=0,0,IF(ISNUMBER('Reference data'!B17),D21*'Reference data'!B17/1000000,"Unknown")) -> 3.86e-05 | G21: =IF(ISNUMBER(E21),ROUND(E21*'Reference data'!$B$2,0),"Unknown") -> 3 | H21: =IF(ISNUMBER(F21),ROUND(F21*'Reference data'!$B$2,0),"Unknown") -> 4
A22: R2 | B22: 1 | C22: Tool definitions
A23: R2 | B23: 1 | C23: System prompt | I23: You are the movies expert. Use search_movie_reference to retrieve evidence before answering the delegated question. Base factual claims on the returned passages and cite their source URLs. If no relevant evidence is found, explain the collection's limits instead of inventing an answer or claiming web research. Answer concisely. The collection is a small local teaching reference, not a complete or continually updated source.
A24: R2 | B24: 1 | C24: Cache write
A25: R2 | B25: 1 | C25: Context · added / total
A26: R2 | B26: 1 | C26: LLM response | D26: 26
A27: R2 | B27: 1 | C27: Output | D27: 26 | E27: =IF(AND(ISNUMBER(F27),ISNUMBER('Reference data'!$B$3)),F27*'Reference data'!$B$3,"Unknown") -> 2.7447888e-05 | F27: =IF(D27=0,0,IF(ISNUMBER('Reference data'!E17),D27*'Reference data'!E17/1000000,"Unknown")) -> 3.12e-05 | G27: =IF(ISNUMBER(E27),ROUND(E27*'Reference data'!$B$2,0),"Unknown") -> 3 | H27: =IF(ISNUMBER(F27),ROUND(F27*'Reference data'!$B$2,0),"Unknown") -> 3
A28: R2 | B28: 1 | C28: Output content | I28: [{"type": "function_call", "name": "search_movie_reference", "arguments": "{\"query\":\"Who directed the film Spirited Away?\"}", "call_id": "call_xhvlnQehC2OlrK6VrpCAqeqz", "id": "fc_0a6acba15b3aeb56006ab5a2e41f1887d2b2ccf86031e8e199", "index": 0}] {"name": "search_movie_reference", "args": {"query": "Who directed the film Spirited Away?"}, "id": "call_xhvlnQehC2OlrK6VrpCAqeqz", "type": "tool_call"}
A29: R2 | B29: 1 | C29: Cache write
A30: R2 | B30: 1 | C30: Context · added / total
A31: R2 | B31: 1 | C31: Call total | E31: =IF(COUNT('Turns'!E21,'Turns'!E27)=2,SUM('Turns'!E21,'Turns'!E27),"Unknown") -> 6.1405852e-05 | F31: =IF(COUNT('Turns'!F21,'Turns'!F27)=2,SUM('Turns'!F21,'Turns'!F27),"Unknown") -> 6.98e-05 | G31: =IF(ISNUMBER(E31),ROUND(E31*'Reference data'!$B$2,0),"Unknown") -> 6 | H31: =IF(ISNUMBER(F31),ROUND(F31*'Reference data'!$B$2,0),"Unknown") -> 7 | K31: ok
B32: 1 | C32: Tool · search_movie_reference | K32: ok | M32: 01a0d584-4c3c-75b1-afe4-cb1749286f01
B33: 1 | C33: Arguments | I33: {'query': 'Who directed the film Spirited Away?'}
B34: 1 | C34: Result | I34: Spirited Away Spirited Away was directed by Hayao Miyazaki and released in 2001. Source: https://www.ghibli.jp/works/
A35: R3 | B35: 1 | C35: LLM request | D35: 267 | J35: gpt-5.6-luna | M35: 01a0d584-4c3e-7600-812e-65a9a52d2618
A36: R3 | B36: 1 | C36: Conversation history · cache read | D36: 0 | E36: =IF(AND(ISNUMBER(F36),ISNUMBER('Reference data'!$B$3)),F36*'Reference data'!$B$3,"Unknown") -> 0 | F36: =IF(D36=0,0,IF(ISNUMBER('Reference data'!C17),D36*'Reference data'!C17/1000000,"Unknown")) -> 0 | G36: =IF(ISNUMBER(E36),ROUND(E36*'Reference data'!$B$2,0),"Unknown") -> 0 | H36: =IF(ISNUMBER(F36),ROUND(F36*'Reference data'!$B$2,0),"Unknown") -> 0
A37: R3 | B37: 1 | C37: Input at standard rate | D37: 267 | E37: =IF(AND(ISNUMBER(F37),ISNUMBER('Reference data'!$B$3)),F37*'Reference data'!$B$3,"Unknown") -> 4.6978116e-05 | F37: =IF(D37=0,0,IF(ISNUMBER('Reference data'!B17),D37*'Reference data'!B17/1000000,"Unknown")) -> 5.34e-05 | G37: =IF(ISNUMBER(E37),ROUND(E37*'Reference data'!$B$2,0),"Unknown") -> 5 | H37: =IF(ISNUMBER(F37),ROUND(F37*'Reference data'!$B$2,0),"Unknown") -> 5
A38: R3 | B38: 1 | C38: Tool result | I38: Spirited Away Spirited Away was directed by Hayao Miyazaki and released in 2001. Source: https://www.ghibli.jp/works/
A39: R3 | B39: 1 | C39: Cache write
A40: R3 | B40: 1 | C40: Context · added / total
...

Sheet Execution tree
A1: Operation | B1: Depth | C1: Type | D1: Model · effort | E1: Status | F1: Input context tokens | G1: Description | H1: Span ID | I1: Parent ID | J1: Input at standard rate tokens | K1: Input at standard rate EUR | L1: Input at standard rate USD | M1: Cache read tokens | N1: Cache read EUR | O1: Cache read USD | P1: Cache write tokens | Q1: Cache write EUR | R1: Cache write USD | S1: Output (non-reasoning) tokens | T1: Output (non-reasoning) EUR | U1: Output (non-reasoning) USD | V1: Reasoning tokens | W1: Reasoning EUR | X1: Reasoning USD | Y1: Total EUR | Z1: Total USD | AA1: Projected EUR | AB1: Projected USD | AC1: Request | AD1: Elapsed ms | AE1: Accounting
A2: dispatcher_agent | B2: 0 | C2: workflow | E2: ok | G2: Execute the dispatcher_agent workflow operation and pass its result to the next graph step. | H2: 01a0d584-431a-7670-a84d-31f4a317f39c | J2: =IF(COUNT('Turns'!D5,'Turns'!D21,'Turns'!D37,'Turns'!D49)=4,SUM('Turns'!D5,'Turns'!D21,'Turns'!D37,'Turns'!D49),"Unknown") -> 1086 | K2: =IF(COUNT('Turns'!E5,'Turns'!E21,'Turns'!E37,'Turns'!E49)=4,SUM('Turns'!E5,'Turns'!E21,'Turns'!E37,'Turns'!E49),"Unknown") -> 0.00019107953 | L2: =IF(COUNT('Turns'!F5,'Turns'!F21,'Turns'!F37,'Turns'!F49)=4,SUM('Turns'!F5,'Turns'!F21,'Turns'!F37,'Turns'!F49),"Unknown") -> 0.0002172 | M2: =IF(COUNT('Turns'!D36,'Turns'!D48)=2,SUM('Turns'!D36,'Turns'!D48),"Unknown") -> 0 | N2: =IF(COUNT('Turns'!E36,'Turns'!E48)=2,SUM('Turns'!E36,'Turns'!E48),"Unknown") -> 0 | O2: =IF(COUNT('Turns'!F36,'Turns'!F48)=2,SUM('Turns'!F36,'Turns'!F48),"Unknown") -> 0 | P2: 0 | Q2: 0 | R2: 0 | S2: =IF(COUNT('Turns'!D12,'Turns'!D27,'Turns'!D42,'Turns'!D54)=4,SUM('Turns'!D12,'Turns'!D27,'Turns'!D42,'Turns'!D54),"Unknown") -> 143 | T2: =IF(COUNT('Turns'!E12,'Turns'!E27,'Turns'!E42,'Turns'!E54)=4,SUM('Turns'!E12,'Turns'!E27,'Turns'!E42,'Turns'!E54),"Unknown") -> 0.00015096338 | U2: =IF(COUNT('Turns'!F12,'Turns'!F27,'Turns'!F42,'Turns'!F54)=4,SUM('Turns'!F12,'Turns'!F27,'Turns'!F42,'Turns'!F54),"Unknown") -> 0.0001716 | V2: 0 | W2: 0 | X2: 0 | Y2: =IF(COUNT('Turns'!E16,'Turns'!E31,'Turns'!E46,'Turns'!E58)=4,SUM('Turns'!E16,'Turns'!E31,'Turns'!E46,'Turns'!E58),"Unknown") -> 0.00034204291 | Z2: =IF(COUNT('Turns'!F16,'Turns'!F31,'Turns'!F46,'Turns'!F58)=4,SUM('Turns'!F16,'Turns'!F31,'Turns'!F46,'Turns'!F58),"Unknown") -> 0.0003888 | AA2: =IF(ISNUMBER(Y2),ROUND(Y2*'Reference data'!$B$2,0),"Unknown") -> 34 | AB2: =IF(ISNUMBER(Z2),ROUND(Z2*'Reference data'!$B$2,0),"Unknown") -> 39 | AD2: 4155.05 | AE2: Subtree total
A3: model | B3: 1 | C3: workflow | E3: ok | G3: Prepare the current conversation, run model middleware, and invoke the chat model. | H3: 01a0d584-431c-7523-a2f9-580d9ae4b19b | I3: 01a0d584-431a-7670-a84d-31f4a317f39c | J3: =IF(COUNT('Turns'!D5)=1,SUM('Turns'!D5),"Unknown") -> 262 | K3: =IF(COUNT('Turns'!E5)=1,SUM('Turns'!E5),"Unknown") -> 4.6098376e-05 | L3: =IF(COUNT('Turns'!F5)=1,SUM('Turns'!F5),"Unknown") -> 5.24e-05 | M3: 0 | N3: 0 | O3: 0 | P3: 0 | Q3: 0 | R3: 0 | S3: =IF(COUNT('Turns'!D12)=1,SUM('Turns'!D12),"Unknown") -> 56 | T3: =IF(COUNT('Turns'!E12)=1,SUM('Turns'!E12),"Unknown") -> 5.9118528e-05 | U3: =IF(COUNT('Turns'!F12)=1,SUM('Turns'!F12),"Unknown") -> 6.72e-05 | V3: 0 | W3: 0 | X3: 0 | Y3: =IF(COUNT('Turns'!E16)=1,SUM('Turns'!E16),"Unknown") -> 0.0001052169 | Z3: =IF(COUNT('Turns'!F16)=1,SUM('Turns'!F16),"Unknown") -> 0.0001196 | AA3: =IF(ISNUMBER(Y3),ROUND(Y3*'Reference data'!$B$2,0),"Unknown") -> 11 | AB3: =IF(ISNUMBER(Z3),ROUND(Z3*'Reference data'!$B$2,0),"Unknown") -> 12 | AD3: 1416.21 | AE3: Subtree total
A4: ChatOpenAI | B4: 2 | C4: model | D4: gpt-5.6-luna | E4: ok | F4: 262 | G4: Generate the next assistant message or tool request from the current conversation. | H4: 01a0d584-431e-7ec2-a707-25d39b0d3bb6 | I4: 01a0d584-431c-7523-a2f9-580d9ae4b19b | J4: =IF(COUNT('Turns'!D5)=1,SUM('Turns'!D5),"Unknown") -> 262 | K4: =IF(COUNT('Turns'!E5)=1,SUM('Turns'!E5),"Unknown") -> 4.6098376e-05 | L4: =IF(COUNT('Turns'!F5)=1,SUM('Turns'!F5),"Unknown") -> 5.24e-05 | M4: 0 | N4: 0 | O4: 0 | P4: 0 | Q4: 0 | R4: 0 | S4: =IF(COUNT('Turns'!D12)=1,SUM('Turns'!D12),"Unknown") -> 56 | T4: =IF(COUNT('Turns'!E12)=1,SUM('Turns'!E12),"Unknown") -> 5.9118528e-05 | U4: =IF(COUNT('Turns'!F12)=1,SUM('Turns'!F12),"Unknown") -> 6.72e-05 | V4: 0 | W4: 0 | X4: 0 | Y4: =IF(COUNT('Turns'!E16)=1,SUM('Turns'!E16),"Unknown") -> 0.0001052169 | Z4: =IF(COUNT('Turns'!F16)=1,SUM('Turns'!F16),"Unknown") -> 0.0001196 | AA4: =IF(ISNUMBER(Y4),ROUND(Y4*'Reference data'!$B$2,0),"Unknown") -> 11 | AB4: =IF(ISNUMBER(Z4),ROUND(Z4*'Reference data'!$B$2,0),"Unknown") -> 12 | AC4: R1 | AD4: 1413.068 | AE4: Own call
A5: tools | B5: 1 | C5: workflow | E5: ok | G5: Execute tool calls requested by the preceding model response and return their observations. | H5: 01a0d584-48a6-7703-97a7-b1d84542a380 | I5: 01a0d584-431a-7670-a84d-31f4a317f39c | J5: =IF(COUNT('Turns'!D21,'Turns'!D37)=2,SUM('Turns'!D21,'Turns'!D37),"Unknown") -> 460 | K5: =IF(COUNT('Turns'!E21,'Turns'!E37)=2,SUM('Turns'!E21,'Turns'!E37),"Unknown") -> 8.093608e-05 | L5: =IF(COUNT('Turns'!F21,'Turns'!F37)=2,SUM('Turns'!F21,'Turns'!F37),"Unknown") -> 9.2e-05 | M5: =IF(COUNT('Turns'!D36)=1,SUM('Turns'!D36),"Unknown") -> 0 | N5: =IF(COUNT('Turns'!E36)=1,SUM('Turns'!E36),"Unknown") -> 0 | O5: =IF(COUNT('Turns'!F36)=1,SUM('Turns'!F36),"Unknown") -> 0 | P5: 0 | Q5: 0 | R5: 0 | S5: =IF(COUNT('Turns'!D27,'Turns'!D42)=2,SUM('Turns'!D27,'Turns'!D42),"Unknown") -> 66 | T5: =IF(COUNT('Turns'!E27,'Turns'!E42)=2,SUM('Turns'!E27,'Turns'!E42),"Unknown") -> 6.9675408e-05 | U5: =IF(COUNT('Turns'!F27,'Turns'!F42)=2,SUM('Turns'!F27,'Turns'!F42),"Unknown") -> 7.92e-05 | V5: 0 | W5: 0 | X5: 0 | Y5: =IF(COUNT('Turns'!E31,'Turns'!E46)=2,SUM('Turns'!E31,'Turns'!E46),"Unknown") -> 0.00015061149 | Z5: =IF(COUNT('Turns'!F31,'Turns'!F46)=2,SUM('Turns'!F31,'Turns'!F46),"Unknown") -> 0.0001712 | AA5: =IF(ISNUMBER(Y5),ROUND(Y5*'Reference data'!$B$2,0),"Unknown") -> 15 | AB5: =IF(ISNUMBER(Z5),ROUND(Z5*'Reference data'!$B$2,0),"Unknown") -> 17 | AD5: 1819.893 | AE5: Subtree total
A6: task | B6: 2 | C6: tool | E6: ok | G6: Delegate a self-contained question to the matching expert. Available experts: - movie_expert: Specialist for questions about movies, with its own local reference lookup. - sports_expert: Specialist for questions about sports, with its own local reference lookup. - history_expert: Specialist for questions about history, with its own local reference lookup. | H6: 01a0d584-48a6-7703-97a7-b1ecc8438e8d | I6: 01a0d584-48a6-7703-97a7-b1d84542a380 | J6: =IF(COUNT('Turns'!D21,'Turns'!D37)=2,SUM('Turns'!D21,'Turns'!D37),"Unknown") -> 460 | K6: =IF(COUNT('Turns'!E21,'Turns'!E37)=2,SUM('Turns'!E21,'Turns'!E37),"Unknown") -> 8.093608e-05 | L6: =IF(COUNT('Turns'!F21,'Turns'!F37)=2,SUM('Turns'!F21,'Turns'!F37),"Unknown") -> 9.2e-05 | M6: =IF(COUNT('Turns'!D36)=1,SUM('Turns'!D36),"Unknown") -> 0 | N6: =IF(COUNT('Turns'!E36)=1,SUM('Turns'!E36),"Unknown") -> 0 | O6: =IF(COUNT('Turns'!F36)=1,SUM('Turns'!F36),"Unknown") -> 0 | P6: 0 | Q6: 0 | R6: 0 | S6: =IF(COUNT('Turns'!D27,'Turns'!D42)=2,SUM('Turns'!D27,'Turns'!D42),"Unknown") -> 66 | T6: =IF(COUNT('Turns'!E27,'Turns'!E42)=2,SUM('Turns'!E27,'Turns'!E42),"Unknown") -> 6.9675408e-05 | U6: =IF(COUNT('Turns'!F27,'Turns'!F42)=2,SUM('Turns'!F27,'Turns'!F42),"Unknown") -> 7.92e-05 | V6: 0 | W6: 0 | X6: 0 | Y6: =IF(COUNT('Turns'!E31,'Turns'!E46)=2,SUM('Turns'!E31,'Turns'!E46),"Unknown") -> 0.00015061149 | Z6: =IF(COUNT('Turns'!F31,'Turns'!F46)=2,SUM('Turns'!F31,'Turns'!F46),"Unknown") -> 0.0001712 | AA6: =IF(ISNUMBER(Y6),ROUND(Y6*'Reference data'!$B$2,0),"Unknown") -> 15 | AB6: =IF(ISNUMBER(Z6),ROUND(Z6*'Reference data'!$B$2,0),"Unknown") -> 17 | AD6: 1818.657 | AE6: Subtree total
A7: movie_expert | B7: 3 | C7: workflow | E7: ok | G7: Execute the movie_expert workflow operation and pass its result to the next graph step. | H7: 01a0d584-48a7-7f42-b873-60570a34271d | I7: 01a0d584-48a6-7703-97a7-b1ecc8438e8d | J7: =IF(COUNT('Turns'!D21,'Turns'!D37)=2,SUM('Turns'!D21,'Turns'!D37),"Unknown") -> 460 | K7: =IF(COUNT('Turns'!E21,'Turns'!E37)=2,SUM('Turns'!E21,'Turns'!E37),"Unknown") -> 8.093608e-05 | L7: =IF(COUNT('Turns'!F21,'Turns'!F37)=2,SUM('Turns'!F21,'Turns'!F37),"Unknown") -> 9.2e-05 | M7: =IF(COUNT('Turns'!D36)=1,SUM('Turns'!D36),"Unknown") -> 0 | N7: =IF(COUNT('Turns'!E36)=1,SUM('Turns'!E36),"Unknown") -> 0 | O7: =IF(COUNT('Turns'!F36)=1,SUM('Turns'!F36),"Unknown") -> 0 | P7: 0 | Q7: 0 | R7: 0 | S7: =IF(COUNT('Turns'!D27,'Turns'!D42)=2,SUM('Turns'!D27,'Turns'!D42),"Unknown") -> 66 | T7: =IF(COUNT('Turns'!E27,'Turns'!E42)=2,SUM('Turns'!E27,'Turns'!E42),"Unknown") -> 6.9675408e-05 | U7: =IF(COUNT('Turns'!F27,'Turns'!F42)=2,SUM('Turns'!F27,'Turns'!F42),"Unknown") -> 7.92e-05 | V7: 0 | W7: 0 | X7: 0 | Y7: =IF(COUNT('Turns'!E31,'Turns'!E46)=2,SUM('Turns'!E31,'Turns'!E46),"Unknown") -> 0.00015061149 | Z7: =IF(COUNT('Turns'!F31,'Turns'!F46)=2,SUM('Turns'!F31,'Turns'!F46),"Unknown") -> 0.0001712 | AA7: =IF(ISNUMBER(Y7),ROUND(Y7*'Reference data'!$B$2,0),"Unknown") -> 15 | AB7: =IF(ISNUMBER(Z7),ROUND(Z7*'Reference data'!$B$2,0),"Unknown") -> 17 | AD7: 1817.685 | AE7: Subtree total
A8: model | B8: 4 | C8: workflow | E8: ok | G8: Prepare the current conversation, run model middleware, and invoke the chat model. | H8: 01a0d584-48a8-79f3-95db-05e3a18e1c6f | I8: 01a0d584-48a7-7f42-b873-60570a34271d | J8: =IF(COUNT('Turns'!D21)=1,SUM('Turns'!D21),"Unknown") -> 193 | K8: =IF(COUNT('Turns'!E21)=1,SUM('Turns'!E21),"Unknown") -> 3.3957964e-05 | L8: =IF(COUNT('Turns'!F21)=1,SUM('Turns'!F21),"Unknown") -> 3.86e-05 | M8: 0 | N8: 0 | O8: 0 | P8: 0 | Q8: 0 | R8: 0 | S8: =IF(COUNT('Turns'!D27)=1,SUM('Turns'!D27),"Unknown") -> 26 | T8: =IF(COUNT('Turns'!E27)=1,SUM('Turns'!E27),"Unknown") -> 2.7447888e-05 | U8: =IF(COUNT('Turns'!F27)=1,SUM('Turns'!F27),"Unknown") -> 3.12e-05 | V8: 0 | W8: 0 | X8: 0 | Y8: =IF(COUNT('Turns'!E31)=1,SUM('Turns'!E31),"Unknown") -> 6.1405852e-05 | Z8: =IF(COUNT('Turns'!F31)=1,SUM('Turns'!F31),"Unknown") -> 6.98e-05 | AA8: =IF(ISNUMBER(Y8),ROUND(Y8*'Reference data'!$B$2,0),"Unknown") -> 6 | AB8: =IF(ISNUMBER(Z8),ROUND(Z8*'Reference data'!$B$2,0),"Unknown") -> 7 | AD8: 914.684 | AE8: Subtree total
A9: ChatOpenAI | B9: 5 | C9: model | D9: gpt-5.6-luna | E9: ok | F9: 193 | G9: Generate the next assistant message or tool request from the current conversation. | H9: 01a0d584-48a9-76d2-b472-9ff9ea6c4ec1 | I9: 01a0d584-48a8-79f3-95db-05e3a18e1c6f | J9: =IF(COUNT('Turns'!D21)=1,SUM('Turns'!D21),"Unknown") -> 193 | K9: =IF(COUNT('Turns'!E21)=1,SUM('Turns'!E21),"Unknown") -> 3.3957964e-05 | L9: =IF(COUNT('Turns'!F21)=1,SUM('Turns'!F21),"Unknown") -> 3.86e-05 | M9: 0 | N9: 0 | O9: 0 | P9: 0 | Q9: 0 | R9: 0 | S9: =IF(COUNT('Turns'!D27)=1,SUM('Turns'!D27),"Unknown") -> 26 | T9: =IF(COUNT('Turns'!E27)=1,SUM('Turns'!E27),"Unknown") -> 2.7447888e-05 | U9: =IF(COUNT('Turns'!F27)=1,SUM('Turns'!F27),"Unknown") -> 3.12e-05 | V9: 0 | W9: 0 | X9: 0 | Y9: =IF(COUNT('Turns'!E31)=1,SUM('Turns'!E31),"Unknown") -> 6.1405852e-05 | Z9: =IF(COUNT('Turns'!F31)=1,SUM('Turns'!F31),"Unknown") -> 6.98e-05 | AA9: =IF(ISNUMBER(Y9),ROUND(Y9*'Reference data'!$B$2,0),"Unknown") -> 6 | AB9: =IF(ISNUMBER(Z9),ROUND(Z9*'Reference data'!$B$2,0),"Unknown") -> 7 | AC9: R2 | AD9: 911.932 | AE9: Own call
A10: tools | B10: 4 | C10: workflow | E10: ok | G10: Execute tool calls requested by the preceding model response and return their observations. | H10: 01a0d584-4c3b-7992-bc25-64c9a339e3b1 | I10: 01a0d584-48a7-7f42-b873-60570a34271d | AD10: 1.782 | AE10: No model charge
A11: search_movie_reference | B11: 5 | C11: tool | E11: ok | G11: Look up local movie evidence by phrase; return sources or an explicit miss. | H11: 01a0d584-4c3c-75b1-afe4-cb1749286f01 | I11: 01a0d584-4c3b-7992-bc25-64c9a339e3b1 | AD11: 0.517 | AE11: No model charge
A12: model | B12: 4 | C12: workflow | E12: ok | G12: Prepare the current conversation, run model middleware, and invoke the chat model. | H12: 01a0d584-4c3e-7600-812e-6594ab68b287 | I12: 01a0d584-48a7-7f42-b873-60570a34271d | J12: =IF(COUNT('Turns'!D37)=1,SUM('Turns'!D37),"Unknown") -> 267 | K12: =IF(COUNT('Turns'!E37)=1,SUM('Turns'!E37),"Unknown") -> 4.6978116e-05 | L12: =IF(COUNT('Turns'!F37)=1,SUM('Turns'!F37),"Unknown") -> 5.34e-05 | M12: =IF(COUNT('Turns'!D36)=1,SUM('Turns'!D36),"Unknown") -> 0 | N12: =IF(COUNT('Turns'!E36)=1,SUM('Turns'!E36),"Unknown") -> 0 | O12: =IF(COUNT('Turns'!F36)=1,SUM('Turns'!F36),"Unknown") -> 0 | P12: 0 | Q12: 0 | R12: 0 | S12: =IF(COUNT('Turns'!D42)=1,SUM('Turns'!D42),"Unknown") -> 40 | T12: =IF(COUNT('Turns'!E42)=1,SUM('Turns'!E42),"Unknown") -> 4.222752e-05 | U12: =IF(COUNT('Turns'!F42)=1,SUM('Turns'!F42),"Unknown") -> 4.8e-05 | V12: 0 | W12: 0 | X12: 0 | Y12: =IF(COUNT('Turns'!E46)=1,SUM('Turns'!E46),"Unknown") -> 8.9205636e-05 | Z12: =IF(COUNT('Turns'!F46)=1,SUM('Turns'!F46),"Unknown") -> 0.0001014 | AA12: =IF(ISNUMBER(Y12),ROUND(Y12*'Reference data'!$B$2,0),"Unknown") -> 9 | AB12: =IF(ISNUMBER(Z12),ROUND(Z12*'Reference data'!$B$2,0),"Unknown") -> 10 | AD12: 898.388 | AE12: Subtree total
A13: ChatOpenAI | B13: 5 | C13: model | D13: gpt-5.6-luna | E13: ok | F13: 267 | G13: Generate the next assistant message or tool request from the current conversation. | H13: 01a0d584-4c3e-7600-812e-65a9a52d2618 | I13: 01a0d584-4c3e-7600-812e-6594ab68b287 | J13: =IF(COUNT('Turns'!D37)=1,SUM('Turns'!D37),"Unknown") -> 267 | K13: =IF(COUNT('Turns'!E37)=1,SUM('Turns'!E37),"Unknown") -> 4.6978116e-05 | L13: =IF(COUNT('Turns'!F37)=1,SUM('Turns'!F37),"Unknown") -> 5.34e-05 | M13: =IF(COUNT('Turns'!D36)=1,SUM('Turns'!D36),"Unknown") -> 0 | N13: =IF(COUNT('Turns'!E36)=1,SUM('Turns'!E36),"Unknown") -> 0 | O13: =IF(COUNT('Turns'!F36)=1,SUM('Turns'!F36),"Unknown") -> 0 | P13: 0 | Q13: 0 | R13: 0 | S13: =IF(COUNT('Turns'!D42)=1,SUM('Turns'!D42),"Unknown") -> 40 | T13: =IF(COUNT('Turns'!E42)=1,SUM('Turns'!E42),"Unknown") -> 4.222752e-05 | U13: =IF(COUNT('Turns'!F42)=1,SUM('Turns'!F42),"Unknown") -> 4.8e-05 | V13: 0 | W13: 0 | X13: 0 | Y13: =IF(COUNT('Turns'!E46)=1,SUM('Turns'!E46),"Unknown") -> 8.9205636e-05 | Z13: =IF(COUNT('Turns'!F46)=1,SUM('Turns'!F46),"Unknown") -> 0.0001014 | AA13: =IF(ISNUMBER(Y13),ROUND(Y13*'Reference data'!$B$2,0),"Unknown") -> 9 | AB13: =IF(ISNUMBER(Z13),ROUND(Z13*'Reference data'!$B$2,0),"Unknown") -> 10 | AC13: R3 | AD13: 897.296 | AE13: Own call
A14: model | B14: 1 | C14: workflow | E14: ok | G14: Prepare the current conversation, run model middleware, and invoke the chat model. | H14: 01a0d584-4fc2-7693-8ae6-2fd09c6b62e0 | I14: 01a0d584-431a-7670-a84d-31f4a317f39c | J14: =IF(COUNT('Turns'!D49)=1,SUM('Turns'!D49),"Unknown") -> 364 | K14: =IF(COUNT('Turns'!E49)=1,SUM('Turns'!E49),"Unknown") -> 6.4045072e-05 | L14: =IF(COUNT('Turns'!F49)=1,SUM('Turns'!F49),"Unknown") -> 7.28e-05 | M14: =IF(COUNT('Turns'!D48)=1,SUM('Turns'!D48),"Unknown") -> 0 | N14: =IF(COUNT('Turns'!E48)=1,SUM('Turns'!E48),"Unknown") -> 0 | O14: =IF(COUNT('Turns'!F48)=1,SUM('Turns'!F48),"Unknown") -> 0 | P14: 0 | Q14: 0 | R14: 0 | S14: =IF(COUNT('Turns'!D54)=1,SUM('Turns'!D54),"Unknown") -> 21 | T14: =IF(COUNT('Turns'!E54)=1,SUM('Turns'!E54),"Unknown") -> 2.2169448e-05 | U14: =IF(COUNT('Turns'!F54)=1,SUM('Turns'!F54),"Unknown") -> 2.52e-05 | V14: 0 | W14: 0 | X14: 0 | Y14: =IF(COUNT('Turns'!E58)=1,SUM('Turns'!E58),"Unknown") -> 8.621452e-05 | Z14: =IF(COUNT('Turns'!F58)=1,SUM('Turns'!F58),"Unknown") -> 9.8e-05 | AA14: =IF(ISNUMBER(Y14),ROUND(Y14*'Reference data'!$B$2,0),"Unknown") -> 9 | AB14: =IF(ISNUMBER(Z14),ROUND(Z14*'Reference data'!$B$2,0),"Unknown") -> 10 | AD14: 915.265 | AE14: Subtree total
A15: ChatOpenAI | B15: 2 | C15: model | D15: gpt-5.6-luna | E15: ok | F15: 364 | G15: Generate the next assistant message or tool request from the current conversation. | H15: 01a0d584-4fc3-7821-a7ce-caccaba0de5b | I15: 01a0d584-4fc2-7693-8ae6-2fd09c6b62e0 | J15: =IF(COUNT('Turns'!D49)=1,SUM('Turns'!D49),"Unknown") -> 364 | K15: =IF(COUNT('Turns'!E49)=1,SUM('Turns'!E49),"Unknown") -> 6.4045072e-05 | L15: =IF(COUNT('Turns'!F49)=1,SUM('Turns'!F49),"Unknown") -> 7.28e-05 | M15: =IF(COUNT('Turns'!D48)=1,SUM('Turns'!D48),"Unknown") -> 0 | N15: =IF(COUNT('Turns'!E48)=1,SUM('Turns'!E48),"Unknown") -> 0 | O15: =IF(COUNT('Turns'!F48)=1,SUM('Turns'!F48),"Unknown") -> 0 | P15: 0 | Q15: 0 | R15: 0 | S15: =IF(COUNT('Turns'!D54)=1,SUM('Turns'!D54),"Unknown") -> 21 | T15: =IF(COUNT('Turns'!E54)=1,SUM('Turns'!E54),"Unknown") -> 2.2169448e-05 | U15: =IF(COUNT('Turns'!F54)=1,SUM('Turns'!F54),"Unknown") -> 2.52e-05 | V15: 0 | W15: 0 | X15: 0 | Y15: =IF(COUNT('Turns'!E58)=1,SUM('Turns'!E58),"Unknown") -> 8.621452e-05 | Z15: =IF(COUNT('Turns'!F58)=1,SUM('Turns'!F58),"Unknown") -> 9.8e-05 | AA15: =IF(ISNUMBER(Y15),ROUND(Y15*'Reference data'!$B$2,0),"Unknown") -> 9 | AB15: =IF(ISNUMBER(Z15),ROUND(Z15*'Reference data'!$B$2,0),"Unknown") -> 10 | AC15: R4 | AD15: 914.054 | AE15: Own call
A16: dispatcher_agent | B16: 0 | C16: workflow | E16: ok | G16: Execute the dispatcher_agent workflow operation and pass its result to the next graph step. | H16: 01a0d584-5367-7a81-9ff9-6737e767749f | J16: =IF(COUNT('Turns'!D62,'Turns'!D76,'Turns'!D92,'Turns'!D104)=4,SUM('Turns'!D62,'Turns'!D76,'Turns'!D92,'Turns'!D104),"Unknown") -> 1438 | K16: =IF(COUNT('Turns'!E62,'Turns'!E76,'Turns'!E92,'Turns'!E104)=4,SUM('Turns'!E62,'Turns'!E76,'Turns'!E92,'Turns'!E104),"Unknown") -> 0.00025301322 | L16: =IF(COUNT('Turns'!F62,'Turns'!F76,'Turns'!F92,'Turns'!F104)=4,SUM('Turns'!F62,'Turns'!F76,'Turns'!F92,'Turns'!F104),"Unknown") -> 0.0002876 | M16: =IF(COUNT('Turns'!D61,'Turns'!D91,'Turns'!D103)=3,SUM('Turns'!D61,'Turns'!D91,'Turns'!D103),"Unknown") -> 0 | N16: =IF(COUNT('Turns'!E61,'Turns'!E91,'Turns'!E103)=3,SUM('Turns'!E61,'Turns'!E91,'Turns'!E103),"Unknown") -> 0 | O16: =IF(COUNT('Turns'!F61,'Turns'!F91,'Turns'!F103)=3,SUM('Turns'!F61,'Turns'!F91,'Turns'!F103),"Unknown") -> 0 | P16: 0 | Q16: 0 | R16: 0 | S16: =IF(COUNT('Turns'!D67,'Turns'!D82,'Turns'!D97,'Turns'!D109)=4,SUM('Turns'!D67,'Turns'!D82,'Turns'!D97,'Turns'!D109),"Unknown") -> 188 | T16: =IF(COUNT('Turns'!E67,'Turns'!E82,'Turns'!E97,'Turns'!E109)=4,SUM('Turns'!E67,'Turns'!E82,'Turns'!E97,'Turns'!E109),"Unknown") -> 0.00019846934 | U16: =IF(COUNT('Turns'!F67,'Turns'!F82,'Turns'!F97,'Turns'!F109)=4,SUM('Turns'!F67,'Turns'!F82,'Turns'!F97,'Turns'!F109),"Unknown") -> 0.0002256 | V16: 0 | W16: 0 | X16: 0 | Y16: =IF(COUNT('Turns'!E71,'Turns'!E86,'Turns'!E101,'Turns'!E113)=4,SUM('Turns'!E71,'Turns'!E86,'Turns'!E101,'Turns'!E113),"Unknown") -> 0.00045148257 | Z16: =IF(COUNT('Turns'!F71,'Turns'!F86,'Turns'!F101,'Turns'!F113)=4,SUM('Turns'!F71,'Turns'!F86,'Turns'!F101,'Turns'!F113),"Unknown") -> 0.0005132 | AA16: =IF(ISNUMBER(Y16),ROUND(Y16*'Reference data'!$B$2,0),"Unknown") -> 45 | AB16: =IF(ISNUMBER(Z16),ROUND(Z16*'Reference data'!$B$2,0),"Unknown") -> 51 | AD16: 6026.143 | AE16: Subtree total
A17: model | B17: 1 | C17: workflow | E17: ok | G17: Prepare the current conversation, run model middleware, and invoke the chat model. | H17: 01a0d584-5368-7600-9dfb-6896090920dc | I17: 01a0d584-5367-7a81-9ff9-6737e767749f | J17: =IF(COUNT('Turns'!D62)=1,SUM('Turns'!D62),"Unknown") -> 402 | K17: =IF(COUNT('Turns'!E62)=1,SUM('Turns'!E62),"Unknown") -> 7.0731096e-05 | L17: =IF(COUNT('Turns'!F62)=1,SUM('Turns'!F62),"Unknown") -> 8.04e-05 | M17: =IF(COUNT('Turns'!D61)=1,SUM('Turns'!D61),"Unknown") -> 0 | N17: =IF(COUNT('Turns'!E61)=1,SUM('Turns'!E61),"Unknown") -> 0 | O17: =IF(COUNT('Turns'!F61)=1,SUM('Turns'!F61),"Unknown") -> 0 | P17: 0 | Q17: 0 | R17: 0 | S17: =IF(COUNT('Turns'!D67)=1,SUM('Turns'!D67),"Unknown") -> 67 | T17: =IF(COUNT('Turns'!E67)=1,SUM('Turns'!E67),"Unknown") -> 7.0731096e-05 | U17: =IF(COUNT('Turns'!F67)=1,SUM('Turns'!F67),"Unknown") -> 8.04e-05 | V17: 0 | W17: 0 | X17: 0 | Y17: =IF(COUNT('Turns'!E71)=1,SUM('Turns'!E71),"Unknown") -> 0.00014146219 | Z17: =IF(COUNT('Turns'!F71)=1,SUM('Turns'!F71),"Unknown") -> 0.0001608 | AA17: =IF(ISNUMBER(Y17),ROUND(Y17*'Reference data'!$B$2,0),"Unknown") -> 14 | AB17: =IF(ISNUMBER(Z17),ROUND(Z17*'Reference data'!$B$2,0),"Unknown") -> 16 | AD17: 1308.409 | AE17: Subtree total
A18: ChatOpenAI | B18: 2 | C18: model | D18: gpt-5.6-luna | E18: ok | F18: 402 | G18: Generate the next assistant message or tool request from the current conversation. | H18: 01a0d584-5369-7f42-a5cf-bbb41a706ecd | I18: 01a0d584-5368-7600-9dfb-6896090920dc | J18: =IF(COUNT('Turns'!D62)=1,SUM('Turns'!D62),"Unknown") -> 402 | K18: =IF(COUNT('Turns'!E62)=1,SUM('Turns'!E62),"Unknown") -> 7.0731096e-05 | L18: =IF(COUNT('Turns'!F62)=1,SUM('Turns'!F62),"Unknown") -> 8.04e-05 | M18: =IF(COUNT('Turns'!D61)=1,SUM('Turns'!D61),"Unknown") -> 0 | N18: =IF(COUNT('Turns'!E61)=1,SUM('Turns'!E61),"Unknown") -> 0 | O18: =IF(COUNT('Turns'!F61)=1,SUM('Turns'!F61),"Unknown") -> 0 | P18: 0 | Q18: 0 | R18: 0 | S18: =IF(COUNT('Turns'!D67)=1,SUM('Turns'!D67),"Unknown") -> 67 | T18: =IF(COUNT('Turns'!E67)=1,SUM('Turns'!E67),"Unknown") -> 7.0731096e-05 | U18: =IF(COUNT('Turns'!F67)=1,SUM('Turns'!F67),"Unknown") -> 8.04e-05 | V18: 0 | W18: 0 | X18: 0 | Y18: =IF(COUNT('Turns'!E71)=1,SUM('Turns'!E71),"Unknown") -> 0.00014146219 | Z18: =IF(COUNT('Turns'!F71)=1,SUM('Turns'!F71),"Unknown") -> 0.0001608 | AA18: =IF(ISNUMBER(Y18),ROUND(Y18*'Reference data'!$B$2,0),"Unknown") -> 14 | AB18: =IF(ISNUMBER(Z18),ROUND(Z18*'Reference data'!$B$2,0),"Unknown") -> 16 | AC18: R5 | AD18: 1307.183 | AE18: Own call
A19: tools | B19: 1 | C19: workflow | E19: ok | G19: Execute tool calls requested by the preceding model response and return their observations. | H19: 01a0d584-5885-7831-97cc-893cdbadd6ff | I19: 01a0d584-5367-7a81-9ff9-6737e767749f | J19: =IF(COUNT('Turns'!D76,'Turns'!D92)=2,SUM('Turns'!D76,'Turns'!D92),"Unknown") -> 501 | K19: =IF(COUNT('Turns'!E76,'Turns'!E92)=2,SUM('Turns'!E76,'Turns'!E92),"Unknown") -> 8.8149948e-05 | L19: =IF(COUNT('Turns'!F76,'Turns'!F92)=2,SUM('Turns'!F76,'Turns'!F92),"Unknown") -> 0.0001002 | M19: =IF(COUNT('Turns'!D91)=1,SUM('Turns'!D91),"Unknown") -> 0 | N19: =IF(COUNT('Turns'!E91)=1,SUM('Turns'!E91),"Unknown") -> 0 | O19: =IF(COUNT('Turns'!F91)=1,SUM('Turns'!F91),"Unknown") -> 0 | P19: 0 | Q19: 0 | R19: 0 | S19: =IF(COUNT('Turns'!D82,'Turns'!D97)=2,SUM('Turns'!D82,'Turns'!D97),"Unknown") -> 102 | T19: =IF(COUNT('Turns'!E82,'Turns'!E97)=2,SUM('Turns'!E82,'Turns'!E97),"Unknown") -> 0.00010768018 | U19: =IF(COUNT('Turns'!F82,'Turns'!F97)=2,SUM('Turns'!F82,'Turns'!F97),"Unknown") -> 0.0001224 | V19: 0 | W19: 0 | X19: 0 | Y19: =IF(COUNT('Turns'!E86,'Turns'!E101)=2,SUM('Turns'!E86,'Turns'!E101),"Unknown") -> 0.00019583012 | Z19: =IF(COUNT('Turns'!F86,'Turns'!F101)=2,SUM('Turns'!F86,'Turns'!F101),"Unknown") -> 0.0002226 | AA19: =IF(ISNUMBER(Y19),ROUND(Y19*'Reference data'!$B$2,0),"Unknown") -> 20 | AB19: =IF(ISNUMBER(Z19),ROUND(Z19*'Reference data'!$B$2,0),"Unknown") -> 22 | AD19: 3753.883 | AE19: Subtree total
A20: task | B20: 2 | C20: tool | E20: ok | G20: Delegate a self-contained question to the matching expert. Available experts: - movie_expert: Specialist for questions about movies, with its own local reference lookup. - sports_expert: Specialist for questions about sports, with its own local reference lookup. - history_expert: Specialist for questions about history, with its own local reference lookup. | H20: 01a0d584-5885-7831-97cc-894aa3f1fa9d | I20: 01a0d584-5885-7831-97cc-893cdbadd6ff | J20: =IF(COUNT('Turns'!D76,'Turns'!D92)=2,SUM('Turns'!D76,'Turns'!D92),"Unknown") -> 501 | K20: =IF(COUNT('Turns'!E76,'Turns'!E92)=2,SUM('Turns'!E76,'Turns'!E92),"Unknown") -> 8.8149948e-05 | L20: =IF(COUNT('Turns'!F76,'Turns'!F92)=2,SUM('Turns'!F76,'Turns'!F92),"Unknown") -> 0.0001002 | M20: =IF(COUNT('Turns'!D91)=1,SUM('Turns'!D91),"Unknown") -> 0 | N20: =IF(COUNT('Turns'!E91)=1,SUM('Turns'!E91),"Unknown") -> 0 | O20: =IF(COUNT('Turns'!F91)=1,SUM('Turns'!F91),"Unknown") -> 0 | P20: 0 | Q20: 0 | R20: 0 | S20: =IF(COUNT('Turns'!D82,'Turns'!D97)=2,SUM('Turns'!D82,'Turns'!D97),"Unknown") -> 102 | T20: =IF(COUNT('Turns'!E82,'Turns'!E97)=2,SUM('Turns'!E82,'Turns'!E97),"Unknown") -> 0.00010768018 | U20: =IF(COUNT('Turns'!F82,'Turns'!F97)=2,SUM('Turns'!F82,'Turns'!F97),"Unknown") -> 0.0001224 | V20: 0 | W20: 0 | X20: 0 | Y20: =IF(COUNT('Turns'!E86,'Turns'!E101)=2,SUM('Turns'!E86,'Turns'!E101),"Unknown") -> 0.00019583012 | Z20: =IF(COUNT('Turns'!F86,'Turns'!F101)=2,SUM('Turns'!F86,'Turns'!F101),"Unknown") -> 0.0002226 | AA20: =IF(ISNUMBER(Y20),ROUND(Y20*'Reference data'!$B$2,0),"Unknown") -> 20 | AB20: =IF(ISNUMBER(Z20),ROUND(Z20*'Reference data'!$B$2,0),"Unknown") -> 22 | AD20: 3752.964 | AE20: Subtree total
A21: sports_expert | B21: 3 | C21: workflow | E21: ok | G21: Execute the sports_expert workflow operation and pass its result to the next graph step. | H21: 01a0d584-5886-77c1-93ee-351efe9d2977 | I21: 01a0d584-5885-7831-97cc-894aa3f1fa9d | J21: =IF(COUNT('Turns'!D76,'Turns'!D92)=2,SUM('Turns'!D76,'Turns'!D92),"Unknown") -> 501 | K21: =IF(COUNT('Turns'!E76,'Turns'!E92)=2,SUM('Turns'!E76,'Turns'!E92),"Unknown") -> 8.8149948e-05 | L21: =IF(COUNT('Turns'!F76,'Turns'!F92)=2,SUM('Turns'!F76,'Turns'!F92),"Unknown") -> 0.0001002 | M21: =IF(COUNT('Turns'!D91)=1,SUM('Turns'!D91),"Unknown") -> 0 | N21: =IF(COUNT('Turns'!E91)=1,SUM('Turns'!E91),"Unknown") -> 0 | O21: =IF(COUNT('Turns'!F91)=1,SUM('Turns'!F91),"Unknown") -> 0 | P21: 0 | Q21: 0 | R21: 0 | S21: =IF(COUNT('Turns'!D82,'Turns'!D97)=2,SUM('Turns'!D82,'Turns'!D97),"Unknown") -> 102 | T21: =IF(COUNT('Turns'!E82,'Turns'!E97)=2,SUM('Turns'!E82,'Turns'!E97),"Unknown") -> 0.00010768018 | U21: =IF(COUNT('Turns'!F82,'Turns'!F97)=2,SUM('Turns'!F82,'Turns'!F97),"Unknown") -> 0.0001224 | V21: 0 | W21: 0 | X21: 0 | Y21: =IF(COUNT('Turns'!E86,'Turns'!E101)=2,SUM('Turns'!E86,'Turns'!E101),"Unknown") -> 0.00019583012 | Z21: =IF(COUNT('Turns'!F86,'Turns'!F101)=2,SUM('Turns'!F86,'Turns'!F101),"Unknown") -> 0.0002226 | AA21: =IF(ISNUMBER(Y21),ROUND(Y21*'Reference data'!$B$2,0),"Unknown") -> 20 | AB21: =IF(ISNUMBER(Z21),ROUND(Z21*'Reference data'!$B$2,0),"Unknown") -> 22 | AD21: 3751.748 | AE21: Subtree total
A22: model | B22: 4 | C22: workflow | E22: ok | G22: Prepare the current conversation, run model middleware, and invoke the chat model. | H22: 01a0d584-5887-7330-82e0-d67124af98e7 | I22: 01a0d584-5886-77c1-93ee-351efe9d2977 | J22: =IF(COUNT('Turns'!D76)=1,SUM('Turns'!D76),"Unknown") -> 201 | K22: =IF(COUNT('Turns'!E76)=1,SUM('Turns'!E76),"Unknown") -> 3.5365548e-05 | L22: =IF(COUNT('Turns'!F76)=1,SUM('Turns'!F76),"Unknown") -> 4.02e-05 | M22: 0 | N22: 0 | O22: 0 | P22: 0 | Q22: 0 | R22: 0 | S22: =IF(COUNT('Turns'!D82)=1,SUM('Turns'!D82),"Unknown") -> 42 | T22: =IF(COUNT('Turns'!E82)=1,SUM('Turns'!E82),"Unknown") -> 4.4338896e-05 | U22: =IF(COUNT('Turns'!F82)=1,SUM('Turns'!F82),"Unknown") -> 5.04e-05 | V22: 0 | W22: 0 | X22: 0 | Y22: =IF(COUNT('Turns'!E86)=1,SUM('Turns'!E86),"Unknown") -> 7.9704444e-05 | Z22: =IF(COUNT('Turns'!F86)=1,SUM('Turns'!F86),"Unknown") -> 9.06e-05 | AA22: =IF(ISNUMBER(Y22),ROUND(Y22*'Reference data'!$B$2,0),"Unknown") -> 8 | AB22: =IF(ISNUMBER(Z22),ROUND(Z22*'Reference data'!$B$2,0),"Unknown") -> 9 | AD22: 2623.669 | AE22: Subtree total
A23: ChatOpenAI | B23: 5 | C23: model | D23: gpt-5.6-luna | E23: ok | F23: 201 | G23: Generate the next assistant message or tool request from the current conversation. | H23: 01a0d584-5889-77d1-806c-33b1e32f9fc9 | I23: 01a0d584-5887-7330-82e0-d67124af98e7 | J23: =IF(COUNT('Turns'!D76)=1,SUM('Turns'!D76),"Unknown") -> 201 | K23: =IF(COUNT('Turns'!E76)=1,SUM('Turns'!E76),"Unknown") -> 3.5365548e-05 | L23: =IF(COUNT('Turns'!F76)=1,SUM('Turns'!F76),"Unknown") -> 4.02e-05 | M23: 0 | N23: 0 | O23: 0 | P23: 0 | Q23: 0 | R23: 0 | S23: =IF(COUNT('Turns'!D82)=1,SUM('Turns'!D82),"Unknown") -> 42 | T23: =IF(COUNT('Turns'!E82)=1,SUM('Turns'!E82),"Unknown") -> 4.4338896e-05 | U23: =IF(COUNT('Turns'!F82)=1,SUM('Turns'!F82),"Unknown") -> 5.04e-05 | V23: 0 | W23: 0 | X23: 0 | Y23: =IF(COUNT('Turns'!E86)=1,SUM('Turns'!E86),"Unknown") -> 7.9704444e-05 | Z23: =IF(COUNT('Turns'!F86)=1,SUM('Turns'!F86),"Unknown") -> 9.06e-05 | AA23: =IF(ISNUMBER(Y23),ROUND(Y23*'Reference data'!$B$2,0),"Unknown") -> 8 | AB23: =IF(ISNUMBER(Z23),ROUND(Z23*'Reference data'!$B$2,0),"Unknown") -> 9 | AC23: R6 | AD23: 2621.446 | AE23: Own call
A24: tools | B24: 4 | C24: workflow | E24: ok | G24: Execute tool calls requested by the preceding model response and return their observations. | H24: 01a0d584-62c8-7bb0-922c-d4ebdbdf4e52 | I24: 01a0d584-5886-77c1-93ee-351efe9d2977 | AD24: 1.503 | AE24: No model charge
A25: search_sports_reference | B25: 5 | C25: tool | E25: ok | G25: Look up local sports evidence by phrase; return sources or an explicit miss. | H25: 01a0d584-62c8-7bb0-922c-d4f92038f303 | I25: 01a0d584-62c8-7bb0-922c-d4ebdbdf4e52 | AD25: 0.445 | AE25: No model charge
A26: model | B26: 4 | C26: workflow | E26: ok | G26: Prepare the current conversation, run model middleware, and invoke the chat model. | H26: 01a0d584-62ca-7361-9d0e-96e6d3fea86c | I26: 01a0d584-5886-77c1-93ee-351efe9d2977 | J26: =IF(COUNT('Turns'!D92)=1,SUM('Turns'!D92),"Unknown") -> 300 | K26: =IF(COUNT('Turns'!E92)=1,SUM('Turns'!E92),"Unknown") -> 5.27844e-05 | L26: =IF(COUNT('Turns'!F92)=1,SUM('Turns'!F92),"Unknown") -> 6e-05 | M26: =IF(COUNT('Turns'!D91)=1,SUM('Turns'!D91),"Unknown") -> 0 | N26: =IF(COUNT('Turns'!E91)=1,SUM('Turns'!E91),"Unknown") -> 0 | O26: =IF(COUNT('Turns'!F91)=1,SUM('Turns'!F91),"Unknown") -> 0 | P26: 0 | Q26: 0 | R26: 0 | S26: =IF(COUNT('Turns'!D97)=1,SUM('Turns'!D97),"Unknown") -> 60 | T26: =IF(COUNT('Turns'!E97)=1,SUM('Turns'!E97),"Unknown") -> 6.334128e-05 | U26: =IF(COUNT('Turns'!F97)=1,SUM('Turns'!F97),"Unknown") -> 7.2e-05 | V26: 0 | W26: 0 | X26: 0 | Y26: =IF(COUNT('Turns'!E101)=1,SUM('Turns'!E101),"Unknown") -> 0.00011612568 | Z26: =IF(COUNT('Turns'!F101)=1,SUM('Turns'!F101),"Unknown") -> 0.000132 | AA26: =IF(ISNUMBER(Y26),ROUND(Y26*'Reference data'!$B$2,0),"Unknown") -> 12 | AB26: =IF(ISNUMBER(Z26),ROUND(Z26*'Reference data'!$B$2,0),"Unknown") -> 13 | AD26: 1123.121 | AE26: Subtree total
A27: ChatOpenAI | B27: 5 | C27: model | D27: gpt-5.6-luna | E27: ok | F27: 300 | G27: Generate the next assistant message or tool request from the current conversation. | H27: 01a0d584-62cb-7a93-87b1-bc6515c5634f | I27: 01a0d584-62ca-7361-9d0e-96e6d3fea86c | J27: =IF(COUNT('Turns'!D92)=1,SUM('Turns'!D92),"Unknown") -> 300 | K27: =IF(COUNT('Turns'!E92)=1,SUM('Turns'!E92),"Unknown") -> 5.27844e-05 | L27: =IF(COUNT('Turns'!F92)=1,SUM('Turns'!F92),"Unknown") -> 6e-05 | M27: =IF(COUNT('Turns'!D91)=1,SUM('Turns'!D91),"Unknown") -> 0 | N27: =IF(COUNT('Turns'!E91)=1,SUM('Turns'!E91),"Unknown") -> 0 | O27: =IF(COUNT('Turns'!F91)=1,SUM('Turns'!F91),"Unknown") -> 0 | P27: 0 | Q27: 0 | R27: 0 | S27: =IF(COUNT('Turns'!D97)=1,SUM('Turns'!D97),"Unknown") -> 60 | T27: =IF(COUNT('Turns'!E97)=1,SUM('Turns'!E97),"Unknown") -> 6.334128e-05 | U27: =IF(COUNT('Turns'!F97)=1,SUM('Turns'!F97),"Unknown") -> 7.2e-05 | V27: 0 | W27: 0 | X27: 0 | Y27: =IF(COUNT('Turns'!E101)=1,SUM('Turns'!E101),"Unknown") -> 0.00011612568 | Z27: =IF(COUNT('Turns'!F101)=1,SUM('Turns'!F101),"Unknown") -> 0.000132 | AA27: =IF(ISNUMBER(Y27),ROUND(Y27*'Reference data'!$B$2,0),"Unknown") -> 12 | AB27: =IF(ISNUMBER(Z27),ROUND(Z27*'Reference data'!$B$2,0),"Unknown") -> 13 | AC27: R7 | AD27: 1121.278 | AE27: Own call
A28: model | B28: 1 | C28: workflow | E28: ok | G28: Prepare the current conversation, run model middleware, and invoke the chat model. | H28: 01a0d584-6730-71c2-9a2f-74c86b7fc06a | I28: 01a0d584-5367-7a81-9ff9-6737e767749f | J28: =IF(COUNT('Turns'!D104)=1,SUM('Turns'!D104),"Unknown") -> 535 | K28: =IF(COUNT('Turns'!E104)=1,SUM('Turns'!E104),"Unknown") -> 9.413218e-05 | L28: =IF(COUNT('Turns'!F104)=1,SUM('Turns'!F104),"Unknown") -> 0.000107 | M28: =IF(COUNT('Turns'!D103)=1,SUM('Turns'!D103),"Unknown") -> 0 | N28: =IF(COUNT('Turns'!E103)=1,SUM('Turns'!E103),"Unknown") -> 0 | O28: =IF(COUNT('Turns'!F103)=1,SUM('Turns'!F103),"Unknown") -> 0 | P28: 0 | Q28: 0 | R28: 0 | S28: =IF(COUNT('Turns'!D109)=1,SUM('Turns'!D109),"Unknown") -> 19 | T28: =IF(COUNT('Turns'!E109)=1,SUM('Turns'!E109),"Unknown") -> 2.0058072e-05 | U28: =IF(COUNT('Turns'!F109)=1,SUM('Turns'!F109),"Unknown") -> 2.28e-05 | V28: 0 | W28: 0 | X28: 0 | Y28: =IF(COUNT('Turns'!E113)=1,SUM('Turns'!E113),"Unknown") -> 0.00011419025 | Z28: =IF(COUNT('Turns'!F113)=1,SUM('Turns'!F113),"Unknown") -> 0.0001298 | AA28: =IF(ISNUMBER(Y28),ROUND(Y28*'Reference data'!$B$2,0),"Unknown") -> 11 | AB28: =IF(ISNUMBER(Z28),ROUND(Z28*'Reference data'!$B$2,0),"Unknown") -> 13 | AD28: 960.659 | AE28: Subtree total
A29: ChatOpenAI | B29: 2 | C29: model | D29: gpt-5.6-luna | E29: ok | F29: 535 | G29: Generate the next assistant message or tool request from the current conversation. | H29: 01a0d584-6730-71c2-9a2f-74de4fbbbee0 | I29: 01a0d584-6730-71c2-9a2f-74c86b7fc06a | J29: =IF(COUNT('Turns'!D104)=1,SUM('Turns'!D104),"Unknown") -> 535 | K29: =IF(COUNT('Turns'!E104)=1,SUM('Turns'!E104),"Unknown") -> 9.413218e-05 | L29: =IF(COUNT('Turns'!F104)=1,SUM('Turns'!F104),"Unknown") -> 0.000107 | M29: =IF(COUNT('Turns'!D103)=1,SUM('Turns'!D103),"Unknown") -> 0 | N29: =IF(COUNT('Turns'!E103)=1,SUM('Turns'!E103),"Unknown") -> 0 | O29: =IF(COUNT('Turns'!F103)=1,SUM('Turns'!F103),"Unknown") -> 0 | P29: 0 | Q29: 0 | R29: 0 | S29: =IF(COUNT('Turns'!D109)=1,SUM('Turns'!D109),"Unknown") -> 19 | T29: =IF(COUNT('Turns'!E109)=1,SUM('Turns'!E109),"Unknown") -> 2.0058072e-05 | U29: =IF(COUNT('Turns'!F109)=1,SUM('Turns'!F109),"Unknown") -> 2.28e-05 | V29: 0 | W29: 0 | X29: 0 | Y29: =IF(COUNT('Turns'!E113)=1,SUM('Turns'!E113),"Unknown") -> 0.00011419025 | Z29: =IF(COUNT('Turns'!F113)=1,SUM('Turns'!F113),"Unknown") -> 0.0001298 | AA29: =IF(ISNUMBER(Y29),ROUND(Y29*'Reference data'!$B$2,0),"Unknown") -> 11 | AB29: =IF(ISNUMBER(Z29),ROUND(Z29*'Reference data'!$B$2,0),"Unknown") -> 13 | AC29: R8 | AD29: 959.207 | AE29: Own call
A30: dispatcher_agent | B30: 0 | C30: workflow | E30: ok | G30: Execute the dispatcher_agent workflow operation and pass its result to the next graph step. | H30: 01a0d584-6b02-76f1-bfa4-ae1854b0704d | J30: =IF(COUNT('Turns'!D117,'Turns'!D131,'Turns'!D148,'Turns'!D160)=4,SUM('Turns'!D117,'Turns'!D131,'Turns'!D148,'Turns'!D160),"Unknown") -> 1723 | K30: =IF(COUNT('Turns'!E117,'Turns'!E131,'Turns'!E148,'Turns'!E160)=4,SUM('Turns'!E117,'Turns'!E131,'Turns'!E148,'Turns'!E160),"Unknown") -> 0.0003031584 | L30: =IF(COUNT('Turns'!F117,'Turns'!F131,'Turns'!F148,'Turns'!F160)=4,SUM('Turns'!F117,'Turns'!F131,'Turns'!F148,'Turns'!F160),"Unknown") -> 0.0003446 | M30: =IF(COUNT('Turns'!D116,'Turns'!D147,'Turns'!D159)=3,SUM('Turns'!D116,'Turns'!D147,'Turns'!D159),"Unknown") -> 0 | N30: =IF(COUNT('Turns'!E116,'Turns'!E147,'Turns'!E159)=3,SUM('Turns'!E116,'Turns'!E147,'Turns'!E159),"Unknown") -> 0 | O30: =IF(COUNT('Turns'!F116,'Turns'!F147,'Turns'!F159)=3,SUM('Turns'!F116,'Turns'!F147,'Turns'!F159),"Unknown") -> 0 | P30: 0 | Q30: 0 | R30: 0 | S30: =IF(COUNT('Turns'!D122,'Turns'!D138,'Turns'!D153,'Turns'!D165)=4,SUM('Turns'!D122,'Turns'!D138,'Turns'!D153,'Turns'!D165),"Unknown") -> 155 | T30: =IF(COUNT('Turns'!E122,'Turns'!E138,'Turns'!E153,'Turns'!E165)=4,SUM('Turns'!E122,'Turns'!E138,'Turns'!E153,'Turns'!E165),"Unknown") -> 0.00016363164 | U30: =IF(COUNT('Turns'!F122,'Turns'!F138,'Turns'!F153,'Turns'!F165)=4,SUM('Turns'!F122,'Turns'!F138,'Turns'!F153,'Turns'!F165),"Unknown") -> 0.000186 | V30: =IF(COUNT('Turns'!D137)=1,SUM('Turns'!D137),"Unknown") -> 9 | W30: =IF(COUNT('Turns'!E137)=1,SUM('Turns'!E137),"Unknown") -> 9.501192e-06 | X30: =IF(COUNT('Turns'!F137)=1,SUM('Turns'!F137),"Unknown") -> 1.08e-05 | Y30: =IF(COUNT('Turns'!E126,'Turns'!E142,'Turns'!E157,'Turns'!E169)=4,SUM('Turns'!E126,'Turns'!E142,'Turns'!E157,'Turns'!E169),"Unknown") -> 0.00047629124 | Z30: =IF(COUNT('Turns'!F126,'Turns'!F142,'Turns'!F157,'Turns'!F169)=4,SUM('Turns'!F126,'Turns'!F142,'Turns'!F157,'Turns'!F169),"Unknown") -> 0.0005414 | AA30: =IF(ISNUMBER(Y30),ROUND(Y30*'Reference data'!$B$2,0),"Unknown") -> 48 | AB30: =IF(ISNUMBER(Z30),ROUND(Z30*'Reference data'!$B$2,0),"Unknown") -> 54 | AD30: 5087.24 | AE30: Subtree total
A31: model | B31: 1 | C31: workflow | E31: ok | G31: Prepare the current conversation, run model middleware, and invoke the chat model. | H31: 01a0d584-6b03-7ab2-ad42-ef710ce199c3 | I31: 01a0d584-6b02-76f1-bfa4-ae1854b0704d | J31: =IF(COUNT('Turns'!D117)=1,SUM('Turns'!D117),"Unknown") -> 569 | K31: =IF(COUNT('Turns'!E117)=1,SUM('Turns'!E117),"Unknown") -> 0.00010011441 | L31: =IF(COUNT('Turns'!F117)=1,SUM('Turns'!F117),"Unknown") -> 0.0001138 | M31: =IF(COUNT('Turns'!D116)=1,SUM('Turns'!D116),"Unknown") -> 0 | N31: =IF(COUNT('Turns'!E116)=1,SUM('Turns'!E116),"Unknown") -> 0 | O31: =IF(COUNT('Turns'!F116)=1,SUM('Turns'!F116),"Unknown") -> 0 | P31: 0 | Q31: 0 | R31: 0 | S31: =IF(COUNT('Turns'!D122)=1,SUM('Turns'!D122),"Unknown") -> 53 | T31: =IF(COUNT('Turns'!E122)=1,SUM('Turns'!E122),"Unknown") -> 5.5951464e-05 | U31: =IF(COUNT('Turns'!F122)=1,SUM('Turns'!F122),"Unknown") -> 6.36e-05 | V31: 0 | W31: 0 | X31: 0 | Y31: =IF(COUNT('Turns'!E126)=1,SUM('Turns'!E126),"Unknown") -> 0.00015606588 | Z31: =IF(COUNT('Turns'!F126)=1,SUM('Turns'!F126),"Unknown") -> 0.0001774 | AA31: =IF(ISNUMBER(Y31),ROUND(Y31*'Reference data'!$B$2,0),"Unknown") -> 16 | AB31: =IF(ISNUMBER(Z31),ROUND(Z31*'Reference data'!$B$2,0),"Unknown") -> 18 | AD31: 1279.051 | AE31: Subtree total
A32: ChatOpenAI | B32: 2 | C32: model | D32: gpt-5.6-luna | E32: ok | F32: 569 | G32: Generate the next assistant message or tool request from the current conversation. | H32: 01a0d584-6b03-7ab2-ad42-ef88e2862f3a | I32: 01a0d584-6b03-7ab2-ad42-ef710ce199c3 | J32: =IF(COUNT('Turns'!D117)=1,SUM('Turns'!D117),"Unknown") -> 569 | K32: =IF(COUNT('Turns'!E117)=1,SUM('Turns'!E117),"Unknown") -> 0.00010011441 | L32: =IF(COUNT('Turns'!F117)=1,SUM('Turns'!F117),"Unknown") -> 0.0001138 | M32: =IF(COUNT('Turns'!D116)=1,SUM('Turns'!D116),"Unknown") -> 0 | N32: =IF(COUNT('Turns'!E116)=1,SUM('Turns'!E116),"Unknown") -> 0 | O32: =IF(COUNT('Turns'!F116)=1,SUM('Turns'!F116),"Unknown") -> 0 | P32: 0 | Q32: 0 | R32: 0 | S32: =IF(COUNT('Turns'!D122)=1,SUM('Turns'!D122),"Unknown") -> 53 | T32: =IF(COUNT('Turns'!E122)=1,SUM('Turns'!E122),"Unknown") -> 5.5951464e-05 | U32: =IF(COUNT('Turns'!F122)=1,SUM('Turns'!F122),"Unknown") -> 6.36e-05 | V32: 0 | W32: 0 | X32: 0 | Y32: =IF(COUNT('Turns'!E126)=1,SUM('Turns'!E126),"Unknown") -> 0.00015606588 | Z32: =IF(COUNT('Turns'!F126)=1,SUM('Turns'!F126),"Unknown") -> 0.0001774 | AA32: =IF(ISNUMBER(Y32),ROUND(Y32*'Reference data'!$B$2,0),"Unknown") -> 16 | AB32: =IF(ISNUMBER(Z32),ROUND(Z32*'Reference data'!$B$2,0),"Unknown") -> 18 | AC32: R9 | AD32: 1276.855 | AE32: Own call
A33: tools | B33: 1 | C33: workflow | E33: ok | G33: Execute tool calls requested by the preceding model response and return their observations. | H33: 01a0d584-7003-79f0-8039-7980c3124a33 | I33: 01a0d584-6b02-76f1-bfa4-ae1854b0704d | J33: =IF(COUNT('Turns'!D131,'Turns'!D148)=2,SUM('Turns'!D131,'Turns'!D148),"Unknown") -> 476 | K33: =IF(COUNT('Turns'!E131,'Turns'!E148)=2,SUM('Turns'!E131,'Turns'!E148),"Unknown") -> 8.3751248e-05 | L33: =IF(COUNT('Turns'!F131,'Turns'!F148)=2,SUM('Turns'!F131,'Turns'!F148),"Unknown") -> 9.52e-05 | M33: =IF(COUNT('Turns'!D147)=1,SUM('Turns'!D147),"Unknown") -> 0 | N33: =IF(COUNT('Turns'!E147)=1,SUM('Turns'!E147),"Unknown") -> 0 | O33: =IF(COUNT('Turns'!F147)=1,SUM('Turns'!F147),"Unknown") -> 0 | P33: 0 | Q33: 0 | R33: 0 | S33: =IF(COUNT('Turns'!D138,'Turns'!D153)=2,SUM('Turns'!D138,'Turns'!D153),"Unknown") -> 82 | T33: =IF(COUNT('Turns'!E138,'Turns'!E153)=2,SUM('Turns'!E138,'Turns'!E153),"Unknown") -> 8.6566416e-05 | U33: =IF(COUNT('Turns'!F138,'Turns'!F153)=2,SUM('Turns'!F138,'Turns'!F153),"Unknown") -> 9.84e-05 | V33: =IF(COUNT('Turns'!D137)=1,SUM('Turns'!D137),"Unknown") -> 9 | W33: =IF(COUNT('Turns'!E137)=1,SUM('Turns'!E137),"Unknown") -> 9.501192e-06 | X33: =IF(COUNT('Turns'!F137)=1,SUM('Turns'!F137),"Unknown") -> 1.08e-05 | Y33: =IF(COUNT('Turns'!E142,'Turns'!E157)=2,SUM('Turns'!E142,'Turns'!E157),"Unknown") -> 0.00017981886 | Z33: =IF(COUNT('Turns'!F142,'Turns'!F157)=2,SUM('Turns'!F142,'Turns'!F157),"Unknown") -> 0.0002044 | AA33: =IF(ISNUMBER(Y33),ROUND(Y33*'Reference data'!$B$2,0),"Unknown") -> 18 | AB33: =IF(ISNUMBER(Z33),ROUND(Z33*'Reference data'!$B$2,0),"Unknown") -> 20 | AD33: 2900.45 | AE33: Subtree total
A34: task | B34: 2 | C34: tool | E34: ok | G34: Delegate a self-contained question to the matching expert. Available experts: - movie_expert: Specialist for questions about movies, with its own local reference lookup. - sports_expert: Specialist for questions about sports, with its own local reference lookup. - history_expert: Specialist for questions about history, with its own local reference lookup. | H34: 01a0d584-7004-7a50-8b49-905e97f10c0c | I34: 01a0d584-7003-79f0-8039-7980c3124a33 | J34: =IF(COUNT('Turns'!D131,'Turns'!D148)=2,SUM('Turns'!D131,'Turns'!D148),"Unknown") -> 476 | K34: =IF(COUNT('Turns'!E131,'Turns'!E148)=2,SUM('Turns'!E131,'Turns'!E148),"Unknown") -> 8.3751248e-05 | L34: =IF(COUNT('Turns'!F131,'Turns'!F148)=2,SUM('Turns'!F131,'Turns'!F148),"Unknown") -> 9.52e-05 | M34: =IF(COUNT('Turns'!D147)=1,SUM('Turns'!D147),"Unknown") -> 0 | N34: =IF(COUNT('Turns'!E147)=1,SUM('Turns'!E147),"Unknown") -> 0 | O34: =IF(COUNT('Turns'!F147)=1,SUM('Turns'!F147),"Unknown") -> 0 | P34: 0 | Q34: 0 | R34: 0 | S34: =IF(COUNT('Turns'!D138,'Turns'!D153)=2,SUM('Turns'!D138,'Turns'!D153),"Unknown") -> 82 | T34: =IF(COUNT('Turns'!E138,'Turns'!E153)=2,SUM('Turns'!E138,'Turns'!E153),"Unknown") -> 8.6566416e-05 | U34: =IF(COUNT('Turns'!F138,'Turns'!F153)=2,SUM('Turns'!F138,'Turns'!F153),"Unknown") -> 9.84e-05 | V34: =IF(COUNT('Turns'!D137)=1,SUM('Turns'!D137),"Unknown") -> 9 | W34: =IF(COUNT('Turns'!E137)=1,SUM('Turns'!E137),"Unknown") -> 9.501192e-06 | X34: =IF(COUNT('Turns'!F137)=1,SUM('Turns'!F137),"Unknown") -> 1.08e-05 | Y34: =IF(COUNT('Turns'!E142,'Turns'!E157)=2,SUM('Turns'!E142,'Turns'!E157),"Unknown") -> 0.00017981886 | Z34: =IF(COUNT('Turns'!F142,'Turns'!F157)=2,SUM('Turns'!F142,'Turns'!F157),"Unknown") -> 0.0002044 | AA34: =IF(ISNUMBER(Y34),ROUND(Y34*'Reference data'!$B$2,0),"Unknown") -> 18 | AB34: =IF(ISNUMBER(Z34),ROUND(Z34*'Reference data'!$B$2,0),"Unknown") -> 20 | AD34: 2899.258 | AE34: Subtree total
A35: history_expert | B35: 3 | C35: workflow | E35: ok | G35: Execute the history_expert workflow operation and pass its result to the next graph step. | H35: 01a0d584-7005-7fc2-b972-df0f7950ab0a | I35: 01a0d584-7004-7a50-8b49-905e97f10c0c | J35: =IF(COUNT('Turns'!D131,'Turns'!D148)=2,SUM('Turns'!D131,'Turns'!D148),"Unknown") -> 476 | K35: =IF(COUNT('Turns'!E131,'Turns'!E148)=2,SUM('Turns'!E131,'Turns'!E148),"Unknown") -> 8.3751248e-05 | L35: =IF(COUNT('Turns'!F131,'Turns'!F148)=2,SUM('Turns'!F131,'Turns'!F148),"Unknown") -> 9.52e-05 | M35: =IF(COUNT('Turns'!D147)=1,SUM('Turns'!D147),"Unknown") -> 0 | N35: =IF(COUNT('Turns'!E147)=1,SUM('Turns'!E147),"Unknown") -> 0 | O35: =IF(COUNT('Turns'!F147)=1,SUM('Turns'!F147),"Unknown") -> 0 | P35: 0 | Q35: 0 | R35: 0 | S35: =IF(COUNT('Turns'!D138,'Turns'!D153)=2,SUM('Turns'!D138,'Turns'!D153),"Unknown") -> 82 | T35: =IF(COUNT('Turns'!E138,'Turns'!E153)=2,SUM('Turns'!E138,'Turns'!E153),"Unknown") -> 8.6566416e-05 | U35: =IF(COUNT('Turns'!F138,'Turns'!F153)=2,SUM('Turns'!F138,'Turns'!F153),"Unknown") -> 9.84e-05 | V35: =IF(COUNT('Turns'!D137)=1,SUM('Turns'!D137),"Unknown") -> 9 | W35: =IF(COUNT('Turns'!E137)=1,SUM('Turns'!E137),"Unknown") -> 9.501192e-06 | X35: =IF(COUNT('Turns'!F137)=1,SUM('Turns'!F137),"Unknown") -> 1.08e-05 | Y35: =IF(COUNT('Turns'!E142,'Turns'!E157)=2,SUM('Turns'!E142,'Turns'!E157),"Unknown") -> 0.00017981886 | Z35: =IF(COUNT('Turns'!F142,'Turns'!F157)=2,SUM('Turns'!F142,'Turns'!F157),"Unknown") -> 0.0002044 | AA35: =IF(ISNUMBER(Y35),ROUND(Y35*'Reference data'!$B$2,0),"Unknown") -> 18 | AB35: =IF(ISNUMBER(Z35),ROUND(Z35*'Reference data'!$B$2,0),"Unknown") -> 20 | AD35: 2898.057 | AE35: Subtree total
A36: model | B36: 4 | C36: workflow | E36: ok | G36: Prepare the current conversation, run model middleware, and invoke the chat model. | H36: 01a0d584-7007-79f3-9822-9d6684519fcc | I36: 01a0d584-7005-7fc2-b972-df0f7950ab0a | J36: =IF(COUNT('Turns'!D131)=1,SUM('Turns'!D131),"Unknown") -> 185 | K36: =IF(COUNT('Turns'!E131)=1,SUM('Turns'!E131),"Unknown") -> 3.255038e-05 | L36: =IF(COUNT('Turns'!F131)=1,SUM('Turns'!F131),"Unknown") -> 3.7e-05 | M36: 0 | N36: 0 | O36: 0 | P36: 0 | Q36: 0 | R36: 0 | S36: =IF(COUNT('Turns'!D138)=1,SUM('Turns'!D138),"Unknown") -> 32 | T36: =IF(COUNT('Turns'!E138)=1,SUM('Turns'!E138),"Unknown") -> 3.3782016e-05 | U36: =IF(COUNT('Turns'!F138)=1,SUM('Turns'!F138),"Unknown") -> 3.84e-05 | V36: =IF(COUNT('Turns'!D137)=1,SUM('Turns'!D137),"Unknown") -> 9 | W36: =IF(COUNT('Turns'!E137)=1,SUM('Turns'!E137),"Unknown") -> 9.501192e-06 | X36: =IF(COUNT('Turns'!F137)=1,SUM('Turns'!F137),"Unknown") -> 1.08e-05 | Y36: =IF(COUNT('Turns'!E142)=1,SUM('Turns'!E142),"Unknown") -> 7.5833588e-05 | Z36: =IF(COUNT('Turns'!F142)=1,SUM('Turns'!F142),"Unknown") -> 8.62e-05 | AA36: =IF(ISNUMBER(Y36),ROUND(Y36*'Reference data'!$B$2,0),"Unknown") -> 8 | AB36: =IF(ISNUMBER(Z36),ROUND(Z36*'Reference data'!$B$2,0),"Unknown") -> 9 | AD36: 1037.289 | AE36: Subtree total
A37: ChatOpenAI | B37: 5 | C37: model | D37: gpt-5.6-luna | E37: ok | F37: 185 | G37: Generate the next assistant message or tool request from the current conversation. | H37: 01a0d584-700a-7741-9922-a5ace39be30c | I37: 01a0d584-7007-79f3-9822-9d6684519fcc | J37: =IF(COUNT('Turns'!D131)=1,SUM('Turns'!D131),"Unknown") -> 185 | K37: =IF(COUNT('Turns'!E131)=1,SUM('Turns'!E131),"Unknown") -> 3.255038e-05 | L37: =IF(COUNT('Turns'!F131)=1,SUM('Turns'!F131),"Unknown") -> 3.7e-05 | M37: 0 | N37: 0 | O37: 0 | P37: 0 | Q37: 0 | R37: 0 | S37: =IF(COUNT('Turns'!D138)=1,SUM('Turns'!D138),"Unknown") -> 32 | T37: =IF(COUNT('Turns'!E138)=1,SUM('Turns'!E138),"Unknown") -> 3.3782016e-05 | U37: =IF(COUNT('Turns'!F138)=1,SUM('Turns'!F138),"Unknown") -> 3.84e-05 | V37: =IF(COUNT('Turns'!D137)=1,SUM('Turns'!D137),"Unknown") -> 9 | W37: =IF(COUNT('Turns'!E137)=1,SUM('Turns'!E137),"Unknown") -> 9.501192e-06 | X37: =IF(COUNT('Turns'!F137)=1,SUM('Turns'!F137),"Unknown") -> 1.08e-05 | Y37: =IF(COUNT('Turns'!E142)=1,SUM('Turns'!E142),"Unknown") -> 7.5833588e-05 | Z37: =IF(COUNT('Turns'!F142)=1,SUM('Turns'!F142),"Unknown") -> 8.62e-05 | AA37: =IF(ISNUMBER(Y37),ROUND(Y37*'Reference data'!$B$2,0),"Unknown") -> 8 | AB37: =IF(ISNUMBER(Z37),ROUND(Z37*'Reference data'!$B$2,0),"Unknown") -> 9 | AC37: R10 | AD37: 1033.674 | AE37: Own call
A38: tools | B38: 4 | C38: workflow | E38: ok | G38: Execute tool calls requested by the preceding model response and return their observations. | H38: 01a0d584-7415-77d0-9667-00d19d31064e | I38: 01a0d584-7005-7fc2-b972-df0f7950ab0a | AD38: 2.105 | AE38: No model charge
A39: search_history_reference | B39: 5 | C39: tool | E39: ok | G39: Look up local history evidence by phrase; return sources or an explicit miss. | H39: 01a0d584-7415-77d0-9667-00eea0564495 | I39: 01a0d584-7415-77d0-9667-00d19d31064e | AD39: 0.557 | AE39: No model charge
A40: model | B40: 4 | C40: workflow | E40: ok | G40: Prepare the current conversation, run model middleware, and invoke the chat model. | H40: 01a0d584-7418-7603-88b5-abf1d3f2c57a | I40: 01a0d584-7005-7fc2-b972-df0f7950ab0a | J40: =IF(COUNT('Turns'!D148)=1,SUM('Turns'!D148),"Unknown") -> 291 | K40: =IF(COUNT('Turns'!E148)=1,SUM('Turns'!E148),"Unknown") -> 5.1200868e-05 | L40: =IF(COUNT('Turns'!F148)=1,SUM('Turns'!F148),"Unknown") -> 5.82e-05 | M40: =IF(COUNT('Turns'!D147)=1,SUM('Turns'!D147),"Unknown") -> 0 | N40: =IF(COUNT('Turns'!E147)=1,SUM('Turns'!E147),"Unknown") -> 0 | O40: =IF(COUNT('Turns'!F147)=1,SUM('Turns'!F147),"Unknown") -> 0 | P40: 0 | Q40: 0 | R40: 0 | S40: =IF(COUNT('Turns'!D153)=1,SUM('Turns'!D153),"Unknown") -> 50 | T40: =IF(COUNT('Turns'!E153)=1,SUM('Turns'!E153),"Unknown") -> 5.27844e-05 | U40: =IF(COUNT('Turns'!F153)=1,SUM('Turns'!F153),"Unknown") -> 6e-05 | V40: 0 | W40: 0 | X40: 0 | Y40: =IF(COUNT('Turns'!E157)=1,SUM('Turns'!E157),"Unknown") -> 0.00010398527 | Z40: =IF(COUNT('Turns'!F157)=1,SUM('Turns'!F157),"Unknown") -> 0.0001182 | AA40: =IF(ISNUMBER(Y40),ROUND(Y40*'Reference data'!$B$2,0),"Unknown") -> 10 | AB40: =IF(ISNUMBER(Z40),ROUND(Z40*'Reference data'!$B$2,0),"Unknown") -> 12 | AD40: 1854.657 | AE40: Subtree total
...

Sheet Reference data
A1: Parameter | B1: Value | C1: Unit
A2: Number of executions | B2: 100000 | C2: executions
A3: USD → EUR | B3: 0.87974 | C3: EUR per USD
A4: Cache duration | B4: 5m
A5: Run ID | B5: 01a0d584-431a-7670-a84d-31f4a317f39c
A6: Recording | B6: Provider trace
A7: FX reference date | B7: 2026-09-24
A8: FX fetched at | B8: 2026-09-24T22:21:31.719587Z | C8: UTC
A9: FX source | B9: https://api.frankfurter.dev/v2/rate/usd/eur?providers=ecb
A10: Rounding | B10: Only projected costs: ROUND(cost × executions, 0)
A11: Tree totals | B11: Parent rows include descendants; do not sum all tree rows.
A12: Cache writes | B12: Simulated context movement is not a provider-billed write.
A13: Pricing scope | B13: Standard online token rates. Verify rates and model access before use. Cache writes with unspecified lifetime use the 5-minute rate unless an explicit cache_write rate is configured. No batch, regional, long-context, tool, or negotiated pricing adjustments are applied.
A15: Model | B15: Input USD / 1M tokens | C15: Cache read USD / 1M tokens | D15: Cache write USD / 1M tokens | E15: Output USD / 1M tokens | F15: Reasoning USD / 1M tokens | G15: Verified date | H15: Source | I15: Notes
A16: openai:gpt-5.5 | B16: 5 | C16: 0.5 | D16: Unknown | E16: 30 | F16: 30 | G16: 2026-09-18 | H16: https://developers.openai.com/api/docs/models/gpt-5.5.md | I16: Cache write assumes 5m when unspecified
A17: openai:gpt-5.6-luna | B17: 0.2 | C17: 0.02 | D17: 0.25 | E17: 1.2 | F17: 1.2 | G17: 2026-09-18 | H17: https://developers.openai.com/api/docs/models/gpt-5.6-luna.md | I17: Cache write assumes 5m when unspecified
A18: openai:gpt-5.6-sol | B18: 4 | C18: 0.4 | D18: 5 | E18: 20 | F18: 20 | G18: 2026-09-18 | H18: https://developers.openai.com/api/docs/models/gpt-5.6-sol.md | I18: Cache write assumes 5m when unspecified
A19: anthropic:claude-sonnet-5 | B19: 2 | C19: 0.2 | D19: 2.5 | E19: 10 | F19: 10 | G19: 2026-09-18 | H19: https://platform.claude.com/docs/en/about-claude/pricing | I19: Cache write assumes 5m when unspecified
A20: anthropic:claude-opus-4-8 | B20: 5 | C20: 0.5 | D20: 6.25 | E20: 25 | F20: 25 | G20: 2026-09-18 | H20: https://platform.claude.com/docs/en/about-claude/pricing | I20: Cache write assumes 5m when unspecified
