Workbook

Sheet Turns
A1: Request | B1: Turn | C1: Sequence | D1: Tokens | E1: EUR / execution | F1: USD / execution | G1: Projected EUR | H1: Projected USD | I1: Content | J1: Model · effort | K1: Status | L1: Context total tokens | M1: Span ID
C2: Run total | E2: =IF(COUNT('Turns'!E17,'Turns'!E33,'Turns'!E49,'Turns'!E65)=4,SUM('Turns'!E17,'Turns'!E33,'Turns'!E49,'Turns'!E65),"Unknown") -> 0.00079405332 | F2: =IF(COUNT('Turns'!F17,'Turns'!F33,'Turns'!F49,'Turns'!F65)=4,SUM('Turns'!F17,'Turns'!F33,'Turns'!F49,'Turns'!F65),"Unknown") -> 0.0009026 | G2: =IF(ISNUMBER(E2),ROUND(E2*'Reference data'!$B$2,0),"Unknown") -> 79 | H2: =IF(ISNUMBER(F2),ROUND(F2*'Reference data'!$B$2,0),"Unknown") -> 90
B3: 1 | C3: Turn 1 | E3: =IF(COUNT('Turns'!E17,'Turns'!E33,'Turns'!E49,'Turns'!E65)=4,SUM('Turns'!E17,'Turns'!E33,'Turns'!E49,'Turns'!E65),"Unknown") -> 0.00079405332 | F3: =IF(COUNT('Turns'!F17,'Turns'!F33,'Turns'!F49,'Turns'!F65)=4,SUM('Turns'!F17,'Turns'!F33,'Turns'!F49,'Turns'!F65),"Unknown") -> 0.0009026 | G3: =IF(ISNUMBER(E3),ROUND(E3*'Reference data'!$B$2,0),"Unknown") -> 79 | H3: =IF(ISNUMBER(F3),ROUND(F3*'Reference data'!$B$2,0),"Unknown") -> 90
A4: R1 | B4: 1 | C4: LLM request | D4: 626 | J4: gpt-5.6-luna | M4: 01a0d582-8938-71f2-aa92-62a27dfb0bf1
A5: R1 | B5: 1 | C5: Input at standard rate | D5: 626 | E5: =IF(AND(ISNUMBER(F5),ISNUMBER('Reference data'!$B$3)),F5*'Reference data'!$B$3,"Unknown") -> 0.00011014345 | F5: =IF(D5=0,0,IF(ISNUMBER('Reference data'!B17),D5*'Reference data'!B17/1000000,"Unknown")) -> 0.0001252 | G5: =IF(ISNUMBER(E5),ROUND(E5*'Reference data'!$B$2,0),"Unknown") -> 11 | H5: =IF(ISNUMBER(F5),ROUND(F5*'Reference data'!$B$2,0),"Unknown") -> 13
A6: R1 | B6: 1 | C6: Tool definitions
A7: R1 | B7: 1 | C7: System prompt | I7: You are the worker in an intentional circuit-breaker demonstration. The defective plan requires /slugify.py, but the backend only allows /plan.md, /slug.py, and /test_slug.py. Reproduce the failure by calling write_file for /slugify.py with the assigned content. After every rejection, request exactly the same write again. Do not change the path or content, and do not claim success. The application, not you, will stop repeated attempts through its call limit.
A8: R1 | B8: 1 | C8: User prompt | I8: Reproduce the defective plan: write /slugify.py containing '# Slug implementation pending'. Repeat the identical write after rejection so the circuit breaker can stop the loop.
A9: R1 | B9: 1 | C9: Cache write
A10: R1 | B10: 1 | C10: Context · added / total
A11: R1 | B11: 1 | C11: LLM response | D11: 63
A12: R1 | B12: 1 | C12: Reasoning | D12: 31 | E12: =IF(AND(ISNUMBER(F12),ISNUMBER('Reference data'!$B$3)),F12*'Reference data'!$B$3,"Unknown") -> 3.2726328e-05 | F12: =IF(D12=0,0,IF(ISNUMBER('Reference data'!F17),D12*'Reference data'!F17/1000000,"Unknown")) -> 3.72e-05 | G12: =IF(ISNUMBER(E12),ROUND(E12*'Reference data'!$B$2,0),"Unknown") -> 3 | H12: =IF(ISNUMBER(F12),ROUND(F12*'Reference data'!$B$2,0),"Unknown") -> 4
A13: R1 | B13: 1 | C13: Output | D13: 32 | E13: =IF(AND(ISNUMBER(F13),ISNUMBER('Reference data'!$B$3)),F13*'Reference data'!$B$3,"Unknown") -> 3.3782016e-05 | F13: =IF(D13=0,0,IF(ISNUMBER('Reference data'!E17),D13*'Reference data'!E17/1000000,"Unknown")) -> 3.84e-05 | G13: =IF(ISNUMBER(E13),ROUND(E13*'Reference data'!$B$2,0),"Unknown") -> 3 | H13: =IF(ISNUMBER(F13),ROUND(F13*'Reference data'!$B$2,0),"Unknown") -> 4
A14: R1 | B14: 1 | C14: Output content | I14: [{"id": "rs_01eea4e71c40a538006ab5a27394dc87d298156d69e70cb140", "summary": [], "type": "reasoning", "content": [], "index": 0, "encrypted_content": "gAAAAABqtaJzzUKX7jyNhUeaLQza_1JyHBUg1h8QJ4T3OZ6CoIlN2njXtl_8Xh2BG91IZsFiNVre1HtiayRrdudM3P91EsEZr1VldRTcAVrAuxJjws5bcq-_BFerc8Ax2fuILzqxyN_iSBhGCiZCMYKRG1GS49uTy8fnjseeebCH_RLXqasvJxG7Iwayy1y3l098h6kXshMssNBcdmoSDXZqA42OxHuDw1WOkYG_gsMhezG4mAkS87-lhq_febiDd0CpCyW8giIpQBm3dfsrZs6L5BxiuJd68-noGpQUkK1v6Q8wnLuK4CGqUUEnApjZplO8atRembQJVT15C1R_chWCiPEHAIklr-LFvcIIY8GOd__mCEqpeJLrbuWMhS4Fx4SdPdLm69xOV93duB5sjt0l7AFjCa0iicGO0bG34JM5cQ9Prxtb8ii9hPH_ai9o0rC5S7MCu3gWHZj4rXKsJzPiNBpz1qujDi_ieieGRu9Y91NSC3-qYqOYacaLT92G0rsqDnggVL-6YbwrM4iR1vE9fA5cah5tDgnw648G2JUZfijY5Lhycblv4ZAtQ0gkqlrDSPHPL2sIi9HvAy3_WXJRgvvJ3OWxu2HLH7wnGNvFa6uSyZ5O0drfAxCs5_1IEJuCLOx_Ecrw4emeFhvXKPufIYJkXEMYoV60jZfoNkVHUepz06CLEr1LfjUqUueyiAzIA0wbKg6rUVCaeGclXD-gyaKjKFjwsBJRSRAgZtgFOaWjDqm8HwPswOxEZxdC3p8_VUBlROESii-z-pR9ZilaweVS7sdyYG_cFz1_9-lJPOLoh-ideypcFn9P11OXyPftUNa-4KnBoriHWbsusU426le_5lp46MG3BNDuoL2gmLc9UrhR2Lz-XJsPrSMGf59Kq6cwc7u0e0HbvvoBbzygRdGZyO-2AWANGgcoooteI1gFHhTMc4473TfECS-Ao0nntj7o3mIH6dZGp7S2WWFpIYKpnVs6an0DTAngJsuq1wIpEmCzTibTrbyKp-ng01cyGJMVYK7HXQLTz83-cFZIS93Mxsoo9UhdbIdQ4kBfpRIob45SywRz-_H4R1XnSA1ugOyCIQv7oql7maEOQaASlZd4AvKgqIB558TDrLJUlYuzm2Nz7s-fU9jJJTTJLhtGE0iXqec1kbZ_L0y_ePztpiReKNjQZkVI_iR0gEVMdJWlRYhpFtNlkflxOpA5oqvfvXdgatsdt8GTvRHo7RCQuh6UalLskIj3WpTgkS0HRhLUXRiNYY4kX8m5Ne_HfuCV2QyiEaPAiuDFVaPccNfzsRo8mfs83h6lqHHeJYTBc0-ipESVzIDdeC1rVuzrtrVEj76CNOT9"}, {"type": "function_call", "name": "write_file", "arguments": "{\"file_path\":\"/slugify.py\",\"content\":\"# Slug implementation pending\"}", "call_id": "call_AoTvV8HHukCyU7ZXXZydDHrV", "id": "fc_01eea4e71c40a538006ab5a273f2f087d2a66ef115628d8310", "index": 1}] {"name": "write_file", "args": {"file_path": "/slugify.py", "content": "# Slug implementation pending"}, "id": "call_AoTvV8HHukCyU7ZXXZydDHrV", "type": "tool_call"}
A15: R1 | B15: 1 | C15: Cache write
A16: R1 | B16: 1 | C16: Context · added / total
A17: R1 | B17: 1 | C17: Call total | E17: =IF(COUNT('Turns'!E5,'Turns'!E12,'Turns'!E13)=3,SUM('Turns'!E5,'Turns'!E12,'Turns'!E13),"Unknown") -> 0.00017665179 | F17: =IF(COUNT('Turns'!F5,'Turns'!F12,'Turns'!F13)=3,SUM('Turns'!F5,'Turns'!F12,'Turns'!F13),"Unknown") -> 0.0002008 | G17: =IF(ISNUMBER(E17),ROUND(E17*'Reference data'!$B$2,0),"Unknown") -> 18 | H17: =IF(ISNUMBER(F17),ROUND(F17*'Reference data'!$B$2,0),"Unknown") -> 20 | K17: ok
B18: 1 | C18: Tool · write_file | K18: error | M18: 01a0d582-963e-7563-8e82-c9dc1b66cced
B19: 1 | C19: Arguments | I19: {'file_path': '/slugify.py', 'content': '# Slug implementation pending'}
B20: 1 | C20: Result | I20: Only /plan.md, /slug.py, and /test_slug.py may be written
A21: R2 | B21: 1 | C21: LLM request | D21: 717 | J21: gpt-5.6-luna | M21: 01a0d582-9649-7292-aa53-d3db05a9d2f1
A22: R2 | B22: 1 | C22: Conversation history · cache read | D22: 0 | E22: =IF(AND(ISNUMBER(F22),ISNUMBER('Reference data'!$B$3)),F22*'Reference data'!$B$3,"Unknown") -> 0 | F22: =IF(D22=0,0,IF(ISNUMBER('Reference data'!C17),D22*'Reference data'!C17/1000000,"Unknown")) -> 0 | G22: =IF(ISNUMBER(E22),ROUND(E22*'Reference data'!$B$2,0),"Unknown") -> 0 | H22: =IF(ISNUMBER(F22),ROUND(F22*'Reference data'!$B$2,0),"Unknown") -> 0
A23: R2 | B23: 1 | C23: Input at standard rate | D23: 717 | E23: =IF(AND(ISNUMBER(F23),ISNUMBER('Reference data'!$B$3)),F23*'Reference data'!$B$3,"Unknown") -> 0.00012615472 | F23: =IF(D23=0,0,IF(ISNUMBER('Reference data'!B17),D23*'Reference data'!B17/1000000,"Unknown")) -> 0.0001434 | G23: =IF(ISNUMBER(E23),ROUND(E23*'Reference data'!$B$2,0),"Unknown") -> 13 | H23: =IF(ISNUMBER(F23),ROUND(F23*'Reference data'!$B$2,0),"Unknown") -> 14
A24: R2 | B24: 1 | C24: Tool result | I24: Only /plan.md, /slug.py, and /test_slug.py may be written
A25: R2 | B25: 1 | C25: Cache write
A26: R2 | B26: 1 | C26: Context · added / total
A27: R2 | B27: 1 | C27: LLM response | D27: 43
A28: R2 | B28: 1 | C28: Reasoning | D28: 11 | E28: =IF(AND(ISNUMBER(F28),ISNUMBER('Reference data'!$B$3)),F28*'Reference data'!$B$3,"Unknown") -> 1.1612568e-05 | F28: =IF(D28=0,0,IF(ISNUMBER('Reference data'!F17),D28*'Reference data'!F17/1000000,"Unknown")) -> 1.32e-05 | G28: =IF(ISNUMBER(E28),ROUND(E28*'Reference data'!$B$2,0),"Unknown") -> 1 | H28: =IF(ISNUMBER(F28),ROUND(F28*'Reference data'!$B$2,0),"Unknown") -> 1
A29: R2 | B29: 1 | C29: Output | D29: 32 | E29: =IF(AND(ISNUMBER(F29),ISNUMBER('Reference data'!$B$3)),F29*'Reference data'!$B$3,"Unknown") -> 3.3782016e-05 | F29: =IF(D29=0,0,IF(ISNUMBER('Reference data'!E17),D29*'Reference data'!E17/1000000,"Unknown")) -> 3.84e-05 | G29: =IF(ISNUMBER(E29),ROUND(E29*'Reference data'!$B$2,0),"Unknown") -> 3 | H29: =IF(ISNUMBER(F29),ROUND(F29*'Reference data'!$B$2,0),"Unknown") -> 4
A30: R2 | B30: 1 | C30: Output content | I30: [{"id": "rs_01eea4e71c40a538006ab5a2754b9487d2819aa15a89ef84f8", "summary": [], "type": "reasoning", "content": [], "index": 0, "encrypted_content": "gAAAAABqtaJ1kaM3PRSyNh1S0MhQ5l02yb-eAvtN5wv2a2t6PHj_KFFa8e4jJRnCO8iyzv29maIDbgoIjPKd5kg8V8eGkhgMR-r2Bd5ZhnAMDxe8pSyAJgVFHvhCUkdMWmX9Kr3SH-5MhKeAKhzCfiDcnF2WVSyX85NgfNrsV8sKmVkZpVRlailtLpS6RWJ4BnfhbLVLxnVVzDXO-JbgHurtHxO3sbGNr6Ch7-rda6-lMeb_JGhHmSJCqkPRVLEXCgn17aEXd_msIzZX89744CZBdb9FK3FUFT1KpxslSWbyPthd1IOXnGeVFVm5IRMM8bVeF97ZBBOtTJriSKbmeiBwcG2SMt8ahijQdAXAwdZUC9Qajz3Z4y0bVK1eVB4cu9t0XToC6tVjHP3r23tQYngBTWDMfyaBOBNcnzNUNS7HvWY6beYgM72L40HbwfGKJj9z4AnEEp0XttT7k2s_WGiTjQwxyU8zyVk6_I9Ygt-hA1odR8KJbDGATw_1Y1oRwMXpx5OgOLDvKbfUkfxHUvKoV9AmfjS5Rwx37CdzR8h_ky6i757S-YcPNoHT91_cqHKQ5TsqC5PAS3TKS3puxeQqh4Lxp3vdakmgx4qg2aolk7waXth-2qxeXiTdM-fbSjswksBXqSMSYZVygArxeWo59tLXfZ87Cv3V6cNhtHK8W44mfhbButOisBYfw6obqmYb4vttZqucYGVOdM90Oi1sFvaz1CDqvEznE8gSZnsF2HceouWpEaEuBP_7B38ebyu3wX8oIaMwZyN-XHhl7SVZ_3CR3_IQ2x3PvlZai1sTdt98-9QAhebSJGgTGY6AQ3pOBWRSgKSvp6PjMWwIpHiHzJUE7U-i4YfhisfA-tA-B9_EHrYRyzOZtyfgPuiqnBTjeRBsPTyI3WlBa_V4KlAnbwv0VArDXSeEwmETM9IAq-1g8QzRW3TqIFMqNHB02eUO9wIBk2oDxpMtcSDGcBgOkIw5bewYdfFOubt9qnocual2cy9Y4oMis19CuL2-Zx896vF0SDs48Dg6CJKGvm8zFJztVPgCjaNJiaClb6czrnXNHO-32IyRrpXQOD1ALrG7VW9SplHewtv3aS2nW1qJYp46OM4CROlzgtnA1lrPPsEIxyPvECfZNSnWA5ZOEnP4CiQYJ2vSE76fzV-9YRIuMS0vH330OQ-Db4lbQ-U1l2ITkTdNicqLmwiGgwJ3SX16-gbOPUAjE73NsGk6D6lYMFs7ORna-A=="}, {"type": "function_call", "name": "write_file", "arguments": "{\"file_path\":\"/slugify.py\",\"content\":\"# Slug implementation pending\"}", "call_id": "call_UZQ6CumicyTUTwBUPzxFS69w", "id": "fc_01eea4e71c40a538006ab5a275757887d28392acc905f79240", "index": 1}] {"name": "write_file", "args": {"file_path": "/slugify.py", "content": "# Slug implementation pending"}, "id": "call_UZQ6CumicyTUTwBUPzxFS69w", "type": "tool_call"}
A31: R2 | B31: 1 | C31: Cache write
A32: R2 | B32: 1 | C32: Context · added / total
A33: R2 | B33: 1 | C33: Call total | E33: =IF(COUNT('Turns'!E22,'Turns'!E23,'Turns'!E28,'Turns'!E29)=4,SUM('Turns'!E22,'Turns'!E23,'Turns'!E28,'Turns'!E29),"Unknown") -> 0.0001715493 | F33: =IF(COUNT('Turns'!F22,'Turns'!F23,'Turns'!F28,'Turns'!F29)=4,SUM('Turns'!F22,'Turns'!F23,'Turns'!F28,'Turns'!F29),"Unknown") -> 0.000195 | G33: =IF(ISNUMBER(E33),ROUND(E33*'Reference data'!$B$2,0),"Unknown") -> 17 | H33: =IF(ISNUMBER(F33),ROUND(F33*'Reference data'!$B$2,0),"Unknown") -> 20 | K33: ok
B34: 1 | C34: Tool · write_file | K34: error | M34: 01a0d582-9c23-7de0-9568-7a34c169a9ee
B35: 1 | C35: Arguments | I35: {'file_path': '/slugify.py', 'content': '# Slug implementation pending'}
B36: 1 | C36: Result | I36: Only /plan.md, /slug.py, and /test_slug.py may be written
A37: R3 | B37: 1 | C37: LLM request | D37: 788 | J37: gpt-5.6-luna | M37: 01a0d582-9c2a-7112-bf30-a1688eb73a8e
A38: R3 | B38: 1 | C38: Conversation history · cache read | D38: 0 | E38: =IF(AND(ISNUMBER(F38),ISNUMBER('Reference data'!$B$3)),F38*'Reference data'!$B$3,"Unknown") -> 0 | F38: =IF(D38=0,0,IF(ISNUMBER('Reference data'!C17),D38*'Reference data'!C17/1000000,"Unknown")) -> 0 | G38: =IF(ISNUMBER(E38),ROUND(E38*'Reference data'!$B$2,0),"Unknown") -> 0 | H38: =IF(ISNUMBER(F38),ROUND(F38*'Reference data'!$B$2,0),"Unknown") -> 0
A39: R3 | B39: 1 | C39: Input at standard rate | D39: 788 | E39: =IF(AND(ISNUMBER(F39),ISNUMBER('Reference data'!$B$3)),F39*'Reference data'!$B$3,"Unknown") -> 0.00013864702 | F39: =IF(D39=0,0,IF(ISNUMBER('Reference data'!B17),D39*'Reference data'!B17/1000000,"Unknown")) -> 0.0001576 | G39: =IF(ISNUMBER(E39),ROUND(E39*'Reference data'!$B$2,0),"Unknown") -> 14 | H39: =IF(ISNUMBER(F39),ROUND(F39*'Reference data'!$B$2,0),"Unknown") -> 16
A40: R3 | B40: 1 | C40: Tool result | I40: Only /plan.md, /slug.py, and /test_slug.py may be written
...

Sheet Execution tree
A1: Operation | B1: Depth | C1: Type | D1: Model · effort | E1: Status | F1: Input context tokens | G1: Description | H1: Span ID | I1: Parent ID | J1: Input at standard rate tokens | K1: Input at standard rate EUR | L1: Input at standard rate USD | M1: Cache read tokens | N1: Cache read EUR | O1: Cache read USD | P1: Cache write tokens | Q1: Cache write EUR | R1: Cache write USD | S1: Output (non-reasoning) tokens | T1: Output (non-reasoning) EUR | U1: Output (non-reasoning) USD | V1: Reasoning tokens | W1: Reasoning EUR | X1: Reasoning USD | Y1: Total EUR | Z1: Total USD | AA1: Projected EUR | AB1: Projected USD | AC1: Request | AD1: Elapsed ms | AE1: Accounting
A2: worker | B2: 0 | C2: workflow | E2: ok | G2: Execute the worker workflow operation and pass its result to the next graph step. | H2: 01a0d582-8931-7792-9e27-0d96663351ed | J2: =IF(COUNT('Turns'!D5,'Turns'!D23,'Turns'!D39,'Turns'!D55)=4,SUM('Turns'!D5,'Turns'!D23,'Turns'!D39,'Turns'!D55),"Unknown") -> 3007 | K2: =IF(COUNT('Turns'!E5,'Turns'!E23,'Turns'!E39,'Turns'!E55)=4,SUM('Turns'!E5,'Turns'!E23,'Turns'!E39,'Turns'!E55),"Unknown") -> 0.00052907564 | L2: =IF(COUNT('Turns'!F5,'Turns'!F23,'Turns'!F39,'Turns'!F55)=4,SUM('Turns'!F5,'Turns'!F23,'Turns'!F39,'Turns'!F55),"Unknown") -> 0.0006014 | M2: =IF(COUNT('Turns'!D22,'Turns'!D38,'Turns'!D54)=3,SUM('Turns'!D22,'Turns'!D38,'Turns'!D54),"Unknown") -> 0 | N2: =IF(COUNT('Turns'!E22,'Turns'!E38,'Turns'!E54)=3,SUM('Turns'!E22,'Turns'!E38,'Turns'!E54),"Unknown") -> 0 | O2: =IF(COUNT('Turns'!F22,'Turns'!F38,'Turns'!F54)=3,SUM('Turns'!F22,'Turns'!F38,'Turns'!F54),"Unknown") -> 0 | P2: 0 | Q2: 0 | R2: 0 | S2: =IF(COUNT('Turns'!D13,'Turns'!D29,'Turns'!D45,'Turns'!D61)=4,SUM('Turns'!D13,'Turns'!D29,'Turns'!D45,'Turns'!D61),"Unknown") -> 128 | T2: =IF(COUNT('Turns'!E13,'Turns'!E29,'Turns'!E45,'Turns'!E61)=4,SUM('Turns'!E13,'Turns'!E29,'Turns'!E45,'Turns'!E61),"Unknown") -> 0.00013512806 | U2: =IF(COUNT('Turns'!F13,'Turns'!F29,'Turns'!F45,'Turns'!F61)=4,SUM('Turns'!F13,'Turns'!F29,'Turns'!F45,'Turns'!F61),"Unknown") -> 0.0001536 | V2: =IF(COUNT('Turns'!D12,'Turns'!D28,'Turns'!D44,'Turns'!D60)=4,SUM('Turns'!D12,'Turns'!D28,'Turns'!D44,'Turns'!D60),"Unknown") -> 123 | W2: =IF(COUNT('Turns'!E12,'Turns'!E28,'Turns'!E44,'Turns'!E60)=4,SUM('Turns'!E12,'Turns'!E28,'Turns'!E44,'Turns'!E60),"Unknown") -> 0.00012984962 | X2: =IF(COUNT('Turns'!F12,'Turns'!F28,'Turns'!F44,'Turns'!F60)=4,SUM('Turns'!F12,'Turns'!F28,'Turns'!F44,'Turns'!F60),"Unknown") -> 0.0001476 | Y2: =IF(COUNT('Turns'!E17,'Turns'!E33,'Turns'!E49,'Turns'!E65)=4,SUM('Turns'!E17,'Turns'!E33,'Turns'!E49,'Turns'!E65),"Unknown") -> 0.00079405332 | Z2: =IF(COUNT('Turns'!F17,'Turns'!F33,'Turns'!F49,'Turns'!F65)=4,SUM('Turns'!F17,'Turns'!F33,'Turns'!F49,'Turns'!F65),"Unknown") -> 0.0009026 | AA2: =IF(ISNUMBER(Y2),ROUND(Y2*'Reference data'!$B$2,0),"Unknown") -> 79 | AB2: =IF(ISNUMBER(Z2),ROUND(Z2*'Reference data'!$B$2,0),"Unknown") -> 90 | AD2: 8731.172 | AE2: Subtree total
A3: ModelCallLimitMiddleware.before_model | B3: 1 | C3: workflow | E3: ok | G3: Execute the ModelCallLimitMiddleware.before_model workflow operation and pass its result to the next graph step. | H3: 01a0d582-8934-7c51-b7e9-20cfc2097d66 | I3: 01a0d582-8931-7792-9e27-0d96663351ed | AD3: 0.967 | AE3: No model charge
A4: model | B4: 1 | C4: workflow | E4: ok | G4: Prepare the current conversation, run model middleware, and invoke the chat model. | H4: 01a0d582-8936-7321-808f-44660c65019a | I4: 01a0d582-8931-7792-9e27-0d96663351ed | J4: =IF(COUNT('Turns'!D5)=1,SUM('Turns'!D5),"Unknown") -> 626 | K4: =IF(COUNT('Turns'!E5)=1,SUM('Turns'!E5),"Unknown") -> 0.00011014345 | L4: =IF(COUNT('Turns'!F5)=1,SUM('Turns'!F5),"Unknown") -> 0.0001252 | M4: 0 | N4: 0 | O4: 0 | P4: 0 | Q4: 0 | R4: 0 | S4: =IF(COUNT('Turns'!D13)=1,SUM('Turns'!D13),"Unknown") -> 32 | T4: =IF(COUNT('Turns'!E13)=1,SUM('Turns'!E13),"Unknown") -> 3.3782016e-05 | U4: =IF(COUNT('Turns'!F13)=1,SUM('Turns'!F13),"Unknown") -> 3.84e-05 | V4: =IF(COUNT('Turns'!D12)=1,SUM('Turns'!D12),"Unknown") -> 31 | W4: =IF(COUNT('Turns'!E12)=1,SUM('Turns'!E12),"Unknown") -> 3.2726328e-05 | X4: =IF(COUNT('Turns'!F12)=1,SUM('Turns'!F12),"Unknown") -> 3.72e-05 | Y4: =IF(COUNT('Turns'!E17)=1,SUM('Turns'!E17),"Unknown") -> 0.00017665179 | Z4: =IF(COUNT('Turns'!F17)=1,SUM('Turns'!F17),"Unknown") -> 0.0002008 | AA4: =IF(ISNUMBER(Y4),ROUND(Y4*'Reference data'!$B$2,0),"Unknown") -> 18 | AB4: =IF(ISNUMBER(Z4),ROUND(Z4*'Reference data'!$B$2,0),"Unknown") -> 20 | AD4: 3330.326 | AE4: Subtree total
A5: ChatOpenAI | B5: 2 | C5: model | D5: gpt-5.6-luna | E5: ok | F5: 626 | G5: Generate the next assistant message or tool request from the current conversation. | H5: 01a0d582-8938-71f2-aa92-62a27dfb0bf1 | I5: 01a0d582-8936-7321-808f-44660c65019a | J5: =IF(COUNT('Turns'!D5)=1,SUM('Turns'!D5),"Unknown") -> 626 | K5: =IF(COUNT('Turns'!E5)=1,SUM('Turns'!E5),"Unknown") -> 0.00011014345 | L5: =IF(COUNT('Turns'!F5)=1,SUM('Turns'!F5),"Unknown") -> 0.0001252 | M5: 0 | N5: 0 | O5: 0 | P5: 0 | Q5: 0 | R5: 0 | S5: =IF(COUNT('Turns'!D13)=1,SUM('Turns'!D13),"Unknown") -> 32 | T5: =IF(COUNT('Turns'!E13)=1,SUM('Turns'!E13),"Unknown") -> 3.3782016e-05 | U5: =IF(COUNT('Turns'!F13)=1,SUM('Turns'!F13),"Unknown") -> 3.84e-05 | V5: =IF(COUNT('Turns'!D12)=1,SUM('Turns'!D12),"Unknown") -> 31 | W5: =IF(COUNT('Turns'!E12)=1,SUM('Turns'!E12),"Unknown") -> 3.2726328e-05 | X5: =IF(COUNT('Turns'!F12)=1,SUM('Turns'!F12),"Unknown") -> 3.72e-05 | Y5: =IF(COUNT('Turns'!E17)=1,SUM('Turns'!E17),"Unknown") -> 0.00017665179 | Z5: =IF(COUNT('Turns'!F17)=1,SUM('Turns'!F17),"Unknown") -> 0.0002008 | AA5: =IF(ISNUMBER(Y5),ROUND(Y5*'Reference data'!$B$2,0),"Unknown") -> 18 | AB5: =IF(ISNUMBER(Z5),ROUND(Z5*'Reference data'!$B$2,0),"Unknown") -> 20 | AC5: R1 | AD5: 3326.678 | AE5: Own call
A6: ModelCallLimitMiddleware.after_model | B6: 1 | C6: workflow | E6: ok | G6: Execute the ModelCallLimitMiddleware.after_model workflow operation and pass its result to the next graph step. | H6: 01a0d582-963a-7731-b92c-0a6c870cb481 | I6: 01a0d582-8931-7792-9e27-0d96663351ed | AD6: 0.439 | AE6: No model charge
A7: ToolCallLimitMiddleware[write_file].after_model | B7: 1 | C7: workflow | E7: ok | G7: Execute the ToolCallLimitMiddleware[write_file].after_model workflow operation and pass its result to the next graph step. | H7: 01a0d582-963c-7d50-a9f6-2eb22b873459 | I7: 01a0d582-8931-7792-9e27-0d96663351ed | AD7: 0.498 | AE7: No model charge
A8: tools | B8: 1 | C8: workflow | E8: ok | G8: Execute tool calls requested by the preceding model response and return their observations. | H8: 01a0d582-963d-7c50-b393-4ef606ff2dcd | I8: 01a0d582-8931-7792-9e27-0d96663351ed | AD8: 5.233 | AE8: No model charge
A9: write_file | B9: 2 | C9: tool | E9: error | G9: Writes content to a file. Creates the file if it does not exist; replaces it entirely if it does. Usage: - Use this tool when you intend to create a new file or replace the whole file. You do not need to read the file first. - Prefer to edit existing files (with the edit_file tool) over creating new ones when possible. | H9: 01a0d582-963e-7563-8e82-c9dc1b66cced | I9: 01a0d582-963d-7c50-b393-4ef606ff2dcd | AD9: 2.346 | AE9: No model charge
A10: ModelCallLimitMiddleware.before_model | B10: 1 | C10: workflow | E10: ok | G10: Execute the ModelCallLimitMiddleware.before_model workflow operation and pass its result to the next graph step. | H10: 01a0d582-9645-7d30-a2be-b2190b5895df | I10: 01a0d582-8931-7792-9e27-0d96663351ed | AD10: 0.931 | AE10: No model charge
A11: model | B11: 1 | C11: workflow | E11: ok | G11: Prepare the current conversation, run model middleware, and invoke the chat model. | H11: 01a0d582-9647-7ce0-a177-cf3386c01d68 | I11: 01a0d582-8931-7792-9e27-0d96663351ed | J11: =IF(COUNT('Turns'!D23)=1,SUM('Turns'!D23),"Unknown") -> 717 | K11: =IF(COUNT('Turns'!E23)=1,SUM('Turns'!E23),"Unknown") -> 0.00012615472 | L11: =IF(COUNT('Turns'!F23)=1,SUM('Turns'!F23),"Unknown") -> 0.0001434 | M11: =IF(COUNT('Turns'!D22)=1,SUM('Turns'!D22),"Unknown") -> 0 | N11: =IF(COUNT('Turns'!E22)=1,SUM('Turns'!E22),"Unknown") -> 0 | O11: =IF(COUNT('Turns'!F22)=1,SUM('Turns'!F22),"Unknown") -> 0 | P11: 0 | Q11: 0 | R11: 0 | S11: =IF(COUNT('Turns'!D29)=1,SUM('Turns'!D29),"Unknown") -> 32 | T11: =IF(COUNT('Turns'!E29)=1,SUM('Turns'!E29),"Unknown") -> 3.3782016e-05 | U11: =IF(COUNT('Turns'!F29)=1,SUM('Turns'!F29),"Unknown") -> 3.84e-05 | V11: =IF(COUNT('Turns'!D28)=1,SUM('Turns'!D28),"Unknown") -> 11 | W11: =IF(COUNT('Turns'!E28)=1,SUM('Turns'!E28),"Unknown") -> 1.1612568e-05 | X11: =IF(COUNT('Turns'!F28)=1,SUM('Turns'!F28),"Unknown") -> 1.32e-05 | Y11: =IF(COUNT('Turns'!E33)=1,SUM('Turns'!E33),"Unknown") -> 0.0001715493 | Z11: =IF(COUNT('Turns'!F33)=1,SUM('Turns'!F33),"Unknown") -> 0.000195 | AA11: =IF(ISNUMBER(Y11),ROUND(Y11*'Reference data'!$B$2,0),"Unknown") -> 17 | AB11: =IF(ISNUMBER(Z11),ROUND(Z11*'Reference data'!$B$2,0),"Unknown") -> 20 | AD11: 1493.528 | AE11: Subtree total
A12: ChatOpenAI | B12: 2 | C12: model | D12: gpt-5.6-luna | E12: ok | F12: 717 | G12: Generate the next assistant message or tool request from the current conversation. | H12: 01a0d582-9649-7292-aa53-d3db05a9d2f1 | I12: 01a0d582-9647-7ce0-a177-cf3386c01d68 | J12: =IF(COUNT('Turns'!D23)=1,SUM('Turns'!D23),"Unknown") -> 717 | K12: =IF(COUNT('Turns'!E23)=1,SUM('Turns'!E23),"Unknown") -> 0.00012615472 | L12: =IF(COUNT('Turns'!F23)=1,SUM('Turns'!F23),"Unknown") -> 0.0001434 | M12: =IF(COUNT('Turns'!D22)=1,SUM('Turns'!D22),"Unknown") -> 0 | N12: =IF(COUNT('Turns'!E22)=1,SUM('Turns'!E22),"Unknown") -> 0 | O12: =IF(COUNT('Turns'!F22)=1,SUM('Turns'!F22),"Unknown") -> 0 | P12: 0 | Q12: 0 | R12: 0 | S12: =IF(COUNT('Turns'!D29)=1,SUM('Turns'!D29),"Unknown") -> 32 | T12: =IF(COUNT('Turns'!E29)=1,SUM('Turns'!E29),"Unknown") -> 3.3782016e-05 | U12: =IF(COUNT('Turns'!F29)=1,SUM('Turns'!F29),"Unknown") -> 3.84e-05 | V12: =IF(COUNT('Turns'!D28)=1,SUM('Turns'!D28),"Unknown") -> 11 | W12: =IF(COUNT('Turns'!E28)=1,SUM('Turns'!E28),"Unknown") -> 1.1612568e-05 | X12: =IF(COUNT('Turns'!F28)=1,SUM('Turns'!F28),"Unknown") -> 1.32e-05 | Y12: =IF(COUNT('Turns'!E33)=1,SUM('Turns'!E33),"Unknown") -> 0.0001715493 | Z12: =IF(COUNT('Turns'!F33)=1,SUM('Turns'!F33),"Unknown") -> 0.000195 | AA12: =IF(ISNUMBER(Y12),ROUND(Y12*'Reference data'!$B$2,0),"Unknown") -> 17 | AB12: =IF(ISNUMBER(Z12),ROUND(Z12*'Reference data'!$B$2,0),"Unknown") -> 20 | AC12: R2 | AD12: 1490.139 | AE12: Own call
A13: ModelCallLimitMiddleware.after_model | B13: 1 | C13: workflow | E13: ok | G13: Execute the ModelCallLimitMiddleware.after_model workflow operation and pass its result to the next graph step. | H13: 01a0d582-9c1e-71d0-ad18-ed2f501c0b26 | I13: 01a0d582-8931-7792-9e27-0d96663351ed | AD13: 0.501 | AE13: No model charge
A14: ToolCallLimitMiddleware[write_file].after_model | B14: 1 | C14: workflow | E14: ok | G14: Execute the ToolCallLimitMiddleware[write_file].after_model workflow operation and pass its result to the next graph step. | H14: 01a0d582-9c20-7e32-88cc-0301251c1979 | I14: 01a0d582-8931-7792-9e27-0d96663351ed | AD14: 0.602 | AE14: No model charge
A15: tools | B15: 1 | C15: workflow | E15: ok | G15: Execute tool calls requested by the preceding model response and return their observations. | H15: 01a0d582-9c21-7d50-9e70-eab6b5cb0f5b | I15: 01a0d582-8931-7792-9e27-0d96663351ed | AD15: 3.818 | AE15: No model charge
A16: write_file | B16: 2 | C16: tool | E16: error | G16: Writes content to a file. Creates the file if it does not exist; replaces it entirely if it does. Usage: - Use this tool when you intend to create a new file or replace the whole file. You do not need to read the file first. - Prefer to edit existing files (with the edit_file tool) over creating new ones when possible. | H16: 01a0d582-9c23-7de0-9568-7a34c169a9ee | I16: 01a0d582-9c21-7d50-9e70-eab6b5cb0f5b | AD16: 1.3 | AE16: No model charge
A17: ModelCallLimitMiddleware.before_model | B17: 1 | C17: workflow | E17: ok | G17: Execute the ModelCallLimitMiddleware.before_model workflow operation and pass its result to the next graph step. | H17: 01a0d582-9c27-7eb2-9c63-cb7911adad49 | I17: 01a0d582-8931-7792-9e27-0d96663351ed | AD17: 0.841 | AE17: No model charge
A18: model | B18: 1 | C18: workflow | E18: ok | G18: Prepare the current conversation, run model middleware, and invoke the chat model. | H18: 01a0d582-9c29-7683-862c-7a0978df651b | I18: 01a0d582-8931-7792-9e27-0d96663351ed | J18: =IF(COUNT('Turns'!D39)=1,SUM('Turns'!D39),"Unknown") -> 788 | K18: =IF(COUNT('Turns'!E39)=1,SUM('Turns'!E39),"Unknown") -> 0.00013864702 | L18: =IF(COUNT('Turns'!F39)=1,SUM('Turns'!F39),"Unknown") -> 0.0001576 | M18: =IF(COUNT('Turns'!D38)=1,SUM('Turns'!D38),"Unknown") -> 0 | N18: =IF(COUNT('Turns'!E38)=1,SUM('Turns'!E38),"Unknown") -> 0 | O18: =IF(COUNT('Turns'!F38)=1,SUM('Turns'!F38),"Unknown") -> 0 | P18: 0 | Q18: 0 | R18: 0 | S18: =IF(COUNT('Turns'!D45)=1,SUM('Turns'!D45),"Unknown") -> 32 | T18: =IF(COUNT('Turns'!E45)=1,SUM('Turns'!E45),"Unknown") -> 3.3782016e-05 | U18: =IF(COUNT('Turns'!F45)=1,SUM('Turns'!F45),"Unknown") -> 3.84e-05 | V18: =IF(COUNT('Turns'!D44)=1,SUM('Turns'!D44),"Unknown") -> 28 | W18: =IF(COUNT('Turns'!E44)=1,SUM('Turns'!E44),"Unknown") -> 2.9559264e-05 | X18: =IF(COUNT('Turns'!F44)=1,SUM('Turns'!F44),"Unknown") -> 3.36e-05 | Y18: =IF(COUNT('Turns'!E49)=1,SUM('Turns'!E49),"Unknown") -> 0.0002019883 | Z18: =IF(COUNT('Turns'!F49)=1,SUM('Turns'!F49),"Unknown") -> 0.0002296 | AA18: =IF(ISNUMBER(Y18),ROUND(Y18*'Reference data'!$B$2,0),"Unknown") -> 20 | AB18: =IF(ISNUMBER(Z18),ROUND(Z18*'Reference data'!$B$2,0),"Unknown") -> 23 | AD18: 1813.829 | AE18: Subtree total
A19: ChatOpenAI | B19: 2 | C19: model | D19: gpt-5.6-luna | E19: ok | F19: 788 | G19: Generate the next assistant message or tool request from the current conversation. | H19: 01a0d582-9c2a-7112-bf30-a1688eb73a8e | I19: 01a0d582-9c29-7683-862c-7a0978df651b | J19: =IF(COUNT('Turns'!D39)=1,SUM('Turns'!D39),"Unknown") -> 788 | K19: =IF(COUNT('Turns'!E39)=1,SUM('Turns'!E39),"Unknown") -> 0.00013864702 | L19: =IF(COUNT('Turns'!F39)=1,SUM('Turns'!F39),"Unknown") -> 0.0001576 | M19: =IF(COUNT('Turns'!D38)=1,SUM('Turns'!D38),"Unknown") -> 0 | N19: =IF(COUNT('Turns'!E38)=1,SUM('Turns'!E38),"Unknown") -> 0 | O19: =IF(COUNT('Turns'!F38)=1,SUM('Turns'!F38),"Unknown") -> 0 | P19: 0 | Q19: 0 | R19: 0 | S19: =IF(COUNT('Turns'!D45)=1,SUM('Turns'!D45),"Unknown") -> 32 | T19: =IF(COUNT('Turns'!E45)=1,SUM('Turns'!E45),"Unknown") -> 3.3782016e-05 | U19: =IF(COUNT('Turns'!F45)=1,SUM('Turns'!F45),"Unknown") -> 3.84e-05 | V19: =IF(COUNT('Turns'!D44)=1,SUM('Turns'!D44),"Unknown") -> 28 | W19: =IF(COUNT('Turns'!E44)=1,SUM('Turns'!E44),"Unknown") -> 2.9559264e-05 | X19: =IF(COUNT('Turns'!F44)=1,SUM('Turns'!F44),"Unknown") -> 3.36e-05 | Y19: =IF(COUNT('Turns'!E49)=1,SUM('Turns'!E49),"Unknown") -> 0.0002019883 | Z19: =IF(COUNT('Turns'!F49)=1,SUM('Turns'!F49),"Unknown") -> 0.0002296 | AA19: =IF(ISNUMBER(Y19),ROUND(Y19*'Reference data'!$B$2,0),"Unknown") -> 20 | AB19: =IF(ISNUMBER(Z19),ROUND(Z19*'Reference data'!$B$2,0),"Unknown") -> 23 | AC19: R3 | AD19: 1810.992 | AE19: Own call
A20: ModelCallLimitMiddleware.after_model | B20: 1 | C20: workflow | E20: ok | G20: Execute the ModelCallLimitMiddleware.after_model workflow operation and pass its result to the next graph step. | H20: 01a0d582-a340-7322-91e6-abcecef72969 | I20: 01a0d582-8931-7792-9e27-0d96663351ed | AD20: 0.499 | AE20: No model charge
A21: ToolCallLimitMiddleware[write_file].after_model | B21: 1 | C21: workflow | E21: ok | G21: Execute the ToolCallLimitMiddleware[write_file].after_model workflow operation and pass its result to the next graph step. | H21: 01a0d582-a342-7282-9a9b-6beea3e23d34 | I21: 01a0d582-8931-7792-9e27-0d96663351ed | AD21: 0.546 | AE21: No model charge
A22: tools | B22: 1 | C22: workflow | E22: ok | G22: Execute tool calls requested by the preceding model response and return their observations. | H22: 01a0d582-a343-77b3-b8d8-44afd0fd486e | I22: 01a0d582-8931-7792-9e27-0d96663351ed | AD22: 2.252 | AE22: No model charge
A23: write_file | B23: 2 | C23: tool | E23: error | G23: Writes content to a file. Creates the file if it does not exist; replaces it entirely if it does. Usage: - Use this tool when you intend to create a new file or replace the whole file. You do not need to read the file first. - Prefer to edit existing files (with the edit_file tool) over creating new ones when possible. | H23: 01a0d582-a344-7150-9da7-c285aea8d940 | I23: 01a0d582-a343-77b3-b8d8-44afd0fd486e | AD23: 0.785 | AE23: No model charge
A24: ModelCallLimitMiddleware.before_model | B24: 1 | C24: workflow | E24: ok | G24: Execute the ModelCallLimitMiddleware.before_model workflow operation and pass its result to the next graph step. | H24: 01a0d582-a346-7030-9a5b-d15cc3b33c29 | I24: 01a0d582-8931-7792-9e27-0d96663351ed | AD24: 0.435 | AE24: No model charge
A25: model | B25: 1 | C25: workflow | E25: ok | G25: Prepare the current conversation, run model middleware, and invoke the chat model. | H25: 01a0d582-a348-7c00-a4db-b4d014b17552 | I25: 01a0d582-8931-7792-9e27-0d96663351ed | J25: =IF(COUNT('Turns'!D55)=1,SUM('Turns'!D55),"Unknown") -> 876 | K25: =IF(COUNT('Turns'!E55)=1,SUM('Turns'!E55),"Unknown") -> 0.00015413045 | L25: =IF(COUNT('Turns'!F55)=1,SUM('Turns'!F55),"Unknown") -> 0.0001752 | M25: =IF(COUNT('Turns'!D54)=1,SUM('Turns'!D54),"Unknown") -> 0 | N25: =IF(COUNT('Turns'!E54)=1,SUM('Turns'!E54),"Unknown") -> 0 | O25: =IF(COUNT('Turns'!F54)=1,SUM('Turns'!F54),"Unknown") -> 0 | P25: 0 | Q25: 0 | R25: 0 | S25: =IF(COUNT('Turns'!D61)=1,SUM('Turns'!D61),"Unknown") -> 32 | T25: =IF(COUNT('Turns'!E61)=1,SUM('Turns'!E61),"Unknown") -> 3.3782016e-05 | U25: =IF(COUNT('Turns'!F61)=1,SUM('Turns'!F61),"Unknown") -> 3.84e-05 | V25: =IF(COUNT('Turns'!D60)=1,SUM('Turns'!D60),"Unknown") -> 53 | W25: =IF(COUNT('Turns'!E60)=1,SUM('Turns'!E60),"Unknown") -> 5.5951464e-05 | X25: =IF(COUNT('Turns'!F60)=1,SUM('Turns'!F60),"Unknown") -> 6.36e-05 | Y25: =IF(COUNT('Turns'!E65)=1,SUM('Turns'!E65),"Unknown") -> 0.00024386393 | Z25: =IF(COUNT('Turns'!F65)=1,SUM('Turns'!F65),"Unknown") -> 0.0002772 | AA25: =IF(ISNUMBER(Y25),ROUND(Y25*'Reference data'!$B$2,0),"Unknown") -> 24 | AB25: =IF(ISNUMBER(Z25),ROUND(Z25*'Reference data'!$B$2,0),"Unknown") -> 28 | AD25: 2046.011 | AE25: Subtree total
A26: ChatOpenAI | B26: 2 | C26: model | D26: gpt-5.6-luna | E26: ok | F26: 876 | G26: Generate the next assistant message or tool request from the current conversation. | H26: 01a0d582-a349-7653-85f6-133afc7c0558 | I26: 01a0d582-a348-7c00-a4db-b4d014b17552 | J26: =IF(COUNT('Turns'!D55)=1,SUM('Turns'!D55),"Unknown") -> 876 | K26: =IF(COUNT('Turns'!E55)=1,SUM('Turns'!E55),"Unknown") -> 0.00015413045 | L26: =IF(COUNT('Turns'!F55)=1,SUM('Turns'!F55),"Unknown") -> 0.0001752 | M26: =IF(COUNT('Turns'!D54)=1,SUM('Turns'!D54),"Unknown") -> 0 | N26: =IF(COUNT('Turns'!E54)=1,SUM('Turns'!E54),"Unknown") -> 0 | O26: =IF(COUNT('Turns'!F54)=1,SUM('Turns'!F54),"Unknown") -> 0 | P26: 0 | Q26: 0 | R26: 0 | S26: =IF(COUNT('Turns'!D61)=1,SUM('Turns'!D61),"Unknown") -> 32 | T26: =IF(COUNT('Turns'!E61)=1,SUM('Turns'!E61),"Unknown") -> 3.3782016e-05 | U26: =IF(COUNT('Turns'!F61)=1,SUM('Turns'!F61),"Unknown") -> 3.84e-05 | V26: =IF(COUNT('Turns'!D60)=1,SUM('Turns'!D60),"Unknown") -> 53 | W26: =IF(COUNT('Turns'!E60)=1,SUM('Turns'!E60),"Unknown") -> 5.5951464e-05 | X26: =IF(COUNT('Turns'!F60)=1,SUM('Turns'!F60),"Unknown") -> 6.36e-05 | Y26: =IF(COUNT('Turns'!E65)=1,SUM('Turns'!E65),"Unknown") -> 0.00024386393 | Z26: =IF(COUNT('Turns'!F65)=1,SUM('Turns'!F65),"Unknown") -> 0.0002772 | AA26: =IF(ISNUMBER(Y26),ROUND(Y26*'Reference data'!$B$2,0),"Unknown") -> 24 | AB26: =IF(ISNUMBER(Z26),ROUND(Z26*'Reference data'!$B$2,0),"Unknown") -> 28 | AC26: R4 | AD26: 2043.332 | AE26: Own call
A27: ModelCallLimitMiddleware.after_model | B27: 1 | C27: workflow | E27: ok | G27: Execute the ModelCallLimitMiddleware.after_model workflow operation and pass its result to the next graph step. | H27: 01a0d582-ab48-7d92-99cd-0715e8e089d7 | I27: 01a0d582-8931-7792-9e27-0d96663351ed | AD27: 0.71 | AE27: No model charge
A28: ToolCallLimitMiddleware[write_file].after_model | B28: 1 | C28: workflow | E28: ok | G28: Circuit breaker tripped | 'write_file' tool call limit reached: run limit exceeded (4/3 calls). | Agent stopped | H28: 01a0d582-ab4a-7921-8b82-e2d4a7d8a175 | I28: 01a0d582-8931-7792-9e27-0d96663351ed | AD28: 1.241 | AE28: No model charge

Sheet Reference data
A1: Parameter | B1: Value | C1: Unit
A2: Number of executions | B2: 100000 | C2: executions
A3: USD → EUR | B3: 0.87974 | C3: EUR per USD
A4: Cache duration | B4: 5m
A5: Run ID | B5: 01a0d582-8931-7792-9e27-0d96663351ed
A6: Recording | B6: Provider trace
A7: FX reference date | B7: 2026-09-24
A8: FX fetched at | B8: 2026-09-24T22:21:31.719587Z | C8: UTC
A9: FX source | B9: https://api.frankfurter.dev/v2/rate/usd/eur?providers=ecb
A10: Rounding | B10: Only projected costs: ROUND(cost × executions, 0)
A11: Tree totals | B11: Parent rows include descendants; do not sum all tree rows.
A12: Cache writes | B12: Simulated context movement is not a provider-billed write.
A13: Pricing scope | B13: Standard online token rates. Verify rates and model access before use. Cache writes with unspecified lifetime use the 5-minute rate unless an explicit cache_write rate is configured. No batch, regional, long-context, tool, or negotiated pricing adjustments are applied.
A15: Model | B15: Input USD / 1M tokens | C15: Cache read USD / 1M tokens | D15: Cache write USD / 1M tokens | E15: Output USD / 1M tokens | F15: Reasoning USD / 1M tokens | G15: Verified date | H15: Source | I15: Notes
A16: openai:gpt-5.5 | B16: 5 | C16: 0.5 | D16: Unknown | E16: 30 | F16: 30 | G16: 2026-09-18 | H16: https://developers.openai.com/api/docs/models/gpt-5.5.md | I16: Cache write assumes 5m when unspecified
A17: openai:gpt-5.6-luna | B17: 0.2 | C17: 0.02 | D17: 0.25 | E17: 1.2 | F17: 1.2 | G17: 2026-09-18 | H17: https://developers.openai.com/api/docs/models/gpt-5.6-luna.md | I17: Cache write assumes 5m when unspecified
A18: openai:gpt-5.6-sol | B18: 4 | C18: 0.4 | D18: 5 | E18: 20 | F18: 20 | G18: 2026-09-18 | H18: https://developers.openai.com/api/docs/models/gpt-5.6-sol.md | I18: Cache write assumes 5m when unspecified
A19: anthropic:claude-sonnet-5 | B19: 2 | C19: 0.2 | D19: 2.5 | E19: 10 | F19: 10 | G19: 2026-09-18 | H19: https://platform.claude.com/docs/en/about-claude/pricing | I19: Cache write assumes 5m when unspecified
A20: anthropic:claude-opus-4-8 | B20: 5 | C20: 0.5 | D20: 6.25 | E20: 25 | F20: 25 | G20: 2026-09-18 | H20: https://platform.claude.com/docs/en/about-claude/pricing | I20: Cache write assumes 5m when unspecified
A21: anthropic:claude-fable-5-1 | B21: 10 | C21: 0.25 | D21: 12.5 | E21: 50 | F21: 50 | G21: 2026-09-18 | H21: https://platform.claude.com/docs/en/about-claude/pricing | I21: Cache write assumes 5m when unspecified
A22: demo:scripted-chat | B22: 0.2 | C22: 0.02 | D22: 0.25 | E22: 1.2 | F22: 1.2 | G22: 2026-09-18 | H22: Illustrative demo rates based on openai:gpt-5.6-luna; no provider billing | I22: Cache write assumes 5m when unspecified
