Workbook

Sheet Turns
A1: Request | B1: Turn | C1: Sequence | D1: Tokens | E1: EUR / execution | F1: USD / execution | G1: Projected EUR | H1: Projected USD | I1: Content | J1: Model · effort | K1: Status | L1: Context total tokens | M1: Span ID
C2: Run total | E2: =IF(COUNT('Turns'!E17,'Turns'!E29,'Turns'!E41)=3,SUM('Turns'!E17,'Turns'!E29,'Turns'!E41),"Unknown") -> 0.0010603835 | F2: =IF(COUNT('Turns'!F17,'Turns'!F29,'Turns'!F41)=3,SUM('Turns'!F17,'Turns'!F29,'Turns'!F41),"Unknown") -> 0.00121 | G2: =IF(ISNUMBER(E2),ROUND(E2*'Reference data'!$B$2,0),"Unknown") -> 106 | H2: =IF(ISNUMBER(F2),ROUND(F2*'Reference data'!$B$2,0),"Unknown") -> 121
B3: 1 | C3: Turn 1 | E3: =IF(COUNT('Turns'!E17,'Turns'!E29,'Turns'!E41)=3,SUM('Turns'!E17,'Turns'!E29,'Turns'!E41),"Unknown") -> 0.0010603835 | F3: =IF(COUNT('Turns'!F17,'Turns'!F29,'Turns'!F41)=3,SUM('Turns'!F17,'Turns'!F29,'Turns'!F41),"Unknown") -> 0.00121 | G3: =IF(ISNUMBER(E3),ROUND(E3*'Reference data'!$B$2,0),"Unknown") -> 106 | H3: =IF(ISNUMBER(F3),ROUND(F3*'Reference data'!$B$2,0),"Unknown") -> 121
A4: R1 | B4: 1 | C4: LLM request | D4: 493 | J4: gpt-5.6-luna | M4: 01a0d132-b47a-7da0-b744-558a9097def7
A5: R1 | B5: 1 | C5: Input at standard rate | D5: 493 | E5: =IF(AND(ISNUMBER(F5),ISNUMBER('Reference data'!$B$3)),F5*'Reference data'!$B$3,"Unknown") -> 8.640811e-05 | F5: =IF(D5=0,0,IF(ISNUMBER('Reference data'!B17),D5*'Reference data'!B17/1000000,"Unknown")) -> 9.86e-05 | G5: =IF(ISNUMBER(E5),ROUND(E5*'Reference data'!$B$2,0),"Unknown") -> 9 | H5: =IF(ISNUMBER(F5),ROUND(F5*'Reference data'!$B$2,0),"Unknown") -> 10
A6: R1 | B6: 1 | C6: Tool definitions
A7: R1 | B7: 1 | C7: System prompt | I7: You help a human prepare a quote request. Read the entire request and clarification conversation. Decide whether its meaning is clear enough to prepare an accurate request. Notice conflicting requirements, implausible scope, ambiguous units, and assumptions that would materially change the quote. Ask the human a focused question in your own words when their judgment or information is needed. Check for multiple independent issues across the whole request, not just the first inconsistency. Keep all unresolved issues in view after every answer. You may group closely related questions; do not complete while a material issue remains unresolved. Explain the concrete uncertainty. This is a conversation, not a required field checklist. Do not silently repair contradictions or invent requirements, prices, feasibility guarantees, or human answers. Reconsider the request after every answer; an unclear answer may need another question. Complete without a question when the request is already coherent. Completion summarizes the agreed scope and any explicitly accepted uncertainty; it does not send a quote or promise supplier acceptance. Return exactly one QuoteDecision tool call.
A8: R1 | B8: 1 | C8: User prompt | I8: {"initial_request": {"name": "Alex", "email": "alex@example.com", "service": "Print 500 individually addressed invitations. Use the exact same text on every copy; no variable printing.", "quantity": 500, "recipients": "650 guests, each must receive their own invitation.", "delivery": "One batch to our office; we will mail them ourselves."}, "conversation": []}
A9: R1 | B9: 1 | C9: Cache write
A10: R1 | B10: 1 | C10: Context · added / total
A11: R1 | B11: 1 | C11: LLM response | D11: 177
A12: R1 | B12: 1 | C12: Reasoning | D12: 61 | E12: =IF(AND(ISNUMBER(F12),ISNUMBER('Reference data'!$B$3)),F12*'Reference data'!$B$3,"Unknown") -> 6.414882e-05 | F12: =IF(D12=0,0,IF(ISNUMBER('Reference data'!F17),D12*'Reference data'!F17/1000000,"Unknown")) -> 7.32e-05 | G12: =IF(ISNUMBER(E12),ROUND(E12*'Reference data'!$B$2,0),"Unknown") -> 6 | H12: =IF(ISNUMBER(F12),ROUND(F12*'Reference data'!$B$2,0),"Unknown") -> 7
A13: R1 | B13: 1 | C13: Output | D13: 116 | E13: =IF(AND(ISNUMBER(F13),ISNUMBER('Reference data'!$B$3)),F13*'Reference data'!$B$3,"Unknown") -> 0.00012198792 | F13: =IF(D13=0,0,IF(ISNUMBER('Reference data'!E17),D13*'Reference data'!E17/1000000,"Unknown")) -> 0.0001392 | G13: =IF(ISNUMBER(E13),ROUND(E13*'Reference data'!$B$2,0),"Unknown") -> 12 | H13: =IF(ISNUMBER(F13),ROUND(F13*'Reference data'!$B$2,0),"Unknown") -> 14
A14: R1 | B14: 1 | C14: Output content | I14: [{"id": "rs_01970afda7ee6687006ab487dd7f6087d290b1326b94b985ff", "summary": [], "type": "reasoning", "content": [], "index": 0, "encrypted_content": "gAAAAABqtIfeO3KWbOdBkRAL-UlrJ7XblOkm6Bv4NRXpP4AscxWSRzIA8hSatVWPX-gt3klOWP-DOAHtPK4XmrZQdrLbyjvHWZgxC2uqp2Sf5XnqhVTXgYkn23_7Lh3_W6b7PM08enJ6XuTEX-SqeI1xtbYKMRaRLhc77pTmAxJT6tSIlc3O5HsiODkkYA-e97iPRxe6RpRkuBO_QSMyNhulgrnAO3u_prWrrUMiS46btTeFgC9bebvWrdZihED0y-IvsYIqJnw2BsFqq9nBCOFVTbP-LK80Pzh8MZT2LJ8ivuVQDDBCqrxPywXcXWVe1pgHmsXKgBz1NZY1Qg1_eHdrD4WlHotQl0-aSKvAmzCzA4tdMGbEas7vcyNH1uwBCLV89HW645K7iiZcb_AtL4qYoSM2JDXkzMCapee_mOIllJ9aMwksTIqK0jnn-W7RB41hrK614QyRTS9JEIKPgNRJsxNlR2Ss-FHCy3Xmzw4Vb1_mXfIwjAOZMMxbOwlUzFNzW6aT0NQ-jvzMjDXzKbK2Kg9BcCtpr-3PwtTzfgDfThutYGGqX2Na2pIF3j-yShXGn9m12yOq-EeeXNY8UjS6R7pUGUWCWVY8V0n3ioGHLvL8bXH7gUZWv38-RCuI_AHrAeEyhaar6DEC3GPFw-QixLXMFmlSixk3SXGnw1cIhu7uBwSPHZvl_DShWq4AxTEy-9rg_0jnITJJOfO2GXxDqOELWvUOfa3fKQh59l-8ztJR1MWPpx9dvOBiIemLV3zRynj1oYYEzPmbrElJbSdonANXIhuekaQnETih08iQwpuL4YR8odjAV8GAuE_-SZD1JNCy4r8z6SJ6lSLIuQ8epikCjC06XCeDj9FlA_nmLluR3E0Nb-PmnQkAMvAu6fftWntBbukrqdOqLk7koso0JavsUVwPPjK7VmNxI4MzARtJc5qfwEg7viIQ0SB196MwM4LyKPS7-ghcqPU7bR4SF3R17c22Ok1R-5vMimpEqt6K2jddZpuTHAPonSqfYJafr2WSKExfVB5zfQ7FUwtRj-A_6EyVjB0DgtwLH54RKIFGspgHy6CGuCaRqEvTwq5TuwBk9xtyyWnFWRruPQk1dcTSSg6FdSqoAL3RQwgGukNEq4NC-VSiDbjli1THaBaKXN7lEjv3IQjCkS2Ot8ffJs6JSFJgtHg5Fm9yiLwFnPnIlhVomODU85DnIqel4kPRZB3NJx-xLkE48zF5uDfbQUGokeEc1aE8cQxOlDHhP4UpKHYDQ2_FTqADy9tR5XDgFxNCcYjZSb-4xBc_vx4Hgd_8EirJoefHS1pVTy0WigfDR9PRgKR7g9hHaF3uf1n72ff_YUhZ2xQx0ixllmauZC2J76Qhz5IRrz1K6JTJHoKXvzz9DU7mI3IbiVs7R-db4SAPIZds5qIhXk1-cnOv29Ba2myqj1t5ls7rcT8ojvdauwSMIi4cQDeW41ZC3j2elvkLfWlu6YUYRbTnkBE-uUAClM2-jY-0gMOwBJmUYma-adHAOYjldiQCkzcYQ7naua-9Om0C_kazC2Ut9OnTlfDUS47ZeoXyxjedkjbFTsRBlZV9gpIfQInZoJAq42CAcTKxvLPt"}, {"type": "function_call", "name": "QuoteDecision", "arguments": "{\"action\":\"ask\",\"reason\":\"The request contains two material scope conflicts: it specifies 500 invitations but 650 guests who must each receive one, and it asks for individually addressed pieces while also requiring identical text with no variable printing.\",\"text\":\"Should the quantity be 650 invitations (one per guest) or 500? Also, do you want the printer to add each guest\u2019s address/name, or should all 650 printed invitations have identical content with your office handling all addressing and mailing?\"}", "call_id": "call_az0rpqrY0qTXBQFVU5BDuxyg", "id": "fc_01970afda7ee6687006ab487dea7d887d2951d38abc69f89c4", "index": 1}] {"name": "QuoteDecision", "args": {"action": "ask", "reason": "The request contains two material scope conflicts: it specifies 500 invitations but 650 guests who must each receive one, and it asks for individually addressed pieces while also requiring identical text with no variable printing.", "text": "Should the quantity be 650 invitations (one per guest) or 500? Also, do you want the printer to add each guest\u2019s address/name, or should all 650 printed invitations have identical content with your office handling all addressing and mailing?"}, "id": "call_az0rpqrY0qTXBQFVU5BDuxyg", "type": "tool_call"}
A15: R1 | B15: 1 | C15: Cache write
A16: R1 | B16: 1 | C16: Context · added / total
A17: R1 | B17: 1 | C17: Call total | E17: =IF(COUNT('Turns'!E5,'Turns'!E12,'Turns'!E13)=3,SUM('Turns'!E5,'Turns'!E12,'Turns'!E13),"Unknown") -> 0.00027254485 | F17: =IF(COUNT('Turns'!F5,'Turns'!F12,'Turns'!F13)=3,SUM('Turns'!F5,'Turns'!F12,'Turns'!F13),"Unknown") -> 0.000311 | G17: =IF(ISNUMBER(E17),ROUND(E17*'Reference data'!$B$2,0),"Unknown") -> 27 | H17: =IF(ISNUMBER(F17),ROUND(F17*'Reference data'!$B$2,0),"Unknown") -> 31 | K17: ok
A18: R2 | B18: 1 | C18: LLM request | D18: 605 | J18: gpt-5.6-luna | M18: 01a0d133-118a-7ce3-a1cf-76986af715ce
A19: R2 | B19: 1 | C19: Conversation history · cache read | D19: 0 | E19: =IF(AND(ISNUMBER(F19),ISNUMBER('Reference data'!$B$3)),F19*'Reference data'!$B$3,"Unknown") -> 0 | F19: =IF(D19=0,0,IF(ISNUMBER('Reference data'!C17),D19*'Reference data'!C17/1000000,"Unknown")) -> 0 | G19: =IF(ISNUMBER(E19),ROUND(E19*'Reference data'!$B$2,0),"Unknown") -> 0 | H19: =IF(ISNUMBER(F19),ROUND(F19*'Reference data'!$B$2,0),"Unknown") -> 0
A20: R2 | B20: 1 | C20: Input at standard rate | D20: 605 | E20: =IF(AND(ISNUMBER(F20),ISNUMBER('Reference data'!$B$3)),F20*'Reference data'!$B$3,"Unknown") -> 0.00010603835 | F20: =IF(D20=0,0,IF(ISNUMBER('Reference data'!B17),D20*'Reference data'!B17/1000000,"Unknown")) -> 0.000121 | G20: =IF(ISNUMBER(E20),ROUND(E20*'Reference data'!$B$2,0),"Unknown") -> 11 | H20: =IF(ISNUMBER(F20),ROUND(F20*'Reference data'!$B$2,0),"Unknown") -> 12
A21: R2 | B21: 1 | C21: Cache write
A22: R2 | B22: 1 | C22: Context · added / total
A23: R2 | B23: 1 | C23: LLM response | D23: 311
A24: R2 | B24: 1 | C24: Reasoning | D24: 181 | E24: =IF(AND(ISNUMBER(F24),ISNUMBER('Reference data'!$B$3)),F24*'Reference data'!$B$3,"Unknown") -> 0.00019034322 | F24: =IF(D24=0,0,IF(ISNUMBER('Reference data'!F17),D24*'Reference data'!F17/1000000,"Unknown")) -> 0.0002172 | G24: =IF(ISNUMBER(E24),ROUND(E24*'Reference data'!$B$2,0),"Unknown") -> 19 | H24: =IF(ISNUMBER(F24),ROUND(F24*'Reference data'!$B$2,0),"Unknown") -> 22
A25: R2 | B25: 1 | C25: Output | D25: 130 | E25: =IF(AND(ISNUMBER(F25),ISNUMBER('Reference data'!$B$3)),F25*'Reference data'!$B$3,"Unknown") -> 0.0001367106 | F25: =IF(D25=0,0,IF(ISNUMBER('Reference data'!E17),D25*'Reference data'!E17/1000000,"Unknown")) -> 0.000156 | G25: =IF(ISNUMBER(E25),ROUND(E25*'Reference data'!$B$2,0),"Unknown") -> 14 | H25: =IF(ISNUMBER(F25),ROUND(F25*'Reference data'!$B$2,0),"Unknown") -> 16
A26: R2 | B26: 1 | C26: Output content | I26: [{"id": "rs_0a7e38912863ce39006ab487f500a487d29fc0a39c06c94d65", "summary": [], "type": "reasoning", "content": [], "index": 0, "encrypted_content": "gAAAAABqtIf4hgNhLoT9OZru5REcX-pIxfrRw0fVUb_GeNBBzJ4SDZEVdnV-xodhbRl9AcfhG-Zq9xqUPpULTGxdzD5SZ4-uwXQ_T45ymrvnmyyvE7XYPL-_M3Myvsu9hT6n55-hQ9lgi--r17R8qHoydqjMdykdykCTgf1G61uzceFo_dZIMYsuQ92rBHq9Apdnxei_Q5rHo_ZAgxnhFwCb206b5hobit9_WxdLoF38untW8-DXRBCFIBkT1hAvQ6tSE3qKXcrMd5pjHp_1jvpfuLx3KJ_gTPrGrwI6JB5xvg-aNzBx1oST3HrBiby9Q2wTYApmJKw2_V4M5Mhw51srAYB2KdRYXYBLMTnKFQWGMzIWPpQLXG37T5RbQ8LO8Tjh_kJRBfwvI4hPJ193O1tuveQa7RPGW2MHcquBPpGuXD5wLsdmsGkhtP3wqcirBTU5zsC5HyZXwQtnIuiaOB2lyaxpAXs7qHmt2L61tT5jEea3SQObJpkuamD4aOpyZVDh5hlkbDcY7pjVVLHETDgxiX-DeCMEQgYWc9kC0UgqMesouz6s7Mycg6apGGyRcUbNpFXw9O-1rk9_JSWmAuukqjwd1V0JYIXfKJ4OUCKYX38V18dBKLd3g_gsL_s3kc7sXD-gtxtVgfJbBAihN6s_zxgcR68j2v-DetUwAlg7vzBlhD1zDklxwBnjGFdexE2m5mAWG4lNyZG5JwmXWdFA0nLVCu7IKgyDJXu2TQ3UqJmwoNhAQjWqx3sRD9WkVkt8ovkDtjPwXbNGiqdBBquHdggWwxMM9mYzVs3y1OnDO5pDu8YX87FPGpY4A24-x7YQ06o5DxbEIr_U8r72MQRZEs1NC1wgpOe_IlsPu1XzgVIFILv8IjczT_U0ejkGwlcnN581IWeVjTO6D29VNx8DOx4Hd22tisW_HjvRd9AAXfQ_PRJMKvVjhf-MV2NpiqVGTgud83fO2H6v5n3K11fDuODcJYdU5p7n_A2RZvqKaqII58z_n9PFTaQSQKuiOmGFeUMpFMuxuFwCmNAVrSgpYNx74U_lCwIWeKCtM_VNdRA3q2hundjzeR6lIhRVticxdhQ27maWhl7U7UJaxLMyWyuXxLdy00UkQz6lnzKEVzpBq_vhNr8BSifouNdZJBm8fLzTB5FDCr650uLxNd-T_ftmJ2ZDi_l1wYecKEry2_9kCeJRv-odOGX2urqc9s5kfcrDHYRWu_TxNkfu7kQufBcHRvTZMasiN8_YJl77Z6QLoubxEbOAsrKgGD0hv0I0rPzsvvU67dtD20fhXwDPr4Gnxf0gm5ETegl07N8m1VW94pqCxRbVY1SjY3O78fkRKPkp6StzQgCPpWs4iARGFXU1VBOX03f5fM8UzYLAdUx4ldoPnJpttwiYPDJPiTfs76tC1zhBo8iCe4zqsj2_rIicRIhFaS1_OR4_ykn0OqIl6ty_mUTfJs-HfLvvR4YmM3mEnnp2TRmN9P_YbwFDjHBxaKi_OqbWjB42PxBCEulliNxcNMHw1MSLBSrskehLaShL60awDA_cJb2mZIAoOsQXiCXmR2CJFHWvbmvO2mYFz8WIp7OtnuB5obacvTIhpC-rZ_vJbqc9szTVXxV-l77XsBaEVB83G9sThqFCLJtZzhMIeQQOVjgKA7ozh58_K7kHrk2_-Rjn307ask1NUFZkxiAXLFxzBf2L-rLbBjjhfbdvfCm2cNtUlEqnGwteQ6H4HT8WV9PLxyVm8eR7Zv8ukJkTqVcUGTbWBvmgGtsinsOXs-T69Q0gNJ7HpOyXG7uKlCb9vjrntZF9tdjbKAjF8o9PnY5e-xdZf-X4LbPIFMx_ySHDeD7v1EiCl57XqmfFmCAJIWGOkQNrVkaHcgGrc_aZgajVFq3Vyd3rixB9-IvJ-DBfjeMu1JxEpHxbNcCTguOBJm4RK1sPub4JxEzMlRwpbGEFk72iNKidu5uc2ybr8XKRI6MH9e4r8zSXTg822zby_XH2v0njI0NPuE2ygiY6vodtFf_NDZ49azIUnWFeFF1ApK00O0oW_X7pw2Fc5x4c0klBXySLfBzH1cJsv156YnbKjPIO4J-PnWVTkbogCAEUJ2lKUzFA1Yq6e_KPgdjI95wlFZKTAJ8xw7hk44cT_PK8OFHKt5y1uXrqh9aFu1KWQcDdn0WNaJ9y_4H9wAtk9GN7HJJvYyZtQDkIdk23EcQy3fLQxDIEfGeg-j1pWObTEmqd9Y78noDWjtVpgILsnZa67_y3MvASfDCRDgTiEYELDxiOhkx_FHMS1QNHL8d3_EqIaKWcz6XV1UQkmdxiSprgXX15zTgmTGITQJ85IWKwHytLc4ZDiwYptUkgxt5OXAy5JTfteZL3_RSqo3mcBg_wMo-UOD1XmGOgczu1N91LJo9XjE00Lt0a5kf3yu547wdtrUnpm6NMue4WxFu4tKCVKzdqVYyg5o-Fe4OArT3ziETkx6gA11g5CWljsawsgdL2u8Ouem_1SE781Bo_bSb2qCSUb5e7-cnoxdhJfKFwhwzeBAsTCXoIkgyUdsxecikvMHiLPTyWfSuqEzkpozB_Xu6uMxUHD3jG9DBMgQ=="}, {"type": "function_call", "name": "QuoteDecision", "arguments": "{\"action\":\"ask\",\"reason\":\"The quantity and addressing scope are now consistent: 500 household invitations, each with identical text, plus 500 envelopes addressed from the supplied spreadsheet. However, it is unclear whether the printer should assemble the pieces by inserting each invitation into its corresponding addressed envelope (and, if so, seal them), or deliver the invitations and addressed envelopes separately.\",\"text\":\"Should the printer insert each invitation into its matching addressed envelope and seal/assemble the 500 pieces, or should the invitations and addressed envelopes be delivered separately for your office to assemble?\"}", "call_id": "call_DQ45b1X9ULyLlOEg0TYixrZh", "id": "fc_0a7e38912863ce39006ab487f8560487d288cfa0b10851cfa1", "index": 1}] {"name": "QuoteDecision", "args": {"action": "ask", "reason": "The quantity and addressing scope are now consistent: 500 household invitations, each with identical text, plus 500 envelopes addressed from the supplied spreadsheet. However, it is unclear whether the printer should assemble the pieces by inserting each invitation into its corresponding addressed envelope (and, if so, seal them), or deliver the invitations and addressed envelopes separately.", "text": "Should the printer insert each invitation into its matching addressed envelope and seal/assemble the 500 pieces, or should the invitations and addressed envelopes be delivered separately for your office to assemble?"}, "id": "call_DQ45b1X9ULyLlOEg0TYixrZh", "type": "tool_call"}
A27: R2 | B27: 1 | C27: Cache write
A28: R2 | B28: 1 | C28: Context · added / total
A29: R2 | B29: 1 | C29: Call total | E29: =IF(COUNT('Turns'!E19,'Turns'!E20,'Turns'!E24,'Turns'!E25)=4,SUM('Turns'!E19,'Turns'!E20,'Turns'!E24,'Turns'!E25),"Unknown") -> 0.00043309217 | F29: =IF(COUNT('Turns'!F19,'Turns'!F20,'Turns'!F24,'Turns'!F25)=4,SUM('Turns'!F19,'Turns'!F20,'Turns'!F24,'Turns'!F25),"Unknown") -> 0.0004942 | G29: =IF(ISNUMBER(E29),ROUND(E29*'Reference data'!$B$2,0),"Unknown") -> 43 | H29: =IF(ISNUMBER(F29),ROUND(F29*'Reference data'!$B$2,0),"Unknown") -> 49 | K29: ok
A30: R3 | B30: 1 | C30: LLM request | D30: 662 | J30: gpt-5.6-luna | M30: 01a0d133-a99c-7e60-8aea-8333e658ca6a
A31: R3 | B31: 1 | C31: Conversation history · cache read | D31: 0 | E31: =IF(AND(ISNUMBER(F31),ISNUMBER('Reference data'!$B$3)),F31*'Reference data'!$B$3,"Unknown") -> 0 | F31: =IF(D31=0,0,IF(ISNUMBER('Reference data'!C17),D31*'Reference data'!C17/1000000,"Unknown")) -> 0 | G31: =IF(ISNUMBER(E31),ROUND(E31*'Reference data'!$B$2,0),"Unknown") -> 0 | H31: =IF(ISNUMBER(F31),ROUND(F31*'Reference data'!$B$2,0),"Unknown") -> 0
A32: R3 | B32: 1 | C32: Input at standard rate | D32: 662 | E32: =IF(AND(ISNUMBER(F32),ISNUMBER('Reference data'!$B$3)),F32*'Reference data'!$B$3,"Unknown") -> 0.00011602874 | F32: =IF(D32=0,0,IF(ISNUMBER('Reference data'!B17),D32*'Reference data'!B17/1000000,"Unknown")) -> 0.0001324 | G32: =IF(ISNUMBER(E32),ROUND(E32*'Reference data'!$B$2,0),"Unknown") -> 12 | H32: =IF(ISNUMBER(F32),ROUND(F32*'Reference data'!$B$2,0),"Unknown") -> 13
A33: R3 | B33: 1 | C33: Cache write
A34: R3 | B34: 1 | C34: Context · added / total
A35: R3 | B35: 1 | C35: LLM response | D35: 227
A36: R3 | B36: 1 | C36: Reasoning | D36: 100 | E36: =IF(AND(ISNUMBER(F36),ISNUMBER('Reference data'!$B$3)),F36*'Reference data'!$B$3,"Unknown") -> 0.000105162 | F36: =IF(D36=0,0,IF(ISNUMBER('Reference data'!F17),D36*'Reference data'!F17/1000000,"Unknown")) -> 0.00012 | G36: =IF(ISNUMBER(E36),ROUND(E36*'Reference data'!$B$2,0),"Unknown") -> 11 | H36: =IF(ISNUMBER(F36),ROUND(F36*'Reference data'!$B$2,0),"Unknown") -> 12
A37: R3 | B37: 1 | C37: Output | D37: 127 | E37: =IF(AND(ISNUMBER(F37),ISNUMBER('Reference data'!$B$3)),F37*'Reference data'!$B$3,"Unknown") -> 0.00013355574 | F37: =IF(D37=0,0,IF(ISNUMBER('Reference data'!E17),D37*'Reference data'!E17/1000000,"Unknown")) -> 0.0001524 | G37: =IF(ISNUMBER(E37),ROUND(E37*'Reference data'!$B$2,0),"Unknown") -> 13 | H37: =IF(ISNUMBER(F37),ROUND(F37*'Reference data'!$B$2,0),"Unknown") -> 15
A38: R3 | B38: 1 | C38: Output content | I38: [{"id": "rs_0a2c09f56a55c5db006ab4881c7a8487d28449fbe438a7f063", "summary": [], "type": "reasoning", "content": [], "index": 0, "encrypted_content": "gAAAAABqtIgeuA24LoKv2SpEH5gg6GH8x-b8bAffq_NCjlyJQxbVJkVy_TEV7v6Ov9NWCsHjCze6jgVrJ4nHeH92ximm_F5NJNFq9S8rdO_XqUYQqrvudrulGF6K7Fcnqk12ep8J5-IiiWDzzUydhWZQUE-o4x_UxZzCBpL_g2NcV90hb1fggPK7DAMIr8b0FYd85S42BXdrQuXoz1mKVmau_FKaP1eQYUFDlbhhD6vC1d3rp5IK8hTM8QrrESwfAjQrWm9viaWnlnj2fXuk2GcKm6zqxziDP5VXuD2cqOjYEcAENbm5E_L9D0YqIEP5MLpe6SzYalHkaAHugtMLp8I4hlwo4rYy7Su8Q_M7nuIAkTE3I-96G7WhoE3lCXztXOSMWEd3SPN2SUSp08g0TWVM4xZrZ9sceiVeolzfSqNHgS8E_WXE-2YjtIoKkmg0JyxMWNWTbHDas9XIejSeHO9ipL7FGcn1k257izjXPotPl4AVb_30EnUbTm72J11EBtPfaQ5QZSGBJGFvG9bPdGlM7btEUjg5ILDL7vRUD5w4CSU7ZPywcl4AYtZ9cyQctQDm4yoL6G53o9631eR-ALXfG9DRgUxn082FbKZ2sVEHJ6B6_oqVtMyVgX0HqkVAq4NOlFaIdMVQZQLpA3Jyq0RqVfrQcZuY9ANw0MVLSbuynIn39UPboCfQfVS2f9NnptcsLRfaEK42zwUt0CgT33dpecYbHQn0OWGIW2ncRpzcW307BURZUCuWsTinTpOFLj4ppX3kzQcpWd7zgGvibG4e_p8vf2RHyJ0Ef1gHtTTpkMPYKX5ZWdI0sPspnstzK3UyRFp-D_b1T3ltIF6pou_Z2Q3fd4wr3eGh7ReTET0OZaPbLBIcWIGcZfcK8d40FxFQVZZ12RL3EawfTntKxpFhi1sNqmsEvssLLmFGPku4Cp3KCBdaGtIAfoFG8SSwmlPm-VZAJ-doc0nXXD6BZBVKluehwgw1nyZkIU0So8dopy-xacVtjYwIm_Vk0HaLbkzG8Ygz13Ta7VTOvbIekfqkXZleb7I88hI5cHkr28qYuEY83qsDSqgLlMJ8EhAHy4FjFYCMqpOEHK2L6Z0M8m1x0Qm91trIi6cViAU21stQT9wOLr6GrSG79H3qRCQDS_1OwQLoyHC1PNeZJwdcPTvYu7sDQX2fWyjBAgdXO6H5xldO2wuGPxfnDyCZvwiNmLxz3obNqyu3X5pxzbeHlFfiz9YwukzhiwMY5pY5X4eu1KwIumpY5bQt_C0bTnY9vEnHVNVOHVMjK04YDdRS1U8Shuwwh3aMF1y96qwnGz95OBNQH6LzHgJOnfrD2Hc-6pPUEr0GD6h0JImkT8H_3sQ94udDf1MKkBDeDoVXy8ffnSHQGTx9UtLQnp_rTF0H7k9Oil-ClH2fUc4Mg4D58jH-RncClGukYE_xqnJpIDiPEl5CugAslg5Pzv_mPT6Hefse5PrVkGpUqmwcMunXBAlNATUK-yOLCYUJ6qP36e6VgKrIQDxk3ZxIHjP4e5BNCrD_Y-aN49eT7YzHyJX-A58q3IoitR9OqSwz213UcD28DjpBQmwUyM18y35PhcRpPiiKFjyB_zyh3ungUXFLeD04_jCL0vMy_fl1RA1Bf6aa-KuhujulcjKvxAgPMoQ97Ktw-Mzj_u7YD94yqN0bw4aq7s1uHFkz9-lc5Niz6puWvB2Q3fbw30lZQrMx_o9zKtj9bEOb5zKab1YMCM3MtoIM_CoEU8tnQO5x2NE_UMVDGeuFgBS02KsLUs_Vv7Jef3UWUEgK_4_GjMffuNokwM9SDXpPZ-Fc6pu2Fg0Fh3Xb_g3CbHLIZuFNOPb5giQdUPnHMm5Di3lUASuUBOAIxoPVeorGPmbQEWH8V0uWJIQB4_NBIzTUpJZ-KqclCUKA5jPeN_I9r6xp"}, {"type": "function_call", "name": "QuoteDecision", "arguments": "{\"action\":\"ask\",\"reason\":\"The quantity and addressing method are clear: 500 identical invitations, one per household, with 500 addressed envelopes for 650 guests. However, it is still unclear whether the printer should insert each invitation into its matching envelope (and possibly seal them) or deliver the invitations and addressed envelopes separately for your office to assemble before mailing.\",\"text\":\"Should the printer deliver 500 invitations and 500 addressed envelopes separately, or insert each invitation into its matching envelope (and seal them) before sending the batch to your office?\"}", "call_id": "call_5bIEcg65zxEWxporkThfN2EP", "id": "fc_0a2c09f56a55c5db006ab4881e329487d2a40a9c9d6e7d471d", "index": 1}] {"name": "QuoteDecision", "args": {"action": "ask", "reason": "The quantity and addressing method are clear: 500 identical invitations, one per household, with 500 addressed envelopes for 650 guests. However, it is still unclear whether the printer should insert each invitation into its matching envelope (and possibly seal them) or deliver the invitations and addressed envelopes separately for your office to assemble before mailing.", "text": "Should the printer deliver 500 invitations and 500 addressed envelopes separately, or insert each invitation into its matching envelope (and seal them) before sending the batch to your office?"}, "id": "call_5bIEcg65zxEWxporkThfN2EP", "type": "tool_call"}
A39: R3 | B39: 1 | C39: Cache write
A40: R3 | B40: 1 | C40: Context · added / total
...

Sheet Execution tree
A1: Operation | B1: Depth | C1: Type | D1: Model · effort | E1: Status | F1: Input context tokens | G1: Description | H1: Span ID | I1: Parent ID | J1: Input at standard rate tokens | K1: Input at standard rate EUR | L1: Input at standard rate USD | M1: Cache read tokens | N1: Cache read EUR | O1: Cache read USD | P1: Cache write tokens | Q1: Cache write EUR | R1: Cache write USD | S1: Output (non-reasoning) tokens | T1: Output (non-reasoning) EUR | U1: Output (non-reasoning) USD | V1: Reasoning tokens | W1: Reasoning EUR | X1: Reasoning USD | Y1: Total EUR | Z1: Total USD | AA1: Projected EUR | AB1: Projected USD | AC1: Request | AD1: Elapsed ms | AE1: Accounting
A2: LangGraph | B2: 0 | C2: workflow | E2: ok | G2: Execute the LangGraph workflow operation and pass its result to the next graph step. | H2: 01a0d132-b474-79e2-bebb-1d3cde2984ea | J2: =IF(COUNT('Turns'!D5)=1,SUM('Turns'!D5),"Unknown") -> 493 | K2: =IF(COUNT('Turns'!E5)=1,SUM('Turns'!E5),"Unknown") -> 8.640811e-05 | L2: =IF(COUNT('Turns'!F5)=1,SUM('Turns'!F5),"Unknown") -> 9.86e-05 | M2: 0 | N2: 0 | O2: 0 | P2: 0 | Q2: 0 | R2: 0 | S2: =IF(COUNT('Turns'!D13)=1,SUM('Turns'!D13),"Unknown") -> 116 | T2: =IF(COUNT('Turns'!E13)=1,SUM('Turns'!E13),"Unknown") -> 0.00012198792 | U2: =IF(COUNT('Turns'!F13)=1,SUM('Turns'!F13),"Unknown") -> 0.0001392 | V2: =IF(COUNT('Turns'!D12)=1,SUM('Turns'!D12),"Unknown") -> 61 | W2: =IF(COUNT('Turns'!E12)=1,SUM('Turns'!E12),"Unknown") -> 6.414882e-05 | X2: =IF(COUNT('Turns'!F12)=1,SUM('Turns'!F12),"Unknown") -> 7.32e-05 | Y2: =IF(COUNT('Turns'!E17)=1,SUM('Turns'!E17),"Unknown") -> 0.00027254485 | Z2: =IF(COUNT('Turns'!F17)=1,SUM('Turns'!F17),"Unknown") -> 0.000311 | AA2: =IF(ISNUMBER(Y2),ROUND(Y2*'Reference data'!$B$2,0),"Unknown") -> 27 | AB2: =IF(ISNUMBER(Z2),ROUND(Z2*'Reference data'!$B$2,0),"Unknown") -> 31 | AD2: 3847.202 | AE2: Subtree total
A3: begin | B3: 1 | C3: workflow | E3: ok | G3: Execute the begin workflow operation and pass its result to the next graph step. | H3: 01a0d132-b476-7663-a711-a6b17af32faf | I3: 01a0d132-b474-79e2-bebb-1d3cde2984ea | AD3: 0.405 | AE3: No model charge
A4: assess | B4: 1 | C4: workflow | E4: ok | G4: Execute the assess workflow operation and pass its result to the next graph step. | H4: 01a0d132-b478-7dc2-ba3f-c8229bf4d00f | I4: 01a0d132-b474-79e2-bebb-1d3cde2984ea | J4: =IF(COUNT('Turns'!D5)=1,SUM('Turns'!D5),"Unknown") -> 493 | K4: =IF(COUNT('Turns'!E5)=1,SUM('Turns'!E5),"Unknown") -> 8.640811e-05 | L4: =IF(COUNT('Turns'!F5)=1,SUM('Turns'!F5),"Unknown") -> 9.86e-05 | M4: 0 | N4: 0 | O4: 0 | P4: 0 | Q4: 0 | R4: 0 | S4: =IF(COUNT('Turns'!D13)=1,SUM('Turns'!D13),"Unknown") -> 116 | T4: =IF(COUNT('Turns'!E13)=1,SUM('Turns'!E13),"Unknown") -> 0.00012198792 | U4: =IF(COUNT('Turns'!F13)=1,SUM('Turns'!F13),"Unknown") -> 0.0001392 | V4: =IF(COUNT('Turns'!D12)=1,SUM('Turns'!D12),"Unknown") -> 61 | W4: =IF(COUNT('Turns'!E12)=1,SUM('Turns'!E12),"Unknown") -> 6.414882e-05 | X4: =IF(COUNT('Turns'!F12)=1,SUM('Turns'!F12),"Unknown") -> 7.32e-05 | Y4: =IF(COUNT('Turns'!E17)=1,SUM('Turns'!E17),"Unknown") -> 0.00027254485 | Z4: =IF(COUNT('Turns'!F17)=1,SUM('Turns'!F17),"Unknown") -> 0.000311 | AA4: =IF(ISNUMBER(Y4),ROUND(Y4*'Reference data'!$B$2,0),"Unknown") -> 27 | AB4: =IF(ISNUMBER(Z4),ROUND(Z4*'Reference data'!$B$2,0),"Unknown") -> 31 | AD4: 3843.273 | AE4: Subtree total
A5: quote_interpreter | B5: 2 | C5: workflow | E5: ok | G5: Interpret quote scope and request human clarification when needed. | H5: 01a0d132-b478-7dc2-ba3f-c83965587b76 | I5: 01a0d132-b478-7dc2-ba3f-c8229bf4d00f | J5: =IF(COUNT('Turns'!D5)=1,SUM('Turns'!D5),"Unknown") -> 493 | K5: =IF(COUNT('Turns'!E5)=1,SUM('Turns'!E5),"Unknown") -> 8.640811e-05 | L5: =IF(COUNT('Turns'!F5)=1,SUM('Turns'!F5),"Unknown") -> 9.86e-05 | M5: 0 | N5: 0 | O5: 0 | P5: 0 | Q5: 0 | R5: 0 | S5: =IF(COUNT('Turns'!D13)=1,SUM('Turns'!D13),"Unknown") -> 116 | T5: =IF(COUNT('Turns'!E13)=1,SUM('Turns'!E13),"Unknown") -> 0.00012198792 | U5: =IF(COUNT('Turns'!F13)=1,SUM('Turns'!F13),"Unknown") -> 0.0001392 | V5: =IF(COUNT('Turns'!D12)=1,SUM('Turns'!D12),"Unknown") -> 61 | W5: =IF(COUNT('Turns'!E12)=1,SUM('Turns'!E12),"Unknown") -> 6.414882e-05 | X5: =IF(COUNT('Turns'!F12)=1,SUM('Turns'!F12),"Unknown") -> 7.32e-05 | Y5: =IF(COUNT('Turns'!E17)=1,SUM('Turns'!E17),"Unknown") -> 0.00027254485 | Z5: =IF(COUNT('Turns'!F17)=1,SUM('Turns'!F17),"Unknown") -> 0.000311 | AA5: =IF(ISNUMBER(Y5),ROUND(Y5*'Reference data'!$B$2,0),"Unknown") -> 27 | AB5: =IF(ISNUMBER(Z5),ROUND(Z5*'Reference data'!$B$2,0),"Unknown") -> 31 | AD5: 3841.727 | AE5: Subtree total
A6: quote_interpreter | B6: 3 | C6: workflow | E6: ok | G6: Interpret quote scope and request human clarification when needed. | H6: 01a0d132-b479-7172-a853-94c430ea0c22 | I6: 01a0d132-b478-7dc2-ba3f-c83965587b76 | J6: =IF(COUNT('Turns'!D5)=1,SUM('Turns'!D5),"Unknown") -> 493 | K6: =IF(COUNT('Turns'!E5)=1,SUM('Turns'!E5),"Unknown") -> 8.640811e-05 | L6: =IF(COUNT('Turns'!F5)=1,SUM('Turns'!F5),"Unknown") -> 9.86e-05 | M6: 0 | N6: 0 | O6: 0 | P6: 0 | Q6: 0 | R6: 0 | S6: =IF(COUNT('Turns'!D13)=1,SUM('Turns'!D13),"Unknown") -> 116 | T6: =IF(COUNT('Turns'!E13)=1,SUM('Turns'!E13),"Unknown") -> 0.00012198792 | U6: =IF(COUNT('Turns'!F13)=1,SUM('Turns'!F13),"Unknown") -> 0.0001392 | V6: =IF(COUNT('Turns'!D12)=1,SUM('Turns'!D12),"Unknown") -> 61 | W6: =IF(COUNT('Turns'!E12)=1,SUM('Turns'!E12),"Unknown") -> 6.414882e-05 | X6: =IF(COUNT('Turns'!F12)=1,SUM('Turns'!F12),"Unknown") -> 7.32e-05 | Y6: =IF(COUNT('Turns'!E17)=1,SUM('Turns'!E17),"Unknown") -> 0.00027254485 | Z6: =IF(COUNT('Turns'!F17)=1,SUM('Turns'!F17),"Unknown") -> 0.000311 | AA6: =IF(ISNUMBER(Y6),ROUND(Y6*'Reference data'!$B$2,0),"Unknown") -> 27 | AB6: =IF(ISNUMBER(Z6),ROUND(Z6*'Reference data'!$B$2,0),"Unknown") -> 31 | AD6: 3840.677 | AE6: Subtree total
A7: model | B7: 4 | C7: workflow | E7: ok | G7: Interpret quote scope and request human clarification when needed. | H7: 01a0d132-b479-7172-a853-94d1a50047c4 | I7: 01a0d132-b479-7172-a853-94c430ea0c22 | J7: =IF(COUNT('Turns'!D5)=1,SUM('Turns'!D5),"Unknown") -> 493 | K7: =IF(COUNT('Turns'!E5)=1,SUM('Turns'!E5),"Unknown") -> 8.640811e-05 | L7: =IF(COUNT('Turns'!F5)=1,SUM('Turns'!F5),"Unknown") -> 9.86e-05 | M7: 0 | N7: 0 | O7: 0 | P7: 0 | Q7: 0 | R7: 0 | S7: =IF(COUNT('Turns'!D13)=1,SUM('Turns'!D13),"Unknown") -> 116 | T7: =IF(COUNT('Turns'!E13)=1,SUM('Turns'!E13),"Unknown") -> 0.00012198792 | U7: =IF(COUNT('Turns'!F13)=1,SUM('Turns'!F13),"Unknown") -> 0.0001392 | V7: =IF(COUNT('Turns'!D12)=1,SUM('Turns'!D12),"Unknown") -> 61 | W7: =IF(COUNT('Turns'!E12)=1,SUM('Turns'!E12),"Unknown") -> 6.414882e-05 | X7: =IF(COUNT('Turns'!F12)=1,SUM('Turns'!F12),"Unknown") -> 7.32e-05 | Y7: =IF(COUNT('Turns'!E17)=1,SUM('Turns'!E17),"Unknown") -> 0.00027254485 | Z7: =IF(COUNT('Turns'!F17)=1,SUM('Turns'!F17),"Unknown") -> 0.000311 | AA7: =IF(ISNUMBER(Y7),ROUND(Y7*'Reference data'!$B$2,0),"Unknown") -> 27 | AB7: =IF(ISNUMBER(Z7),ROUND(Z7*'Reference data'!$B$2,0),"Unknown") -> 31 | AD7: 3838.793 | AE7: Subtree total
A8: ChatOpenAI | B8: 5 | C8: model | D8: gpt-5.6-luna | E8: ok | F8: 493 | G8: Interpret quote scope and request human clarification when needed. | H8: 01a0d132-b47a-7da0-b744-558a9097def7 | I8: 01a0d132-b479-7172-a853-94d1a50047c4 | J8: =IF(COUNT('Turns'!D5)=1,SUM('Turns'!D5),"Unknown") -> 493 | K8: =IF(COUNT('Turns'!E5)=1,SUM('Turns'!E5),"Unknown") -> 8.640811e-05 | L8: =IF(COUNT('Turns'!F5)=1,SUM('Turns'!F5),"Unknown") -> 9.86e-05 | M8: 0 | N8: 0 | O8: 0 | P8: 0 | Q8: 0 | R8: 0 | S8: =IF(COUNT('Turns'!D13)=1,SUM('Turns'!D13),"Unknown") -> 116 | T8: =IF(COUNT('Turns'!E13)=1,SUM('Turns'!E13),"Unknown") -> 0.00012198792 | U8: =IF(COUNT('Turns'!F13)=1,SUM('Turns'!F13),"Unknown") -> 0.0001392 | V8: =IF(COUNT('Turns'!D12)=1,SUM('Turns'!D12),"Unknown") -> 61 | W8: =IF(COUNT('Turns'!E12)=1,SUM('Turns'!E12),"Unknown") -> 6.414882e-05 | X8: =IF(COUNT('Turns'!F12)=1,SUM('Turns'!F12),"Unknown") -> 7.32e-05 | Y8: =IF(COUNT('Turns'!E17)=1,SUM('Turns'!E17),"Unknown") -> 0.00027254485 | Z8: =IF(COUNT('Turns'!F17)=1,SUM('Turns'!F17),"Unknown") -> 0.000311 | AA8: =IF(ISNUMBER(Y8),ROUND(Y8*'Reference data'!$B$2,0),"Unknown") -> 27 | AB8: =IF(ISNUMBER(Z8),ROUND(Z8*'Reference data'!$B$2,0),"Unknown") -> 31 | AC8: R1 | AD8: 3837.028 | AE8: Own call
A9: route_after_assessment | B9: 2 | C9: workflow | E9: ok | G9: Execute the route_after_assessment workflow operation and pass its result to the next graph step. | H9: 01a0d132-c37a-7e32-983e-5632d71a7d69 | I9: 01a0d132-b478-7dc2-ba3f-c8229bf4d00f | AD9: 0.302 | AE9: No model charge
A10: ask | B10: 1 | C10: workflow | E10: interrupted | G10: Execute the ask workflow operation and pass its result to the next graph step. | H10: 01a0d132-c37b-7222-8913-854965114e1e | I10: 01a0d132-b474-79e2-bebb-1d3cde2984ea | AD10: 0.457 | AE10: No model charge
A11: LangGraph | B11: 0 | C11: workflow | E11: ok | G11: Execute the LangGraph workflow operation and pass its result to the next graph step. | H11: 01a0d133-117e-7412-a0e6-e01193fa09a8 | J11: =IF(COUNT('Turns'!D20)=1,SUM('Turns'!D20),"Unknown") -> 605 | K11: =IF(COUNT('Turns'!E20)=1,SUM('Turns'!E20),"Unknown") -> 0.00010603835 | L11: =IF(COUNT('Turns'!F20)=1,SUM('Turns'!F20),"Unknown") -> 0.000121 | M11: =IF(COUNT('Turns'!D19)=1,SUM('Turns'!D19),"Unknown") -> 0 | N11: =IF(COUNT('Turns'!E19)=1,SUM('Turns'!E19),"Unknown") -> 0 | O11: =IF(COUNT('Turns'!F19)=1,SUM('Turns'!F19),"Unknown") -> 0 | P11: 0 | Q11: 0 | R11: 0 | S11: =IF(COUNT('Turns'!D25)=1,SUM('Turns'!D25),"Unknown") -> 130 | T11: =IF(COUNT('Turns'!E25)=1,SUM('Turns'!E25),"Unknown") -> 0.0001367106 | U11: =IF(COUNT('Turns'!F25)=1,SUM('Turns'!F25),"Unknown") -> 0.000156 | V11: =IF(COUNT('Turns'!D24)=1,SUM('Turns'!D24),"Unknown") -> 181 | W11: =IF(COUNT('Turns'!E24)=1,SUM('Turns'!E24),"Unknown") -> 0.00019034322 | X11: =IF(COUNT('Turns'!F24)=1,SUM('Turns'!F24),"Unknown") -> 0.0002172 | Y11: =IF(COUNT('Turns'!E29)=1,SUM('Turns'!E29),"Unknown") -> 0.00043309217 | Z11: =IF(COUNT('Turns'!F29)=1,SUM('Turns'!F29),"Unknown") -> 0.0004942 | AA11: =IF(ISNUMBER(Y11),ROUND(Y11*'Reference data'!$B$2,0),"Unknown") -> 43 | AB11: =IF(ISNUMBER(Z11),ROUND(Z11*'Reference data'!$B$2,0),"Unknown") -> 49 | AD11: 6080.118 | AE11: Subtree total
A12: ask | B12: 1 | C12: workflow | E12: ok | G12: Execute the ask workflow operation and pass its result to the next graph step. | H12: 01a0d133-117f-7d83-aa06-63185f83ad93 | I12: 01a0d133-117e-7412-a0e6-e01193fa09a8 | AD12: 3.092 | AE12: No model charge
A13: route_after_answer | B13: 2 | C13: workflow | E13: ok | G13: Execute the route_after_answer workflow operation and pass its result to the next graph step. | H13: 01a0d133-1180-7270-866d-0c9dd907bde1 | I13: 01a0d133-117f-7d83-aa06-63185f83ad93 | AD13: 1.142 | AE13: No model charge
A14: assess | B14: 1 | C14: workflow | E14: ok | G14: Execute the assess workflow operation and pass its result to the next graph step. | H14: 01a0d133-1184-7871-b971-e47d33011813 | I14: 01a0d133-117e-7412-a0e6-e01193fa09a8 | J14: =IF(COUNT('Turns'!D20)=1,SUM('Turns'!D20),"Unknown") -> 605 | K14: =IF(COUNT('Turns'!E20)=1,SUM('Turns'!E20),"Unknown") -> 0.00010603835 | L14: =IF(COUNT('Turns'!F20)=1,SUM('Turns'!F20),"Unknown") -> 0.000121 | M14: =IF(COUNT('Turns'!D19)=1,SUM('Turns'!D19),"Unknown") -> 0 | N14: =IF(COUNT('Turns'!E19)=1,SUM('Turns'!E19),"Unknown") -> 0 | O14: =IF(COUNT('Turns'!F19)=1,SUM('Turns'!F19),"Unknown") -> 0 | P14: 0 | Q14: 0 | R14: 0 | S14: =IF(COUNT('Turns'!D25)=1,SUM('Turns'!D25),"Unknown") -> 130 | T14: =IF(COUNT('Turns'!E25)=1,SUM('Turns'!E25),"Unknown") -> 0.0001367106 | U14: =IF(COUNT('Turns'!F25)=1,SUM('Turns'!F25),"Unknown") -> 0.000156 | V14: =IF(COUNT('Turns'!D24)=1,SUM('Turns'!D24),"Unknown") -> 181 | W14: =IF(COUNT('Turns'!E24)=1,SUM('Turns'!E24),"Unknown") -> 0.00019034322 | X14: =IF(COUNT('Turns'!F24)=1,SUM('Turns'!F24),"Unknown") -> 0.0002172 | Y14: =IF(COUNT('Turns'!E29)=1,SUM('Turns'!E29),"Unknown") -> 0.00043309217 | Z14: =IF(COUNT('Turns'!F29)=1,SUM('Turns'!F29),"Unknown") -> 0.0004942 | AA14: =IF(ISNUMBER(Y14),ROUND(Y14*'Reference data'!$B$2,0),"Unknown") -> 43 | AB14: =IF(ISNUMBER(Z14),ROUND(Z14*'Reference data'!$B$2,0),"Unknown") -> 49 | AD14: 6072.375 | AE14: Subtree total
A15: quote_interpreter | B15: 2 | C15: workflow | E15: ok | G15: Interpret quote scope and request human clarification when needed. | H15: 01a0d133-1185-7b63-bb1f-e8eefc719b54 | I15: 01a0d133-1184-7871-b971-e47d33011813 | J15: =IF(COUNT('Turns'!D20)=1,SUM('Turns'!D20),"Unknown") -> 605 | K15: =IF(COUNT('Turns'!E20)=1,SUM('Turns'!E20),"Unknown") -> 0.00010603835 | L15: =IF(COUNT('Turns'!F20)=1,SUM('Turns'!F20),"Unknown") -> 0.000121 | M15: =IF(COUNT('Turns'!D19)=1,SUM('Turns'!D19),"Unknown") -> 0 | N15: =IF(COUNT('Turns'!E19)=1,SUM('Turns'!E19),"Unknown") -> 0 | O15: =IF(COUNT('Turns'!F19)=1,SUM('Turns'!F19),"Unknown") -> 0 | P15: 0 | Q15: 0 | R15: 0 | S15: =IF(COUNT('Turns'!D25)=1,SUM('Turns'!D25),"Unknown") -> 130 | T15: =IF(COUNT('Turns'!E25)=1,SUM('Turns'!E25),"Unknown") -> 0.0001367106 | U15: =IF(COUNT('Turns'!F25)=1,SUM('Turns'!F25),"Unknown") -> 0.000156 | V15: =IF(COUNT('Turns'!D24)=1,SUM('Turns'!D24),"Unknown") -> 181 | W15: =IF(COUNT('Turns'!E24)=1,SUM('Turns'!E24),"Unknown") -> 0.00019034322 | X15: =IF(COUNT('Turns'!F24)=1,SUM('Turns'!F24),"Unknown") -> 0.0002172 | Y15: =IF(COUNT('Turns'!E29)=1,SUM('Turns'!E29),"Unknown") -> 0.00043309217 | Z15: =IF(COUNT('Turns'!F29)=1,SUM('Turns'!F29),"Unknown") -> 0.0004942 | AA15: =IF(ISNUMBER(Y15),ROUND(Y15*'Reference data'!$B$2,0),"Unknown") -> 43 | AB15: =IF(ISNUMBER(Z15),ROUND(Z15*'Reference data'!$B$2,0),"Unknown") -> 49 | AD15: 6070.035 | AE15: Subtree total
A16: quote_interpreter | B16: 3 | C16: workflow | E16: ok | G16: Interpret quote scope and request human clarification when needed. | H16: 01a0d133-1186-7842-b2fa-bed9045fbb69 | I16: 01a0d133-1185-7b63-bb1f-e8eefc719b54 | J16: =IF(COUNT('Turns'!D20)=1,SUM('Turns'!D20),"Unknown") -> 605 | K16: =IF(COUNT('Turns'!E20)=1,SUM('Turns'!E20),"Unknown") -> 0.00010603835 | L16: =IF(COUNT('Turns'!F20)=1,SUM('Turns'!F20),"Unknown") -> 0.000121 | M16: =IF(COUNT('Turns'!D19)=1,SUM('Turns'!D19),"Unknown") -> 0 | N16: =IF(COUNT('Turns'!E19)=1,SUM('Turns'!E19),"Unknown") -> 0 | O16: =IF(COUNT('Turns'!F19)=1,SUM('Turns'!F19),"Unknown") -> 0 | P16: 0 | Q16: 0 | R16: 0 | S16: =IF(COUNT('Turns'!D25)=1,SUM('Turns'!D25),"Unknown") -> 130 | T16: =IF(COUNT('Turns'!E25)=1,SUM('Turns'!E25),"Unknown") -> 0.0001367106 | U16: =IF(COUNT('Turns'!F25)=1,SUM('Turns'!F25),"Unknown") -> 0.000156 | V16: =IF(COUNT('Turns'!D24)=1,SUM('Turns'!D24),"Unknown") -> 181 | W16: =IF(COUNT('Turns'!E24)=1,SUM('Turns'!E24),"Unknown") -> 0.00019034322 | X16: =IF(COUNT('Turns'!F24)=1,SUM('Turns'!F24),"Unknown") -> 0.0002172 | Y16: =IF(COUNT('Turns'!E29)=1,SUM('Turns'!E29),"Unknown") -> 0.00043309217 | Z16: =IF(COUNT('Turns'!F29)=1,SUM('Turns'!F29),"Unknown") -> 0.0004942 | AA16: =IF(ISNUMBER(Y16),ROUND(Y16*'Reference data'!$B$2,0),"Unknown") -> 43 | AB16: =IF(ISNUMBER(Z16),ROUND(Z16*'Reference data'!$B$2,0),"Unknown") -> 49 | AD16: 6067.659 | AE16: Subtree total
A17: model | B17: 4 | C17: workflow | E17: ok | G17: Interpret quote scope and request human clarification when needed. | H17: 01a0d133-1189-7511-974a-d5358dde7c37 | I17: 01a0d133-1186-7842-b2fa-bed9045fbb69 | J17: =IF(COUNT('Turns'!D20)=1,SUM('Turns'!D20),"Unknown") -> 605 | K17: =IF(COUNT('Turns'!E20)=1,SUM('Turns'!E20),"Unknown") -> 0.00010603835 | L17: =IF(COUNT('Turns'!F20)=1,SUM('Turns'!F20),"Unknown") -> 0.000121 | M17: =IF(COUNT('Turns'!D19)=1,SUM('Turns'!D19),"Unknown") -> 0 | N17: =IF(COUNT('Turns'!E19)=1,SUM('Turns'!E19),"Unknown") -> 0 | O17: =IF(COUNT('Turns'!F19)=1,SUM('Turns'!F19),"Unknown") -> 0 | P17: 0 | Q17: 0 | R17: 0 | S17: =IF(COUNT('Turns'!D25)=1,SUM('Turns'!D25),"Unknown") -> 130 | T17: =IF(COUNT('Turns'!E25)=1,SUM('Turns'!E25),"Unknown") -> 0.0001367106 | U17: =IF(COUNT('Turns'!F25)=1,SUM('Turns'!F25),"Unknown") -> 0.000156 | V17: =IF(COUNT('Turns'!D24)=1,SUM('Turns'!D24),"Unknown") -> 181 | W17: =IF(COUNT('Turns'!E24)=1,SUM('Turns'!E24),"Unknown") -> 0.00019034322 | X17: =IF(COUNT('Turns'!F24)=1,SUM('Turns'!F24),"Unknown") -> 0.0002172 | Y17: =IF(COUNT('Turns'!E29)=1,SUM('Turns'!E29),"Unknown") -> 0.00043309217 | Z17: =IF(COUNT('Turns'!F29)=1,SUM('Turns'!F29),"Unknown") -> 0.0004942 | AA17: =IF(ISNUMBER(Y17),ROUND(Y17*'Reference data'!$B$2,0),"Unknown") -> 43 | AB17: =IF(ISNUMBER(Z17),ROUND(Z17*'Reference data'!$B$2,0),"Unknown") -> 49 | AD17: 6064.297 | AE17: Subtree total
A18: ChatOpenAI | B18: 5 | C18: model | D18: gpt-5.6-luna | E18: ok | F18: 605 | G18: Interpret quote scope and request human clarification when needed. | H18: 01a0d133-118a-7ce3-a1cf-76986af715ce | I18: 01a0d133-1189-7511-974a-d5358dde7c37 | J18: =IF(COUNT('Turns'!D20)=1,SUM('Turns'!D20),"Unknown") -> 605 | K18: =IF(COUNT('Turns'!E20)=1,SUM('Turns'!E20),"Unknown") -> 0.00010603835 | L18: =IF(COUNT('Turns'!F20)=1,SUM('Turns'!F20),"Unknown") -> 0.000121 | M18: =IF(COUNT('Turns'!D19)=1,SUM('Turns'!D19),"Unknown") -> 0 | N18: =IF(COUNT('Turns'!E19)=1,SUM('Turns'!E19),"Unknown") -> 0 | O18: =IF(COUNT('Turns'!F19)=1,SUM('Turns'!F19),"Unknown") -> 0 | P18: 0 | Q18: 0 | R18: 0 | S18: =IF(COUNT('Turns'!D25)=1,SUM('Turns'!D25),"Unknown") -> 130 | T18: =IF(COUNT('Turns'!E25)=1,SUM('Turns'!E25),"Unknown") -> 0.0001367106 | U18: =IF(COUNT('Turns'!F25)=1,SUM('Turns'!F25),"Unknown") -> 0.000156 | V18: =IF(COUNT('Turns'!D24)=1,SUM('Turns'!D24),"Unknown") -> 181 | W18: =IF(COUNT('Turns'!E24)=1,SUM('Turns'!E24),"Unknown") -> 0.00019034322 | X18: =IF(COUNT('Turns'!F24)=1,SUM('Turns'!F24),"Unknown") -> 0.0002172 | Y18: =IF(COUNT('Turns'!E29)=1,SUM('Turns'!E29),"Unknown") -> 0.00043309217 | Z18: =IF(COUNT('Turns'!F29)=1,SUM('Turns'!F29),"Unknown") -> 0.0004942 | AA18: =IF(ISNUMBER(Y18),ROUND(Y18*'Reference data'!$B$2,0),"Unknown") -> 43 | AB18: =IF(ISNUMBER(Z18),ROUND(Z18*'Reference data'!$B$2,0),"Unknown") -> 49 | AC18: R2 | AD18: 6061.903 | AE18: Own call
A19: route_after_assessment | B19: 2 | C19: workflow | E19: ok | G19: Execute the route_after_assessment workflow operation and pass its result to the next graph step. | H19: 01a0d133-293b-7c40-b4c1-4ab184998a15 | I19: 01a0d133-1184-7871-b971-e47d33011813 | AD19: 0.465 | AE19: No model charge
A20: ask | B20: 1 | C20: workflow | E20: interrupted | G20: Execute the ask workflow operation and pass its result to the next graph step. | H20: 01a0d133-293d-7640-b1f5-6d6a5e4cf7fa | I20: 01a0d133-117e-7412-a0e6-e01193fa09a8 | AD20: 0.538 | AE20: No model charge
A21: LangGraph | B21: 0 | C21: workflow | E21: ok | G21: Execute the LangGraph workflow operation and pass its result to the next graph step. | H21: 01a0d133-a990-7020-bcb1-e6bdf0ea3b0c | J21: =IF(COUNT('Turns'!D32)=1,SUM('Turns'!D32),"Unknown") -> 662 | K21: =IF(COUNT('Turns'!E32)=1,SUM('Turns'!E32),"Unknown") -> 0.00011602874 | L21: =IF(COUNT('Turns'!F32)=1,SUM('Turns'!F32),"Unknown") -> 0.0001324 | M21: =IF(COUNT('Turns'!D31)=1,SUM('Turns'!D31),"Unknown") -> 0 | N21: =IF(COUNT('Turns'!E31)=1,SUM('Turns'!E31),"Unknown") -> 0 | O21: =IF(COUNT('Turns'!F31)=1,SUM('Turns'!F31),"Unknown") -> 0 | P21: 0 | Q21: 0 | R21: 0 | S21: =IF(COUNT('Turns'!D37)=1,SUM('Turns'!D37),"Unknown") -> 127 | T21: =IF(COUNT('Turns'!E37)=1,SUM('Turns'!E37),"Unknown") -> 0.00013355574 | U21: =IF(COUNT('Turns'!F37)=1,SUM('Turns'!F37),"Unknown") -> 0.0001524 | V21: =IF(COUNT('Turns'!D36)=1,SUM('Turns'!D36),"Unknown") -> 100 | W21: =IF(COUNT('Turns'!E36)=1,SUM('Turns'!E36),"Unknown") -> 0.000105162 | X21: =IF(COUNT('Turns'!F36)=1,SUM('Turns'!F36),"Unknown") -> 0.00012 | Y21: =IF(COUNT('Turns'!E41)=1,SUM('Turns'!E41),"Unknown") -> 0.00035474648 | Z21: =IF(COUNT('Turns'!F41)=1,SUM('Turns'!F41),"Unknown") -> 0.0004048 | AA21: =IF(ISNUMBER(Y21),ROUND(Y21*'Reference data'!$B$2,0),"Unknown") -> 35 | AB21: =IF(ISNUMBER(Z21),ROUND(Z21*'Reference data'!$B$2,0),"Unknown") -> 40 | AD21: 4584.89 | AE21: Subtree total
A22: ask | B22: 1 | C22: workflow | E22: ok | G22: Execute the ask workflow operation and pass its result to the next graph step. | H22: 01a0d133-a993-7572-83c9-41bb34523e45 | I22: 01a0d133-a990-7020-bcb1-e6bdf0ea3b0c | AD22: 2.44 | AE22: No model charge
A23: route_after_answer | B23: 2 | C23: workflow | E23: ok | G23: Execute the route_after_answer workflow operation and pass its result to the next graph step. | H23: 01a0d133-a994-7192-af2f-8c42f1fa2726 | I23: 01a0d133-a993-7572-83c9-41bb34523e45 | AD23: 0.59 | AE23: No model charge
A24: assess | B24: 1 | C24: workflow | E24: ok | G24: Execute the assess workflow operation and pass its result to the next graph step. | H24: 01a0d133-a997-7f12-a380-e6d1a5350a86 | I24: 01a0d133-a990-7020-bcb1-e6bdf0ea3b0c | J24: =IF(COUNT('Turns'!D32)=1,SUM('Turns'!D32),"Unknown") -> 662 | K24: =IF(COUNT('Turns'!E32)=1,SUM('Turns'!E32),"Unknown") -> 0.00011602874 | L24: =IF(COUNT('Turns'!F32)=1,SUM('Turns'!F32),"Unknown") -> 0.0001324 | M24: =IF(COUNT('Turns'!D31)=1,SUM('Turns'!D31),"Unknown") -> 0 | N24: =IF(COUNT('Turns'!E31)=1,SUM('Turns'!E31),"Unknown") -> 0 | O24: =IF(COUNT('Turns'!F31)=1,SUM('Turns'!F31),"Unknown") -> 0 | P24: 0 | Q24: 0 | R24: 0 | S24: =IF(COUNT('Turns'!D37)=1,SUM('Turns'!D37),"Unknown") -> 127 | T24: =IF(COUNT('Turns'!E37)=1,SUM('Turns'!E37),"Unknown") -> 0.00013355574 | U24: =IF(COUNT('Turns'!F37)=1,SUM('Turns'!F37),"Unknown") -> 0.0001524 | V24: =IF(COUNT('Turns'!D36)=1,SUM('Turns'!D36),"Unknown") -> 100 | W24: =IF(COUNT('Turns'!E36)=1,SUM('Turns'!E36),"Unknown") -> 0.000105162 | X24: =IF(COUNT('Turns'!F36)=1,SUM('Turns'!F36),"Unknown") -> 0.00012 | Y24: =IF(COUNT('Turns'!E41)=1,SUM('Turns'!E41),"Unknown") -> 0.00035474648 | Z24: =IF(COUNT('Turns'!F41)=1,SUM('Turns'!F41),"Unknown") -> 0.0004048 | AA24: =IF(ISNUMBER(Y24),ROUND(Y24*'Reference data'!$B$2,0),"Unknown") -> 35 | AB24: =IF(ISNUMBER(Z24),ROUND(Z24*'Reference data'!$B$2,0),"Unknown") -> 40 | AD24: 4574.805 | AE24: Subtree total
A25: quote_interpreter | B25: 2 | C25: workflow | E25: ok | G25: Interpret quote scope and request human clarification when needed. | H25: 01a0d133-a998-7eb1-a02c-60bfd6776ae5 | I25: 01a0d133-a997-7f12-a380-e6d1a5350a86 | J25: =IF(COUNT('Turns'!D32)=1,SUM('Turns'!D32),"Unknown") -> 662 | K25: =IF(COUNT('Turns'!E32)=1,SUM('Turns'!E32),"Unknown") -> 0.00011602874 | L25: =IF(COUNT('Turns'!F32)=1,SUM('Turns'!F32),"Unknown") -> 0.0001324 | M25: =IF(COUNT('Turns'!D31)=1,SUM('Turns'!D31),"Unknown") -> 0 | N25: =IF(COUNT('Turns'!E31)=1,SUM('Turns'!E31),"Unknown") -> 0 | O25: =IF(COUNT('Turns'!F31)=1,SUM('Turns'!F31),"Unknown") -> 0 | P25: 0 | Q25: 0 | R25: 0 | S25: =IF(COUNT('Turns'!D37)=1,SUM('Turns'!D37),"Unknown") -> 127 | T25: =IF(COUNT('Turns'!E37)=1,SUM('Turns'!E37),"Unknown") -> 0.00013355574 | U25: =IF(COUNT('Turns'!F37)=1,SUM('Turns'!F37),"Unknown") -> 0.0001524 | V25: =IF(COUNT('Turns'!D36)=1,SUM('Turns'!D36),"Unknown") -> 100 | W25: =IF(COUNT('Turns'!E36)=1,SUM('Turns'!E36),"Unknown") -> 0.000105162 | X25: =IF(COUNT('Turns'!F36)=1,SUM('Turns'!F36),"Unknown") -> 0.00012 | Y25: =IF(COUNT('Turns'!E41)=1,SUM('Turns'!E41),"Unknown") -> 0.00035474648 | Z25: =IF(COUNT('Turns'!F41)=1,SUM('Turns'!F41),"Unknown") -> 0.0004048 | AA25: =IF(ISNUMBER(Y25),ROUND(Y25*'Reference data'!$B$2,0),"Unknown") -> 35 | AB25: =IF(ISNUMBER(Z25),ROUND(Z25*'Reference data'!$B$2,0),"Unknown") -> 40 | AD25: 4571.756 | AE25: Subtree total
A26: quote_interpreter | B26: 3 | C26: workflow | E26: ok | G26: Interpret quote scope and request human clarification when needed. | H26: 01a0d133-a99a-75a1-ae01-3125ed1cdf9f | I26: 01a0d133-a998-7eb1-a02c-60bfd6776ae5 | J26: =IF(COUNT('Turns'!D32)=1,SUM('Turns'!D32),"Unknown") -> 662 | K26: =IF(COUNT('Turns'!E32)=1,SUM('Turns'!E32),"Unknown") -> 0.00011602874 | L26: =IF(COUNT('Turns'!F32)=1,SUM('Turns'!F32),"Unknown") -> 0.0001324 | M26: =IF(COUNT('Turns'!D31)=1,SUM('Turns'!D31),"Unknown") -> 0 | N26: =IF(COUNT('Turns'!E31)=1,SUM('Turns'!E31),"Unknown") -> 0 | O26: =IF(COUNT('Turns'!F31)=1,SUM('Turns'!F31),"Unknown") -> 0 | P26: 0 | Q26: 0 | R26: 0 | S26: =IF(COUNT('Turns'!D37)=1,SUM('Turns'!D37),"Unknown") -> 127 | T26: =IF(COUNT('Turns'!E37)=1,SUM('Turns'!E37),"Unknown") -> 0.00013355574 | U26: =IF(COUNT('Turns'!F37)=1,SUM('Turns'!F37),"Unknown") -> 0.0001524 | V26: =IF(COUNT('Turns'!D36)=1,SUM('Turns'!D36),"Unknown") -> 100 | W26: =IF(COUNT('Turns'!E36)=1,SUM('Turns'!E36),"Unknown") -> 0.000105162 | X26: =IF(COUNT('Turns'!F36)=1,SUM('Turns'!F36),"Unknown") -> 0.00012 | Y26: =IF(COUNT('Turns'!E41)=1,SUM('Turns'!E41),"Unknown") -> 0.00035474648 | Z26: =IF(COUNT('Turns'!F41)=1,SUM('Turns'!F41),"Unknown") -> 0.0004048 | AA26: =IF(ISNUMBER(Y26),ROUND(Y26*'Reference data'!$B$2,0),"Unknown") -> 35 | AB26: =IF(ISNUMBER(Z26),ROUND(Z26*'Reference data'!$B$2,0),"Unknown") -> 40 | AD26: 4569.265 | AE26: Subtree total
A27: model | B27: 4 | C27: workflow | E27: ok | G27: Interpret quote scope and request human clarification when needed. | H27: 01a0d133-a99b-7f83-a110-9f23643bd343 | I27: 01a0d133-a99a-75a1-ae01-3125ed1cdf9f | J27: =IF(COUNT('Turns'!D32)=1,SUM('Turns'!D32),"Unknown") -> 662 | K27: =IF(COUNT('Turns'!E32)=1,SUM('Turns'!E32),"Unknown") -> 0.00011602874 | L27: =IF(COUNT('Turns'!F32)=1,SUM('Turns'!F32),"Unknown") -> 0.0001324 | M27: =IF(COUNT('Turns'!D31)=1,SUM('Turns'!D31),"Unknown") -> 0 | N27: =IF(COUNT('Turns'!E31)=1,SUM('Turns'!E31),"Unknown") -> 0 | O27: =IF(COUNT('Turns'!F31)=1,SUM('Turns'!F31),"Unknown") -> 0 | P27: 0 | Q27: 0 | R27: 0 | S27: =IF(COUNT('Turns'!D37)=1,SUM('Turns'!D37),"Unknown") -> 127 | T27: =IF(COUNT('Turns'!E37)=1,SUM('Turns'!E37),"Unknown") -> 0.00013355574 | U27: =IF(COUNT('Turns'!F37)=1,SUM('Turns'!F37),"Unknown") -> 0.0001524 | V27: =IF(COUNT('Turns'!D36)=1,SUM('Turns'!D36),"Unknown") -> 100 | W27: =IF(COUNT('Turns'!E36)=1,SUM('Turns'!E36),"Unknown") -> 0.000105162 | X27: =IF(COUNT('Turns'!F36)=1,SUM('Turns'!F36),"Unknown") -> 0.00012 | Y27: =IF(COUNT('Turns'!E41)=1,SUM('Turns'!E41),"Unknown") -> 0.00035474648 | Z27: =IF(COUNT('Turns'!F41)=1,SUM('Turns'!F41),"Unknown") -> 0.0004048 | AA27: =IF(ISNUMBER(Y27),ROUND(Y27*'Reference data'!$B$2,0),"Unknown") -> 35 | AB27: =IF(ISNUMBER(Z27),ROUND(Z27*'Reference data'!$B$2,0),"Unknown") -> 40 | AD27: 4566.051 | AE27: Subtree total
A28: ChatOpenAI | B28: 5 | C28: model | D28: gpt-5.6-luna | E28: ok | F28: 662 | G28: Interpret quote scope and request human clarification when needed. | H28: 01a0d133-a99c-7e60-8aea-8333e658ca6a | I28: 01a0d133-a99b-7f83-a110-9f23643bd343 | J28: =IF(COUNT('Turns'!D32)=1,SUM('Turns'!D32),"Unknown") -> 662 | K28: =IF(COUNT('Turns'!E32)=1,SUM('Turns'!E32),"Unknown") -> 0.00011602874 | L28: =IF(COUNT('Turns'!F32)=1,SUM('Turns'!F32),"Unknown") -> 0.0001324 | M28: =IF(COUNT('Turns'!D31)=1,SUM('Turns'!D31),"Unknown") -> 0 | N28: =IF(COUNT('Turns'!E31)=1,SUM('Turns'!E31),"Unknown") -> 0 | O28: =IF(COUNT('Turns'!F31)=1,SUM('Turns'!F31),"Unknown") -> 0 | P28: 0 | Q28: 0 | R28: 0 | S28: =IF(COUNT('Turns'!D37)=1,SUM('Turns'!D37),"Unknown") -> 127 | T28: =IF(COUNT('Turns'!E37)=1,SUM('Turns'!E37),"Unknown") -> 0.00013355574 | U28: =IF(COUNT('Turns'!F37)=1,SUM('Turns'!F37),"Unknown") -> 0.0001524 | V28: =IF(COUNT('Turns'!D36)=1,SUM('Turns'!D36),"Unknown") -> 100 | W28: =IF(COUNT('Turns'!E36)=1,SUM('Turns'!E36),"Unknown") -> 0.000105162 | X28: =IF(COUNT('Turns'!F36)=1,SUM('Turns'!F36),"Unknown") -> 0.00012 | Y28: =IF(COUNT('Turns'!E41)=1,SUM('Turns'!E41),"Unknown") -> 0.00035474648 | Z28: =IF(COUNT('Turns'!F41)=1,SUM('Turns'!F41),"Unknown") -> 0.0004048 | AA28: =IF(ISNUMBER(Y28),ROUND(Y28*'Reference data'!$B$2,0),"Unknown") -> 35 | AB28: =IF(ISNUMBER(Z28),ROUND(Z28*'Reference data'!$B$2,0),"Unknown") -> 40 | AC28: R3 | AD28: 4563.701 | AE28: Own call
A29: route_after_assessment | B29: 2 | C29: workflow | E29: ok | G29: Execute the route_after_assessment workflow operation and pass its result to the next graph step. | H29: 01a0d133-bb75-7d21-9e45-fe5f7dc4d9e9 | I29: 01a0d133-a997-7f12-a380-e6d1a5350a86 | AD29: 0.597 | AE29: No model charge
A30: ask | B30: 1 | C30: workflow | E30: interrupted | G30: Execute the ask workflow operation and pass its result to the next graph step. | H30: 01a0d133-bb78-7f83-be1f-0e66998fc57b | I30: 01a0d133-a990-7020-bcb1-e6bdf0ea3b0c | AD30: 0.758 | AE30: No model charge
A31: LangGraph | B31: 0 | C31: workflow | E31: ok | G31: Execute the LangGraph workflow operation and pass its result to the next graph step. | H31: 01a0d134-1e7b-72a0-a391-742e647aa97d | AD31: 5.252 | AE31: No model charge
A32: ask | B32: 1 | C32: workflow | E32: ok | G32: Execute the ask workflow operation and pass its result to the next graph step. | H32: 01a0d134-1e7e-7a73-b27e-6a89544ed930 | I32: 01a0d134-1e7b-72a0-a391-742e647aa97d | AD32: 2.306 | AE32: No model charge
A33: route_after_answer | B33: 2 | C33: workflow | E33: ok | G33: Execute the route_after_answer workflow operation and pass its result to the next graph step. | H33: 01a0d134-1e7f-7ae1-a52d-3808669adb78 | I33: 01a0d134-1e7e-7a73-b27e-6a89544ed930 | AD33: 0.487 | AE33: No model charge

Sheet Reference data
A1: Parameter | B1: Value | C1: Unit
A2: Number of executions | B2: 100000 | C2: executions
A3: USD → EUR | B3: 0.87635 | C3: EUR per USD
A4: Cache duration | B4: 5m
A5: Run ID | B5: 01a0d132-b474-79e2-bebb-1d3cde2984ea
A6: Recording | B6: Provider trace
A7: FX reference date | B7: 2026-09-23
A8: FX fetched at | B8: 2026-09-24T02:09:35.117183Z | C8: UTC
A9: FX source | B9: https://api.frankfurter.dev/v2/rate/usd/eur?providers=ecb
A10: Rounding | B10: Only projected costs: ROUND(cost × executions, 0)
A11: Tree totals | B11: Parent rows include descendants; do not sum all tree rows.
A12: Cache writes | B12: Simulated context movement is not a provider-billed write.
A13: Pricing scope | B13: Standard online token rates. Verify rates and model access before use. Cache writes with unspecified lifetime use the 5-minute rate unless an explicit cache_write rate is configured. No batch, regional, long-context, tool, or negotiated pricing adjustments are applied.
A15: Model | B15: Input USD / 1M tokens | C15: Cache read USD / 1M tokens | D15: Cache write USD / 1M tokens | E15: Output USD / 1M tokens | F15: Reasoning USD / 1M tokens | G15: Verified date | H15: Source | I15: Notes
A16: openai:gpt-5.5 | B16: 5 | C16: 0.5 | D16: Unknown | E16: 30 | F16: 30 | G16: 2026-09-18 | H16: https://developers.openai.com/api/docs/models/gpt-5.5.md | I16: Cache write assumes 5m when unspecified
A17: openai:gpt-5.6-luna | B17: 0.2 | C17: 0.02 | D17: 0.25 | E17: 1.2 | F17: 1.2 | G17: 2026-09-18 | H17: https://developers.openai.com/api/docs/models/gpt-5.6-luna.md | I17: Cache write assumes 5m when unspecified
A18: openai:gpt-5.6-sol | B18: 4 | C18: 0.4 | D18: 5 | E18: 20 | F18: 20 | G18: 2026-09-18 | H18: https://developers.openai.com/api/docs/models/gpt-5.6-sol.md | I18: Cache write assumes 5m when unspecified
A19: anthropic:claude-sonnet-5 | B19: 2 | C19: 0.2 | D19: 2.5 | E19: 10 | F19: 10 | G19: 2026-09-18 | H19: https://platform.claude.com/docs/en/about-claude/pricing | I19: Cache write assumes 5m when unspecified
A20: anthropic:claude-opus-4-8 | B20: 5 | C20: 0.5 | D20: 6.25 | E20: 25 | F20: 25 | G20: 2026-09-18 | H20: https://platform.claude.com/docs/en/about-claude/pricing | I20: Cache write assumes 5m when unspecified
A21: anthropic:claude-fable-5-1 | B21: 10 | C21: 0.25 | D21: 12.5 | E21: 50 | F21: 50 | G21: 2026-09-18 | H21: https://platform.claude.com/docs/en/about-claude/pricing | I21: Cache write assumes 5m when unspecified
A22: demo:scripted-chat | B22: 0.2 | C22: 0.02 | D22: 0.25 | E22: 1.2 | F22: 1.2 | G22: 2026-09-18 | H22: Illustrative demo rates based on openai:gpt-5.6-luna; no provider billing | I22: Cache write assumes 5m when unspecified
