Workbook

Sheet Turns
A1: Request | B1: Turn | C1: Sequence | D1: Tokens | E1: EUR / execution | F1: USD / execution | G1: Projected EUR | H1: Projected USD | I1: Content | J1: Model · effort | K1: Status | L1: Context total tokens | M1: Span ID
C2: Run total | E2: =IF(COUNT('Turns'!E16,'Turns'!E31,'Turns'!E46,'Turns'!E63,'Turns'!E80,'Turns'!E97,'Turns'!E114)=7,SUM('Turns'!E16,'Turns'!E31,'Turns'!E46,'Turns'!E63,'Turns'!E80,'Turns'!E97,'Turns'!E114),"Unknown") -> 0.016465231 | F2: =IF(COUNT('Turns'!F16,'Turns'!F31,'Turns'!F46,'Turns'!F63,'Turns'!F80,'Turns'!F97,'Turns'!F114)=7,SUM('Turns'!F16,'Turns'!F31,'Turns'!F46,'Turns'!F63,'Turns'!F80,'Turns'!F97,'Turns'!F114),"Unknown") -> 0.01871602 | G2: =IF(ISNUMBER(E2),ROUND(E2*'Reference data'!$B$2,0),"Unknown") -> 1647 | H2: =IF(ISNUMBER(F2),ROUND(F2*'Reference data'!$B$2,0),"Unknown") -> 1872
B3: 1 | C3: Turn 1 | E3: =IF(COUNT('Turns'!E16,'Turns'!E31,'Turns'!E46,'Turns'!E63,'Turns'!E80,'Turns'!E97,'Turns'!E114)=7,SUM('Turns'!E16,'Turns'!E31,'Turns'!E46,'Turns'!E63,'Turns'!E80,'Turns'!E97,'Turns'!E114),"Unknown") -> 0.016465231 | F3: =IF(COUNT('Turns'!F16,'Turns'!F31,'Turns'!F46,'Turns'!F63,'Turns'!F80,'Turns'!F97,'Turns'!F114)=7,SUM('Turns'!F16,'Turns'!F31,'Turns'!F46,'Turns'!F63,'Turns'!F80,'Turns'!F97,'Turns'!F114),"Unknown") -> 0.01871602 | G3: =IF(ISNUMBER(E3),ROUND(E3*'Reference data'!$B$2,0),"Unknown") -> 1647 | H3: =IF(ISNUMBER(F3),ROUND(F3*'Reference data'!$B$2,0),"Unknown") -> 1872
A4: R1 | B4: 1 | C4: LLM request | D4: 257 | J4: scripted-chat | M4: 01a1143f-6fb7-72c1-ade0-8618aca31160
A5: R1 | B5: 1 | C5: Input at standard rate | D5: 257 | E5: =IF(AND(ISNUMBER(F5),ISNUMBER('Reference data'!$B$3)),F5*'Reference data'!$B$3,"Unknown") -> 4.5218636e-05 | F5: =IF(D5=0,0,IF(ISNUMBER('Reference data'!B22),D5*'Reference data'!B22/1000000,"Unknown")) -> 5.14e-05 | G5: =IF(ISNUMBER(E5),ROUND(E5*'Reference data'!$B$2,0),"Unknown") -> 5 | H5: =IF(ISNUMBER(F5),ROUND(F5*'Reference data'!$B$2,0),"Unknown") -> 5
A6: R1 | B6: 1 | C6: Tool definitions | D6: 173
A7: R1 | B7: 1 | C7: System prompt | D7: 49 | I7: Use the fictional service evidence to propose and validate a latency improvement. Inspect traffic, database behavior, and constraints before testing the plan.
A8: R1 | B8: 1 | C8: User prompt | D8: 35 | I8: Investigate service latency and validate a plan meeting the constraints.
A9: R1 | B9: 1 | C9: Cache write | D9: 257
A10: R1 | B10: 1 | C10: Context · added / total | D10: 257 | L10: 257
A11: R1 | B11: 1 | C11: LLM response | D11: 58
A12: R1 | B12: 1 | C12: Output | D12: 58 | E12: =IF(AND(ISNUMBER(F12),ISNUMBER('Reference data'!$B$3)),F12*'Reference data'!$B$3,"Unknown") -> 6.1229904e-05 | F12: =IF(D12=0,0,IF(ISNUMBER('Reference data'!E22),D12*'Reference data'!E22/1000000,"Unknown")) -> 6.96e-05 | G12: =IF(ISNUMBER(E12),ROUND(E12*'Reference data'!$B$2,0),"Unknown") -> 6 | H12: =IF(ISNUMBER(F12),ROUND(F12*'Reference data'!$B$2,0),"Unknown") -> 7
A13: R1 | B13: 1 | C13: Output content | I13: Inspect the traffic evidence. {"name": "inspect_service", "args": {"section": "traffic"}, "id": "inspect-0", "type": "tool_call"}
A14: R1 | B14: 1 | C14: Cache write | D14: 58
A15: R1 | B15: 1 | C15: Context · added / total | D15: 58 | L15: 315
A16: R1 | B16: 1 | C16: Call total | E16: =IF(COUNT('Turns'!E5,'Turns'!E12)=2,SUM('Turns'!E5,'Turns'!E12),"Unknown") -> 0.00010644854 | F16: =IF(COUNT('Turns'!F5,'Turns'!F12)=2,SUM('Turns'!F5,'Turns'!F12),"Unknown") -> 0.000121 | G16: =IF(ISNUMBER(E16),ROUND(E16*'Reference data'!$B$2,0),"Unknown") -> 11 | H16: =IF(ISNUMBER(F16),ROUND(F16*'Reference data'!$B$2,0),"Unknown") -> 12 | K16: ok
B17: 1 | C17: Tool · inspect_service | K17: ok | M17: 01a1143f-7039-72a2-9539-5cdd3f56af5e
B18: 1 | C18: Arguments | I18: {'section': 'traffic'}
B19: 1 | C19: Result | I19: Peak 240 requests/s; p95 1.8s; 12 workers. Latency rises during database bursts.
A20: R2 | B20: 1 | C20: LLM request | D20: 366 | J20: scripted-chat | M20: 01a1143f-703b-7053-91dc-e3b7fa6e1526
A21: R2 | B21: 1 | C21: Conversation history · cache read | D21: 315 | E21: =IF(AND(ISNUMBER(F21),ISNUMBER('Reference data'!$B$3)),F21*'Reference data'!$B$3,"Unknown") -> 5.542362e-06 | F21: =IF(D21=0,0,IF(ISNUMBER('Reference data'!C22),D21*'Reference data'!C22/1000000,"Unknown")) -> 6.3e-06 | G21: =IF(ISNUMBER(E21),ROUND(E21*'Reference data'!$B$2,0),"Unknown") -> 1 | H21: =IF(ISNUMBER(F21),ROUND(F21*'Reference data'!$B$2,0),"Unknown") -> 1
A22: R2 | B22: 1 | C22: Input at standard rate | D22: 51 | E22: =IF(AND(ISNUMBER(F22),ISNUMBER('Reference data'!$B$3)),F22*'Reference data'!$B$3,"Unknown") -> 8.973348e-06 | F22: =IF(D22=0,0,IF(ISNUMBER('Reference data'!B22),D22*'Reference data'!B22/1000000,"Unknown")) -> 1.02e-05 | G22: =IF(ISNUMBER(E22),ROUND(E22*'Reference data'!$B$2,0),"Unknown") -> 1 | H22: =IF(ISNUMBER(F22),ROUND(F22*'Reference data'!$B$2,0),"Unknown") -> 1
A23: R2 | B23: 1 | C23: Tool result | D23: 51 | I23: Peak 240 requests/s; p95 1.8s; 12 workers. Latency rises during database bursts.
A24: R2 | B24: 1 | C24: Cache write | D24: 51
A25: R2 | B25: 1 | C25: Context · added / total | D25: 51 | L25: 366
A26: R2 | B26: 1 | C26: LLM response | D26: 58
A27: R2 | B27: 1 | C27: Output | D27: 58 | E27: =IF(AND(ISNUMBER(F27),ISNUMBER('Reference data'!$B$3)),F27*'Reference data'!$B$3,"Unknown") -> 6.1229904e-05 | F27: =IF(D27=0,0,IF(ISNUMBER('Reference data'!E22),D27*'Reference data'!E22/1000000,"Unknown")) -> 6.96e-05 | G27: =IF(ISNUMBER(E27),ROUND(E27*'Reference data'!$B$2,0),"Unknown") -> 6 | H27: =IF(ISNUMBER(F27),ROUND(F27*'Reference data'!$B$2,0),"Unknown") -> 7
A28: R2 | B28: 1 | C28: Output content | I28: Inspect the database evidence. {"name": "inspect_service", "args": {"section": "database"}, "id": "inspect-1", "type": "tool_call"}
A29: R2 | B29: 1 | C29: Cache write | D29: 58
A30: R2 | B30: 1 | C30: Context · added / total | D30: 58 | L30: 424
A31: R2 | B31: 1 | C31: Call total | E31: =IF(COUNT('Turns'!E21,'Turns'!E22,'Turns'!E27)=3,SUM('Turns'!E21,'Turns'!E22,'Turns'!E27),"Unknown") -> 7.5745614e-05 | F31: =IF(COUNT('Turns'!F21,'Turns'!F22,'Turns'!F27)=3,SUM('Turns'!F21,'Turns'!F22,'Turns'!F27),"Unknown") -> 8.61e-05 | G31: =IF(ISNUMBER(E31),ROUND(E31*'Reference data'!$B$2,0),"Unknown") -> 8 | H31: =IF(ISNUMBER(F31),ROUND(F31*'Reference data'!$B$2,0),"Unknown") -> 9 | K31: ok
B32: 1 | C32: Tool · inspect_service | K32: ok | M32: 01a1143f-703f-7790-957a-0826ef48d8d6
B33: 1 | C33: Arguments | I33: {'section': 'database'}
B34: 1 | C34: Result | I34: Pool limit 12. Median query 80ms; p95 900ms. Duplicate account lookups appear per request.
A35: R3 | B35: 1 | C35: LLM request | D35: 475 | J35: scripted-chat | M35: 01a1143f-7041-7961-9676-f3d146921a51
A36: R3 | B36: 1 | C36: Conversation history · cache read | D36: 424 | E36: =IF(AND(ISNUMBER(F36),ISNUMBER('Reference data'!$B$3)),F36*'Reference data'!$B$3,"Unknown") -> 7.4601952e-06 | F36: =IF(D36=0,0,IF(ISNUMBER('Reference data'!C22),D36*'Reference data'!C22/1000000,"Unknown")) -> 8.48e-06 | G36: =IF(ISNUMBER(E36),ROUND(E36*'Reference data'!$B$2,0),"Unknown") -> 1 | H36: =IF(ISNUMBER(F36),ROUND(F36*'Reference data'!$B$2,0),"Unknown") -> 1
A37: R3 | B37: 1 | C37: Input at standard rate | D37: 51 | E37: =IF(AND(ISNUMBER(F37),ISNUMBER('Reference data'!$B$3)),F37*'Reference data'!$B$3,"Unknown") -> 8.973348e-06 | F37: =IF(D37=0,0,IF(ISNUMBER('Reference data'!B22),D37*'Reference data'!B22/1000000,"Unknown")) -> 1.02e-05 | G37: =IF(ISNUMBER(E37),ROUND(E37*'Reference data'!$B$2,0),"Unknown") -> 1 | H37: =IF(ISNUMBER(F37),ROUND(F37*'Reference data'!$B$2,0),"Unknown") -> 1
A38: R3 | B38: 1 | C38: Tool result | D38: 51 | I38: Pool limit 12. Median query 80ms; p95 900ms. Duplicate account lookups appear per request.
A39: R3 | B39: 1 | C39: Cache write | D39: 51
A40: R3 | B40: 1 | C40: Context · added / total | D40: 51 | L40: 475
...

Sheet Execution tree
A1: Operation | B1: Depth | C1: Type | D1: Model · effort | E1: Status | F1: Input context tokens | G1: Description | H1: Span ID | I1: Parent ID | J1: Input at standard rate tokens | K1: Input at standard rate EUR | L1: Input at standard rate USD | M1: Cache read tokens | N1: Cache read EUR | O1: Cache read USD | P1: Cache write tokens | Q1: Cache write EUR | R1: Cache write USD | S1: Output (non-reasoning) tokens | T1: Output (non-reasoning) EUR | U1: Output (non-reasoning) USD | V1: Reasoning tokens | W1: Reasoning EUR | X1: Reasoning USD | Y1: Total EUR | Z1: Total USD | AA1: Projected EUR | AB1: Projected USD | AC1: Request | AD1: Elapsed ms | AE1: Accounting
A2: investigation_agent | B2: 0 | C2: workflow | E2: ok | G2: Execute the investigation_agent workflow operation and pass its result to the next graph step. | H2: 01a1143f-6fb3-7ca0-8d46-937eae9c46c0 | J2: =IF(COUNT('Turns'!D5,'Turns'!D22,'Turns'!D37,'Turns'!D52,'Turns'!D69,'Turns'!D86,'Turns'!D103)=7,SUM('Turns'!D5,'Turns'!D22,'Turns'!D37,'Turns'!D52,'Turns'!D69,'Turns'!D86,'Turns'!D103),"Unknown") -> 545 | K2: =IF(COUNT('Turns'!E5,'Turns'!E22,'Turns'!E37,'Turns'!E52,'Turns'!E69,'Turns'!E86,'Turns'!E103)=7,SUM('Turns'!E5,'Turns'!E22,'Turns'!E37,'Turns'!E52,'Turns'!E69,'Turns'!E86,'Turns'!E103),"Unknown") -> 9.589166e-05 | L2: =IF(COUNT('Turns'!F5,'Turns'!F22,'Turns'!F37,'Turns'!F52,'Turns'!F69,'Turns'!F86,'Turns'!F103)=7,SUM('Turns'!F5,'Turns'!F22,'Turns'!F37,'Turns'!F52,'Turns'!F69,'Turns'!F86,'Turns'!F103),"Unknown") -> 0.000109 | M2: =IF(COUNT('Turns'!D21,'Turns'!D36,'Turns'!D51,'Turns'!D68,'Turns'!D85,'Turns'!D102)=6,SUM('Turns'!D21,'Turns'!D36,'Turns'!D51,'Turns'!D68,'Turns'!D85,'Turns'!D102),"Unknown") -> 3591 | N2: =IF(COUNT('Turns'!E21,'Turns'!E36,'Turns'!E51,'Turns'!E68,'Turns'!E85,'Turns'!E102)=6,SUM('Turns'!E21,'Turns'!E36,'Turns'!E51,'Turns'!E68,'Turns'!E85,'Turns'!E102),"Unknown") -> 6.3182927e-05 | O2: =IF(COUNT('Turns'!F21,'Turns'!F36,'Turns'!F51,'Turns'!F68,'Turns'!F85,'Turns'!F102)=6,SUM('Turns'!F21,'Turns'!F36,'Turns'!F51,'Turns'!F68,'Turns'!F85,'Turns'!F102),"Unknown") -> 7.182e-05 | P2: 0 | Q2: 0 | R2: 0 | S2: =IF(COUNT('Turns'!D12,'Turns'!D27,'Turns'!D42,'Turns'!D59,'Turns'!D76,'Turns'!D93,'Turns'!D110)=7,SUM('Turns'!D12,'Turns'!D27,'Turns'!D42,'Turns'!D59,'Turns'!D76,'Turns'!D93,'Turns'!D110),"Unknown") -> 446 | T2: =IF(COUNT('Turns'!E12,'Turns'!E27,'Turns'!E42,'Turns'!E59,'Turns'!E76,'Turns'!E93,'Turns'!E110)=7,SUM('Turns'!E12,'Turns'!E27,'Turns'!E42,'Turns'!E59,'Turns'!E76,'Turns'!E93,'Turns'!E110),"Unknown") -> 0.00047083685 | U2: =IF(COUNT('Turns'!F12,'Turns'!F27,'Turns'!F42,'Turns'!F59,'Turns'!F76,'Turns'!F93,'Turns'!F110)=7,SUM('Turns'!F12,'Turns'!F27,'Turns'!F42,'Turns'!F59,'Turns'!F76,'Turns'!F93,'Turns'!F110),"Unknown") -> 0.0005352 | V2: =IF(COUNT('Turns'!D57,'Turns'!D74,'Turns'!D91,'Turns'!D108)=4,SUM('Turns'!D57,'Turns'!D74,'Turns'!D91,'Turns'!D108),"Unknown") -> 15000 | W2: =IF(COUNT('Turns'!E57,'Turns'!E74,'Turns'!E91,'Turns'!E108)=4,SUM('Turns'!E57,'Turns'!E74,'Turns'!E91,'Turns'!E108),"Unknown") -> 0.01583532 | X2: =IF(COUNT('Turns'!F57,'Turns'!F74,'Turns'!F91,'Turns'!F108)=4,SUM('Turns'!F57,'Turns'!F74,'Turns'!F91,'Turns'!F108),"Unknown") -> 0.018 | Y2: =IF(COUNT('Turns'!E16,'Turns'!E31,'Turns'!E46,'Turns'!E63,'Turns'!E80,'Turns'!E97,'Turns'!E114)=7,SUM('Turns'!E16,'Turns'!E31,'Turns'!E46,'Turns'!E63,'Turns'!E80,'Turns'!E97,'Turns'!E114),"Unknown") -> 0.016465231 | Z2: =IF(COUNT('Turns'!F16,'Turns'!F31,'Turns'!F46,'Turns'!F63,'Turns'!F80,'Turns'!F97,'Turns'!F114)=7,SUM('Turns'!F16,'Turns'!F31,'Turns'!F46,'Turns'!F63,'Turns'!F80,'Turns'!F97,'Turns'!F114),"Unknown") -> 0.01871602 | AA2: =IF(ISNUMBER(Y2),ROUND(Y2*'Reference data'!$B$2,0),"Unknown") -> 1647 | AB2: =IF(ISNUMBER(Z2),ROUND(Z2*'Reference data'!$B$2,0),"Unknown") -> 1872 | AD2: 167.023 | AE2: Subtree total
A3: model | B3: 1 | C3: workflow | E3: ok | G3: Prepare the current conversation, run model middleware, and invoke the chat model. | H3: 01a1143f-6fb5-7a40-a454-bfd2c043d6a6 | I3: 01a1143f-6fb3-7ca0-8d46-937eae9c46c0 | J3: =IF(COUNT('Turns'!D5)=1,SUM('Turns'!D5),"Unknown") -> 257 | K3: =IF(COUNT('Turns'!E5)=1,SUM('Turns'!E5),"Unknown") -> 4.5218636e-05 | L3: =IF(COUNT('Turns'!F5)=1,SUM('Turns'!F5),"Unknown") -> 5.14e-05 | M3: 0 | N3: 0 | O3: 0 | P3: 0 | Q3: 0 | R3: 0 | S3: =IF(COUNT('Turns'!D12)=1,SUM('Turns'!D12),"Unknown") -> 58 | T3: =IF(COUNT('Turns'!E12)=1,SUM('Turns'!E12),"Unknown") -> 6.1229904e-05 | U3: =IF(COUNT('Turns'!F12)=1,SUM('Turns'!F12),"Unknown") -> 6.96e-05 | V3: 0 | W3: 0 | X3: 0 | Y3: =IF(COUNT('Turns'!E16)=1,SUM('Turns'!E16),"Unknown") -> 0.00010644854 | Z3: =IF(COUNT('Turns'!F16)=1,SUM('Turns'!F16),"Unknown") -> 0.000121 | AA3: =IF(ISNUMBER(Y3),ROUND(Y3*'Reference data'!$B$2,0),"Unknown") -> 11 | AB3: =IF(ISNUMBER(Z3),ROUND(Z3*'Reference data'!$B$2,0),"Unknown") -> 12 | AD3: 129.34 | AE3: Subtree total
A4: SimulatedModel | B4: 2 | C4: model | D4: scripted-chat | E4: ok | F4: 257 | G4: Investigate evidence and test a hypothesis. | H4: 01a1143f-6fb7-72c1-ade0-8618aca31160 | I4: 01a1143f-6fb5-7a40-a454-bfd2c043d6a6 | J4: =IF(COUNT('Turns'!D5)=1,SUM('Turns'!D5),"Unknown") -> 257 | K4: =IF(COUNT('Turns'!E5)=1,SUM('Turns'!E5),"Unknown") -> 4.5218636e-05 | L4: =IF(COUNT('Turns'!F5)=1,SUM('Turns'!F5),"Unknown") -> 5.14e-05 | M4: 0 | N4: 0 | O4: 0 | P4: 0 | Q4: 0 | R4: 0 | S4: =IF(COUNT('Turns'!D12)=1,SUM('Turns'!D12),"Unknown") -> 58 | T4: =IF(COUNT('Turns'!E12)=1,SUM('Turns'!E12),"Unknown") -> 6.1229904e-05 | U4: =IF(COUNT('Turns'!F12)=1,SUM('Turns'!F12),"Unknown") -> 6.96e-05 | V4: 0 | W4: 0 | X4: 0 | Y4: =IF(COUNT('Turns'!E16)=1,SUM('Turns'!E16),"Unknown") -> 0.00010644854 | Z4: =IF(COUNT('Turns'!F16)=1,SUM('Turns'!F16),"Unknown") -> 0.000121 | AA4: =IF(ISNUMBER(Y4),ROUND(Y4*'Reference data'!$B$2,0),"Unknown") -> 11 | AB4: =IF(ISNUMBER(Z4),ROUND(Z4*'Reference data'!$B$2,0),"Unknown") -> 12 | AC4: R1 | AD4: 127.41 | AE4: Own call
A5: tools | B5: 1 | C5: workflow | E5: ok | G5: Execute tool calls requested by the preceding model response and return their observations. | H5: 01a1143f-7038-7493-b25f-5dd3069acde7 | I5: 01a1143f-6fb3-7ca0-8d46-937eae9c46c0 | AD5: 1.428 | AE5: No model charge
A6: inspect_service | B6: 2 | C6: tool | E6: ok | G6: Read fictional service evidence; no live service is inspected. | H6: 01a1143f-7039-72a2-9539-5cdd3f56af5e | I6: 01a1143f-7038-7493-b25f-5dd3069acde7 | AD6: 0.449 | AE6: No model charge
A7: model | B7: 1 | C7: workflow | E7: ok | G7: Prepare the current conversation, run model middleware, and invoke the chat model. | H7: 01a1143f-703a-7242-9ed2-7056864c3c5d | I7: 01a1143f-6fb3-7ca0-8d46-937eae9c46c0 | J7: =IF(COUNT('Turns'!D22)=1,SUM('Turns'!D22),"Unknown") -> 51 | K7: =IF(COUNT('Turns'!E22)=1,SUM('Turns'!E22),"Unknown") -> 8.973348e-06 | L7: =IF(COUNT('Turns'!F22)=1,SUM('Turns'!F22),"Unknown") -> 1.02e-05 | M7: =IF(COUNT('Turns'!D21)=1,SUM('Turns'!D21),"Unknown") -> 315 | N7: =IF(COUNT('Turns'!E21)=1,SUM('Turns'!E21),"Unknown") -> 5.542362e-06 | O7: =IF(COUNT('Turns'!F21)=1,SUM('Turns'!F21),"Unknown") -> 6.3e-06 | P7: 0 | Q7: 0 | R7: 0 | S7: =IF(COUNT('Turns'!D27)=1,SUM('Turns'!D27),"Unknown") -> 58 | T7: =IF(COUNT('Turns'!E27)=1,SUM('Turns'!E27),"Unknown") -> 6.1229904e-05 | U7: =IF(COUNT('Turns'!F27)=1,SUM('Turns'!F27),"Unknown") -> 6.96e-05 | V7: 0 | W7: 0 | X7: 0 | Y7: =IF(COUNT('Turns'!E31)=1,SUM('Turns'!E31),"Unknown") -> 7.5745614e-05 | Z7: =IF(COUNT('Turns'!F31)=1,SUM('Turns'!F31),"Unknown") -> 8.61e-05 | AA7: =IF(ISNUMBER(Y7),ROUND(Y7*'Reference data'!$B$2,0),"Unknown") -> 8 | AB7: =IF(ISNUMBER(Z7),ROUND(Z7*'Reference data'!$B$2,0),"Unknown") -> 9 | AD7: 3.765 | AE7: Subtree total
A8: SimulatedModel | B8: 2 | C8: model | D8: scripted-chat | E8: ok | F8: 366 | G8: Investigate evidence and test a hypothesis. | H8: 01a1143f-703b-7053-91dc-e3b7fa6e1526 | I8: 01a1143f-703a-7242-9ed2-7056864c3c5d | J8: =IF(COUNT('Turns'!D22)=1,SUM('Turns'!D22),"Unknown") -> 51 | K8: =IF(COUNT('Turns'!E22)=1,SUM('Turns'!E22),"Unknown") -> 8.973348e-06 | L8: =IF(COUNT('Turns'!F22)=1,SUM('Turns'!F22),"Unknown") -> 1.02e-05 | M8: =IF(COUNT('Turns'!D21)=1,SUM('Turns'!D21),"Unknown") -> 315 | N8: =IF(COUNT('Turns'!E21)=1,SUM('Turns'!E21),"Unknown") -> 5.542362e-06 | O8: =IF(COUNT('Turns'!F21)=1,SUM('Turns'!F21),"Unknown") -> 6.3e-06 | P8: 0 | Q8: 0 | R8: 0 | S8: =IF(COUNT('Turns'!D27)=1,SUM('Turns'!D27),"Unknown") -> 58 | T8: =IF(COUNT('Turns'!E27)=1,SUM('Turns'!E27),"Unknown") -> 6.1229904e-05 | U8: =IF(COUNT('Turns'!F27)=1,SUM('Turns'!F27),"Unknown") -> 6.96e-05 | V8: 0 | W8: 0 | X8: 0 | Y8: =IF(COUNT('Turns'!E31)=1,SUM('Turns'!E31),"Unknown") -> 7.5745614e-05 | Z8: =IF(COUNT('Turns'!F31)=1,SUM('Turns'!F31),"Unknown") -> 8.61e-05 | AA8: =IF(ISNUMBER(Y8),ROUND(Y8*'Reference data'!$B$2,0),"Unknown") -> 8 | AB8: =IF(ISNUMBER(Z8),ROUND(Z8*'Reference data'!$B$2,0),"Unknown") -> 9 | AC8: R2 | AD8: 2.957 | AE8: Own call
A9: tools | B9: 1 | C9: workflow | E9: ok | G9: Execute tool calls requested by the preceding model response and return their observations. | H9: 01a1143f-703f-7790-957a-0813924e38da | I9: 01a1143f-6fb3-7ca0-8d46-937eae9c46c0 | AD9: 1.183 | AE9: No model charge
A10: inspect_service | B10: 2 | C10: tool | E10: ok | G10: Read fictional service evidence; no live service is inspected. | H10: 01a1143f-703f-7790-957a-0826ef48d8d6 | I10: 01a1143f-703f-7790-957a-0813924e38da | AD10: 0.372 | AE10: No model charge
A11: model | B11: 1 | C11: workflow | E11: ok | G11: Prepare the current conversation, run model middleware, and invoke the chat model. | H11: 01a1143f-7040-7e31-87f6-de9fe83c1086 | I11: 01a1143f-6fb3-7ca0-8d46-937eae9c46c0 | J11: =IF(COUNT('Turns'!D37)=1,SUM('Turns'!D37),"Unknown") -> 51 | K11: =IF(COUNT('Turns'!E37)=1,SUM('Turns'!E37),"Unknown") -> 8.973348e-06 | L11: =IF(COUNT('Turns'!F37)=1,SUM('Turns'!F37),"Unknown") -> 1.02e-05 | M11: =IF(COUNT('Turns'!D36)=1,SUM('Turns'!D36),"Unknown") -> 424 | N11: =IF(COUNT('Turns'!E36)=1,SUM('Turns'!E36),"Unknown") -> 7.4601952e-06 | O11: =IF(COUNT('Turns'!F36)=1,SUM('Turns'!F36),"Unknown") -> 8.48e-06 | P11: 0 | Q11: 0 | R11: 0 | S11: =IF(COUNT('Turns'!D42)=1,SUM('Turns'!D42),"Unknown") -> 58 | T11: =IF(COUNT('Turns'!E42)=1,SUM('Turns'!E42),"Unknown") -> 6.1229904e-05 | U11: =IF(COUNT('Turns'!F42)=1,SUM('Turns'!F42),"Unknown") -> 6.96e-05 | V11: 0 | W11: 0 | X11: 0 | Y11: =IF(COUNT('Turns'!E46)=1,SUM('Turns'!E46),"Unknown") -> 7.7663447e-05 | Z11: =IF(COUNT('Turns'!F46)=1,SUM('Turns'!F46),"Unknown") -> 8.828e-05 | AA11: =IF(ISNUMBER(Y11),ROUND(Y11*'Reference data'!$B$2,0),"Unknown") -> 8 | AB11: =IF(ISNUMBER(Z11),ROUND(Z11*'Reference data'!$B$2,0),"Unknown") -> 9 | AD11: 2.641 | AE11: Subtree total
A12: SimulatedModel | B12: 2 | C12: model | D12: scripted-chat | E12: ok | F12: 475 | G12: Investigate evidence and test a hypothesis. | H12: 01a1143f-7041-7961-9676-f3d146921a51 | I12: 01a1143f-7040-7e31-87f6-de9fe83c1086 | J12: =IF(COUNT('Turns'!D37)=1,SUM('Turns'!D37),"Unknown") -> 51 | K12: =IF(COUNT('Turns'!E37)=1,SUM('Turns'!E37),"Unknown") -> 8.973348e-06 | L12: =IF(COUNT('Turns'!F37)=1,SUM('Turns'!F37),"Unknown") -> 1.02e-05 | M12: =IF(COUNT('Turns'!D36)=1,SUM('Turns'!D36),"Unknown") -> 424 | N12: =IF(COUNT('Turns'!E36)=1,SUM('Turns'!E36),"Unknown") -> 7.4601952e-06 | O12: =IF(COUNT('Turns'!F36)=1,SUM('Turns'!F36),"Unknown") -> 8.48e-06 | P12: 0 | Q12: 0 | R12: 0 | S12: =IF(COUNT('Turns'!D42)=1,SUM('Turns'!D42),"Unknown") -> 58 | T12: =IF(COUNT('Turns'!E42)=1,SUM('Turns'!E42),"Unknown") -> 6.1229904e-05 | U12: =IF(COUNT('Turns'!F42)=1,SUM('Turns'!F42),"Unknown") -> 6.96e-05 | V12: 0 | W12: 0 | X12: 0 | Y12: =IF(COUNT('Turns'!E46)=1,SUM('Turns'!E46),"Unknown") -> 7.7663447e-05 | Z12: =IF(COUNT('Turns'!F46)=1,SUM('Turns'!F46),"Unknown") -> 8.828e-05 | AA12: =IF(ISNUMBER(Y12),ROUND(Y12*'Reference data'!$B$2,0),"Unknown") -> 8 | AB12: =IF(ISNUMBER(Z12),ROUND(Z12*'Reference data'!$B$2,0),"Unknown") -> 9 | AC12: R3 | AD12: 1.867 | AE12: Own call
A13: tools | B13: 1 | C13: workflow | E13: ok | G13: Execute tool calls requested by the preceding model response and return their observations. | H13: 01a1143f-7043-7101-9b19-abcdd5e8bf96 | I13: 01a1143f-6fb3-7ca0-8d46-937eae9c46c0 | AD13: 1.222 | AE13: No model charge
A14: inspect_service | B14: 2 | C14: tool | E14: ok | G14: Read fictional service evidence; no live service is inspected. | H14: 01a1143f-7044-7150-93d2-7954c9f640c3 | I14: 01a1143f-7043-7101-9b19-abcdd5e8bf96 | AD14: 0.324 | AE14: No model charge
A15: model | B15: 1 | C15: workflow | E15: ok | G15: Prepare the current conversation, run model middleware, and invoke the chat model. | H15: 01a1143f-7045-7223-947a-5b966d7a4a77 | I15: 01a1143f-6fb3-7ca0-8d46-937eae9c46c0 | J15: =IF(COUNT('Turns'!D52)=1,SUM('Turns'!D52),"Unknown") -> 48 | K15: =IF(COUNT('Turns'!E52)=1,SUM('Turns'!E52),"Unknown") -> 8.445504e-06 | L15: =IF(COUNT('Turns'!F52)=1,SUM('Turns'!F52),"Unknown") -> 9.6e-06 | M15: =IF(COUNT('Turns'!D51)=1,SUM('Turns'!D51),"Unknown") -> 533 | N15: =IF(COUNT('Turns'!E51)=1,SUM('Turns'!E51),"Unknown") -> 9.3780284e-06 | O15: =IF(COUNT('Turns'!F51)=1,SUM('Turns'!F51),"Unknown") -> 1.066e-05 | P15: 0 | Q15: 0 | R15: 0 | S15: =IF(COUNT('Turns'!D59)=1,SUM('Turns'!D59),"Unknown") -> 80 | T15: =IF(COUNT('Turns'!E59)=1,SUM('Turns'!E59),"Unknown") -> 8.445504e-05 | U15: =IF(COUNT('Turns'!F59)=1,SUM('Turns'!F59),"Unknown") -> 9.6e-05 | V15: =IF(COUNT('Turns'!D57)=1,SUM('Turns'!D57),"Unknown") -> 12000 | W15: =IF(COUNT('Turns'!E57)=1,SUM('Turns'!E57),"Unknown") -> 0.012668256 | X15: =IF(COUNT('Turns'!F57)=1,SUM('Turns'!F57),"Unknown") -> 0.0144 | Y15: =IF(COUNT('Turns'!E63)=1,SUM('Turns'!E63),"Unknown") -> 0.012770535 | Z15: =IF(COUNT('Turns'!F63)=1,SUM('Turns'!F63),"Unknown") -> 0.01451626 | AA15: =IF(ISNUMBER(Y15),ROUND(Y15*'Reference data'!$B$2,0),"Unknown") -> 1277 | AB15: =IF(ISNUMBER(Z15),ROUND(Z15*'Reference data'!$B$2,0),"Unknown") -> 1452 | AD15: 2.766 | AE15: Subtree total
A16: SimulatedModel | B16: 2 | C16: model | D16: scripted-chat | E16: ok | F16: 581 | G16: Investigate evidence and test a hypothesis. | H16: 01a1143f-7046-7e13-9013-5323af20f982 | I16: 01a1143f-7045-7223-947a-5b966d7a4a77 | J16: =IF(COUNT('Turns'!D52)=1,SUM('Turns'!D52),"Unknown") -> 48 | K16: =IF(COUNT('Turns'!E52)=1,SUM('Turns'!E52),"Unknown") -> 8.445504e-06 | L16: =IF(COUNT('Turns'!F52)=1,SUM('Turns'!F52),"Unknown") -> 9.6e-06 | M16: =IF(COUNT('Turns'!D51)=1,SUM('Turns'!D51),"Unknown") -> 533 | N16: =IF(COUNT('Turns'!E51)=1,SUM('Turns'!E51),"Unknown") -> 9.3780284e-06 | O16: =IF(COUNT('Turns'!F51)=1,SUM('Turns'!F51),"Unknown") -> 1.066e-05 | P16: 0 | Q16: 0 | R16: 0 | S16: =IF(COUNT('Turns'!D59)=1,SUM('Turns'!D59),"Unknown") -> 80 | T16: =IF(COUNT('Turns'!E59)=1,SUM('Turns'!E59),"Unknown") -> 8.445504e-05 | U16: =IF(COUNT('Turns'!F59)=1,SUM('Turns'!F59),"Unknown") -> 9.6e-05 | V16: =IF(COUNT('Turns'!D57)=1,SUM('Turns'!D57),"Unknown") -> 12000 | W16: =IF(COUNT('Turns'!E57)=1,SUM('Turns'!E57),"Unknown") -> 0.012668256 | X16: =IF(COUNT('Turns'!F57)=1,SUM('Turns'!F57),"Unknown") -> 0.0144 | Y16: =IF(COUNT('Turns'!E63)=1,SUM('Turns'!E63),"Unknown") -> 0.012770535 | Z16: =IF(COUNT('Turns'!F63)=1,SUM('Turns'!F63),"Unknown") -> 0.01451626 | AA16: =IF(ISNUMBER(Y16),ROUND(Y16*'Reference data'!$B$2,0),"Unknown") -> 1277 | AB16: =IF(ISNUMBER(Z16),ROUND(Z16*'Reference data'!$B$2,0),"Unknown") -> 1452 | AC16: R4 | AD16: 1.952 | AE16: Own call
A17: tools | B17: 1 | C17: workflow | E17: ok | G17: Execute tool calls requested by the preceding model response and return their observations. | H17: 01a1143f-7049-7a62-9029-fae41eb66121 | I17: 01a1143f-6fb3-7ca0-8d46-937eae9c46c0 | AD17: 1.64 | AE17: No model charge
A18: test_plan | B18: 2 | C18: tool | E18: ok | G18: Return a fixed fictional plan-check result; no real test is executed. | H18: 01a1143f-7049-7a62-9029-faf1bcce99ac | I18: 01a1143f-7049-7a62-9029-fae41eb66121 | AD18: 0.556 | AE18: No model charge
A19: model | B19: 1 | C19: workflow | E19: ok | G19: Prepare the current conversation, run model middleware, and invoke the chat model. | H19: 01a1143f-704b-7543-8e48-cfb70c01dc2b | I19: 01a1143f-6fb3-7ca0-8d46-937eae9c46c0 | J19: =IF(COUNT('Turns'!D69)=1,SUM('Turns'!D69),"Unknown") -> 56 | K19: =IF(COUNT('Turns'!E69)=1,SUM('Turns'!E69),"Unknown") -> 9.853088e-06 | L19: =IF(COUNT('Turns'!F69)=1,SUM('Turns'!F69),"Unknown") -> 1.12e-05 | M19: =IF(COUNT('Turns'!D68)=1,SUM('Turns'!D68),"Unknown") -> 661 | N19: =IF(COUNT('Turns'!E68)=1,SUM('Turns'!E68),"Unknown") -> 1.1630163e-05 | O19: =IF(COUNT('Turns'!F68)=1,SUM('Turns'!F68),"Unknown") -> 1.322e-05 | P19: 0 | Q19: 0 | R19: 0 | S19: =IF(COUNT('Turns'!D76)=1,SUM('Turns'!D76),"Unknown") -> 61 | T19: =IF(COUNT('Turns'!E76)=1,SUM('Turns'!E76),"Unknown") -> 6.4396968e-05 | U19: =IF(COUNT('Turns'!F76)=1,SUM('Turns'!F76),"Unknown") -> 7.32e-05 | V19: =IF(COUNT('Turns'!D74)=1,SUM('Turns'!D74),"Unknown") -> 600 | W19: =IF(COUNT('Turns'!E74)=1,SUM('Turns'!E74),"Unknown") -> 0.0006334128 | X19: =IF(COUNT('Turns'!F74)=1,SUM('Turns'!F74),"Unknown") -> 0.00072 | Y19: =IF(COUNT('Turns'!E80)=1,SUM('Turns'!E80),"Unknown") -> 0.00071929302 | Z19: =IF(COUNT('Turns'!F80)=1,SUM('Turns'!F80),"Unknown") -> 0.00081762 | AA19: =IF(ISNUMBER(Y19),ROUND(Y19*'Reference data'!$B$2,0),"Unknown") -> 72 | AB19: =IF(ISNUMBER(Z19),ROUND(Z19*'Reference data'!$B$2,0),"Unknown") -> 82 | AD19: 4.663 | AE19: Subtree total
A20: SimulatedModel | B20: 2 | C20: model | D20: scripted-chat | E20: ok | F20: 717 | G20: Investigate evidence and test a hypothesis. | H20: 01a1143f-704c-73b3-afbc-eceb0e6ed002 | I20: 01a1143f-704b-7543-8e48-cfb70c01dc2b | J20: =IF(COUNT('Turns'!D69)=1,SUM('Turns'!D69),"Unknown") -> 56 | K20: =IF(COUNT('Turns'!E69)=1,SUM('Turns'!E69),"Unknown") -> 9.853088e-06 | L20: =IF(COUNT('Turns'!F69)=1,SUM('Turns'!F69),"Unknown") -> 1.12e-05 | M20: =IF(COUNT('Turns'!D68)=1,SUM('Turns'!D68),"Unknown") -> 661 | N20: =IF(COUNT('Turns'!E68)=1,SUM('Turns'!E68),"Unknown") -> 1.1630163e-05 | O20: =IF(COUNT('Turns'!F68)=1,SUM('Turns'!F68),"Unknown") -> 1.322e-05 | P20: 0 | Q20: 0 | R20: 0 | S20: =IF(COUNT('Turns'!D76)=1,SUM('Turns'!D76),"Unknown") -> 61 | T20: =IF(COUNT('Turns'!E76)=1,SUM('Turns'!E76),"Unknown") -> 6.4396968e-05 | U20: =IF(COUNT('Turns'!F76)=1,SUM('Turns'!F76),"Unknown") -> 7.32e-05 | V20: =IF(COUNT('Turns'!D74)=1,SUM('Turns'!D74),"Unknown") -> 600 | W20: =IF(COUNT('Turns'!E74)=1,SUM('Turns'!E74),"Unknown") -> 0.0006334128 | X20: =IF(COUNT('Turns'!F74)=1,SUM('Turns'!F74),"Unknown") -> 0.00072 | Y20: =IF(COUNT('Turns'!E80)=1,SUM('Turns'!E80),"Unknown") -> 0.00071929302 | Z20: =IF(COUNT('Turns'!F80)=1,SUM('Turns'!F80),"Unknown") -> 0.00081762 | AA20: =IF(ISNUMBER(Y20),ROUND(Y20*'Reference data'!$B$2,0),"Unknown") -> 72 | AB20: =IF(ISNUMBER(Z20),ROUND(Z20*'Reference data'!$B$2,0),"Unknown") -> 82 | AC20: R5 | AD20: 2.59 | AE20: Own call
A21: tools | B21: 1 | C21: workflow | E21: ok | G21: Execute tool calls requested by the preceding model response and return their observations. | H21: 01a1143f-7050-7833-8614-faff8b3a8045 | I21: 01a1143f-6fb3-7ca0-8d46-937eae9c46c0 | AD21: 1.589 | AE21: No model charge
A22: test_plan | B22: 2 | C22: tool | E22: ok | G22: Return a fixed fictional plan-check result; no real test is executed. | H22: 01a1143f-7051-75b2-969f-16aa797fe63a | I22: 01a1143f-7050-7833-8614-faff8b3a8045 | AD22: 0.561 | AE22: No model charge
A23: model | B23: 1 | C23: workflow | E23: ok | G23: Prepare the current conversation, run model middleware, and invoke the chat model. | H23: 01a1143f-7053-7d91-83b6-86b453c33df4 | I23: 01a1143f-6fb3-7ca0-8d46-937eae9c46c0 | J23: =IF(COUNT('Turns'!D86)=1,SUM('Turns'!D86),"Unknown") -> 42 | K23: =IF(COUNT('Turns'!E86)=1,SUM('Turns'!E86),"Unknown") -> 7.389816e-06 | L23: =IF(COUNT('Turns'!F86)=1,SUM('Turns'!F86),"Unknown") -> 8.4e-06 | M23: =IF(COUNT('Turns'!D85)=1,SUM('Turns'!D85),"Unknown") -> 778 | N23: =IF(COUNT('Turns'!E85)=1,SUM('Turns'!E85),"Unknown") -> 1.3688754e-05 | O23: =IF(COUNT('Turns'!F85)=1,SUM('Turns'!F85),"Unknown") -> 1.556e-05 | P23: 0 | Q23: 0 | R23: 0 | S23: =IF(COUNT('Turns'!D93)=1,SUM('Turns'!D93),"Unknown") -> 60 | T23: =IF(COUNT('Turns'!E93)=1,SUM('Turns'!E93),"Unknown") -> 6.334128e-05 | U23: =IF(COUNT('Turns'!F93)=1,SUM('Turns'!F93),"Unknown") -> 7.2e-05 | V23: =IF(COUNT('Turns'!D91)=1,SUM('Turns'!D91),"Unknown") -> 600 | W23: =IF(COUNT('Turns'!E91)=1,SUM('Turns'!E91),"Unknown") -> 0.0006334128 | X23: =IF(COUNT('Turns'!F91)=1,SUM('Turns'!F91),"Unknown") -> 0.00072 | Y23: =IF(COUNT('Turns'!E97)=1,SUM('Turns'!E97),"Unknown") -> 0.00071783265 | Z23: =IF(COUNT('Turns'!F97)=1,SUM('Turns'!F97),"Unknown") -> 0.00081596 | AA23: =IF(ISNUMBER(Y23),ROUND(Y23*'Reference data'!$B$2,0),"Unknown") -> 72 | AB23: =IF(ISNUMBER(Z23),ROUND(Z23*'Reference data'!$B$2,0),"Unknown") -> 82 | AD23: 3.514 | AE23: Subtree total
A24: SimulatedModel | B24: 2 | C24: model | D24: scripted-chat | E24: ok | F24: 820 | G24: Investigate evidence and test a hypothesis. | H24: 01a1143f-7053-7d91-83b6-86c8b626333d | I24: 01a1143f-7053-7d91-83b6-86b453c33df4 | J24: =IF(COUNT('Turns'!D86)=1,SUM('Turns'!D86),"Unknown") -> 42 | K24: =IF(COUNT('Turns'!E86)=1,SUM('Turns'!E86),"Unknown") -> 7.389816e-06 | L24: =IF(COUNT('Turns'!F86)=1,SUM('Turns'!F86),"Unknown") -> 8.4e-06 | M24: =IF(COUNT('Turns'!D85)=1,SUM('Turns'!D85),"Unknown") -> 778 | N24: =IF(COUNT('Turns'!E85)=1,SUM('Turns'!E85),"Unknown") -> 1.3688754e-05 | O24: =IF(COUNT('Turns'!F85)=1,SUM('Turns'!F85),"Unknown") -> 1.556e-05 | P24: 0 | Q24: 0 | R24: 0 | S24: =IF(COUNT('Turns'!D93)=1,SUM('Turns'!D93),"Unknown") -> 60 | T24: =IF(COUNT('Turns'!E93)=1,SUM('Turns'!E93),"Unknown") -> 6.334128e-05 | U24: =IF(COUNT('Turns'!F93)=1,SUM('Turns'!F93),"Unknown") -> 7.2e-05 | V24: =IF(COUNT('Turns'!D91)=1,SUM('Turns'!D91),"Unknown") -> 600 | W24: =IF(COUNT('Turns'!E91)=1,SUM('Turns'!E91),"Unknown") -> 0.0006334128 | X24: =IF(COUNT('Turns'!F91)=1,SUM('Turns'!F91),"Unknown") -> 0.00072 | Y24: =IF(COUNT('Turns'!E97)=1,SUM('Turns'!E97),"Unknown") -> 0.00071783265 | Z24: =IF(COUNT('Turns'!F97)=1,SUM('Turns'!F97),"Unknown") -> 0.00081596 | AA24: =IF(ISNUMBER(Y24),ROUND(Y24*'Reference data'!$B$2,0),"Unknown") -> 72 | AB24: =IF(ISNUMBER(Z24),ROUND(Z24*'Reference data'!$B$2,0),"Unknown") -> 82 | AC24: R6 | AD24: 2.592 | AE24: Own call
A25: tools | B25: 1 | C25: workflow | E25: ok | G25: Execute tool calls requested by the preceding model response and return their observations. | H25: 01a1143f-7057-7130-a82e-f8a21b6b344f | I25: 01a1143f-6fb3-7ca0-8d46-937eae9c46c0 | AD25: 1.177 | AE25: No model charge
A26: test_plan | B26: 2 | C26: tool | E26: ok | G26: Return a fixed fictional plan-check result; no real test is executed. | H26: 01a1143f-7057-7130-a82e-f8bc772ed094 | I26: 01a1143f-7057-7130-a82e-f8a21b6b344f | AD26: 0.375 | AE26: No model charge
A27: model | B27: 1 | C27: workflow | E27: ok | G27: Prepare the current conversation, run model middleware, and invoke the chat model. | H27: 01a1143f-7059-7c80-a9da-c937acaf0d5c | I27: 01a1143f-6fb3-7ca0-8d46-937eae9c46c0 | J27: =IF(COUNT('Turns'!D103)=1,SUM('Turns'!D103),"Unknown") -> 40 | K27: =IF(COUNT('Turns'!E103)=1,SUM('Turns'!E103),"Unknown") -> 7.03792e-06 | L27: =IF(COUNT('Turns'!F103)=1,SUM('Turns'!F103),"Unknown") -> 8e-06 | M27: =IF(COUNT('Turns'!D102)=1,SUM('Turns'!D102),"Unknown") -> 880 | N27: =IF(COUNT('Turns'!E102)=1,SUM('Turns'!E102),"Unknown") -> 1.5483424e-05 | O27: =IF(COUNT('Turns'!F102)=1,SUM('Turns'!F102),"Unknown") -> 1.76e-05 | P27: 0 | Q27: 0 | R27: 0 | S27: =IF(COUNT('Turns'!D110)=1,SUM('Turns'!D110),"Unknown") -> 71 | T27: =IF(COUNT('Turns'!E110)=1,SUM('Turns'!E110),"Unknown") -> 7.4953848e-05 | U27: =IF(COUNT('Turns'!F110)=1,SUM('Turns'!F110),"Unknown") -> 8.52e-05 | V27: =IF(COUNT('Turns'!D108)=1,SUM('Turns'!D108),"Unknown") -> 1800 | W27: =IF(COUNT('Turns'!E108)=1,SUM('Turns'!E108),"Unknown") -> 0.0019002384 | X27: =IF(COUNT('Turns'!F108)=1,SUM('Turns'!F108),"Unknown") -> 0.00216 | Y27: =IF(COUNT('Turns'!E114)=1,SUM('Turns'!E114),"Unknown") -> 0.0019977136 | Z27: =IF(COUNT('Turns'!F114)=1,SUM('Turns'!F114),"Unknown") -> 0.0022708 | AA27: =IF(ISNUMBER(Y27),ROUND(Y27*'Reference data'!$B$2,0),"Unknown") -> 200 | AB27: =IF(ISNUMBER(Z27),ROUND(Z27*'Reference data'!$B$2,0),"Unknown") -> 227 | AD27: 2.19 | AE27: Subtree total
A28: SimulatedModel | B28: 2 | C28: model | D28: scripted-chat | E28: ok | F28: 920 | G28: Investigate evidence and test a hypothesis. | H28: 01a1143f-7059-7c80-a9da-c943371274eb | I28: 01a1143f-7059-7c80-a9da-c937acaf0d5c | J28: =IF(COUNT('Turns'!D103)=1,SUM('Turns'!D103),"Unknown") -> 40 | K28: =IF(COUNT('Turns'!E103)=1,SUM('Turns'!E103),"Unknown") -> 7.03792e-06 | L28: =IF(COUNT('Turns'!F103)=1,SUM('Turns'!F103),"Unknown") -> 8e-06 | M28: =IF(COUNT('Turns'!D102)=1,SUM('Turns'!D102),"Unknown") -> 880 | N28: =IF(COUNT('Turns'!E102)=1,SUM('Turns'!E102),"Unknown") -> 1.5483424e-05 | O28: =IF(COUNT('Turns'!F102)=1,SUM('Turns'!F102),"Unknown") -> 1.76e-05 | P28: 0 | Q28: 0 | R28: 0 | S28: =IF(COUNT('Turns'!D110)=1,SUM('Turns'!D110),"Unknown") -> 71 | T28: =IF(COUNT('Turns'!E110)=1,SUM('Turns'!E110),"Unknown") -> 7.4953848e-05 | U28: =IF(COUNT('Turns'!F110)=1,SUM('Turns'!F110),"Unknown") -> 8.52e-05 | V28: =IF(COUNT('Turns'!D108)=1,SUM('Turns'!D108),"Unknown") -> 1800 | W28: =IF(COUNT('Turns'!E108)=1,SUM('Turns'!E108),"Unknown") -> 0.0019002384 | X28: =IF(COUNT('Turns'!F108)=1,SUM('Turns'!F108),"Unknown") -> 0.00216 | Y28: =IF(COUNT('Turns'!E114)=1,SUM('Turns'!E114),"Unknown") -> 0.0019977136 | Z28: =IF(COUNT('Turns'!F114)=1,SUM('Turns'!F114),"Unknown") -> 0.0022708 | AA28: =IF(ISNUMBER(Y28),ROUND(Y28*'Reference data'!$B$2,0),"Unknown") -> 200 | AB28: =IF(ISNUMBER(Z28),ROUND(Z28*'Reference data'!$B$2,0),"Unknown") -> 227 | AC28: R7 | AD28: 1.437 | AE28: Own call

Sheet Reference data
A1: Parameter | B1: Value | C1: Unit
A2: Number of executions | B2: 100000 | C2: executions
A3: USD → EUR | B3: 0.87974 | C3: EUR per USD
A4: Cache duration | B4: 5m
A5: Run ID | B5: 01a1143f-6fb3-7ca0-8d46-937eae9c46c0
A6: Recording | B6: Offline simulation
A7: FX reference date | B7: 2026-09-24
A8: FX fetched at | B8: 2026-09-24T22:21:31.719587Z | C8: UTC
A9: FX source | B9: https://api.frankfurter.dev/v2/rate/usd/eur?providers=ecb
A10: Rounding | B10: Only projected costs: ROUND(cost × executions, 0)
A11: Tree totals | B11: Parent rows include descendants; do not sum all tree rows.
A12: Cache writes | B12: Simulated context movement is not a provider-billed write.
A13: Pricing scope | B13: Published online token rates verified 2026-10-05. Copilot uses GitHub rates, including saved long-context tiers, before plan allowances; these are usage estimates, not subscription invoices. Cache writes with unspecified lifetime use the 5-minute rate unless an explicit cache_write rate is configured. Direct OpenAI and Anthropic entries use standard rates; no batch, regional, tool, negotiated, or unrecorded context-tier adjustments are applied. Model availability and context capacity require separate verification.
A15: Model | B15: Input USD / 1M tokens | C15: Cache read USD / 1M tokens | D15: Cache write USD / 1M tokens | E15: Output USD / 1M tokens | F15: Reasoning USD / 1M tokens | G15: Verified date | H15: Source | I15: Notes
A16: openai:gpt-5.5 | B16: 5 | C16: 0.5 | D16: Unknown | E16: 30 | F16: 30 | G16: 2026-10-05 | H16: https://developers.openai.com/api/docs/models/gpt-5.5.md | I16: Cache write assumes 5m when unspecified
A17: openai:gpt-5.6-luna | B17: 0.2 | C17: 0.02 | D17: 0.25 | E17: 1.2 | F17: 1.2 | G17: 2026-10-05 | H17: https://developers.openai.com/api/docs/models/gpt-5.6-luna.md | I17: Cache write assumes 5m when unspecified
A18: openai:gpt-5.6-sol | B18: 4 | C18: 0.4 | D18: 5 | E18: 20 | F18: 20 | G18: 2026-10-05 | H18: https://developers.openai.com/api/docs/models/gpt-5.6-sol.md | I18: Cache write assumes 5m when unspecified
A19: anthropic:claude-sonnet-5 | B19: 2 | C19: 0.2 | D19: 2.5 | E19: 10 | F19: 10 | G19: 2026-10-05 | H19: https://platform.claude.com/docs/en/about-claude/pricing | I19: Cache write assumes 5m when unspecified
A20: anthropic:claude-opus-4-8 | B20: 5 | C20: 0.5 | D20: 6.25 | E20: 25 | F20: 25 | G20: 2026-10-05 | H20: https://platform.claude.com/docs/en/about-claude/pricing | I20: Cache write assumes 5m when unspecified
A21: anthropic:claude-fable-5-1 | B21: 10 | C21: 0.25 | D21: 12.5 | E21: 50 | F21: 50 | G21: 2026-10-05 | H21: https://platform.claude.com/docs/en/about-claude/pricing | I21: Cache write assumes 5m when unspecified
A22: demo:scripted-chat | B22: 0.2 | C22: 0.02 | D22: 0.25 | E22: 1.2 | F22: 1.2 | G22: 2026-10-05 | H22: Illustrative demo rates based on openai:gpt-5.6-luna; no provider billing | I22: Cache write assumes 5m when unspecified
A23: anthropic:claude-haiku-4-5 | B23: 1 | C23: 0.1 | D23: 1.25 | E23: 5 | F23: 5 | G23: 2026-10-05 | H23: https://platform.claude.com/docs/en/about-claude/pricing | I23: Cache write assumes 5m when unspecified
A24: anthropic:claude-haiku-4-5-20251001 | B24: 1 | C24: 0.1 | D24: 1.25 | E24: 5 | F24: 5 | G24: 2026-10-05 | H24: https://platform.claude.com/docs/en/about-claude/pricing | I24: Cache write assumes 5m when unspecified
A25: anthropic:claude-opus-5-5 | B25: 4 | C25: 0.2 | D25: 5 | E25: 20 | F25: 20 | G25: 2026-10-05 | H25: https://platform.claude.com/docs/en/about-claude/pricing | I25: Cache write assumes 5m when unspecified
A26: anthropic:claude-sonnet-4-6 | B26: 3 | C26: 0.3 | D26: 3.75 | E26: 15 | F26: 15 | G26: 2026-10-05 | H26: https://platform.claude.com/docs/en/about-claude/pricing | I26: Cache write assumes 5m when unspecified
A27: anthropic:claude-sonnet-5-5 | B27: 2 | C27: 0.2 | D27: 2.5 | E27: 10 | F27: 10 | G27: 2026-10-05 | H27: https://platform.claude.com/docs/en/about-claude/pricing | I27: Cache write assumes 5m when unspecified
A28: copilot:claude-haiku-4.5 | B28: 1 | C28: 0.1 | D28: 1.25 | E28: 5 | F28: 5 | G28: 2026-10-05 | H28: https://docs.github.com/en/copilot/reference/copilot-billing/models-and-pricing | I28: Cache write assumes 5m when unspecified
... A31: copilot:claude-sonnet-5.5 | B31: 2 | C31: 0.2 | D31: 2.5 | E31: 10 | F31: 10 | G31: 2026-10-05 | H31: https://docs.github.com/en/copilot/reference/copilot-billing/models-and-pricing | I31: Cache write assumes 5m when unspecified
A32: copilot:gemini-3.8-flash | B32: 0.75 | C32: 0.075 | D32: Unknown | E32: 3.75 | F32: 3.75 | G32: 2026-10-05 | H32: https://docs.github.com/en/copilot/reference/copilot-billing/models-and-pricing | I32: Cache write assumes 5m when unspecified
A33: copilot:gpt-5.3-codex | B33: 1.75 | C33: 0.175 | D33: Unknown | E33: 14 | F33: 14 | G33: 2026-10-05 | H33: https://docs.github.com/en/copilot/reference/copilot-billing/models-and-pricing | I33: Cache write assumes 5m when unspecified
A34: copilot:gpt-5.4 | B34: 2.5 | C34: 0.25 | D34: Unknown | E34: 15 | F34: 15 | G34: 2026-10-05 | H34: https://docs.github.com/en/copilot/reference/copilot-billing/models-and-pricing | I34: Cache write assumes 5m when unspecified
A35: copilot:gpt-6-astra | B35: 10 | C35: 1 | D35: 12.5 | E35: 50 | F35: 50 | G35: 2026-10-05 | H35: https://docs.github.com/en/copilot/reference/copilot-billing/models-and-pricing | I35: Cache write assumes 5m when unspecified
A36: copilot:gpt-6-luna | B36: 0.1 | C36: 0.01 | D36: 0.125 | E36: 0.5 | F36: 0.5 | G36: 2026-10-05 | H36: https://docs.github.com/en/copilot/reference/copilot-billing/models-and-pricing | I36: Cache write assumes 5m when unspecified
A37: copilot:gpt-6-sol | B37: 2 | C37: 0.2 | D37: 2.5 | E37: 10 | F37: 10 | G37: 2026-10-05 | H37: https://docs.github.com/en/copilot/reference/copilot-billing/models-and-pricing | I37: Cache write assumes 5m when unspecified
A38: copilot:gpt-6.1-sol | B38: 2 | C38: 0.1 | D38: 2.5 | E38: 10 | F38: 10 | G38: 2026-10-05 | H38: https://docs.github.com/en/copilot/reference/copilot-billing/models-and-pricing | I38: Cache write assumes 5m when unspecified
A39: openai:gpt-6-astra | B39: 10 | C39: 1 | D39: 12.5 | E39: 50 | F39: 50 | G39: 2026-10-05 | H39: https://developers.openai.com/api/docs/models/gpt-6-astra.md | I39: Cache write assumes 5m when unspecified
A40: openai:gpt-6-luna | B40: 0.1 | C40: 0.01 | D40: 0.125 | E40: 0.5 | F40: 0.5 | G40: 2026-10-05 | H40: https://developers.openai.com/api/docs/models/gpt-6-luna.md | I40: Cache write assumes 5m when unspecified
A41: openai:gpt-6-sol | B41: 2 | C41: 0.2 | D41: 2.5 | E41: 10 | F41: 10 | G41: 2026-10-05 | H41: https://developers.openai.com/api/docs/models/gpt-6-sol.md | I41: Cache write assumes 5m when unspecified
A42: openai:gpt-6.1-sol | B42: 2 | C42: 0.1 | D42: 2.5 | E42: 10 | F42: 10 | G42: 2026-10-05 | H42: https://developers.openai.com/api/docs/models/gpt-6.1-sol.md | I42: Cache write assumes 5m when unspecified
A43: copilot:gpt-5.4 [long context] | B43: 5 | C43: 0.5 | D43: Unknown | E43: 22.5 | F43: 22.5 | G43: 2026-10-05 | H43: https://docs.github.com/en/copilot/reference/copilot-billing/models-and-pricing | I43: Above 272,000 input tokens
...
