Workbook

Sheet Turns
A1: Request | B1: Turn | C1: Sequence | D1: Tokens | E1: EUR / execution | F1: USD / execution | G1: Projected EUR | H1: Projected USD | I1: Content | J1: Model · effort | K1: Status | L1: Context total tokens | M1: Span ID
C2: Run total | E2: =IF(COUNT('Turns'!E16,'Turns'!E31,'Turns'!E46,'Turns'!E58)=4,SUM('Turns'!E16,'Turns'!E31,'Turns'!E46,'Turns'!E58),"Unknown") -> 0.00038620586 | F2: =IF(COUNT('Turns'!F16,'Turns'!F31,'Turns'!F46,'Turns'!F58)=4,SUM('Turns'!F16,'Turns'!F31,'Turns'!F46,'Turns'!F58),"Unknown") -> 0.000439 | G2: =IF(ISNUMBER(E2),ROUND(E2*'Reference data'!$B$2,0),"Unknown") -> 39 | H2: =IF(ISNUMBER(F2),ROUND(F2*'Reference data'!$B$2,0),"Unknown") -> 44
B3: 1 | C3: Turn 1 | E3: =IF(COUNT('Turns'!E16,'Turns'!E31,'Turns'!E46,'Turns'!E58)=4,SUM('Turns'!E16,'Turns'!E31,'Turns'!E46,'Turns'!E58),"Unknown") -> 0.00038620586 | F3: =IF(COUNT('Turns'!F16,'Turns'!F31,'Turns'!F46,'Turns'!F58)=4,SUM('Turns'!F16,'Turns'!F31,'Turns'!F46,'Turns'!F58),"Unknown") -> 0.000439 | G3: =IF(ISNUMBER(E3),ROUND(E3*'Reference data'!$B$2,0),"Unknown") -> 39 | H3: =IF(ISNUMBER(F3),ROUND(F3*'Reference data'!$B$2,0),"Unknown") -> 44
A4: R1 | B4: 1 | C4: LLM request | D4: 468 | J4: scripted-chat | M4: 01a1143f-8321-79b2-85c0-d160373e18e6
A5: R1 | B5: 1 | C5: Input at standard rate | D5: 468 | E5: =IF(AND(ISNUMBER(F5),ISNUMBER('Reference data'!$B$3)),F5*'Reference data'!$B$3,"Unknown") -> 8.2343664e-05 | F5: =IF(D5=0,0,IF(ISNUMBER('Reference data'!B22),D5*'Reference data'!B22/1000000,"Unknown")) -> 9.36e-05 | G5: =IF(ISNUMBER(E5),ROUND(E5*'Reference data'!$B$2,0),"Unknown") -> 8 | H5: =IF(ISNUMBER(F5),ROUND(F5*'Reference data'!$B$2,0),"Unknown") -> 9
A6: R1 | B6: 1 | C6: Tool definitions | D6: 360
A7: R1 | B7: 1 | C7: System prompt | D7: 68 | I7: Delegate echoing the supplied text to isolated-subagent using task. Provide a self-contained assignment. After its summary returns, answer the user concisely. The specialist uses an echo tool, which supplies no independent factual evidence.
A8: R1 | B8: 1 | C8: User prompt | D8: 40 | I8: Have the specialist echo ReAct and explain how its tool result returns to the parent.
A9: R1 | B9: 1 | C9: Cache write | D9: 468
A10: R1 | B10: 1 | C10: Context · added / total | D10: 468 | L10: 468
A11: R1 | B11: 1 | C11: LLM response | D11: 75
A12: R1 | B12: 1 | C12: Output | D12: 75 | E12: =IF(AND(ISNUMBER(F12),ISNUMBER('Reference data'!$B$3)),F12*'Reference data'!$B$3,"Unknown") -> 7.91766e-05 | F12: =IF(D12=0,0,IF(ISNUMBER('Reference data'!E22),D12*'Reference data'!E22/1000000,"Unknown")) -> 9e-05 | G12: =IF(ISNUMBER(E12),ROUND(E12*'Reference data'!$B$2,0),"Unknown") -> 8 | H12: =IF(ISNUMBER(F12),ROUND(F12*'Reference data'!$B$2,0),"Unknown") -> 9
A13: R1 | B13: 1 | C13: Output content | I13: {"name": "task", "args": {"subagent_type": "isolated-subagent", "description": "Call echo_tool with the text ReAct and summarize what it returned."}, "id": "delegate-1", "type": "tool_call"}
A14: R1 | B14: 1 | C14: Cache write | D14: 75
A15: R1 | B15: 1 | C15: Context · added / total | D15: 75 | L15: 543
A16: R1 | B16: 1 | C16: Call total | E16: =IF(COUNT('Turns'!E5,'Turns'!E12)=2,SUM('Turns'!E5,'Turns'!E12),"Unknown") -> 0.00016152026 | F16: =IF(COUNT('Turns'!F5,'Turns'!F12)=2,SUM('Turns'!F5,'Turns'!F12),"Unknown") -> 0.0001836 | G16: =IF(ISNUMBER(E16),ROUND(E16*'Reference data'!$B$2,0),"Unknown") -> 16 | H16: =IF(ISNUMBER(F16),ROUND(F16*'Reference data'!$B$2,0),"Unknown") -> 18 | K16: ok
B17: 1 | C17: Tool · task | K17: ok | M17: 01a1143f-83a1-7520-8dc2-d4d6a652d02d
B18: 1 | C18: Arguments | I18: {'subagent_type': 'isolated-subagent', 'description': 'Call echo_tool with the text ReAct and summarize what it returned.'}
B19: 1 | C19: Result | I19: Command(update={'messages': [ToolMessage(content='The echo tool returned Your input was: ReAct. It repeated the supplied text without adding factual evidence.', tool_call_id='delegate-1')]})
A20: R2 | B20: 1 | C20: LLM request | D20: 180 | J20: scripted-chat | M20: 01a1143f-83a3-7d82-b3d1-8b1bb7bad08e
A21: R2 | B21: 1 | C21: Input at standard rate | D21: 180 | E21: =IF(AND(ISNUMBER(F21),ISNUMBER('Reference data'!$B$3)),F21*'Reference data'!$B$3,"Unknown") -> 3.167064e-05 | F21: =IF(D21=0,0,IF(ISNUMBER('Reference data'!B22),D21*'Reference data'!B22/1000000,"Unknown")) -> 3.6e-05 | G21: =IF(ISNUMBER(E21),ROUND(E21*'Reference data'!$B$2,0),"Unknown") -> 3 | H21: =IF(ISNUMBER(F21),ROUND(F21*'Reference data'!$B$2,0),"Unknown") -> 4
A22: R2 | B22: 1 | C22: Tool definitions | D22: 79
A23: R2 | B23: 1 | C23: System prompt | D23: 64 | I23: You are a workflow teaching specialist. Call echo_tool with the assigned text, then summarize the returned echo for the parent. The echo repeats supplied input and provides no independent factual evidence. Do not delegate further.
A24: R2 | B24: 1 | C24: Cache write | D24: 180
A25: R2 | B25: 1 | C25: Context · added / total | D25: 180 | L25: 180
A26: R2 | B26: 1 | C26: LLM response | D26: 57
A27: R2 | B27: 1 | C27: Output | D27: 57 | E27: =IF(AND(ISNUMBER(F27),ISNUMBER('Reference data'!$B$3)),F27*'Reference data'!$B$3,"Unknown") -> 6.0174216e-05 | F27: =IF(D27=0,0,IF(ISNUMBER('Reference data'!E22),D27*'Reference data'!E22/1000000,"Unknown")) -> 6.84e-05 | G27: =IF(ISNUMBER(E27),ROUND(E27*'Reference data'!$B$2,0),"Unknown") -> 6 | H27: =IF(ISNUMBER(F27),ROUND(F27*'Reference data'!$B$2,0),"Unknown") -> 7
A28: R2 | B28: 1 | C28: Output content | I28: {"name": "echo_tool", "args": {"text": "ReAct"}, "id": "specialist-lookup-1", "type": "tool_call"}
A29: R2 | B29: 1 | C29: Cache write | D29: 57
A30: R2 | B30: 1 | C30: Context · added / total | D30: 57 | L30: 237
A31: R2 | B31: 1 | C31: Call total | E31: =IF(COUNT('Turns'!E21,'Turns'!E27)=2,SUM('Turns'!E21,'Turns'!E27),"Unknown") -> 9.1844856e-05 | F31: =IF(COUNT('Turns'!F21,'Turns'!F27)=2,SUM('Turns'!F21,'Turns'!F27),"Unknown") -> 0.0001044 | G31: =IF(ISNUMBER(E31),ROUND(E31*'Reference data'!$B$2,0),"Unknown") -> 9 | H31: =IF(ISNUMBER(F31),ROUND(F31*'Reference data'!$B$2,0),"Unknown") -> 10 | K31: ok
B32: 1 | C32: Tool · echo_tool | K32: ok | M32: 01a1143f-83a7-7720-bac4-bde63a0cdabd
B33: 1 | C33: Arguments | I33: {'text': 'ReAct'}
B34: 1 | C34: Result | I34: Your input was: ReAct
A35: R3 | B35: 1 | C35: LLM request | D35: 273 | J35: scripted-chat | M35: 01a1143f-83a8-7422-b1b7-e3e23ebcb479
A36: R3 | B36: 1 | C36: Conversation history · cache read | D36: 237 | E36: =IF(AND(ISNUMBER(F36),ISNUMBER('Reference data'!$B$3)),F36*'Reference data'!$B$3,"Unknown") -> 4.1699676e-06 | F36: =IF(D36=0,0,IF(ISNUMBER('Reference data'!C22),D36*'Reference data'!C22/1000000,"Unknown")) -> 4.74e-06 | G36: =IF(ISNUMBER(E36),ROUND(E36*'Reference data'!$B$2,0),"Unknown") -> 0 | H36: =IF(ISNUMBER(F36),ROUND(F36*'Reference data'!$B$2,0),"Unknown") -> 0
A37: R3 | B37: 1 | C37: Input at standard rate | D37: 36 | E37: =IF(AND(ISNUMBER(F37),ISNUMBER('Reference data'!$B$3)),F37*'Reference data'!$B$3,"Unknown") -> 6.334128e-06 | F37: =IF(D37=0,0,IF(ISNUMBER('Reference data'!B22),D37*'Reference data'!B22/1000000,"Unknown")) -> 7.2e-06 | G37: =IF(ISNUMBER(E37),ROUND(E37*'Reference data'!$B$2,0),"Unknown") -> 1 | H37: =IF(ISNUMBER(F37),ROUND(F37*'Reference data'!$B$2,0),"Unknown") -> 1
A38: R3 | B38: 1 | C38: Tool result | D38: 36 | I38: Your input was: ReAct
A39: R3 | B39: 1 | C39: Cache write | D39: 36
A40: R3 | B40: 1 | C40: Context · added / total | D40: 36 | L40: 273
...

Sheet Execution tree
A1: Operation | B1: Depth | C1: Type | D1: Model · effort | E1: Status | F1: Input context tokens | G1: Description | H1: Span ID | I1: Parent ID | J1: Input at standard rate tokens | K1: Input at standard rate EUR | L1: Input at standard rate USD | M1: Cache read tokens | N1: Cache read EUR | O1: Cache read USD | P1: Cache write tokens | Q1: Cache write EUR | R1: Cache write USD | S1: Output (non-reasoning) tokens | T1: Output (non-reasoning) EUR | U1: Output (non-reasoning) USD | V1: Reasoning tokens | W1: Reasoning EUR | X1: Reasoning USD | Y1: Total EUR | Z1: Total USD | AA1: Projected EUR | AB1: Projected USD | AC1: Request | AD1: Elapsed ms | AE1: Accounting
A2: delegating_parent | B2: 0 | C2: workflow | E2: ok | G2: Execute the delegating_parent workflow operation and pass its result to the next graph step. | H2: 01a1143f-831e-7141-818a-14f77faabd17 | J2: =IF(COUNT('Turns'!D5,'Turns'!D21,'Turns'!D37,'Turns'!D49)=4,SUM('Turns'!D5,'Turns'!D21,'Turns'!D37,'Turns'!D49),"Unknown") -> 731 | K2: =IF(COUNT('Turns'!E5,'Turns'!E21,'Turns'!E37,'Turns'!E49)=4,SUM('Turns'!E5,'Turns'!E21,'Turns'!E37,'Turns'!E49),"Unknown") -> 0.00012861799 | L2: =IF(COUNT('Turns'!F5,'Turns'!F21,'Turns'!F37,'Turns'!F49)=4,SUM('Turns'!F5,'Turns'!F21,'Turns'!F37,'Turns'!F49),"Unknown") -> 0.0001462 | M2: =IF(COUNT('Turns'!D36,'Turns'!D48)=2,SUM('Turns'!D36,'Turns'!D48),"Unknown") -> 780 | N2: =IF(COUNT('Turns'!E36,'Turns'!E48)=2,SUM('Turns'!E36,'Turns'!E48),"Unknown") -> 1.3723944e-05 | O2: =IF(COUNT('Turns'!F36,'Turns'!F48)=2,SUM('Turns'!F36,'Turns'!F48),"Unknown") -> 1.56e-05 | P2: 0 | Q2: 0 | R2: 0 | S2: =IF(COUNT('Turns'!D12,'Turns'!D27,'Turns'!D42,'Turns'!D54)=4,SUM('Turns'!D12,'Turns'!D27,'Turns'!D42,'Turns'!D54),"Unknown") -> 231 | T2: =IF(COUNT('Turns'!E12,'Turns'!E27,'Turns'!E42,'Turns'!E54)=4,SUM('Turns'!E12,'Turns'!E27,'Turns'!E42,'Turns'!E54),"Unknown") -> 0.00024386393 | U2: =IF(COUNT('Turns'!F12,'Turns'!F27,'Turns'!F42,'Turns'!F54)=4,SUM('Turns'!F12,'Turns'!F27,'Turns'!F42,'Turns'!F54),"Unknown") -> 0.0002772 | V2: 0 | W2: 0 | X2: 0 | Y2: =IF(COUNT('Turns'!E16,'Turns'!E31,'Turns'!E46,'Turns'!E58)=4,SUM('Turns'!E16,'Turns'!E31,'Turns'!E46,'Turns'!E58),"Unknown") -> 0.00038620586 | Z2: =IF(COUNT('Turns'!F16,'Turns'!F31,'Turns'!F46,'Turns'!F58)=4,SUM('Turns'!F16,'Turns'!F31,'Turns'!F46,'Turns'!F58),"Unknown") -> 0.000439 | AA2: =IF(ISNUMBER(Y2),ROUND(Y2*'Reference data'!$B$2,0),"Unknown") -> 39 | AB2: =IF(ISNUMBER(Z2),ROUND(Z2*'Reference data'!$B$2,0),"Unknown") -> 44 | AD2: 143.492 | AE2: Subtree total
A3: model | B3: 1 | C3: workflow | E3: ok | G3: Prepare the current conversation, run model middleware, and invoke the chat model. | H3: 01a1143f-8320-7372-b5ea-fdac72f8bdfa | I3: 01a1143f-831e-7141-818a-14f77faabd17 | J3: =IF(COUNT('Turns'!D5)=1,SUM('Turns'!D5),"Unknown") -> 468 | K3: =IF(COUNT('Turns'!E5)=1,SUM('Turns'!E5),"Unknown") -> 8.2343664e-05 | L3: =IF(COUNT('Turns'!F5)=1,SUM('Turns'!F5),"Unknown") -> 9.36e-05 | M3: 0 | N3: 0 | O3: 0 | P3: 0 | Q3: 0 | R3: 0 | S3: =IF(COUNT('Turns'!D12)=1,SUM('Turns'!D12),"Unknown") -> 75 | T3: =IF(COUNT('Turns'!E12)=1,SUM('Turns'!E12),"Unknown") -> 7.91766e-05 | U3: =IF(COUNT('Turns'!F12)=1,SUM('Turns'!F12),"Unknown") -> 9e-05 | V3: 0 | W3: 0 | X3: 0 | Y3: =IF(COUNT('Turns'!E16)=1,SUM('Turns'!E16),"Unknown") -> 0.00016152026 | Z3: =IF(COUNT('Turns'!F16)=1,SUM('Turns'!F16),"Unknown") -> 0.0001836 | AA3: =IF(ISNUMBER(Y3),ROUND(Y3*'Reference data'!$B$2,0),"Unknown") -> 16 | AB3: =IF(ISNUMBER(Z3),ROUND(Z3*'Reference data'!$B$2,0),"Unknown") -> 18 | AD3: 127.488 | AE3: Subtree total
A4: SimulatedModel | B4: 2 | C4: model | D4: scripted-chat | E4: ok | F4: 468 | G4: A parent agent delegates to a specialist. | H4: 01a1143f-8321-79b2-85c0-d160373e18e6 | I4: 01a1143f-8320-7372-b5ea-fdac72f8bdfa | J4: =IF(COUNT('Turns'!D5)=1,SUM('Turns'!D5),"Unknown") -> 468 | K4: =IF(COUNT('Turns'!E5)=1,SUM('Turns'!E5),"Unknown") -> 8.2343664e-05 | L4: =IF(COUNT('Turns'!F5)=1,SUM('Turns'!F5),"Unknown") -> 9.36e-05 | M4: 0 | N4: 0 | O4: 0 | P4: 0 | Q4: 0 | R4: 0 | S4: =IF(COUNT('Turns'!D12)=1,SUM('Turns'!D12),"Unknown") -> 75 | T4: =IF(COUNT('Turns'!E12)=1,SUM('Turns'!E12),"Unknown") -> 7.91766e-05 | U4: =IF(COUNT('Turns'!F12)=1,SUM('Turns'!F12),"Unknown") -> 9e-05 | V4: 0 | W4: 0 | X4: 0 | Y4: =IF(COUNT('Turns'!E16)=1,SUM('Turns'!E16),"Unknown") -> 0.00016152026 | Z4: =IF(COUNT('Turns'!F16)=1,SUM('Turns'!F16),"Unknown") -> 0.0001836 | AA4: =IF(ISNUMBER(Y4),ROUND(Y4*'Reference data'!$B$2,0),"Unknown") -> 16 | AB4: =IF(ISNUMBER(Z4),ROUND(Z4*'Reference data'!$B$2,0),"Unknown") -> 18 | AC4: R1 | AD4: 125.611 | AE4: Own call
A5: tools | B5: 1 | C5: workflow | E5: ok | G5: Execute tool calls requested by the preceding model response and return their observations. | H5: 01a1143f-83a0-7292-b546-b39421c51891 | I5: 01a1143f-831e-7141-818a-14f77faabd17 | J5: =IF(COUNT('Turns'!D21,'Turns'!D37)=2,SUM('Turns'!D21,'Turns'!D37),"Unknown") -> 216 | K5: =IF(COUNT('Turns'!E21,'Turns'!E37)=2,SUM('Turns'!E21,'Turns'!E37),"Unknown") -> 3.8004768e-05 | L5: =IF(COUNT('Turns'!F21,'Turns'!F37)=2,SUM('Turns'!F21,'Turns'!F37),"Unknown") -> 4.32e-05 | M5: =IF(COUNT('Turns'!D36)=1,SUM('Turns'!D36),"Unknown") -> 237 | N5: =IF(COUNT('Turns'!E36)=1,SUM('Turns'!E36),"Unknown") -> 4.1699676e-06 | O5: =IF(COUNT('Turns'!F36)=1,SUM('Turns'!F36),"Unknown") -> 4.74e-06 | P5: 0 | Q5: 0 | R5: 0 | S5: =IF(COUNT('Turns'!D27,'Turns'!D42)=2,SUM('Turns'!D27,'Turns'!D42),"Unknown") -> 101 | T5: =IF(COUNT('Turns'!E27,'Turns'!E42)=2,SUM('Turns'!E27,'Turns'!E42),"Unknown") -> 0.00010662449 | U5: =IF(COUNT('Turns'!F27,'Turns'!F42)=2,SUM('Turns'!F27,'Turns'!F42),"Unknown") -> 0.0001212 | V5: 0 | W5: 0 | X5: 0 | Y5: =IF(COUNT('Turns'!E31,'Turns'!E46)=2,SUM('Turns'!E31,'Turns'!E46),"Unknown") -> 0.00014879922 | Z5: =IF(COUNT('Turns'!F31,'Turns'!F46)=2,SUM('Turns'!F31,'Turns'!F46),"Unknown") -> 0.00016914 | AA5: =IF(ISNUMBER(Y5),ROUND(Y5*'Reference data'!$B$2,0),"Unknown") -> 15 | AB5: =IF(ISNUMBER(Z5),ROUND(Z5*'Reference data'!$B$2,0),"Unknown") -> 17 | AD5: 10.78 | AE5: Subtree total
A6: task | B6: 2 | C6: tool | E6: ok | G6: Launch an ephemeral subagent to handle a complex, multi-step task. Available agent types and the tools they have access to: - isolated-subagent: Echoes assigned text with a local tool and summarizes its result. Specify subagent_type to select the agent. Usage notes: - Launch multiple agents concurrently when their tasks are independent, using a single message with multiple tool calls. - Each invocation is stateless by default: the agent sees only the prompt you give it and returns a single final report. Put full detail in the prompt and state exactly what it should return — unless an agent type below says it inherits your conversation instead. - The agent's report is not shown to the user; relay a summary yourself. - Tell the agent whether to create content, analyze, or only research, since it can't necessarily see the user's intent unless it inherits your conversation, as noted per agent type below. - If an agent's description says to use it proactively, do so without waiting to be asked. - When only general-purpose is available, use it for any complex, context-heavy task; it has the same capabilities as the main agent. | H6: 01a1143f-83a1-7520-8dc2-d4d6a652d02d | I6: 01a1143f-83a0-7292-b546-b39421c51891 | J6: =IF(COUNT('Turns'!D21,'Turns'!D37)=2,SUM('Turns'!D21,'Turns'!D37),"Unknown") -> 216 | K6: =IF(COUNT('Turns'!E21,'Turns'!E37)=2,SUM('Turns'!E21,'Turns'!E37),"Unknown") -> 3.8004768e-05 | L6: =IF(COUNT('Turns'!F21,'Turns'!F37)=2,SUM('Turns'!F21,'Turns'!F37),"Unknown") -> 4.32e-05 | M6: =IF(COUNT('Turns'!D36)=1,SUM('Turns'!D36),"Unknown") -> 237 | N6: =IF(COUNT('Turns'!E36)=1,SUM('Turns'!E36),"Unknown") -> 4.1699676e-06 | O6: =IF(COUNT('Turns'!F36)=1,SUM('Turns'!F36),"Unknown") -> 4.74e-06 | P6: 0 | Q6: 0 | R6: 0 | S6: =IF(COUNT('Turns'!D27,'Turns'!D42)=2,SUM('Turns'!D27,'Turns'!D42),"Unknown") -> 101 | T6: =IF(COUNT('Turns'!E27,'Turns'!E42)=2,SUM('Turns'!E27,'Turns'!E42),"Unknown") -> 0.00010662449 | U6: =IF(COUNT('Turns'!F27,'Turns'!F42)=2,SUM('Turns'!F27,'Turns'!F42),"Unknown") -> 0.0001212 | V6: 0 | W6: 0 | X6: 0 | Y6: =IF(COUNT('Turns'!E31,'Turns'!E46)=2,SUM('Turns'!E31,'Turns'!E46),"Unknown") -> 0.00014879922 | Z6: =IF(COUNT('Turns'!F31,'Turns'!F46)=2,SUM('Turns'!F31,'Turns'!F46),"Unknown") -> 0.00016914 | AA6: =IF(ISNUMBER(Y6),ROUND(Y6*'Reference data'!$B$2,0),"Unknown") -> 15 | AB6: =IF(ISNUMBER(Z6),ROUND(Z6*'Reference data'!$B$2,0),"Unknown") -> 17 | AD6: 9.879 | AE6: Subtree total
A7: isolated-subagent | B7: 3 | C7: workflow | E7: ok | G7: Execute the isolated-subagent workflow operation and pass its result to the next graph step. | H7: 01a1143f-83a1-7520-8dc2-d4e9a12dc0c4 | I7: 01a1143f-83a1-7520-8dc2-d4d6a652d02d | J7: =IF(COUNT('Turns'!D21,'Turns'!D37)=2,SUM('Turns'!D21,'Turns'!D37),"Unknown") -> 216 | K7: =IF(COUNT('Turns'!E21,'Turns'!E37)=2,SUM('Turns'!E21,'Turns'!E37),"Unknown") -> 3.8004768e-05 | L7: =IF(COUNT('Turns'!F21,'Turns'!F37)=2,SUM('Turns'!F21,'Turns'!F37),"Unknown") -> 4.32e-05 | M7: =IF(COUNT('Turns'!D36)=1,SUM('Turns'!D36),"Unknown") -> 237 | N7: =IF(COUNT('Turns'!E36)=1,SUM('Turns'!E36),"Unknown") -> 4.1699676e-06 | O7: =IF(COUNT('Turns'!F36)=1,SUM('Turns'!F36),"Unknown") -> 4.74e-06 | P7: 0 | Q7: 0 | R7: 0 | S7: =IF(COUNT('Turns'!D27,'Turns'!D42)=2,SUM('Turns'!D27,'Turns'!D42),"Unknown") -> 101 | T7: =IF(COUNT('Turns'!E27,'Turns'!E42)=2,SUM('Turns'!E27,'Turns'!E42),"Unknown") -> 0.00010662449 | U7: =IF(COUNT('Turns'!F27,'Turns'!F42)=2,SUM('Turns'!F27,'Turns'!F42),"Unknown") -> 0.0001212 | V7: 0 | W7: 0 | X7: 0 | Y7: =IF(COUNT('Turns'!E31,'Turns'!E46)=2,SUM('Turns'!E31,'Turns'!E46),"Unknown") -> 0.00014879922 | Z7: =IF(COUNT('Turns'!F31,'Turns'!F46)=2,SUM('Turns'!F31,'Turns'!F46),"Unknown") -> 0.00016914 | AA7: =IF(ISNUMBER(Y7),ROUND(Y7*'Reference data'!$B$2,0),"Unknown") -> 15 | AB7: =IF(ISNUMBER(Z7),ROUND(Z7*'Reference data'!$B$2,0),"Unknown") -> 17 | AD7: 9.098 | AE7: Subtree total
A8: model | B8: 4 | C8: workflow | E8: ok | G8: Prepare the current conversation, run model middleware, and invoke the chat model. | H8: 01a1143f-83a2-7f61-a440-1209bd5d888c | I8: 01a1143f-83a1-7520-8dc2-d4e9a12dc0c4 | J8: =IF(COUNT('Turns'!D21)=1,SUM('Turns'!D21),"Unknown") -> 180 | K8: =IF(COUNT('Turns'!E21)=1,SUM('Turns'!E21),"Unknown") -> 3.167064e-05 | L8: =IF(COUNT('Turns'!F21)=1,SUM('Turns'!F21),"Unknown") -> 3.6e-05 | M8: 0 | N8: 0 | O8: 0 | P8: 0 | Q8: 0 | R8: 0 | S8: =IF(COUNT('Turns'!D27)=1,SUM('Turns'!D27),"Unknown") -> 57 | T8: =IF(COUNT('Turns'!E27)=1,SUM('Turns'!E27),"Unknown") -> 6.0174216e-05 | U8: =IF(COUNT('Turns'!F27)=1,SUM('Turns'!F27),"Unknown") -> 6.84e-05 | V8: 0 | W8: 0 | X8: 0 | Y8: =IF(COUNT('Turns'!E31)=1,SUM('Turns'!E31),"Unknown") -> 9.1844856e-05 | Z8: =IF(COUNT('Turns'!F31)=1,SUM('Turns'!F31),"Unknown") -> 0.0001044 | AA8: =IF(ISNUMBER(Y8),ROUND(Y8*'Reference data'!$B$2,0),"Unknown") -> 9 | AB8: =IF(ISNUMBER(Z8),ROUND(Z8*'Reference data'!$B$2,0),"Unknown") -> 10 | AD8: 3.53 | AE8: Subtree total
A9: SimulatedModel | B9: 5 | C9: model | D9: scripted-chat | E9: ok | F9: 180 | G9: A parent agent delegates to a specialist. | H9: 01a1143f-83a3-7d82-b3d1-8b1bb7bad08e | I9: 01a1143f-83a2-7f61-a440-1209bd5d888c | J9: =IF(COUNT('Turns'!D21)=1,SUM('Turns'!D21),"Unknown") -> 180 | K9: =IF(COUNT('Turns'!E21)=1,SUM('Turns'!E21),"Unknown") -> 3.167064e-05 | L9: =IF(COUNT('Turns'!F21)=1,SUM('Turns'!F21),"Unknown") -> 3.6e-05 | M9: 0 | N9: 0 | O9: 0 | P9: 0 | Q9: 0 | R9: 0 | S9: =IF(COUNT('Turns'!D27)=1,SUM('Turns'!D27),"Unknown") -> 57 | T9: =IF(COUNT('Turns'!E27)=1,SUM('Turns'!E27),"Unknown") -> 6.0174216e-05 | U9: =IF(COUNT('Turns'!F27)=1,SUM('Turns'!F27),"Unknown") -> 6.84e-05 | V9: 0 | W9: 0 | X9: 0 | Y9: =IF(COUNT('Turns'!E31)=1,SUM('Turns'!E31),"Unknown") -> 9.1844856e-05 | Z9: =IF(COUNT('Turns'!F31)=1,SUM('Turns'!F31),"Unknown") -> 0.0001044 | AA9: =IF(ISNUMBER(Y9),ROUND(Y9*'Reference data'!$B$2,0),"Unknown") -> 9 | AB9: =IF(ISNUMBER(Z9),ROUND(Z9*'Reference data'!$B$2,0),"Unknown") -> 10 | AC9: R2 | AD9: 1.935 | AE9: Own call
A10: tools | B10: 4 | C10: workflow | E10: ok | G10: Execute tool calls requested by the preceding model response and return their observations. | H10: 01a1143f-83a6-75f1-9b66-69c65f85322e | I10: 01a1143f-83a1-7520-8dc2-d4e9a12dc0c4 | AD10: 1.283 | AE10: No model charge
A11: echo_tool | B11: 5 | C11: tool | E11: ok | G11: Return the provided text prefixed with "Your input was: ". | H11: 01a1143f-83a7-7720-bac4-bde63a0cdabd | I11: 01a1143f-83a6-75f1-9b66-69c65f85322e | AD11: 0.397 | AE11: No model charge
A12: model | B12: 4 | C12: workflow | E12: ok | G12: Prepare the current conversation, run model middleware, and invoke the chat model. | H12: 01a1143f-83a8-7422-b1b7-e3ddc0922340 | I12: 01a1143f-83a1-7520-8dc2-d4e9a12dc0c4 | J12: =IF(COUNT('Turns'!D37)=1,SUM('Turns'!D37),"Unknown") -> 36 | K12: =IF(COUNT('Turns'!E37)=1,SUM('Turns'!E37),"Unknown") -> 6.334128e-06 | L12: =IF(COUNT('Turns'!F37)=1,SUM('Turns'!F37),"Unknown") -> 7.2e-06 | M12: =IF(COUNT('Turns'!D36)=1,SUM('Turns'!D36),"Unknown") -> 237 | N12: =IF(COUNT('Turns'!E36)=1,SUM('Turns'!E36),"Unknown") -> 4.1699676e-06 | O12: =IF(COUNT('Turns'!F36)=1,SUM('Turns'!F36),"Unknown") -> 4.74e-06 | P12: 0 | Q12: 0 | R12: 0 | S12: =IF(COUNT('Turns'!D42)=1,SUM('Turns'!D42),"Unknown") -> 44 | T12: =IF(COUNT('Turns'!E42)=1,SUM('Turns'!E42),"Unknown") -> 4.6450272e-05 | U12: =IF(COUNT('Turns'!F42)=1,SUM('Turns'!F42),"Unknown") -> 5.28e-05 | V12: 0 | W12: 0 | X12: 0 | Y12: =IF(COUNT('Turns'!E46)=1,SUM('Turns'!E46),"Unknown") -> 5.6954368e-05 | Z12: =IF(COUNT('Turns'!F46)=1,SUM('Turns'!F46),"Unknown") -> 6.474e-05 | AA12: =IF(ISNUMBER(Y12),ROUND(Y12*'Reference data'!$B$2,0),"Unknown") -> 6 | AB12: =IF(ISNUMBER(Z12),ROUND(Z12*'Reference data'!$B$2,0),"Unknown") -> 6 | AD12: 2.028 | AE12: Subtree total
A13: SimulatedModel | B13: 5 | C13: model | D13: scripted-chat | E13: ok | F13: 273 | G13: A parent agent delegates to a specialist. | H13: 01a1143f-83a8-7422-b1b7-e3e23ebcb479 | I13: 01a1143f-83a8-7422-b1b7-e3ddc0922340 | J13: =IF(COUNT('Turns'!D37)=1,SUM('Turns'!D37),"Unknown") -> 36 | K13: =IF(COUNT('Turns'!E37)=1,SUM('Turns'!E37),"Unknown") -> 6.334128e-06 | L13: =IF(COUNT('Turns'!F37)=1,SUM('Turns'!F37),"Unknown") -> 7.2e-06 | M13: =IF(COUNT('Turns'!D36)=1,SUM('Turns'!D36),"Unknown") -> 237 | N13: =IF(COUNT('Turns'!E36)=1,SUM('Turns'!E36),"Unknown") -> 4.1699676e-06 | O13: =IF(COUNT('Turns'!F36)=1,SUM('Turns'!F36),"Unknown") -> 4.74e-06 | P13: 0 | Q13: 0 | R13: 0 | S13: =IF(COUNT('Turns'!D42)=1,SUM('Turns'!D42),"Unknown") -> 44 | T13: =IF(COUNT('Turns'!E42)=1,SUM('Turns'!E42),"Unknown") -> 4.6450272e-05 | U13: =IF(COUNT('Turns'!F42)=1,SUM('Turns'!F42),"Unknown") -> 5.28e-05 | V13: 0 | W13: 0 | X13: 0 | Y13: =IF(COUNT('Turns'!E46)=1,SUM('Turns'!E46),"Unknown") -> 5.6954368e-05 | Z13: =IF(COUNT('Turns'!F46)=1,SUM('Turns'!F46),"Unknown") -> 6.474e-05 | AA13: =IF(ISNUMBER(Y13),ROUND(Y13*'Reference data'!$B$2,0),"Unknown") -> 6 | AB13: =IF(ISNUMBER(Z13),ROUND(Z13*'Reference data'!$B$2,0),"Unknown") -> 6 | AC13: R3 | AD13: 1.239 | AE13: Own call
A14: model | B14: 1 | C14: workflow | E14: ok | G14: Prepare the current conversation, run model middleware, and invoke the chat model. | H14: 01a1143f-83ac-7cf1-a37c-455dddb17dd4 | I14: 01a1143f-831e-7141-818a-14f77faabd17 | J14: =IF(COUNT('Turns'!D49)=1,SUM('Turns'!D49),"Unknown") -> 47 | K14: =IF(COUNT('Turns'!E49)=1,SUM('Turns'!E49),"Unknown") -> 8.269556e-06 | L14: =IF(COUNT('Turns'!F49)=1,SUM('Turns'!F49),"Unknown") -> 9.4e-06 | M14: =IF(COUNT('Turns'!D48)=1,SUM('Turns'!D48),"Unknown") -> 543 | N14: =IF(COUNT('Turns'!E48)=1,SUM('Turns'!E48),"Unknown") -> 9.5539764e-06 | O14: =IF(COUNT('Turns'!F48)=1,SUM('Turns'!F48),"Unknown") -> 1.086e-05 | P14: 0 | Q14: 0 | R14: 0 | S14: =IF(COUNT('Turns'!D54)=1,SUM('Turns'!D54),"Unknown") -> 55 | T14: =IF(COUNT('Turns'!E54)=1,SUM('Turns'!E54),"Unknown") -> 5.806284e-05 | U14: =IF(COUNT('Turns'!F54)=1,SUM('Turns'!F54),"Unknown") -> 6.6e-05 | V14: 0 | W14: 0 | X14: 0 | Y14: =IF(COUNT('Turns'!E58)=1,SUM('Turns'!E58),"Unknown") -> 7.5886372e-05 | Z14: =IF(COUNT('Turns'!F58)=1,SUM('Turns'!F58),"Unknown") -> 8.626e-05 | AA14: =IF(ISNUMBER(Y14),ROUND(Y14*'Reference data'!$B$2,0),"Unknown") -> 8 | AB14: =IF(ISNUMBER(Z14),ROUND(Z14*'Reference data'!$B$2,0),"Unknown") -> 9 | AD14: 2.186 | AE14: Subtree total
A15: SimulatedModel | B15: 2 | C15: model | D15: scripted-chat | E15: ok | F15: 590 | G15: A parent agent delegates to a specialist. | H15: 01a1143f-83ac-7cf1-a37c-45609fd63031 | I15: 01a1143f-83ac-7cf1-a37c-455dddb17dd4 | J15: =IF(COUNT('Turns'!D49)=1,SUM('Turns'!D49),"Unknown") -> 47 | K15: =IF(COUNT('Turns'!E49)=1,SUM('Turns'!E49),"Unknown") -> 8.269556e-06 | L15: =IF(COUNT('Turns'!F49)=1,SUM('Turns'!F49),"Unknown") -> 9.4e-06 | M15: =IF(COUNT('Turns'!D48)=1,SUM('Turns'!D48),"Unknown") -> 543 | N15: =IF(COUNT('Turns'!E48)=1,SUM('Turns'!E48),"Unknown") -> 9.5539764e-06 | O15: =IF(COUNT('Turns'!F48)=1,SUM('Turns'!F48),"Unknown") -> 1.086e-05 | P15: 0 | Q15: 0 | R15: 0 | S15: =IF(COUNT('Turns'!D54)=1,SUM('Turns'!D54),"Unknown") -> 55 | T15: =IF(COUNT('Turns'!E54)=1,SUM('Turns'!E54),"Unknown") -> 5.806284e-05 | U15: =IF(COUNT('Turns'!F54)=1,SUM('Turns'!F54),"Unknown") -> 6.6e-05 | V15: 0 | W15: 0 | X15: 0 | Y15: =IF(COUNT('Turns'!E58)=1,SUM('Turns'!E58),"Unknown") -> 7.5886372e-05 | Z15: =IF(COUNT('Turns'!F58)=1,SUM('Turns'!F58),"Unknown") -> 8.626e-05 | AA15: =IF(ISNUMBER(Y15),ROUND(Y15*'Reference data'!$B$2,0),"Unknown") -> 8 | AB15: =IF(ISNUMBER(Z15),ROUND(Z15*'Reference data'!$B$2,0),"Unknown") -> 9 | AC15: R4 | AD15: 1.28 | AE15: Own call

Sheet Reference data
A1: Parameter | B1: Value | C1: Unit
A2: Number of executions | B2: 100000 | C2: executions
A3: USD → EUR | B3: 0.87974 | C3: EUR per USD
A4: Cache duration | B4: 5m
A5: Run ID | B5: 01a1143f-831e-7141-818a-14f77faabd17
A6: Recording | B6: Offline simulation
A7: FX reference date | B7: 2026-09-24
A8: FX fetched at | B8: 2026-09-24T22:21:31.719587Z | C8: UTC
A9: FX source | B9: https://api.frankfurter.dev/v2/rate/usd/eur?providers=ecb
A10: Rounding | B10: Only projected costs: ROUND(cost × executions, 0)
A11: Tree totals | B11: Parent rows include descendants; do not sum all tree rows.
A12: Cache writes | B12: Simulated context movement is not a provider-billed write.
A13: Pricing scope | B13: Published online token rates verified 2026-10-05. Copilot uses GitHub rates, including saved long-context tiers, before plan allowances; these are usage estimates, not subscription invoices. Cache writes with unspecified lifetime use the 5-minute rate unless an explicit cache_write rate is configured. Direct OpenAI and Anthropic entries use standard rates; no batch, regional, tool, negotiated, or unrecorded context-tier adjustments are applied. Model availability and context capacity require separate verification.
A15: Model | B15: Input USD / 1M tokens | C15: Cache read USD / 1M tokens | D15: Cache write USD / 1M tokens | E15: Output USD / 1M tokens | F15: Reasoning USD / 1M tokens | G15: Verified date | H15: Source | I15: Notes
A16: openai:gpt-5.5 | B16: 5 | C16: 0.5 | D16: Unknown | E16: 30 | F16: 30 | G16: 2026-10-05 | H16: https://developers.openai.com/api/docs/models/gpt-5.5.md | I16: Cache write assumes 5m when unspecified
A17: openai:gpt-5.6-luna | B17: 0.2 | C17: 0.02 | D17: 0.25 | E17: 1.2 | F17: 1.2 | G17: 2026-10-05 | H17: https://developers.openai.com/api/docs/models/gpt-5.6-luna.md | I17: Cache write assumes 5m when unspecified
A18: openai:gpt-5.6-sol | B18: 4 | C18: 0.4 | D18: 5 | E18: 20 | F18: 20 | G18: 2026-10-05 | H18: https://developers.openai.com/api/docs/models/gpt-5.6-sol.md | I18: Cache write assumes 5m when unspecified
A19: anthropic:claude-sonnet-5 | B19: 2 | C19: 0.2 | D19: 2.5 | E19: 10 | F19: 10 | G19: 2026-10-05 | H19: https://platform.claude.com/docs/en/about-claude/pricing | I19: Cache write assumes 5m when unspecified
A20: anthropic:claude-opus-4-8 | B20: 5 | C20: 0.5 | D20: 6.25 | E20: 25 | F20: 25 | G20: 2026-10-05 | H20: https://platform.claude.com/docs/en/about-claude/pricing | I20: Cache write assumes 5m when unspecified
A21: anthropic:claude-fable-5-1 | B21: 10 | C21: 0.25 | D21: 12.5 | E21: 50 | F21: 50 | G21: 2026-10-05 | H21: https://platform.claude.com/docs/en/about-claude/pricing | I21: Cache write assumes 5m when unspecified
A22: demo:scripted-chat | B22: 0.2 | C22: 0.02 | D22: 0.25 | E22: 1.2 | F22: 1.2 | G22: 2026-10-05 | H22: Illustrative demo rates based on openai:gpt-5.6-luna; no provider billing | I22: Cache write assumes 5m when unspecified
A23: anthropic:claude-haiku-4-5 | B23: 1 | C23: 0.1 | D23: 1.25 | E23: 5 | F23: 5 | G23: 2026-10-05 | H23: https://platform.claude.com/docs/en/about-claude/pricing | I23: Cache write assumes 5m when unspecified
A24: anthropic:claude-haiku-4-5-20251001 | B24: 1 | C24: 0.1 | D24: 1.25 | E24: 5 | F24: 5 | G24: 2026-10-05 | H24: https://platform.claude.com/docs/en/about-claude/pricing | I24: Cache write assumes 5m when unspecified
A25: anthropic:claude-opus-5-5 | B25: 4 | C25: 0.2 | D25: 5 | E25: 20 | F25: 20 | G25: 2026-10-05 | H25: https://platform.claude.com/docs/en/about-claude/pricing | I25: Cache write assumes 5m when unspecified
A26: anthropic:claude-sonnet-4-6 | B26: 3 | C26: 0.3 | D26: 3.75 | E26: 15 | F26: 15 | G26: 2026-10-05 | H26: https://platform.claude.com/docs/en/about-claude/pricing | I26: Cache write assumes 5m when unspecified
A27: anthropic:claude-sonnet-5-5 | B27: 2 | C27: 0.2 | D27: 2.5 | E27: 10 | F27: 10 | G27: 2026-10-05 | H27: https://platform.claude.com/docs/en/about-claude/pricing | I27: Cache write assumes 5m when unspecified
A28: copilot:claude-haiku-4.5 | B28: 1 | C28: 0.1 | D28: 1.25 | E28: 5 | F28: 5 | G28: 2026-10-05 | H28: https://docs.github.com/en/copilot/reference/copilot-billing/models-and-pricing | I28: Cache write assumes 5m when unspecified
... A31: copilot:claude-sonnet-5.5 | B31: 2 | C31: 0.2 | D31: 2.5 | E31: 10 | F31: 10 | G31: 2026-10-05 | H31: https://docs.github.com/en/copilot/reference/copilot-billing/models-and-pricing | I31: Cache write assumes 5m when unspecified
A32: copilot:gemini-3.8-flash | B32: 0.75 | C32: 0.075 | D32: Unknown | E32: 3.75 | F32: 3.75 | G32: 2026-10-05 | H32: https://docs.github.com/en/copilot/reference/copilot-billing/models-and-pricing | I32: Cache write assumes 5m when unspecified
A33: copilot:gpt-5.3-codex | B33: 1.75 | C33: 0.175 | D33: Unknown | E33: 14 | F33: 14 | G33: 2026-10-05 | H33: https://docs.github.com/en/copilot/reference/copilot-billing/models-and-pricing | I33: Cache write assumes 5m when unspecified
A34: copilot:gpt-5.4 | B34: 2.5 | C34: 0.25 | D34: Unknown | E34: 15 | F34: 15 | G34: 2026-10-05 | H34: https://docs.github.com/en/copilot/reference/copilot-billing/models-and-pricing | I34: Cache write assumes 5m when unspecified
A35: copilot:gpt-6-astra | B35: 10 | C35: 1 | D35: 12.5 | E35: 50 | F35: 50 | G35: 2026-10-05 | H35: https://docs.github.com/en/copilot/reference/copilot-billing/models-and-pricing | I35: Cache write assumes 5m when unspecified
A36: copilot:gpt-6-luna | B36: 0.1 | C36: 0.01 | D36: 0.125 | E36: 0.5 | F36: 0.5 | G36: 2026-10-05 | H36: https://docs.github.com/en/copilot/reference/copilot-billing/models-and-pricing | I36: Cache write assumes 5m when unspecified
A37: copilot:gpt-6-sol | B37: 2 | C37: 0.2 | D37: 2.5 | E37: 10 | F37: 10 | G37: 2026-10-05 | H37: https://docs.github.com/en/copilot/reference/copilot-billing/models-and-pricing | I37: Cache write assumes 5m when unspecified
A38: copilot:gpt-6.1-sol | B38: 2 | C38: 0.1 | D38: 2.5 | E38: 10 | F38: 10 | G38: 2026-10-05 | H38: https://docs.github.com/en/copilot/reference/copilot-billing/models-and-pricing | I38: Cache write assumes 5m when unspecified
A39: openai:gpt-6-astra | B39: 10 | C39: 1 | D39: 12.5 | E39: 50 | F39: 50 | G39: 2026-10-05 | H39: https://developers.openai.com/api/docs/models/gpt-6-astra.md | I39: Cache write assumes 5m when unspecified
A40: openai:gpt-6-luna | B40: 0.1 | C40: 0.01 | D40: 0.125 | E40: 0.5 | F40: 0.5 | G40: 2026-10-05 | H40: https://developers.openai.com/api/docs/models/gpt-6-luna.md | I40: Cache write assumes 5m when unspecified
A41: openai:gpt-6-sol | B41: 2 | C41: 0.2 | D41: 2.5 | E41: 10 | F41: 10 | G41: 2026-10-05 | H41: https://developers.openai.com/api/docs/models/gpt-6-sol.md | I41: Cache write assumes 5m when unspecified
A42: openai:gpt-6.1-sol | B42: 2 | C42: 0.1 | D42: 2.5 | E42: 10 | F42: 10 | G42: 2026-10-05 | H42: https://developers.openai.com/api/docs/models/gpt-6.1-sol.md | I42: Cache write assumes 5m when unspecified
A43: copilot:gpt-5.4 [long context] | B43: 5 | C43: 0.5 | D43: Unknown | E43: 22.5 | F43: 22.5 | G43: 2026-10-05 | H43: https://docs.github.com/en/copilot/reference/copilot-billing/models-and-pricing | I43: Above 272,000 input tokens
...
